Workbook

Sheet CoverPage
A1: 3D BioOptima Quality That Matters
A2: 实验报告
A3: 实验标题 | B3: HW356009-P1在PBS（pH 7.4）、FaSSGF（pH 1.6）和FaSSIF（pH 6.5）中的热力学溶解度测定
A4: 实验方案编号 | B4: 3D_PN322880
A5: 课题编号 | B5: 3D_SN322438
A6: 课题负责人 | B6: 杨德孝
A7: 化合物 | B7: HW356009-P1
A8: 实验开始时间 | B8: 2025 年09月03日
A9: 实验结束时间 | B9: 2025 年09月05日
A10: 实验参与人员 | B10: 韩晓逸和蔡鑫鑫
A11: 报告撰写 | B11: 卜乐亮
A12: 数据质控 | B12: 程翠
A13: 实验负责方 | B13: 苏州圣苏新药开发有限公司 中国苏州市吴中区吴中大道1338号
A14: 实验委托方 | B14: 湖北生物医药产业技术研究院有限公司 武汉市东湖高新区高新大道666号C7栋217室

Sheet Summary
B2: 试剂信息
B3: 试剂 | C3: 品牌 | D3: 货号 | E3: 批号
B4: HW356009-P1 | C4: 湖北生物医药产业技术研究院有限公司 | D4: NA | E4: HWH817-YBC-035-4-54-2
B8: 汇总
B9: 受试化合物 | C9: PH | D9: 溶解度 (μg/mL)
B10: =B4 -> HW356009-P1 | C10: PBS (PH=7.4) | D10: ='Solubility Determination'!E4 -> 4.035
C11: FaSSIF (PH=6.5) | D11: ='Solubility Determination'!E5 -> 4.775
C12: FaSSGF (PH=1.6) | D12: ='Solubility Determination'!E6 -> 4.815

Sheet Solubility Determination
B1: LC-MS
B2: 溶解度测定
B3: 受试化合物 | C3: PH | D3: 计算浓度 (ng/mL) | E3: 浓度 (μg/mL)
B4: =CONCATENATE(Summary!B4,"_Solubility") -> HW356009-P1_Solubility | C4: PBS (PH=7.4) | D4: =Calculation!H17 -> 4035 | E4: =D4/1000 -> 4.035
C5: FaSSIF (PH=6.5) | D5: =Calculation!H23 -> 4775 | E5: =D5/1000 -> 4.775
C6: FaSSGF (PH=1.6) | D6: =Calculation!H29 -> 4815 | E6: =D6/1000 -> 4.815

Sheet Calculation
B2: =Summary!B$4 -> HW356009-P1
B3: =CONCATENATE("Calibration Curve and QC-",Summary!B4) -> Calibration Curve and QC-HW356009-P1
B4: Sample Name | C4: Specified Conc (ng/mL) | D4: Response | E4: ISTD Response | F4: Response Ratio | G4: Conc. (ng/mL) | H4: % RE
B5: HW356009-P1_Solubility_10ng/mL | C5: =VLOOKUP($B5,'Raw Data'!$A$1:$Q$301,3,0) -> 10 | D5: =VLOOKUP($B5,'Raw Data'!$A$1:$Q$301,5,0) -> 220000 | E5: =VLOOKUP($B5,'Raw Data'!$A$1:$Q$301,6,0) -> 2300000 | F5: =IF(VLOOKUP($B5,'Raw Data'!$A$1:$Q$301,7,0)<0,0,VLOOKUP($B5,'Raw Data'!$A$1:$Q$301,7,0)) -> 0.0956 | G5: =IF(OR(VLOOKUP($B5,'Raw Data'!$A$1:$Q$301,10,0)="N/A",VLOOKUP($B5,'Raw Data'!$A$1:$Q$301,10,0)="NA"),"NA",VLOOKUP($B5,'Raw Data'!$A$1:$Q$301,10,0)) -> 9.85 | H5: =IF(VLOOKUP($B5,'Raw Data'!$A$1:$Q$301,11,0)="N/A","NA",VLOOKUP($B5,'Raw Data'!$A$1:$Q$301,11,0))-100 -> -1.5
B6: HW356009-P1_Solubility_20ng/mL | C6: =VLOOKUP($B6,'Raw Data'!$A$1:$Q$301,3,0) -> 20 | D6: =VLOOKUP($B6,'Raw Data'!$A$1:$Q$301,5,0) -> 445000 | E6: =VLOOKUP($B6,'Raw Data'!$A$1:$Q$301,6,0) -> 2320000 | F6: =IF(VLOOKUP($B6,'Raw Data'!$A$1:$Q$301,7,0)<0,0,VLOOKUP($B6,'Raw Data'!$A$1:$Q$301,7,0)) -> 0.192 | G6: =IF(OR(VLOOKUP($B6,'Raw Data'!$A$1:$Q$301,10,0)="N/A",VLOOKUP($B6,'Raw Data'!$A$1:$Q$301,10,0)="NA"),"NA",VLOOKUP($B6,'Raw Data'!$A$1:$Q$301,10,0)) -> 20.1 | H6: =IF(VLOOKUP($B6,'Raw Data'!$A$1:$Q$301,11,0)="N/A","NA",VLOOKUP($B6,'Raw Data'!$A$1:$Q$301,11,0))-100 -> 0.5
B7: HW356009-P1_Solubility_50ng/mL | C7: =VLOOKUP($B7,'Raw Data'!$A$1:$Q$301,3,0) -> 50 | D7: =VLOOKUP($B7,'Raw Data'!$A$1:$Q$301,5,0) -> 1120000 | E7: =VLOOKUP($B7,'Raw Data'!$A$1:$Q$301,6,0) -> 2290000 | F7: =IF(VLOOKUP($B7,'Raw Data'!$A$1:$Q$301,7,0)<0,0,VLOOKUP($B7,'Raw Data'!$A$1:$Q$301,7,0)) -> 0.49 | G7: =IF(OR(VLOOKUP($B7,'Raw Data'!$A$1:$Q$301,10,0)="N/A",VLOOKUP($B7,'Raw Data'!$A$1:$Q$301,10,0)="NA"),"NA",VLOOKUP($B7,'Raw Data'!$A$1:$Q$301,10,0)) -> 51.9 | H7: =IF(VLOOKUP($B7,'Raw Data'!$A$1:$Q$301,11,0)="N/A","NA",VLOOKUP($B7,'Raw Data'!$A$1:$Q$301,11,0))-100 -> 3.8
B8: HW356009-P1_Solubility_100ng/mL | C8: =VLOOKUP($B8,'Raw Data'!$A$1:$Q$301,3,0) -> 100 | D8: =VLOOKUP($B8,'Raw Data'!$A$1:$Q$301,5,0) -> 2090000 | E8: =VLOOKUP($B8,'Raw Data'!$A$1:$Q$301,6,0) -> 2250000 | F8: =IF(VLOOKUP($B8,'Raw Data'!$A$1:$Q$301,7,0)<0,0,VLOOKUP($B8,'Raw Data'!$A$1:$Q$301,7,0)) -> 0.928 | G8: =IF(OR(VLOOKUP($B8,'Raw Data'!$A$1:$Q$301,10,0)="N/A",VLOOKUP($B8,'Raw Data'!$A$1:$Q$301,10,0)="NA"),"NA",VLOOKUP($B8,'Raw Data'!$A$1:$Q$301,10,0)) -> 98.6 | H8: =IF(VLOOKUP($B8,'Raw Data'!$A$1:$Q$301,11,0)="N/A","NA",VLOOKUP($B8,'Raw Data'!$A$1:$Q$301,11,0))-100 -> -1.4
B9: HW356009-P1_Solubility_200ng/mL | C9: =VLOOKUP($B9,'Raw Data'!$A$1:$Q$301,3,0) -> 200 | D9: =VLOOKUP($B9,'Raw Data'!$A$1:$Q$301,5,0) -> 4730000 | E9: =VLOOKUP($B9,'Raw Data'!$A$1:$Q$301,6,0) -> 2250000 | F9: =IF(VLOOKUP($B9,'Raw Data'!$A$1:$Q$301,7,0)<0,0,VLOOKUP($B9,'Raw Data'!$A$1:$Q$301,7,0)) -> 2.1 | G9: =IF(OR(VLOOKUP($B9,'Raw Data'!$A$1:$Q$301,10,0)="N/A",VLOOKUP($B9,'Raw Data'!$A$1:$Q$301,10,0)="NA"),"NA",VLOOKUP($B9,'Raw Data'!$A$1:$Q$301,10,0)) -> 224 | H9: =IF(VLOOKUP($B9,'Raw Data'!$A$1:$Q$301,11,0)="N/A","NA",VLOOKUP($B9,'Raw Data'!$A$1:$Q$301,11,0))-100 -> 12
B10: HW356009-P1_Solubility_500ng/mL | C10: =VLOOKUP($B10,'Raw Data'!$A$1:$Q$301,3,0) -> 500 | D10: =VLOOKUP($B10,'Raw Data'!$A$1:$Q$301,5,0) -> 11500000 | E10: =VLOOKUP($B10,'Raw Data'!$A$1:$Q$301,6,0) -> 2290000 | F10: =IF(VLOOKUP($B10,'Raw Data'!$A$1:$Q$301,7,0)<0,0,VLOOKUP($B10,'Raw Data'!$A$1:$Q$301,7,0)) -> 5.03 | G10: =IF(OR(VLOOKUP($B10,'Raw Data'!$A$1:$Q$301,10,0)="N/A",VLOOKUP($B10,'Raw Data'!$A$1:$Q$301,10,0)="NA"),"NA",VLOOKUP($B10,'Raw Data'!$A$1:$Q$301,10,0)) -> 536 | H10: =IF(VLOOKUP($B10,'Raw Data'!$A$1:$Q$301,11,0)="N/A","NA",VLOOKUP($B10,'Raw Data'!$A$1:$Q$301,11,0))-100 -> 7.3
B11: HW356009-P1_Solubility_1000ng/mL | C11: =VLOOKUP($B11,'Raw Data'!$A$1:$Q$301,3,0) -> 1000 | D11: =VLOOKUP($B11,'Raw Data'!$A$1:$Q$301,5,0) -> 20300000 | E11: =VLOOKUP($B11,'Raw Data'!$A$1:$Q$301,6,0) -> 2290000 | F11: =IF(VLOOKUP($B11,'Raw Data'!$A$1:$Q$301,7,0)<0,0,VLOOKUP($B11,'Raw Data'!$A$1:$Q$301,7,0)) -> 8.87 | G11: =IF(OR(VLOOKUP($B11,'Raw Data'!$A$1:$Q$301,10,0)="N/A",VLOOKUP($B11,'Raw Data'!$A$1:$Q$301,10,0)="NA"),"NA",VLOOKUP($B11,'Raw Data'!$A$1:$Q$301,10,0)) -> 945 | H11: =IF(VLOOKUP($B11,'Raw Data'!$A$1:$Q$301,11,0)="N/A","NA",VLOOKUP($B11,'Raw Data'!$A$1:$Q$301,11,0))-100 -> -5.5
B12: HW356009-P1_Solubility_2000ng/mL | C12: =VLOOKUP($B12,'Raw Data'!$A$1:$Q$301,3,0) -> 2000 | D12: =VLOOKUP($B12,'Raw Data'!$A$1:$Q$301,5,0) -> 34700000 | E12: =VLOOKUP($B12,'Raw Data'!$A$1:$Q$301,6,0) -> 2180000 | F12: =IF(VLOOKUP($B12,'Raw Data'!$A$1:$Q$301,7,0)<0,0,VLOOKUP($B12,'Raw Data'!$A$1:$Q$301,7,0)) -> 15.9 | G12: =IF(OR(VLOOKUP($B12,'Raw Data'!$A$1:$Q$301,10,0)="N/A",VLOOKUP($B12,'Raw Data'!$A$1:$Q$301,10,0)="NA"),"NA",VLOOKUP($B12,'Raw Data'!$A$1:$Q$301,10,0)) -> 1690 | H12: =IF(VLOOKUP($B12,'Raw Data'!$A$1:$Q$301,11,0)="N/A","NA",VLOOKUP($B12,'Raw Data'!$A$1:$Q$301,11,0))-100 -> -15.3
B15: PBS (PH=7.4)
B16: Sample Name | C16: Dil Factor | D16: Response | E16: ISTD Response | F16: Response Ratio | G16: Conc. (ng/mL) | H16: Mean Conc. (ng/mL)
B17: HW356009-P1_PBS_2mg/mL_DL50-1 | C17: =VLOOKUP($B17,'Raw Data'!$A$2:$Q$442,4,0) -> 50 | D17: =VLOOKUP($B17,'Raw Data'!$A$2:$Q$442,5,0) -> 1800000 | E17: =VLOOKUP($B17,'Raw Data'!$A$2:$Q$442,6,0) -> 2310000 | F17: =IF(VLOOKUP($B17,'Raw Data'!$A$2:$Q$442,7,0)<0,0,VLOOKUP($B17,'Raw Data'!$A$2:$Q$442,7,0)) -> 0.778 | G17: =IF(OR(VLOOKUP($B17,'Raw Data'!$A$2:$Q$442,10,0)="N/A",VLOOKUP($B17,'Raw Data'!$A$2:$Q$442,10,0)="NA"),"NA",VLOOKUP($B17,'Raw Data'!$A$2:$Q$442,10,0)) -> 4130 | H17: =AVERAGE(G17:G18) -> 4035
B18: HW356009-P1_PBS_2mg/mL_DL50-2 | C18: =VLOOKUP($B18,'Raw Data'!$A$2:$Q$442,4,0) -> 50 | D18: =VLOOKUP($B18,'Raw Data'!$A$2:$Q$442,5,0) -> 1720000 | E18: =VLOOKUP($B18,'Raw Data'!$A$2:$Q$442,6,0) -> 2320000 | F18: =IF(VLOOKUP($B18,'Raw Data'!$A$2:$Q$442,7,0)<0,0,VLOOKUP($B18,'Raw Data'!$A$2:$Q$442,7,0)) -> 0.742 | G18: =IF(OR(VLOOKUP($B18,'Raw Data'!$A$2:$Q$442,10,0)="N/A",VLOOKUP($B18,'Raw Data'!$A$2:$Q$442,10,0)="NA"),"NA",VLOOKUP($B18,'Raw Data'!$A$2:$Q$442,10,0)) -> 3940
B21: FaSSIF (PH=6.5)
B22: Sample Name | C22: Dil Factor | D22: Response | E22: ISTD Response | F22: Response Ratio | G22: Conc. (ng/mL) | H22: Mean Conc. (ng/mL)
B23: HW356009-P1_FaSSIF_2mg/mL_DL50-1 | C23: =VLOOKUP($B23,'Raw Data'!$A$2:$Q$442,4,0) -> 50 | D23: =VLOOKUP($B23,'Raw Data'!$A$2:$Q$442,5,0) -> 2170000 | E23: =VLOOKUP($B23,'Raw Data'!$A$2:$Q$442,6,0) -> 2360000 | F23: =IF(VLOOKUP($B23,'Raw Data'!$A$2:$Q$442,7,0)<0,0,VLOOKUP($B23,'Raw Data'!$A$2:$Q$442,7,0)) -> 0.917 | G23: =IF(OR(VLOOKUP($B23,'Raw Data'!$A$2:$Q$442,10,0)="N/A",VLOOKUP($B23,'Raw Data'!$A$2:$Q$442,10,0)="NA"),"NA",VLOOKUP($B23,'Raw Data'!$A$2:$Q$442,10,0)) -> 4870 | H23: =AVERAGE(G23:G24) -> 4775
B24: HW356009-P1_FaSSIF_2mg/mL_DL50-2 | C24: =VLOOKUP($B24,'Raw Data'!$A$2:$Q$442,4,0) -> 50 | D24: =VLOOKUP($B24,'Raw Data'!$A$2:$Q$442,5,0) -> 2100000 | E24: =VLOOKUP($B24,'Raw Data'!$A$2:$Q$442,6,0) -> 2380000 | F24: =IF(VLOOKUP($B24,'Raw Data'!$A$2:$Q$442,7,0)<0,0,VLOOKUP($B24,'Raw Data'!$A$2:$Q$442,7,0)) -> 0.882 | G24: =IF(OR(VLOOKUP($B24,'Raw Data'!$A$2:$Q$442,10,0)="N/A",VLOOKUP($B24,'Raw Data'!$A$2:$Q$442,10,0)="NA"),"NA",VLOOKUP($B24,'Raw Data'!$A$2:$Q$442,10,0)) -> 4680
B27: FaSSGF (PH=1.6)
B28: Sample Name | C28: Dil Factor | D28: Response | E28: ISTD Response | F28: Response Ratio | G28: Conc. (ng/mL) | H28: Mean Conc. (ng/mL)
B29: HW356009-P1_FaSSGF_2mg/mL_DL50-1 | C29: =VLOOKUP($B29,'Raw Data'!$A$2:$Q$442,4,0) -> 50 | D29: =VLOOKUP($B29,'Raw Data'!$A$2:$Q$442,5,0) -> 2140000 | E29: =VLOOKUP($B29,'Raw Data'!$A$2:$Q$442,6,0) -> 2300000 | F29: =IF(VLOOKUP($B29,'Raw Data'!$A$2:$Q$442,7,0)<0,0,VLOOKUP($B29,'Raw Data'!$A$2:$Q$442,7,0)) -> 0.932 | G29: =IF(OR(VLOOKUP($B29,'Raw Data'!$A$2:$Q$442,10,0)="N/A",VLOOKUP($B29,'Raw Data'!$A$2:$Q$442,10,0)="NA"),"NA",VLOOKUP($B29,'Raw Data'!$A$2:$Q$442,10,0)) -> 4950 | H29: =AVERAGE(G29:G30) -> 4815
B30: HW356009-P1_FaSSGF_2mg/mL_DL50-2 | C30: =VLOOKUP($B30,'Raw Data'!$A$2:$Q$442,4,0) -> 50 | D30: =VLOOKUP($B30,'Raw Data'!$A$2:$Q$442,5,0) -> 2040000 | E30: =VLOOKUP($B30,'Raw Data'!$A$2:$Q$442,6,0) -> 2310000 | F30: =IF(VLOOKUP($B30,'Raw Data'!$A$2:$Q$442,7,0)<0,0,VLOOKUP($B30,'Raw Data'!$A$2:$Q$442,7,0)) -> 0.88 | G30: =IF(OR(VLOOKUP($B30,'Raw Data'!$A$2:$Q$442,10,0)="N/A",VLOOKUP($B30,'Raw Data'!$A$2:$Q$442,10,0)="NA"),"NA",VLOOKUP($B30,'Raw Data'!$A$2:$Q$442,10,0)) -> 4680

Sheet Raw Data
A1: =Summary!B$4 -> HW356009-P1
A2: Peak Name: GLBN
A3: Use as Internal Standard
A4: Q1/Q3 Masses: 494.20/169.10 Da
A5: Peak Name: VERA
A6: Use as Internal Standard
A7: Q1/Q3 Masses: 455.20/165.10 Da
A9: Peak Name: HW356009-P1-Ver
A10: Internal Standard: VERA
A11: Q1/Q3 Masses: 604.30/411.10 Da
A13: Fit | B13: Linear | C13: Weighting | D13: 1 / (x * x) | E13: Iterate | F13: No
A14: Intercept | B14: 0.0032
A15: Slope | B15: 0.00938
A16: Correlation coefficient | B16: 0.9955
A17: Use Area
A19: Peak Name: HW356009-P1-Gli
A20: Internal Standard: GLBN
A21: Q1/Q3 Masses: 604.30/411.10 Da
A23: Fit | B23: Linear | C23: Weighting | D23: 1 / (x * x) | E23: Iterate | F23: No
A24: Error | B24: Can't calculate regression because the system of equations is degenerate.
A25: Use Area
A29: Sample Name | B29: Sample Type | C29: Analyte Concentration (ng/mL) | D29: Dilution Factor | E29: Analyte Peak Area (counts) | F29: IS Peak Area (counts) | G29: Area Ratio | H29: Use Record | I29: Record Modified | J29: Calculated Concentration (ng/mL) | K29: Accuracy (%) | L29: Vial Position | M29: Plate Position | N29: Acquisition Date
A30: Wash | B30: Unknown | C30: N/A | D30: 1 | E30: 0 | F30: 0 | G30: #DIV/0! | I30: 0 | J30: #DIV/0! | K30: N/A | L30: 20001 | M30: 1 | N30: 9/5/2025 4:29:18 AM
A31: Wash | B31: Unknown | C31: N/A | D31: 1 | E31: 0 | F31: 0 | G31: #DIV/0! | I31: 0 | J31: #DIV/0! | K31: N/A | L31: 20001 | M31: 1 | N31: 9/5/2025 4:32:43 AM
A32: HW356009-P1_Solubility_10ng/mL | B32: Standard | C32: 10 | D32: 1 | E32: 220000 | F32: 2300000 | G32: 0.0956 | H32: 1 | I32: 0 | J32: 9.85 | K32: 98.5 | L32: 31 | M32: 5 | N32: 9/5/2025 4:36:05 AM
A33: HW356009-P1_Solubility_20ng/mL | B33: Standard | C33: 20 | D33: 1 | E33: 445000 | F33: 2320000 | G33: 0.192 | H33: 1 | I33: 0 | J33: 20.1 | K33: 100.5 | L33: 32 | M33: 5 | N33: 9/5/2025 4:39:27 AM
A34: HW356009-P1_Solubility_50ng/mL | B34: Standard | C34: 50 | D34: 1 | E34: 1120000 | F34: 2290000 | G34: 0.49 | H34: 1 | I34: 0 | J34: 51.9 | K34: 103.8 | L34: 33 | M34: 5 | N34: 9/5/2025 4:42:50 AM
A35: HW356009-P1_Solubility_100ng/mL | B35: Standard | C35: 100 | D35: 1 | E35: 2090000 | F35: 2250000 | G35: 0.928 | H35: 1 | I35: 0 | J35: 98.6 | K35: 98.6 | L35: 34 | M35: 5 | N35: 9/5/2025 4:46:13 AM
A36: HW356009-P1_Solubility_200ng/mL | B36: Standard | C36: 200 | D36: 1 | E36: 4730000 | F36: 2250000 | G36: 2.1 | H36: 1 | I36: 0 | J36: 224 | K36: 112 | L36: 35 | M36: 5 | N36: 9/5/2025 4:49:33 AM
A37: HW356009-P1_Solubility_500ng/mL | B37: Standard | C37: 500 | D37: 1 | E37: 11500000 | F37: 2290000 | G37: 5.03 | H37: 1 | I37: 0 | J37: 536 | K37: 107.3 | L37: 36 | M37: 5 | N37: 9/5/2025 4:52:57 AM
A38: HW356009-P1_Solubility_1000ng/mL | B38: Standard | C38: 1000 | D38: 1 | E38: 20300000 | F38: 2290000 | G38: 8.87 | H38: 1 | I38: 0 | J38: 945 | K38: 94.5 | L38: 57 | M38: 5 | N38: 9/5/2025 4:56:19 AM
A39: HW356009-P1_Solubility_2000ng/mL | B39: Standard | C39: 2000 | D39: 1 | E39: 34700000 | F39: 2180000 | G39: 15.9 | H39: 1 | I39: 0 | J39: 1690 | K39: 84.7 | L39: 58 | M39: 5 | N39: 9/5/2025 4:59:39 AM
A40: Wash | B40: Unknown | C40: N/A | D40: 1 | E40: 16000 | F40: 0 | G40: #DIV/0! | I40: 0 | J40: #DIV/0! | K40: N/A | L40: 20001 | M40: 1 | N40: 9/5/2025 5:03:03 AM
A41: Wash | B41: Unknown | C41: N/A | D41: 1 | E41: 3390 | F41: 0 | G41: #DIV/0! | I41: 0 | J41: #DIV/0! | K41: N/A | L41: 20001 | M41: 1 | N41: 9/5/2025 5:06:25 AM
A42: HW356009-P1_PBS_2mg/mL_DL50-1 | B42: Unknown | C42: N/A | D42: 50 | E42: 1800000 | F42: 2310000 | G42: 0.778 | I42: 0 | J42: 4130 | K42: N/A | L42: 91 | M42: 6 | N42: 9/5/2025 5:09:47 AM
A43: HW356009-P1_PBS_2mg/mL_DL50-2 | B43: Unknown | C43: N/A | D43: 50 | E43: 1720000 | F43: 2320000 | G43: 0.742 | I43: 0 | J43: 3940 | K43: N/A | L43: 92 | M43: 6 | N43: 9/5/2025 5:13:11 AM
A44: Wash | B44: Unknown | C44: N/A | D44: 1 | E44: 1350 | F44: 0 | G44: #DIV/0! | I44: 0 | J44: #DIV/0! | K44: N/A | L44: 20001 | M44: 1 | N44: 9/5/2025 5:16:34 AM
A45: Wash | B45: Unknown | C45: N/A | D45: 1 | E45: 465 | F45: 0 | G45: #DIV/0! | I45: 0 | J45: #DIV/0! | K45: N/A | L45: 20001 | M45: 1 | N45: 9/5/2025 5:19:56 AM
A46: HW356009-P1_FaSSIF_2mg/mL_DL50-1 | B46: Unknown | C46: N/A | D46: 50 | E46: 2170000 | F46: 2360000 | G46: 0.917 | I46: 0 | J46: 4870 | K46: N/A | L46: 93 | M46: 6 | N46: 9/5/2025 5:23:19 AM
A47: HW356009-P1_FaSSIF_2mg/mL_DL50-2 | B47: Unknown | C47: N/A | D47: 50 | E47: 2100000 | F47: 2380000 | G47: 0.882 | I47: 0 | J47: 4680 | K47: N/A | L47: 94 | M47: 6 | N47: 9/5/2025 5:26:42 AM
...

Sheet Experiment detail
B1: LC-MS Conditions
B3: LC Condition
B4: Binary Gradient | D4: Instrument | E4: QTrap5500: LC-MS-MS-011
B5: Time / min | C5: B% | D5: Flow | E5: 0.5 mL/min
B6: 0.7 | C6: 30 | D6: Phase A | E6: H2O - 0.1% Formic Acid
B7: 1 | C7: 95 | D7: Phase B | E7: ACN - 0.1% Formic Acid
B8: 1.8 | C8: 95
B9: =B8+0.01 -> 1.81 | C9: =C6 -> 30 | D9: Column | E9: Agilent ZORBAX XDB-C18 (5 µm, 50 × 2.1 mm)(50-482)
B10: 3 | C10: stop
B12: MS Condition
B13: Compounds | C13: Q1/Q3 | E13: DP | F13: CE | G13: CXP
B14: =Summary!B4 -> HW356009-P1 | C14: 604.30/411.10 | E14: 90 | F14: 42 | G14: 15
B15: IS (verapamil) | C15: 455.20/165.10 | E15: 90 | F15: 35 | G15: 15
