Workbook

Sheet CoverPage
A1: 3D BioOptima Quality That Matters
A2: 实验标题 | B2: 体外评估HW356009-P1在Caco-2细胞模型中的双向渗透性
A3: 实验方案编号 | B3: 3D_PN322881
A4: 课题编号 | B4: 3D_SN322438
A5: 课题负责人 | B5: 杨德孝
A6: 化合物 | B6: HW356009-P1
A7: 实验开始时间 | B7: 2025年09月03日
A8: 实验结束时间 | B8: 2025年09月08日
A9: 实验参与人员 | B9: 彭珊和许洁
A10: 报告撰写 | B10: 钱晨艳
A11: 数据质控 | B11: 程翠
A12: 实验负责方 | B12: 苏州圣苏新药开发有限公司 苏州市吴中区吴中大道1338号
A13: 实验委托方 | B13: 湖北生物医药产业技术研究院有限公司 武汉市东湖高新区高新大道666号C7栋217室
B15: 保密

Sheet Summary
B2: Measurement of Monodirectional Papp of Controls | I2: Parameters | J2: Type | K2: Evaluation criteria
B4: Compound | C4: Direction | D4: Recovery (%) | E4: Papp (cm/s´10-6) | F4: Efflux Ratio | G4: Stability(%) | I4: Permeability | J4: Low | K4: Papp(A→B)test Compound<Papp(A→B)Atenolol(0.257)
B5: Digoxin (5 µM) | C5: A to B | D5: =Processed!O33 -> 102.77783 | E5: =Processed!M33 -> 0.25685839 | F5: =Processed!P33 -> 50.88821 | G5: =Processed!M47 -> 116.78747 | J5: Medium | K5: Papp(A→B)Atenolol(0.307) ≤ Papp(A→B)test Compound≤Papp(A→B)Minoxidil (5.47)
C6: B to A | D6: =Processed!O39 -> 106.67193 | E6: =Processed!M39 -> 13.071064 | J6: High | K6: Papp(A→B)test Compound>Papp(A→B)Minoxidil (5.47)
B7: Minoxidil (5 µM) | C7: A to B | D7: =Processed!O18 -> 102.92965 | E7: =Processed!M18 -> 5.4722851 | F7: NA | G7: =Processed!M26 -> 109.79814 | I7: Efflux transporters | J7: Potential | K7: ER ≥ 2
B8: Atenolol (5 µM) | C8: A to B | D8: =Processed!O3 -> 97.908561 | E8: =Processed!M3 -> 0.30651378 | F8: NA | G8: =Processed!M11 -> 104.7141
B11: Measurement of Bi-directional Papp and Efflux Ratio of HW356009-P1
B13: Compound | C13: Direction | D13: Recovery (%) | E13: Papp (cm/s´10-6) | F13: Efflux Ratio | G13: Stability(%)
B14: =CONCATENATE('Assay Outline'!B21," (2 µM)") -> HW356009-P1 (2 µM) | C14: A to B | D14: =Processed!O54 -> 87.901087 | E14: =Processed!M54 -> 10.1451 | F14: =Processed!P54 -> 1.9102827 | G14: =Processed!M68 -> 104.71826
C15: B to A | D15: =Processed!O60 -> 113.57032 | E15: =Processed!M60 -> 19.38001
B16: =CONCATENATE('Assay Outline'!B22," (1 µM)") -> (1 µM) | C16: A to B | D16: =Processed!O75 -> #N/A | E16: =Processed!M75 -> #N/A | F16: =Processed!P75 -> #N/A | G16: =Processed!M89 -> #N/A
C17: B to A | D17: =Processed!O81 -> #N/A | E17: =Processed!M81 -> #N/A
B18: =CONCATENATE('Assay Outline'!B23," (1 µM)") -> (1 µM) | C18: A to B | D18: =Processed!O96 -> #N/A | E18: =Processed!M96 -> #N/A | F18: =Processed!P96 -> #N/A | G18: =Processed!M110 -> #N/A
C19: B to A | D19: =Processed!O102 -> #N/A | E19: =Processed!M102 -> #N/A
B20: =CONCATENATE('Assay Outline'!B24," (10 µM)") -> (10 µM) | C20: A to B | D20: =Processed!O117 -> #N/A | E20: =Processed!M117 -> #N/A | F20: =Processed!P117 -> #N/A | G20: =Processed!M131 -> #N/A
C21: B to A | D21: =Processed!O123 -> #N/A | E21: =Processed!M123 -> #N/A
B22: =CONCATENATE('Assay Outline'!B25," (10 µM)") -> (10 µM) | C22: A to B | D22: =Processed!O138 -> #N/A | E22: =Processed!M138 -> #N/A | F22: =Processed!P138 -> #N/A | G22: =Processed!M152 -> #N/A
C23: B to A | D23: =Processed!O144 -> #N/A | E23: =Processed!M144 -> #N/A
B24: =CONCATENATE('Assay Outline'!B26," (10 µM)") -> (10 µM) | C24: A to B | D24: =Processed!O159 -> #N/A | E24: =Processed!M159 -> #N/A | F24: =Processed!P159 -> #N/A | G24: =Processed!M173 -> #N/A
C25: B to A | D25: =Processed!O165 -> #N/A | E25: =Processed!M165 -> #N/A
B26: =CONCATENATE('Assay Outline'!B27," (10 µM)") -> (10 µM) | C26: A to B | D26: =Processed!O180 -> #N/A | E26: =Processed!M180 -> #N/A | F26: =Processed!P180 -> #N/A | G26: =Processed!M194 -> #N/A
C27: B to A | D27: =Processed!O186 -> #N/A | E27: =Processed!M186 -> #N/A
B28: =CONCATENATE('Assay Outline'!B28," (10 µM)") -> (10 µM) | C28: A to B | D28: =Processed!O201 -> #N/A | E28: =Processed!M201 -> #N/A | F28: =Processed!P201 -> #N/A | G28: =Processed!M215 -> #N/A
C29: B to A | D29: =Processed!O207 -> #N/A | E29: =Processed!M207 -> #N/A
B30: =CONCATENATE('Assay Outline'!B29," (10 µM)") -> (10 µM) | C30: A to B | D30: =Processed!O222 -> #N/A | E30: =Processed!M222 -> #N/A | F30: =Processed!P222 -> #N/A | G30: =Processed!M236 -> #N/A
C31: B to A | D31: =Processed!O228 -> #N/A | E31: =Processed!M228 -> #N/A
B32: =CONCATENATE('Assay Outline'!B30," (10 µM)") -> (10 µM) | C32: A to B | D32: =Processed!O243 -> #N/A | E32: =Processed!M243 -> #N/A | F32: =Processed!P243 -> #N/A | G32: =Processed!M257 -> #N/A
C33: B to A | D33: =Processed!O249 -> #N/A | E33: =Processed!M249 -> #N/A
B35: Conclusion
B36: HW356009-P1 was a high permeability compound and was not a substrate of efflux transporters.

Sheet Processed
A2: Compound | B2: Direction | C2: Sampling Side | D2: Time Point (min) | E2: Sample Name | F2: Sample | G2: Dilution Factor | H2: Analyte Peak Area | I2: IS Peak Area | J2: Area Ratio | K2: Mean Area Ratio | L2: Papp (10-6 cm/s) | M2: Mean Papp (10-6 cm/s) | N2: Recovery (%) | O2: Mean Recovery (%) | P2: Efflux Ratio
A3: Atenolol | B3: A to B | C3: B | D3: 120 | E3: Ate_A-B_B1 | F3: B-120-1 | G3: =VLOOKUP($E3,'Controls raw data'!$B$2:$L$797,4,0) -> 1 | H3: =VLOOKUP($E3,'Controls raw data'!$B$2:$L$797,5,0) -> 1800 | I3: =VLOOKUP($E3,'Controls raw data'!$B$2:$L$797,6,0) -> 633000 | J3: =VLOOKUP($E3,'Controls raw data'!$B$2:$L$797,7,0) -> 0.00285 | K3: =AVERAGE(J3:J4) -> 0.002675 | L3: =J3*1.3*G3/120/60/0.33/(G7*J7)*1000000 -> 0.31823335 | M3: =AVERAGE(L3:L4) -> 0.30651378 | N3: =(J3*1.3*G3+J5*0.2*G5)/(G7*0.2*J7)*100 -> 99.561735 | O3: =AVERAGE(N3:N4) -> 97.908561 | P3: NA
E4: Ate_A-B_B2 | F4: B-120-2 | G4: =VLOOKUP($E4,'Controls raw data'!$B$2:$L$797,4,0) -> 1 | H4: =VLOOKUP($E4,'Controls raw data'!$B$2:$L$797,5,0) -> 1610 | I4: =VLOOKUP($E4,'Controls raw data'!$B$2:$L$797,6,0) -> 643000 | J4: =VLOOKUP($E4,'Controls raw data'!$B$2:$L$797,7,0) -> 0.0025 | L4: =J4*1.3*G4/120/60/0.33/(G8*J8)*1000000 -> 0.29479421 | N4: =(J4*1.3*G4+J6*0.2*G6)/(G8*0.2*J8)*100 -> 96.255388
C5: A | D5: 120 | E5: Ate_A-B_A1 | F5: A-120-1 | G5: =VLOOKUP($E5,'Controls raw data'!$B$2:$L$797,4,0) -> 10 | H5: =VLOOKUP($E5,'Controls raw data'!$B$2:$L$797,5,0) -> 303000 | I5: =VLOOKUP($E5,'Controls raw data'!$B$2:$L$797,6,0) -> 623000 | J5: =VLOOKUP($E5,'Controls raw data'!$B$2:$L$797,7,0) -> 0.486 | K5: =AVERAGE(J5:J6) -> 0.4655 | L5: NA | M5: NA | N5: NA | O5: NA
E6: Ate_A-B_A2 | F6: A-120-2 | G6: =VLOOKUP($E6,'Controls raw data'!$B$2:$L$797,4,0) -> 10 | H6: =VLOOKUP($E6,'Controls raw data'!$B$2:$L$797,5,0) -> 289000 | I6: =VLOOKUP($E6,'Controls raw data'!$B$2:$L$797,6,0) -> 650000 | J6: =VLOOKUP($E6,'Controls raw data'!$B$2:$L$797,7,0) -> 0.445
B7: Donor TA0 | C7: NA | D7: 0 | E7: Ate_TA-1 | F7: TA0-1 | G7: =VLOOKUP($E7,'Controls raw data'!$B$2:$L$797,4,0) -> 10 | H7: =VLOOKUP($E7,'Controls raw data'!$B$2:$L$797,5,0) -> 314000 | I7: =VLOOKUP($E7,'Controls raw data'!$B$2:$L$797,6,0) -> 641000 | J7: =VLOOKUP($E7,'Controls raw data'!$B$2:$L$797,7,0) -> 0.49 | K7: =AVERAGE(J7:J8) -> 0.477 | L7: NA | M7: NA | N7: NA | O7: NA
E8: Ate_TA-2 | F8: TA0-2 | G8: =VLOOKUP($E8,'Controls raw data'!$B$2:$L$797,4,0) -> 10 | H8: =VLOOKUP($E8,'Controls raw data'!$B$2:$L$797,5,0) -> 292000 | I8: =VLOOKUP($E8,'Controls raw data'!$B$2:$L$797,6,0) -> 629000 | J8: =VLOOKUP($E8,'Controls raw data'!$B$2:$L$797,7,0) -> 0.464
A10: Compound | B10: Sample name | D10: Time Point (min) | E10: Sample Name | F10: Sample | G10: Dilution Factor | H10: Analyte Peak Area | I10: IS Peak Area | J10: Area Ratio | K10: Mean Area Ratio | L10: Remaining after 120 min Incubation (% ) | M10: Mean (%)
A11: Atenolol | B11: Stability | D11: 120 | E11: Ate_T120-1 | F11: T120-1 | G11: =VLOOKUP($E11,'Controls raw data'!$B$2:$L$797,4,0) -> 10 | H11: =VLOOKUP($E11,'Controls raw data'!$B$2:$L$797,5,0) -> 307000 | I11: =VLOOKUP($E11,'Controls raw data'!$B$2:$L$797,6,0) -> 632000 | J11: =VLOOKUP($E11,'Controls raw data'!$B$2:$L$797,7,0) -> 0.486 | K11: =AVERAGE(J11:J12) -> 0.5065 | L11: =J11*G11/(G13*J13)*100 -> 102.53165 | M11: =AVERAGE(L11:L12) -> 104.7141
E12: Ate_T120-2 | F12: T120-2 | G12: =VLOOKUP($E12,'Controls raw data'!$B$2:$L$797,4,0) -> 10 | H12: =VLOOKUP($E12,'Controls raw data'!$B$2:$L$797,5,0) -> 329000 | I12: =VLOOKUP($E12,'Controls raw data'!$B$2:$L$797,6,0) -> 625000 | J12: =VLOOKUP($E12,'Controls raw data'!$B$2:$L$797,7,0) -> 0.527 | L12: =J12*G12/(G14*J14)*100 -> 106.89655
D13: 0 | E13: Ate_T0-1 | F13: T0-1 | G13: =VLOOKUP($E13,'Controls raw data'!$B$2:$L$797,4,0) -> 10 | H13: =VLOOKUP($E13,'Controls raw data'!$B$2:$L$797,5,0) -> 302000 | I13: =VLOOKUP($E13,'Controls raw data'!$B$2:$L$797,6,0) -> 637000 | J13: =VLOOKUP($E13,'Controls raw data'!$B$2:$L$797,7,0) -> 0.474 | K13: =AVERAGE(J13:J14) -> 0.4835 | L13: NA | M13: NA
E14: Ate_T0-2 | F14: T0-2 | G14: =VLOOKUP($E14,'Controls raw data'!$B$2:$L$797,4,0) -> 10 | H14: =VLOOKUP($E14,'Controls raw data'!$B$2:$L$797,5,0) -> 308000 | I14: =VLOOKUP($E14,'Controls raw data'!$B$2:$L$797,6,0) -> 625000 | J14: =VLOOKUP($E14,'Controls raw data'!$B$2:$L$797,7,0) -> 0.493
A17: Compound | B17: Direction | C17: Sampling Side | D17: Time Point (min) | E17: Sample Name | F17: Sample | G17: Dilution Factor | H17: Analyte Peak Area | I17: IS Peak Area | J17: Area Ratio | K17: Mean Area Ratio | L17: Papp (10-6 cm/s) | M17: Mean Papp (10-6 cm/s) | N17: Recovery (%) | O17: Mean Recovery (%) | P17: Efflux Ratio
A18: Minoxidil | B18: A to B | C18: B | D18: 120 | E18: Min_A-B_B1 | F18: B-120-1 | G18: =VLOOKUP($E18,'Controls raw data'!$B$2:$L$797,4,0) -> 1 | H18: =VLOOKUP($E18,'Controls raw data'!$B$2:$L$797,5,0) -> 33800 | I18: =VLOOKUP($E18,'Controls raw data'!$B$2:$L$797,6,0) -> 305000 | J18: =VLOOKUP($E18,'Controls raw data'!$B$2:$L$797,7,0) -> 0.111 | K18: =AVERAGE(J18:J19) -> 0.11 | L18: =J18*1.3*G18/120/60/0.33/(G22*J22)*1000000 -> 5.4225289 | M18: =AVERAGE(L18:L19) -> 5.4722851 | N18: =(J18*1.3*G18+J20*0.2*G20)/(G22*0.2*J22)*100 -> 99.299107 | O18: =AVERAGE(N18:N19) -> 102.92965 | P18: NA
E19: Min_A-B_B2 | F19: B-120-2 | G19: =VLOOKUP($E19,'Controls raw data'!$B$2:$L$797,4,0) -> 1 | H19: =VLOOKUP($E19,'Controls raw data'!$B$2:$L$797,5,0) -> 32700 | I19: =VLOOKUP($E19,'Controls raw data'!$B$2:$L$797,6,0) -> 300000 | J19: =VLOOKUP($E19,'Controls raw data'!$B$2:$L$797,7,0) -> 0.109 | L19: =J19*1.3*G19/120/60/0.33/(G23*J23)*1000000 -> 5.5220414 | N19: =(J19*1.3*G19+J21*0.2*G21)/(G23*0.2*J23)*100 -> 106.56019
C20: A | D20: 120 | E20: Min_A-B_A1 | F20: A-120-1 | G20: =VLOOKUP($E20,'Controls raw data'!$B$2:$L$797,4,0) -> 10 | H20: =VLOOKUP($E20,'Controls raw data'!$B$2:$L$797,5,0) -> 318000 | I20: =VLOOKUP($E20,'Controls raw data'!$B$2:$L$797,6,0) -> 305000 | J20: =VLOOKUP($E20,'Controls raw data'!$B$2:$L$797,7,0) -> 1.04 | K20: =AVERAGE(J20:J21) -> 1.06 | L20: NA | M20: NA | N20: NA | O20: NA
E21: Min_A-B_A2 | F21: A-120-2 | G21: =VLOOKUP($E21,'Controls raw data'!$B$2:$L$797,4,0) -> 10 | H21: =VLOOKUP($E21,'Controls raw data'!$B$2:$L$797,5,0) -> 323000 | I21: =VLOOKUP($E21,'Controls raw data'!$B$2:$L$797,6,0) -> 300000 | J21: =VLOOKUP($E21,'Controls raw data'!$B$2:$L$797,7,0) -> 1.08
B22: Donor TA0 | C22: NA | D22: 0 | E22: Min_TA-1 | F22: TA0-1 | G22: =VLOOKUP($E22,'Controls raw data'!$B$2:$L$797,4,0) -> 10 | H22: =VLOOKUP($E22,'Controls raw data'!$B$2:$L$797,5,0) -> 355000 | I22: =VLOOKUP($E22,'Controls raw data'!$B$2:$L$797,6,0) -> 316000 | J22: =VLOOKUP($E22,'Controls raw data'!$B$2:$L$797,7,0) -> 1.12 | K22: =AVERAGE(J22:J23) -> 1.1 | L22: NA | M22: NA | N22: NA | O22: NA
E23: Min_TA-2 | F23: TA0-2 | G23: =VLOOKUP($E23,'Controls raw data'!$B$2:$L$797,4,0) -> 10 | H23: =VLOOKUP($E23,'Controls raw data'!$B$2:$L$797,5,0) -> 317000 | I23: =VLOOKUP($E23,'Controls raw data'!$B$2:$L$797,6,0) -> 293000 | J23: =VLOOKUP($E23,'Controls raw data'!$B$2:$L$797,7,0) -> 1.08
A25: Compound | B25: Sample name | D25: Time Point (min) | E25: Sample Name | F25: Sample | G25: Dilution Factor | H25: Analyte Peak Area | I25: IS Peak Area | J25: Area Ratio | K25: Mean Area Ratio | L25: Remaining after 120 min Incubation (% ) | M25: Mean (%)
A26: Minoxidil | B26: Stability | D26: 120 | E26: Min_T120-1 | F26: T120-1 | G26: =VLOOKUP($E26,'Controls raw data'!$B$2:$L$797,4,0) -> 10 | H26: =VLOOKUP($E26,'Controls raw data'!$B$2:$L$797,5,0) -> 367000 | I26: =VLOOKUP($E26,'Controls raw data'!$B$2:$L$797,6,0) -> 277000 | J26: =VLOOKUP($E26,'Controls raw data'!$B$2:$L$797,7,0) -> 1.32 | K26: =AVERAGE(J26:J27) -> 1.245 | L26: =J26*G26/(G28*J28)*100 -> 117.85714 | M26: =AVERAGE(L26:L27) -> 109.79814
E27: Min_T120-2 | F27: T120-2 | G27: =VLOOKUP($E27,'Controls raw data'!$B$2:$L$797,4,0) -> 10 | H27: =VLOOKUP($E27,'Controls raw data'!$B$2:$L$797,5,0) -> 351000 | I27: =VLOOKUP($E27,'Controls raw data'!$B$2:$L$797,6,0) -> 301000 | J27: =VLOOKUP($E27,'Controls raw data'!$B$2:$L$797,7,0) -> 1.17 | L27: =J27*G27/(G29*J29)*100 -> 101.73913
D28: 0 | E28: Min_T0-1 | F28: T0-1 | G28: =VLOOKUP($E28,'Controls raw data'!$B$2:$L$797,4,0) -> 10 | H28: =VLOOKUP($E28,'Controls raw data'!$B$2:$L$797,5,0) -> 366000 | I28: =VLOOKUP($E28,'Controls raw data'!$B$2:$L$797,6,0) -> 327000 | J28: =VLOOKUP($E28,'Controls raw data'!$B$2:$L$797,7,0) -> 1.12 | K28: =AVERAGE(J28:J29) -> 1.135 | L28: NA | M28: NA
E29: Min_T0-2 | F29: T0-2 | G29: =VLOOKUP($E29,'Controls raw data'!$B$2:$L$797,4,0) -> 10 | H29: =VLOOKUP($E29,'Controls raw data'!$B$2:$L$797,5,0) -> 364000 | I29: =VLOOKUP($E29,'Controls raw data'!$B$2:$L$797,6,0) -> 316000 | J29: =VLOOKUP($E29,'Controls raw data'!$B$2:$L$797,7,0) -> 1.15
A32: Compound | B32: Direction | C32: Sampling Side | D32: Time Point (min) | E32: Sample Name | F32: Sample | G32: Dilution Factor | H32: Analyte Peak Area | I32: IS Peak Area | J32: Area Ratio | K32: Mean Area Ratio | L32: Papp (10-6 cm/s) | M32: Mean Papp (10-6 cm/s) | N32: Recovery (%) | O32: Mean Recovery (%) | P32: Efflux Ratio
A33: Digoxin | B33: A to B | C33: B | D33: 120 | E33: Dig_A-B_B1 | F33: B-120-1 | G33: =VLOOKUP($E33,'Controls raw data'!$B$2:$L$797,4,0) -> 1 | H33: =VLOOKUP($E33,'Controls raw data'!$B$2:$L$797,5,0) -> 1190 | I33: =VLOOKUP($E33,'Controls raw data'!$B$2:$L$797,6,0) -> 1390000 | J33: =VLOOKUP($E33,'Controls raw data'!$B$2:$L$797,7,0) -> 0.000853 | K33: =AVERAGE(J33:J34) -> 0.000852 | L33: =J33*1.3*G33/120/60/0.33/(G37*J37)*1000000 -> 0.25928264 | M33: =AVERAGE(L33:L34) -> 0.25685839 | N33: =(J33*1.3*G33+J35*0.2*G35)/(G37*0.2*J37)*100 -> 101.97469 | O33: =AVERAGE(N33:N34) -> 102.77783 | P33: =M39/M33 -> 50.88821
E34: Dig_A-B_B2 | F34: B-120-2 | G34: =VLOOKUP($E34,'Controls raw data'!$B$2:$L$797,4,0) -> 1 | H34: =VLOOKUP($E34,'Controls raw data'!$B$2:$L$797,5,0) -> 1300 | I34: =VLOOKUP($E34,'Controls raw data'!$B$2:$L$797,6,0) -> 1520000 | J34: =VLOOKUP($E34,'Controls raw data'!$B$2:$L$797,7,0) -> 0.000851 | L34: =J34*1.3*G34/120/60/0.33/(G38*J38)*1000000 -> 0.25443414 | N34: =(J34*1.3*G34+J36*0.2*G36)/(G38*0.2*J38)*100 -> 103.58096
C35: A | D35: 120 | E35: Dig_A-B_A1 | F35: A-120-1 | G35: =VLOOKUP($E35,'Controls raw data'!$B$2:$L$797,4,0) -> 10 | H35: =VLOOKUP($E35,'Controls raw data'!$B$2:$L$797,5,0) -> 281000 | I35: =VLOOKUP($E35,'Controls raw data'!$B$2:$L$797,6,0) -> 1530000 | J35: =VLOOKUP($E35,'Controls raw data'!$B$2:$L$797,7,0) -> 0.183 | K35: =AVERAGE(J35:J36) -> 0.186 | L35: NA | M35: NA | N35: NA | O35: NA
E36: Dig_A-B_A2 | F36: A-120-2 | G36: =VLOOKUP($E36,'Controls raw data'!$B$2:$L$797,4,0) -> 10 | H36: =VLOOKUP($E36,'Controls raw data'!$B$2:$L$797,5,0) -> 291000 | I36: =VLOOKUP($E36,'Controls raw data'!$B$2:$L$797,6,0) -> 1540000 | J36: =VLOOKUP($E36,'Controls raw data'!$B$2:$L$797,7,0) -> 0.189
B37: Donor TA0 | C37: NA | D37: 0 | E37: Dig_TA-1 | F37: TA0-1 | G37: =VLOOKUP($E37,'Controls raw data'!$B$2:$L$797,4,0) -> 10 | H37: =VLOOKUP($E37,'Controls raw data'!$B$2:$L$797,5,0) -> 281000 | I37: =VLOOKUP($E37,'Controls raw data'!$B$2:$L$797,6,0) -> 1560000 | J37: =VLOOKUP($E37,'Controls raw data'!$B$2:$L$797,7,0) -> 0.18 | K37: =AVERAGE(J37:J38) -> 0.1815 | L37: NA | M37: NA | N37: NA | O37: NA
E38: Dig_TA-2 | F38: TA0-2 | G38: =VLOOKUP($E38,'Controls raw data'!$B$2:$L$797,4,0) -> 10 | H38: =VLOOKUP($E38,'Controls raw data'!$B$2:$L$797,5,0) -> 279000 | I38: =VLOOKUP($E38,'Controls raw data'!$B$2:$L$797,6,0) -> 1520000 | J38: =VLOOKUP($E38,'Controls raw data'!$B$2:$L$797,7,0) -> 0.183
B39: B to A | C39: A | D39: 120 | E39: Dig_B-A_A1 | F39: A-120-1 | G39: =VLOOKUP($E39,'Controls raw data'!$B$2:$L$797,4,0) -> 1 | H39: =VLOOKUP($E39,'Controls raw data'!$B$2:$L$797,5,0) -> 415000 | I39: =VLOOKUP($E39,'Controls raw data'!$B$2:$L$797,6,0) -> 1560000 | J39: =VLOOKUP($E39,'Controls raw data'!$B$2:$L$797,7,0) -> 0.266 | K39: =AVERAGE(J39:J40) -> 0.273 | L39: =J39*0.2*G39/120/60/0.33/(J43*G43)*1000000 -> 12.439207 | M39: =AVERAGE(L39:L40) -> 13.071064 | N39: =(J39*0.2*G39+J41*1.3*G41)/(J43*1.3*G43)*100 -> 105.60684 | O39: =AVERAGE(N39:N40) -> 106.67193
E40: Dig_B-A_A2 | F40: A-120-2 | G40: =VLOOKUP($E40,'Controls raw data'!$B$2:$L$797,4,0) -> 1 | H40: =VLOOKUP($E40,'Controls raw data'!$B$2:$L$797,5,0) -> 439000 | I40: =VLOOKUP($E40,'Controls raw data'!$B$2:$L$797,6,0) -> 1570000 | J40: =VLOOKUP($E40,'Controls raw data'!$B$2:$L$797,7,0) -> 0.28 | L40: =J40*0.2*G40/120/60/0.33/(J44*G44)*1000000 -> 13.702921 | N40: =(J40*0.2*G40+J42*1.3*G42)/(J44*1.3*G44)*100 -> 107.73703
C41: B | D41: 120 | E41: Dig_B-A_B1 | F41: B-120-1 | G41: =VLOOKUP($E41,'Controls raw data'!$B$2:$L$797,4,0) -> 10 | H41: =VLOOKUP($E41,'Controls raw data'!$B$2:$L$797,5,0) -> 290000 | I41: =VLOOKUP($E41,'Controls raw data'!$B$2:$L$797,6,0) -> 1560000 | J41: =VLOOKUP($E41,'Controls raw data'!$B$2:$L$797,7,0) -> 0.186 | K41: =AVERAGE(J41:J42) -> 0.1835 | L41: NA | M41: NA | N41: NA | O41: NA
E42: Dig_B-A_B2 | F42: B-120-2 | G42: =VLOOKUP($E42,'Controls raw data'!$B$2:$L$797,4,0) -> 10 | H42: =VLOOKUP($E42,'Controls raw data'!$B$2:$L$797,5,0) -> 267000 | I42: =VLOOKUP($E42,'Controls raw data'!$B$2:$L$797,6,0) -> 1480000 | J42: =VLOOKUP($E42,'Controls raw data'!$B$2:$L$797,7,0) -> 0.181
B43: Donor TB0 | C43: NA | D43: 0 | E43: Dig_TB-1 | F43: TB0-1 | G43: =VLOOKUP($E43,'Controls raw data'!$B$2:$L$797,4,0) -> 10 | H43: =VLOOKUP($E43,'Controls raw data'!$B$2:$L$797,5,0) -> 287000 | I43: =VLOOKUP($E43,'Controls raw data'!$B$2:$L$797,6,0) -> 1590000 | J43: =VLOOKUP($E43,'Controls raw data'!$B$2:$L$797,7,0) -> 0.18 | K43: =AVERAGE(J43:J44) -> 0.176 | L43: NA | M43: NA | N43: NA | O43: NA
E44: Dig_TB-2 | F44: TB0-2 | G44: =VLOOKUP($E44,'Controls raw data'!$B$2:$L$797,4,0) -> 10 | H44: =VLOOKUP($E44,'Controls raw data'!$B$2:$L$797,5,0) -> 264000 | I44: =VLOOKUP($E44,'Controls raw data'!$B$2:$L$797,6,0) -> 1530000 | J44: =VLOOKUP($E44,'Controls raw data'!$B$2:$L$797,7,0) -> 0.172
A46: Compound | B46: Sample name | D46: Time Point (min) | E46: Sample Name | F46: Sample | G46: Dilution Factor | H46: Analyte Peak Area | I46: IS Peak Area | J46: Area Ratio | K46: Mean Area Ratio | L46: Remaining after 120 min Incubation (% ) | M46: Mean (%)
A47: Digoxin | B47: Stability | D47: 120 | E47: Dig_T120-1 | F47: T120-1 | G47: =VLOOKUP($E47,'Controls raw data'!$B$2:$L$797,4,0) -> 10 | H47: =VLOOKUP($E47,'Controls raw data'!$B$2:$L$797,5,0) -> 315000 | I47: =VLOOKUP($E47,'Controls raw data'!$B$2:$L$797,6,0) -> 1450000 | J47: =VLOOKUP($E47,'Controls raw data'!$B$2:$L$797,7,0) -> 0.216 | K47: =AVERAGE(J47:J48) -> 0.216 | L47: =J47*G47/(G49*J49)*100 -> 114.89362 | M47: =AVERAGE(L47:L48) -> 116.78747
E48: Dig_T120-2 | F48: T120-2 | G48: =VLOOKUP($E48,'Controls raw data'!$B$2:$L$797,4,0) -> 10 | H48: =VLOOKUP($E48,'Controls raw data'!$B$2:$L$797,5,0) -> 317000 | I48: =VLOOKUP($E48,'Controls raw data'!$B$2:$L$797,6,0) -> 1470000 | J48: =VLOOKUP($E48,'Controls raw data'!$B$2:$L$797,7,0) -> 0.216 | L48: =J48*G48/(G50*J50)*100 -> 118.68132
...

Sheet Layout
B2: Layout For Plate *08-08-2025-P2
B3: HW356009-P1 A-B (2 µM) | C3: HW356009-P1 A-B (2 µM) | D3: HW356009-P1 B-A (2 µM) | E3: HW356009-P1 B-A (2 µM) | F3: Atenolol (5 µM) A-B | G3: Atenolol (5 µM) A-B
B4: NA | C4: NA | D4: NA | E4: NA | F4: Digoxin A-B (5 µM) | G4: Digoxin A-B (5 µM)
B5: NA | C5: NA | D5: NA | E5: NA | F5: Digoxin B-A (5 µM) | G5: Digoxin B-A (5 µM)
B6: NA | C6: NA | D6: NA | E6: NA | F6: Minoxidil (5 µM) A-B | G6: Minoxidil (5 µM) A-B

Sheet TEER
B2: Before | C2: (Plate ID: 08-08-2025-P2)
B3: TEER (Ω·cm2) Before the Drug Transport Experiment
B4: 825 | C4: 726 | D4: 693 | E4: 660 | F4: 627 | G4: 792
B5: NA | C5: NA | D5: NA | E5: NA | F5: 660 | G5: 693
B6: NA | C6: NA | D6: NA | E6: NA | F6: 693 | G6: 660
B7: NA | C7: NA | D7: NA | E7: NA | F7: 726 | G7: 759
B9: After | C9: =C2 -> (Plate ID: 08-08-2025-P2)
B10: TEER (Ω·cm2) After the Drug Transport Experiment
B11: 627 | C11: 528 | D11: 528 | E11: 495 | F11: 462 | G11: 429
B12: NA | C12: NA | D12: NA | E12: NA | F12: 462 | G12: 462
B13: NA | C13: NA | D13: NA | E13: NA | F13: 528 | G13: 495
B14: NA | C14: NA | D14: NA | E14: NA | F14: 528 | G14: 561
B16: TEER should be ≥ 230 ohms•cm2

Sheet Assay Outline
B2: Cell Culture
B3: Cell Source | F3: CAS
B4: Cell Passage Number | F4: 40 | H4: 30~32
B5: Cell Seeding Density | F5: 2.4 × 105 cells/cm2 | H5: 1.7 × 105 cells/cm2
B6: Culture Time on the Membrane | F6: 28 days | H6: 19 days
B7: Criteria for TEER Value | F7: > 230 Ω·cm2 | H7: >150 Ω·cm2
B9: Assay Design For HW356009-P1 Bi-directional Papp and Efflux Ratio Measurement
B10: Drug Transport Direction | F10: A→B/B→A | H10: A→B/B→A
B11: Test Compound Concentration | F11: 2 µM | H11: 1 µM, 3 µM, 10 µM
B12: Incubation Time | F12: 120 min | H12: 120 min
B13: Replicate | F13: n = 2 | H13: 2/plate, 2 plates
B14: Low Permeability Marker | F14: Atenolol (5 µM) | H14: Antenolol (10 µM)
B15: High Permeability Marker | F15: Minoxidil (5 µM) | H15: Propranolol (10 µM)
B16: P-gp Expression Marker | F16: Digoxin (5 µM) | H16: Digoxin (10 µM)
B17: Donor Buffer | F17: HBSS+1%BSA | H17: HBSS containing 0.002% Tween-80
B18: Receiver Buffer | F18: HBSS+1%BSA | H18: HBSS containing 0.002% Tween-80
B20: Compound Name | F20: Lot#
B21: =CoverPage!B6 -> HW356009-P1 | C21: HW033061-P2 | D21: HW033061-P2 | E21: HW033061-P2 | F21: HWH817-YBC-035-4-54-2

Sheet Method
B2: 液相分析条件
B3: 液相条件
B4: Time | C4: B% | D4: Instrument | E4: LC-MS/MS (Triple Quad 5500: LC-MS-MS-013)
B5: 0.5 | C5: 10
B6: 1 | C6: 95 | D6: Phase A | E6: A：水（含0.1%甲酸）
B7: 1.6 | C7: 95 | D7: Phase B | E7: B：乙腈（含0.1%甲酸）
B8: 1.61 | C8: 10
B9: 3 | C9: stop | D9: Column | E9: Agilent ZORBAX XDB-C18 (5.0 µm, 50×2.1 mm)（50-481）
B11: 质谱条件
B12: 名称 | C12: Q1 | D12: Q3 | E12: DP | F12: EP | G12: CE | H12: CXP
B13: ='Assay Outline'!B21:E21 -> HW356009-P1 | C13: 602.3 | D13: 502.1 | E13: -160 | F13: -10 | G13: -23 | H13: -16
B14: Glibenclamide | C14: 492.2 | D14: 367.1 | E14: -60 | F14: -10 | G14: -23 | H14: -30

Sheet Article(s) Raw Data
A1: Analyte | B1: Sample Name | C1: Sample Type | D1: Analyte Concentration (nM) | E1: Dilution Factor | F1: Analyte Peak Area (counts) | G1: IS Peak Area (counts) | H1: Area Ratio | I1: Use Record | J1: Record Modified | K1: Calculated Concentration (nM) | L1: Accuracy (%) | M1: Vial Position | N1: Plate Position | O1: Acquisition Date | P1: Analyte Retention Time (min) | Q1: IS Retention Time (min) | R1: Analyte Peak Name | S1: IS Peak Name
A2: =Summary!B14 -> HW356009-P1 (2 µM) | B2: Wash | C2: Unknown | D2: N/A | E2: 1 | F2: 0 | G2: 0 | H2: #DIV/0! | J2: 0 | K2: #DIV/0! | L2: N/A | M2: 20001 | N2: 3 | O2: 9/4/2025 6:49:58 PM | P2: 0 | Q2: 0 | R2: HW356009-P1 | S2: GLBN
B3: Wash | C3: Unknown | D3: N/A | E3: 1 | F3: 0 | G3: 0 | H3: #DIV/0! | J3: 0 | K3: #DIV/0! | L3: N/A | M3: 20001 | N3: 3 | O3: 9/4/2025 6:53:31 PM | P3: 0 | Q3: 0 | R3: HW356009-P1 | S3: GLBN
B4: HW356009-P1_A-B_B1 | C4: Unknown | D4: N/A | E4: 1 | F4: 52500 | G4: 414000 | H4: 0.127 | J4: 0 | K4: 0 | L4: N/A | M4: 53 | N4: 3 | O4: 9/4/2025 6:57:01 PM | P4: 1.68 | Q4: 1.66 | R4: HW356009-P1 | S4: GLBN
B5: HW356009-P1_A-B_B2 | C5: Unknown | D5: N/A | E5: 1 | F5: 50400 | G5: 465000 | H5: 0.108 | J5: 0 | K5: 0 | L5: N/A | M5: 54 | N5: 3 | O5: 9/4/2025 7:00:38 PM | P5: 1.67 | Q5: 1.66 | R5: HW356009-P1 | S5: GLBN
B6: HW356009-P1_B-A_A1 | C6: Unknown | D6: N/A | E6: 1 | F6: 693000 | G6: 453000 | H6: 1.53 | J6: 0 | K6: 0 | L6: N/A | M6: 51 | N6: 3 | O6: 9/4/2025 7:04:14 PM | P6: 1.68 | Q6: 1.66 | R6: HW356009-P1 | S6: GLBN
B7: HW356009-P1_B-A_A2 | C7: Unknown | D7: N/A | E7: 1 | F7: 736000 | G7: 478000 | H7: 1.54 | J7: 0 | K7: 0 | L7: N/A | M7: 52 | N7: 3 | O7: 9/4/2025 7:07:47 PM | P7: 1.67 | Q7: 1.65 | R7: HW356009-P1 | S7: GLBN
B8: HW356009-P1_A-B_A1 | C8: Unknown | D8: N/A | E8: 10 | F8: 234000 | G8: 487000 | H8: 0.482 | J8: 0 | K8: 0 | L8: N/A | M8: 49 | N8: 3 | O8: 9/4/2025 7:11:17 PM | P8: 1.67 | Q8: 1.66 | R8: HW356009-P1 | S8: GLBN
B9: HW356009-P1_A-B_A2 | C9: Unknown | D9: N/A | E9: 10 | F9: 237000 | G9: 495000 | H9: 0.479 | J9: 0 | K9: 0 | L9: N/A | M9: 50 | N9: 3 | O9: 9/4/2025 7:14:53 PM | P9: 1.66 | Q9: 1.64 | R9: HW356009-P1 | S9: GLBN
B10: HW356009-P1_B-A_B1 | C10: Unknown | D10: N/A | E10: 10 | F10: 375000 | G10: 496000 | H10: 0.756 | J10: 0 | K10: 0 | L10: N/A | M10: 55 | N10: 3 | O10: 9/4/2025 7:18:26 PM | P10: 1.68 | Q10: 1.66 | R10: HW356009-P1 | S10: GLBN
B11: HW356009-P1_B-A_B2 | C11: Unknown | D11: N/A | E11: 10 | F11: 358000 | G11: 504000 | H11: 0.71 | J11: 0 | K11: 0 | L11: N/A | M11: 56 | N11: 3 | O11: 9/4/2025 7:21:58 PM | P11: 1.68 | Q11: 1.66 | R11: HW356009-P1 | S11: GLBN
B12: HW356009-P1_TA-1 | C12: Unknown | D12: N/A | E12: 10 | F12: 326000 | G12: 513000 | H12: 0.636 | J12: 0 | K12: 0 | L12: N/A | M12: 5 | N12: 3 | O12: 9/4/2025 7:25:35 PM | P12: 1.67 | Q12: 1.65 | R12: HW356009-P1 | S12: GLBN
B13: HW356009-P1_TA-2 | C13: Unknown | D13: N/A | E13: 10 | F13: 332000 | G13: 527000 | H13: 0.631 | J13: 0 | K13: 0 | L13: N/A | M13: 6 | N13: 3 | O13: 9/4/2025 7:29:11 PM | P13: 1.67 | Q13: 1.66 | R13: HW356009-P1 | S13: GLBN
B14: HW356009-P1_TB-1 | C14: Unknown | D14: N/A | E14: 10 | F14: 342000 | G14: 525000 | H14: 0.652 | J14: 0 | K14: 0 | L14: N/A | M14: 17 | N14: 3 | O14: 9/4/2025 7:32:44 PM | P14: 1.67 | Q14: 1.65 | R14: HW356009-P1 | S14: GLBN
B15: HW356009-P1_TB-2 | C15: Unknown | D15: N/A | E15: 10 | F15: 350000 | G15: 513000 | H15: 0.682 | J15: 0 | K15: 0 | L15: N/A | M15: 18 | N15: 3 | O15: 9/4/2025 7:36:18 PM | P15: 1.67 | Q15: 1.65 | R15: HW356009-P1 | S15: GLBN
B16: Wash | C16: Unknown | D16: N/A | E16: 1 | F16: 0 | G16: 0 | H16: #DIV/0! | J16: 0 | K16: #DIV/0! | L16: N/A | M16: 20001 | N16: 3 | O16: 9/4/2025 7:39:52 PM | P16: 0 | Q16: 0 | R16: HW356009-P1 | S16: GLBN
B17: Wash | C17: Unknown | D17: N/A | E17: 1 | F17: 0 | G17: 0 | H17: #DIV/0! | J17: 0 | K17: #DIV/0! | L17: N/A | M17: 20001 | N17: 3 | O17: 9/4/2025 7:43:25 PM | P17: 0 | Q17: 0 | R17: HW356009-P1 | S17: GLBN
B18: HW356009-P1_T120-1 | C18: Unknown | D18: N/A | E18: 10 | F18: 349000 | G18: 504000 | H18: 0.693 | J18: 0 | K18: 0 | L18: N/A | M18: 43 | N18: 3 | O18: 9/4/2025 7:46:58 PM | P18: 1.67 | Q18: 1.66 | R18: HW356009-P1 | S18: GLBN
B19: HW356009-P1_T120-2 | C19: Unknown | D19: N/A | E19: 10 | F19: 399000 | G19: 527000 | H19: 0.757 | J19: 0 | K19: 0 | L19: N/A | M19: 44 | N19: 3 | O19: 9/4/2025 7:50:32 PM | P19: 1.68 | Q19: 1.66 | R19: HW356009-P1 | S19: GLBN
B20: HW356009-P1_T0-1 | C20: Unknown | D20: N/A | E20: 10 | F20: 382000 | G20: 534000 | H20: 0.716 | J20: 0 | K20: 0 | L20: N/A | M20: 31 | N20: 3 | O20: 9/4/2025 7:54:08 PM | P20: 1.67 | Q20: 1.66 | R20: HW356009-P1 | S20: GLBN
B21: HW356009-P1_T0-2 | C21: Unknown | D21: N/A | E21: 10 | F21: 380000 | G21: 566000 | H21: 0.672 | J21: 0 | K21: 0 | L21: N/A | M21: 32 | N21: 3 | O21: 9/4/2025 7:57:44 PM | P21: 1.68 | Q21: 1.66 | R21: HW356009-P1 | S21: GLBN
A22: =Summary!B16 -> (1 µM)
A42: =Summary!B18 -> (1 µM)
A62: =Summary!B20 -> (10 µM)
A82: =Summary!B22 -> (10 µM)
A102: =Summary!B24 -> (10 µM)
A122: =Summary!B26 -> (10 µM)
A142: =Summary!B28 -> (10 µM)
A162: =Summary!B30 -> (10 µM)
A182: =Summary!B32 -> (10 µM)

Sheet Controls raw data
A2: Analyte | B2: Sample Name | C2: Sample Type | D2: Analyte Concentration (nM) | E2: Dilution Factor | F2: Analyte Peak Area (counts) | G2: IS Peak Area (counts) | H2: Area Ratio | I2: Use Record | J2: Record Modified | K2: Calculated Concentration (nM) | L2: Accuracy (%) | M2: Vial Position | N2: Plate Position | O2: Acquisition Date | P2: Analyte Retention Time (min) | Q2: IS Retention Time (min) | R2: Analyte Peak Name | S2: IS Peak Name
A3: Atenolol | B3: Wash | C3: Unknown | D3: N/A | E3: 1 | F3: 0 | G3: 0 | H3: #DIV/0! | J3: 0 | K3: #DIV/0! | L3: N/A | M3: 20001 | N3: 3 | O3: 9/4/2025 5:10:23 PM | P3: 0 | Q3: 0 | R3: Atenolol-Gli | S3: GLBN
B4: Wash | C4: Unknown | D4: N/A | E4: 1 | F4: 0 | G4: 0 | H4: #DIV/0! | J4: 0 | K4: #DIV/0! | L4: N/A | M4: 20001 | N4: 3 | O4: 9/4/2025 5:13:55 PM | P4: 0 | Q4: 0 | R4: Atenolol-Gli | S4: GLBN
B5: Ate_A-B_B1 | C5: Unknown | D5: N/A | E5: 1 | F5: 1800 | G5: 633000 | H5: 0.00285 | J5: 0 | K5: 0 | L5: N/A | M5: 59 | N5: 3 | O5: 9/4/2025 5:17:28 PM | P5: 1.39 | Q5: 1.6 | R5: Atenolol-Gli | S5: GLBN
B6: Ate_A-B_B2 | C6: Unknown | D6: N/A | E6: 1 | F6: 1610 | G6: 643000 | H6: 0.0025 | J6: 0 | K6: 0 | L6: N/A | M6: 60 | N6: 3 | O6: 9/4/2025 5:20:58 PM | P6: 1.4 | Q6: 1.6 | R6: Atenolol-Gli | S6: GLBN
B7: Ate_A-B_A1 | C7: Unknown | D7: N/A | E7: 10 | F7: 303000 | G7: 623000 | H7: 0.486 | J7: 0 | K7: 0 | L7: N/A | M7: 57 | N7: 3 | O7: 9/4/2025 5:24:34 PM | P7: 1.4 | Q7: 1.6 | R7: Atenolol-Gli | S7: GLBN
B8: Ate_A-B_A2 | C8: Unknown | D8: N/A | E8: 10 | F8: 289000 | G8: 650000 | H8: 0.445 | J8: 0 | K8: 0 | L8: N/A | M8: 58 | N8: 3 | O8: 9/4/2025 5:28:07 PM | P8: 1.4 | Q8: 1.6 | R8: Atenolol-Gli | S8: GLBN
B9: Ate_TA-1 | C9: Unknown | D9: N/A | E9: 10 | F9: 314000 | G9: 641000 | H9: 0.49 | J9: 0 | K9: 0 | L9: N/A | M9: 1 | N9: 3 | O9: 9/4/2025 5:31:42 PM | P9: 1.4 | Q9: 1.6 | R9: Atenolol-Gli | S9: GLBN
B10: Ate_TA-2 | C10: Unknown | D10: N/A | E10: 10 | F10: 292000 | G10: 629000 | H10: 0.464 | J10: 0 | K10: 0 | L10: N/A | M10: 2 | N10: 3 | O10: 9/4/2025 5:35:17 PM | P10: 1.4 | Q10: 1.6 | R10: Atenolol-Gli | S10: GLBN
B11: Wash | C11: Unknown | D11: N/A | E11: 1 | F11: 5560 | G11: 0 | H11: #DIV/0! | J11: 0 | K11: #DIV/0! | L11: N/A | M11: 20001 | N11: 3 | O11: 9/4/2025 5:38:50 PM | P11: 1.39 | Q11: 0 | R11: Atenolol-Gli | S11: GLBN
B12: Wash | C12: Unknown | D12: N/A | E12: 1 | F12: 0 | G12: 0 | H12: #DIV/0! | J12: 0 | K12: #DIV/0! | L12: N/A | M12: 20001 | N12: 3 | O12: 9/4/2025 5:42:23 PM | P12: 0 | Q12: 0 | R12: Atenolol-Gli | S12: GLBN
B13: Ate_T120-1 | C13: Unknown | D13: N/A | E13: 10 | F13: 307000 | G13: 632000 | H13: 0.486 | J13: 0 | K13: 0 | L13: N/A | M13: 37 | N13: 3 | O13: 9/4/2025 5:45:56 PM | P13: 1.4 | Q13: 1.6 | R13: Atenolol-Gli | S13: GLBN
B14: Ate_T120-2 | C14: Unknown | D14: N/A | E14: 10 | F14: 329000 | G14: 625000 | H14: 0.527 | J14: 0 | K14: 0 | L14: N/A | M14: 38 | N14: 3 | O14: 9/4/2025 5:49:31 PM | P14: 1.39 | Q14: 1.59 | R14: Atenolol-Gli | S14: GLBN
B15: Ate_T0-1 | C15: Unknown | D15: N/A | E15: 10 | F15: 302000 | G15: 637000 | H15: 0.474 | J15: 0 | K15: 0 | L15: N/A | M15: 25 | N15: 3 | O15: 9/4/2025 5:53:07 PM | P15: 1.4 | Q15: 1.6 | R15: Atenolol-Gli | S15: GLBN
B16: Ate_T0-2 | C16: Unknown | D16: N/A | E16: 10 | F16: 308000 | G16: 625000 | H16: 0.493 | J16: 0 | K16: 0 | L16: N/A | M16: 26 | N16: 3 | O16: 9/4/2025 5:56:42 PM | P16: 1.39 | Q16: 1.6 | R16: Atenolol-Gli | S16: GLBN
A17: Minoxidil | B17: Wash | C17: Unknown | D17: N/A | E17: 1 | F17: 0 | G17: 0 | H17: #DIV/0! | J17: 0 | K17: #DIV/0! | L17: N/A | M17: 20001 | N17: 3 | O17: 9/4/2025 6:00:16 PM | P17: 0 | Q17: 0 | R17: Minoxidil-Gli | S17: GLBN
B18: Wash | C18: Unknown | D18: N/A | E18: 1 | F18: 0 | G18: 0 | H18: #DIV/0! | J18: 0 | K18: #DIV/0! | L18: N/A | M18: 20001 | N18: 3 | O18: 9/4/2025 6:03:50 PM | P18: 0 | Q18: 0 | R18: Minoxidil-Gli | S18: GLBN
B19: Min_A-B_B1 | C19: Unknown | D19: N/A | E19: 1 | F19: 33800 | G19: 305000 | H19: 0.111 | J19: 0 | K19: 0 | L19: N/A | M19: 95 | N19: 3 | O19: 9/4/2025 6:07:21 PM | P19: 1.59 | Q19: 1.85 | R19: Minoxidil-Gli | S19: GLBN
B20: Min_A-B_B2 | C20: Unknown | D20: N/A | E20: 1 | F20: 32700 | G20: 300000 | H20: 0.109 | J20: 0 | K20: 0 | L20: N/A | M20: 96 | N20: 3 | O20: 9/4/2025 6:10:54 PM | P20: 1.6 | Q20: 1.85 | R20: Minoxidil-Gli | S20: GLBN
B21: Min_A-B_A1 | C21: Unknown | D21: N/A | E21: 10 | F21: 318000 | G21: 305000 | H21: 1.04 | J21: 0 | K21: 0 | L21: N/A | M21: 93 | N21: 3 | O21: 9/4/2025 6:14:26 PM | P21: 1.6 | Q21: 1.85 | R21: Minoxidil-Gli | S21: GLBN
B22: Min_A-B_A2 | C22: Unknown | D22: N/A | E22: 10 | F22: 323000 | G22: 300000 | H22: 1.08 | J22: 0 | K22: 0 | L22: N/A | M22: 94 | N22: 3 | O22: 9/4/2025 6:17:56 PM | P22: 1.6 | Q22: 1.85 | R22: Minoxidil-Gli | S22: GLBN
B23: Min_TA-1 | C23: Unknown | D23: N/A | E23: 10 | F23: 355000 | G23: 316000 | H23: 1.12 | J23: 0 | K23: 0 | L23: N/A | M23: 13 | N23: 3 | O23: 9/4/2025 6:21:28 PM | P23: 1.6 | Q23: 1.85 | R23: Minoxidil-Gli | S23: GLBN
B24: Min_TA-2 | C24: Unknown | D24: N/A | E24: 10 | F24: 317000 | G24: 293000 | H24: 1.08 | J24: 0 | K24: 0 | L24: N/A | M24: 14 | N24: 3 | O24: 9/4/2025 6:25:04 PM | P24: 1.59 | Q24: 1.85 | R24: Minoxidil-Gli | S24: GLBN
B25: Wash | C25: Unknown | D25: N/A | E25: 1 | F25: 0 | G25: 0 | H25: #DIV/0! | J25: 0 | K25: #DIV/0! | L25: N/A | M25: 20001 | N25: 3 | O25: 9/4/2025 6:28:37 PM | P25: 0 | Q25: 0 | R25: Minoxidil-Gli | S25: GLBN
B26: Wash | C26: Unknown | D26: N/A | E26: 1 | F26: 0 | G26: 0 | H26: #DIV/0! | J26: 0 | K26: #DIV/0! | L26: N/A | M26: 20001 | N26: 3 | O26: 9/4/2025 6:32:11 PM | P26: 0 | Q26: 0 | R26: Minoxidil-Gli | S26: GLBN
B27: Min_T120-1 | C27: Unknown | D27: N/A | E27: 10 | F27: 367000 | G27: 277000 | H27: 1.32 | J27: 0 | K27: 0 | L27: N/A | M27: 39 | N27: 3 | O27: 9/4/2025 6:35:45 PM | P27: 1.59 | Q27: 1.85 | R27: Minoxidil-Gli | S27: GLBN
B28: Min_T120-2 | C28: Unknown | D28: N/A | E28: 10 | F28: 351000 | G28: 301000 | H28: 1.17 | J28: 0 | K28: 0 | L28: N/A | M28: 40 | N28: 3 | O28: 9/4/2025 6:39:17 PM | P28: 1.59 | Q28: 1.84 | R28: Minoxidil-Gli | S28: GLBN
B29: Min_T0-1 | C29: Unknown | D29: N/A | E29: 10 | F29: 366000 | G29: 327000 | H29: 1.12 | J29: 0 | K29: 0 | L29: N/A | M29: 27 | N29: 3 | O29: 9/4/2025 6:42:51 PM | P29: 1.6 | Q29: 1.85 | R29: Minoxidil-Gli | S29: GLBN
B30: Min_T0-2 | C30: Unknown | D30: N/A | E30: 10 | F30: 364000 | G30: 316000 | H30: 1.15 | J30: 0 | K30: 0 | L30: N/A | M30: 28 | N30: 3 | O30: 9/4/2025 6:46:24 PM | P30: 1.59 | Q30: 1.85 | R30: Minoxidil-Gli | S30: GLBN
A31: Digoxin | B31: Wash | C31: Unknown | D31: N/A | E31: 1 | F31: 0 | G31: 0 | H31: #DIV/0! | J31: 0 | K31: #DIV/0! | L31: N/A | M31: 20001 | N31: 3 | O31: 9/4/2025 3:58:37 PM | P31: 0 | Q31: 0 | R31: Digoxin-Gli | S31: GLBN
B32: Wash | C32: Unknown | D32: N/A | E32: 1 | F32: 0 | G32: 0 | H32: #DIV/0! | J32: 0 | K32: #DIV/0! | L32: N/A | M32: 20001 | N32: 3 | O32: 9/4/2025 4:02:12 PM | P32: 0 | Q32: 0 | R32: Digoxin-Gli | S32: GLBN
B33: Dig_A-B_B1 | C33: Unknown | D33: N/A | E33: 1 | F33: 1190 | G33: 1390000 | H33: 0.000853 | J33: 0 | K33: 0 | L33: N/A | M33: 81 | N33: 3 | O33: 9/4/2025 4:05:46 PM | P33: 1.64 | Q33: 1.84 | R33: Digoxin-Gli | S33: GLBN
B34: Dig_A-B_B2 | C34: Unknown | D34: N/A | E34: 1 | F34: 1300 | G34: 1520000 | H34: 0.000851 | J34: 0 | K34: 0 | L34: N/A | M34: 82 | N34: 3 | O34: 9/4/2025 4:09:20 PM | P34: 1.64 | Q34: 1.84 | R34: Digoxin-Gli | S34: GLBN
B35: Dig_B-A_A1 | C35: Unknown | D35: N/A | E35: 1 | F35: 415000 | G35: 1560000 | H35: 0.266 | J35: 0 | K35: 0 | L35: N/A | M35: 71 | N35: 3 | O35: 9/4/2025 4:12:54 PM | P35: 1.64 | Q35: 1.84 | R35: Digoxin-Gli | S35: GLBN
B36: Dig_B-A_A2 | C36: Unknown | D36: N/A | E36: 1 | F36: 439000 | G36: 1570000 | H36: 0.28 | J36: 0 | K36: 0 | L36: N/A | M36: 72 | N36: 3 | O36: 9/4/2025 4:16:30 PM | P36: 1.63 | Q36: 1.84 | R36: Digoxin-Gli | S36: GLBN
B37: Dig_A-B_A1 | C37: Unknown | D37: N/A | E37: 10 | F37: 281000 | G37: 1530000 | H37: 0.183 | J37: 0 | K37: 0 | L37: N/A | M37: 69 | N37: 3 | O37: 9/4/2025 4:20:05 PM | P37: 1.63 | Q37: 1.84 | R37: Digoxin-Gli | S37: GLBN
B38: Dig_A-B_A2 | C38: Unknown | D38: N/A | E38: 10 | F38: 291000 | G38: 1540000 | H38: 0.189 | J38: 0 | K38: 0 | L38: N/A | M38: 70 | N38: 3 | O38: 9/4/2025 4:23:41 PM | P38: 1.65 | Q38: 1.85 | R38: Digoxin-Gli | S38: GLBN
B39: Dig_B-A_B1 | C39: Unknown | D39: N/A | E39: 10 | F39: 290000 | G39: 1560000 | H39: 0.186 | J39: 0 | K39: 0 | L39: N/A | M39: 83 | N39: 3 | O39: 9/4/2025 4:27:15 PM | P39: 1.64 | Q39: 1.85 | R39: Digoxin-Gli | S39: GLBN
B40: Dig_B-A_B2 | C40: Unknown | D40: N/A | E40: 10 | F40: 267000 | G40: 1480000 | H40: 0.181 | J40: 0 | K40: 0 | L40: N/A | M40: 84 | N40: 3 | O40: 9/4/2025 4:30:50 PM | P40: 1.64 | Q40: 1.85 | R40: Digoxin-Gli | S40: GLBN
B41: Dig_TA-1 | C41: Unknown | D41: N/A | E41: 10 | F41: 281000 | G41: 1560000 | H41: 0.18 | J41: 0 | K41: 0 | L41: N/A | M41: 3 | N41: 3 | O41: 9/4/2025 4:34:25 PM | P41: 1.64 | Q41: 1.85 | R41: Digoxin-Gli | S41: GLBN
...
