Workbook

Sheet CoverPage
A1: 3D BioOptima Quality That Matters
A2: 实验报告
A3: 实验标题 | B3: HW356060在人、犬、猴、大鼠和小鼠(五种属)肝微粒体代谢稳定性研究（加入二相代谢辅酶）
A4: 实验方案编号 | B4: 3D_PN322805
A5: 课题编号 | B5: 3D_SN322409
A6: 课题负责人 | B6: 杨德孝
A7: 化合物 | B7: =Summary!B10 -> HW356060
A8: 实验开始时间 | B8: 2025 年 03 月 25 日
A9: 实验结束时间 | B9: 2025 年 03 月 27 日
A10: 实验参与人员 | B10: 韩晓逸和蔡鑫鑫
A11: 报告撰写 | B11: 卜乐亮
A12: 数据质控 | B12: 程翠
A13: 实验负责方 | B13: 苏州圣苏新药开发有限公司 苏州市吴中区吴中大道1338号
A14: 实验委托方 | B14: 湖北生物医药产业技术研究院有限公司 武汉市东湖高新区高新大道666号C7栋217室

Sheet Summary
B2: 试剂信息
B3: 试剂 | C3: 品牌 | D3: 货号 | E3: 批号
B4: 人肝微粒体 | C4: BIOIVT | D4: X008070 | E4: IVX
B5: 猴肝微粒体 | C5: RILD | D5: MZYM | E5: MZYM
B6: 犬肝微粒体 | C6: CORNING | D6: 452601 | E6: 1291001
B7: 大鼠肝微粒体 | C7: CORNING | D7: 452501 | E7: 2175001
B8: 小鼠肝微粒体 | C8: CORNING | D8: 452701 | E8: 1237001
B9: NADPH | C9: REGAL | D9: 44332900-Y | E9: 050201
B10: HW356060 | C10: 湖北生物医药产业技术研究院有限公司 | D10: NA | E10: HWH817-YBC-035-4-38-1
D11: NA
B14: 孵育体系
B15: 肝微粒体 | C15: 0.5 mg/mL（受试化合物） 0.2 mg/mL（咪达唑仑，7-HC）
B16: 孵育缓冲液 | C16: 磷酸缓冲液 (100 mM，pH 7.4)
B17: 受试物 | C17: 1 µM
B18: 孵育体积 | C18: 0.2 mL（受试化合物） 0.1 mL（咪达唑仑，7-HC）
B19: 孵育时间 | C19: 0、5、15、30、60 min (受试化合物) 0、5、20 min（咪达唑仑，7-HC）
B20: MgCl2 | C20: 3 mM
B21: NADPH | C21: 1 mM
B22: 平行试验 | C22: 平行2份
B25: Summary
B26: 化合物 | C26: 种属 | D26: k (1/min) | E26: T1/2 (min) | F26: CLint, microsome (µL/min/mg proteins) | G26: CLint, in vivo (mL/min/kg)
B27: =B10 -> HW356060 | C27: Human | D27: ='HW356060'!D19 -> 0.00055753774 | E27: ='HW356060'!E19 -> 1504.1025 | F27: ='HW356060'!F19 -> 1.1150755 | G27: =IFERROR(F27*VLOOKUP($C27,$B$54:$F$60,4,0)*VLOOKUP($C27,$B$54:$F$60,5,0)/1000,"NA") -> 1.0537463
C28: Monkey | D28: ='HW356060'!D38 -> NA | E28: ='HW356060'!E38 -> NA | F28: ='HW356060'!F38 -> NA | G28: =IFERROR(F28*VLOOKUP($C28,$B$54:$F$60,4,0)*VLOOKUP($C28,$B$54:$F$60,5,0)/1000,"NA") -> NA
C29: Dog | D29: ='HW356060'!D57 -> NA | E29: ='HW356060'!E57 -> NA | F29: ='HW356060'!F57 -> NA | G29: =IFERROR(F29*VLOOKUP($C29,$B$54:$F$60,4,0)*VLOOKUP($C29,$B$54:$F$60,5,0)/1000,"NA") -> NA
C30: Rat | D30: ='HW356060'!D76 -> NA | E30: ='HW356060'!E76 -> NA | F30: ='HW356060'!F76 -> NA | G30: =IFERROR(F30*VLOOKUP($C30,$B$54:$F$60,4,0)*VLOOKUP($C30,$B$54:$F$60,5,0)/1000,"NA") -> NA
C31: Mouse | D31: ='HW356060'!D96 -> 0.00090213852 | E31: ='HW356060'!E96 -> 768.17472 | F31: ='HW356060'!F96 -> 1.804277 | G31: =IFERROR(F31*VLOOKUP($C31,$B$54:$F$60,4,0)*VLOOKUP($C31,$B$54:$F$60,5,0)/1000,"NA") -> 7.1043408
B32: Midazolam | C32: Human | D32: =Midazolam!D15 -> 0.090710164 | E32: =Midazolam!E15 -> 7.6398474 | F32: =Midazolam!F15 -> 453.55082 | G32: =F32*VLOOKUP($C32,$B$54:$F$60,4,0)*VLOOKUP($C32,$B$54:$F$60,5,0)/1000 -> 428.60552
C33: Monkey | D33: =Midazolam!D30 -> 0.13685071 | E33: =Midazolam!E30 -> 5.0639141 | F33: =Midazolam!F30 -> 684.25353 | G33: =F33*VLOOKUP($C33,$B$54:$F$60,4,0)*VLOOKUP($C33,$B$54:$F$60,5,0)/1000 -> 985.32508
C34: Dog | D34: =Midazolam!D45 -> 0.14782409 | E34: =Midazolam!E45 -> 4.6881135 | F34: =Midazolam!F45 -> 739.12043 | G34: =F34*VLOOKUP($C34,$B$54:$F$60,4,0)*VLOOKUP($C34,$B$54:$F$60,5,0)/1000 -> 1064.3334
C35: Rat | D35: =Midazolam!D60 -> 0.095423121 | E35: =Midazolam!E60 -> 7.2669698 | F35: =Midazolam!F60 -> 477.11561 | G35: =F35*VLOOKUP($C35,$B$54:$F$60,4,0)*VLOOKUP($C35,$B$54:$F$60,5,0)/1000 -> 858.80809
C36: Mouse | D36: =Midazolam!D75 -> 0.30578362 | E36: =Midazolam!E75 -> 2.2674421 | F36: =Midazolam!F75 -> 1528.9181 | G36: =F36*VLOOKUP($C36,$B$54:$F$60,4,0)*VLOOKUP($C36,$B$54:$F$60,5,0)/1000 -> 6020.1149
B37: 7-HC | C37: Human | D37: ='7-HC'!D15 -> 0.043827744 | E37: ='7-HC'!E15 -> 16.004496 | F37: ='7-HC'!F15 -> 219.13872 | G37: =F37*VLOOKUP($C37,$B$54:$F$60,4,0)*VLOOKUP($C37,$B$54:$F$60,5,0)/1000 -> 207.08609
C38: Monkey | D38: ='7-HC'!D30 -> 0.027622221 | E38: ='7-HC'!E30 -> 25.334907 | F38: ='7-HC'!F30 -> 138.1111 | G38: =F38*VLOOKUP($C38,$B$54:$F$60,4,0)*VLOOKUP($C38,$B$54:$F$60,5,0)/1000 -> 198.87999
C39: Dog | D39: ='7-HC'!D45 -> 0.039934367 | E39: ='7-HC'!E45 -> 17.41495 | F39: ='7-HC'!F45 -> 199.67184 | G39: =F39*VLOOKUP($C39,$B$54:$F$60,4,0)*VLOOKUP($C39,$B$54:$F$60,5,0)/1000 -> 287.52745
C40: Rat | D40: ='7-HC'!D60 -> 0.034704832 | E40: ='7-HC'!E60 -> 19.968401 | F40: ='7-HC'!F60 -> 173.52416 | G40: =F40*VLOOKUP($C40,$B$54:$F$60,4,0)*VLOOKUP($C40,$B$54:$F$60,5,0)/1000 -> 312.34349
C41: Mouse | D41: ='7-HC'!D75 -> 0.087695038 | E41: ='7-HC'!E75 -> 7.9063829 | F41: ='7-HC'!F75 -> 438.47519 | G41: =F41*VLOOKUP($C41,$B$54:$F$60,4,0)*VLOOKUP($C41,$B$54:$F$60,5,0)/1000 -> 1726.4961
B43: Drug elimination rate constant k (1/min), elimination half-life T1/2 (min), and in vitro intrinsic clearance CLint, in vitro (µL/min/mg protein) were calculated according to the following equations: k = - slope T1/2 = 0.693/k CLint, in vitro = k/Cprotein where Cprotein (mg/mL) is the microsomal protein concentration in the incubation system.
B50: CLint, in vivo = CLint, in vitro (mL/min/mg microsomal protein) × Scaling factor (physiological parameter) = CLint, in vitro (mL/min/mg microsomal protein) × Microsomal protein (mg protein/g liver) × Liver weight (g liver/kg body weight)
B51: CLint, in vivo is the intrinsic hepatic clearance, CLint, in vitro is the intrinsic clearance in LMs.
B54: Species | C54: Body Weight | D54: Qh | E54: Microsomes Protein | F54: Liver Weight
...

Sheet HW356060
B2: =CONCATENATE(Summary!$B$10,"在人肝微粒体中的代谢稳定性评估") -> HW356060在人肝微粒体中的代谢稳定性评估
B3: 样品 | D3: 孵育时间 (min) | E3: 峰面积比值 | F3: 平均值 | G3: 原药剩余量% | H3: Ln (原药剩余量%) | J3: 平均值
H4: #1 | I4: #2
B5: =B2 -> HW356060在人肝微粒体中的代谢稳定性评估 | C5: HW356060_HM-LM_60min-1 | D5: 60 | E5: =VLOOKUP($C5,'Raw Data'!$A$1:$S$2198,7,0) -> 1.01 | F5: =AVERAGE(E5:E6) -> 1.03 | G5: =E5/E13*100 -> 97.115385 | H5: =LN(G5) -> 4.5758998 | I5: =LN(G6) -> 4.5496003 | J5: =AVERAGE(H5:I6) -> 4.5627501
C6: HW356060_HM-LM_60min-2 | E6: =VLOOKUP($C6,'Raw Data'!$A$1:$S$2198,7,0) -> 1.05 | G6: =E6/E14*100 -> 94.594595
C7: HW356060_HM-LM_30min-1 | D7: 30 | E7: =VLOOKUP($C7,'Raw Data'!$A$1:$S$2198,7,0) -> 1.09 | F7: =AVERAGE(E7:E8) -> 1.045 | G7: =E7/E13*100 -> 104.80769 | H7: =LN(G7) -> 4.6521272 | I7: =LN(G8) -> 4.5008102 | J7: =AVERAGE(H7:I8) -> 4.5764687
C8: HW356060_HM-LM_30min-2 | E8: =VLOOKUP($C8,'Raw Data'!$A$1:$S$2198,7,0) -> 1 | G8: =E8/E14*100 -> 90.09009
C9: HW356060_HM-LM_15min-1 | D9: 15 | E9: =VLOOKUP($C9,'Raw Data'!$A$1:$S$2198,7,0) -> 1.12 | F9: =AVERAGE(E9:E10) -> 1.09 | G9: =E9/E13*100 -> 107.69231 | H9: =LN(G9) -> 4.6792782 | I9: =LN(G10) -> 4.5590791 | J9: =AVERAGE(H9:I10) -> 4.6191786
C10: HW356060_HM-LM_15min-2 | E10: =VLOOKUP($C10,'Raw Data'!$A$1:$S$2198,7,0) -> 1.06 | G10: =E10/E14*100 -> 95.495495
C11: HW356060_HM-LM_5min-1 | D11: 5 | E11: =VLOOKUP($C11,'Raw Data'!$A$1:$S$2198,7,0) -> 1.01 | F11: =AVERAGE(E11:E12) -> 1.035 | G11: =E11/E13*100 -> 97.115385 | H11: =LN(G11) -> 4.5758998 | I11: =LN(G12) -> 4.5590791 | J11: =AVERAGE(H11:I12) -> 4.5674894
C12: HW356060_HM-LM_5min-2 | E12: =VLOOKUP($C12,'Raw Data'!$A$1:$S$2198,7,0) -> 1.06 | G12: =E12/E14*100 -> 95.495495
C13: HW356060_HM-LM_0min-1 | D13: 0 | E13: =VLOOKUP($C13,'Raw Data'!$A$1:$S$2198,7,0) -> 1.04 | F13: =AVERAGE(E13:E14) -> 1.075 | G13: =E13/E13*100 -> 100 | H13: =LN(G13) -> 4.6051702 | I13: =LN(G14) -> 4.6051702 | J13: =AVERAGE(H13:I14) -> 4.6051702
C14: HW356060_HM-LM_0min-2 | E14: =VLOOKUP($C14,'Raw Data'!$A$1:$S$2198,7,0) -> 1.11 | G14: =E14/E14*100 -> 100
B15: 概要 | D15: =B5 -> HW356060在人肝微粒体中的代谢稳定性评估
D16: k (1/min) | E16: T1/2 (min) | F16: CLint, microsome (µL/min/mg proteins)
B17: #1 | D17: =IF(-SLOPE(H5:H14,D5:D14)<0,"NA",-SLOPE(H5:H14,D5:D14)) -> 0.0003252266 | E17: =IFERROR(0.693/D17,"NA") -> 2130.822 | F17: =IFERROR(D17/0.5*1000,"NA") -> 0.65045319
B18: #2 | D18: =IF(-SLOPE(I5:I14,D5:D14)<0,"NA",-SLOPE(I5:I14,D5:D14)) -> 0.00078984888 | E18: =IFERROR(0.693/D18,"NA") -> 877.38302 | F18: =IFERROR(D18/0.5*1000,"NA") -> 1.5796978
B19: 平均值 | D19: =IFERROR(AVERAGE(D17:D18),"NA") -> 0.00055753774 | E19: =IFERROR(AVERAGE(E17:E18),"NA") -> 1504.1025 | F19: =IFERROR(AVERAGE(F17:F18),"NA") -> 1.1150755
B21: =CONCATENATE(Summary!$B$10,"在猴肝微粒体中的代谢稳定性评估") -> HW356060在猴肝微粒体中的代谢稳定性评估
B22: 样品 | D22: 孵育时间 (min) | E22: 峰面积比值 | F22: 平均值 | G22: 原药剩余量% | H22: Ln (原药剩余量%) | J22: 平均值
H23: #1 | I23: #2
B24: =B21 -> HW356060在猴肝微粒体中的代谢稳定性评估 | C24: HW356060_MK-LM_60min-1 | D24: 60 | E24: =VLOOKUP($C24,'Raw Data'!$A$1:$S$2198,7,0) -> 1.18 | F24: =AVERAGE(E24:E25) -> 1.15 | G24: =E24/E32*100 -> 112.38095 | H24: =LN(G24) -> 4.7218945 | I24: =LN(G25) -> 4.7085485 | J24: =AVERAGE(H24:I25) -> 4.7152215
C25: HW356060_MK-LM_60min-2 | E25: =VLOOKUP($C25,'Raw Data'!$A$1:$S$2198,7,0) -> 1.12 | G25: =E25/E33*100 -> 110.89109
C26: HW356060_MK-LM_30min-1 | D26: 30 | E26: =VLOOKUP($C26,'Raw Data'!$A$1:$S$2198,7,0) -> 1.08 | F26: =AVERAGE(E26:E27) -> 1.045 | G26: =E26/E32*100 -> 102.85714 | H26: =LN(G26) -> 4.6333411 | I26: =LN(G27) -> 4.6051702 | J26: =AVERAGE(H26:I27) -> 4.6192556
C27: HW356060_MK-LM_30min-2 | E27: =VLOOKUP($C27,'Raw Data'!$A$1:$S$2198,7,0) -> 1.01 | G27: =E27/E33*100 -> 100
C28: HW356060_MK-LM_15min-1 | D28: 15 | E28: =VLOOKUP($C28,'Raw Data'!$A$1:$S$2198,7,0) -> 1.12 | F28: =AVERAGE(E28:E29) -> 1.11 | G28: =E28/E32*100 -> 106.66667 | H28: =LN(G28) -> 4.6697087 | I28: =LN(G29) -> 4.69053 | J28: =AVERAGE(H28:I29) -> 4.6801194
C29: HW356060_MK-LM_15min-2 | E29: =VLOOKUP($C29,'Raw Data'!$A$1:$S$2198,7,0) -> 1.1 | G29: =E29/E33*100 -> 108.91089
C30: HW356060_MK-LM_5min-1 | D30: 5 | E30: =VLOOKUP($C30,'Raw Data'!$A$1:$S$2198,7,0) -> 1.04 | F30: =AVERAGE(E30:E31) -> 1.04 | G30: =E30/E32*100 -> 99.047619 | H30: =LN(G30) -> 4.5956007 | I30: =LN(G31) -> 4.6344406 | J30: =AVERAGE(H30:I31) -> 4.6150207
C31: HW356060_MK-LM_5min-2 | E31: =VLOOKUP($C31,'Raw Data'!$A$1:$S$2198,7,0) -> 1.04 | G31: =E31/E33*100 -> 102.9703
C32: HW356060_MK-LM_0min-1 | D32: 0 | E32: =VLOOKUP($C32,'Raw Data'!$A$1:$S$2198,7,0) -> 1.05 | F32: =AVERAGE(E32:E33) -> 1.03 | G32: =E32/E32*100 -> 100 | H32: =LN(G32) -> 4.6051702 | I32: =LN(G33) -> 4.6051702 | J32: =AVERAGE(H32:I33) -> 4.6051702
C33: HW356060_MK-LM_0min-2 | E33: =VLOOKUP($C33,'Raw Data'!$A$1:$S$2198,7,0) -> 1.01 | G33: =E33/E33*100 -> 100
B34: 概要 | D34: =B24 -> HW356060在猴肝微粒体中的代谢稳定性评估
D35: k (1/min) | E35: T1/2 (min) | F35: CLint, microsome (µL/min/mg proteins)
B36: #1 | D36: =IF(-SLOPE(H24:H33,D24:D33)<0,"NA",-SLOPE(H24:H33,D24:D33)) -> NA | E36: =IFERROR(0.693/D36,"NA") -> NA | F36: =IFERROR(D36/0.5*1000,"NA") -> NA
B37: #2 | D37: =IF(-SLOPE(I24:I33,D24:D33)<0,"NA",-SLOPE(I24:I33,D24:D33)) -> NA | E37: =IFERROR(0.693/D37,"NA") -> NA | F37: =IFERROR(D37/0.5*1000,"NA") -> NA
B38: 平均值 | D38: =IFERROR(AVERAGE(D36:D37),"NA") -> NA | E38: =IFERROR(AVERAGE(E36:E37),"NA") -> NA | F38: =IFERROR(AVERAGE(F36:F37),"NA") -> NA
B40: =CONCATENATE(Summary!$B$10,"在犬肝微粒体中的代谢稳定性评估") -> HW356060在犬肝微粒体中的代谢稳定性评估
B41: 样品 | D41: 孵育时间 (min) | E41: 峰面积比值 | F41: 平均值 | G41: 原药剩余量% | H41: Ln (原药剩余量%) | J41: 平均值
H42: #1 | I42: #2
B43: =B40 -> HW356060在犬肝微粒体中的代谢稳定性评估 | C43: HW356060_BD-LM_60min-1 | D43: 60 | E43: =VLOOKUP($C43,'Raw Data'!$A$1:$S$2198,7,0) -> 1.26 | F43: =AVERAGE(E43:E44) -> 1.275 | G43: =E43/E51*100 -> 100 | H43: =LN(G43) -> 4.6051702 | I43: =LN(G44) -> 4.7113924 | J43: =AVERAGE(H43:I44) -> 4.6582813
...

Sheet Midazolam
B2: 咪达唑仑在人肝微粒体中的代谢稳定性评估
B3: 样品 | D3: 孵育时间 (min) | E3: 峰面积比值 | F3: 平均值 | G3: 原药剩余量% | H3: Ln (原药剩余量%) | J3: 平均值
H4: #1 | I4: #2
B5: 咪达唑仑 人肝微粒体 | C5: Midazolam_HM-LM_20min-1 | D5: 20 | E5: =VLOOKUP($C5,'Raw Data'!$A$92:$S$1716,7,0) -> 0.567 | F5: =AVERAGE(E5:E6) -> 0.579 | G5: =E5/E9*100 -> 16.107955 | H5: =LN(G5) -> 2.7793132 | I5: =LN(G6) -> 2.8236149 | J5: =AVERAGE(H5:I6) -> 2.8014641
C6: Midazolam_HM-LM_20min-2 | E6: =VLOOKUP($C6,'Raw Data'!$A$92:$S$1716,7,0) -> 0.591 | G6: =E6/E10*100 -> 16.837607
C7: Midazolam_HM-LM_5min-1 | D7: 5 | E7: =VLOOKUP($C7,'Raw Data'!$A$92:$S$1716,7,0) -> 2.2 | F7: =AVERAGE(E7:E8) -> 2.32 | G7: =E7/E9*100 -> 62.5 | H7: =LN(G7) -> 4.1351666 | I7: =LN(G8) -> 4.2415522 | J7: =AVERAGE(H7:I8) -> 4.1883594
C8: Midazolam_HM-LM_5min-2 | E8: =VLOOKUP($C8,'Raw Data'!$A$92:$S$1716,7,0) -> 2.44 | G8: =E8/E10*100 -> 69.51567
C9: Midazolam_HM-LM_0min-1 | D9: 0 | E9: =VLOOKUP($C9,'Raw Data'!$A$92:$S$1716,7,0) -> 3.52 | F9: =AVERAGE(E9:E10) -> 3.515 | G9: =E9/E9*100 -> 100 | H9: =LN(G9) -> 4.6051702 | I9: =LN(G10) -> 4.6051702 | J9: =AVERAGE(H9:I10) -> 4.6051702
C10: Midazolam_HM-LM_0min-2 | E10: =VLOOKUP($C10,'Raw Data'!$A$92:$S$1716,7,0) -> 3.51 | G10: =E10/E10*100 -> 100
B11: 概要 | D11: =B5 -> 咪达唑仑 人肝微粒体
D12: k (1/min) | E12: T1/2 (min) | F12: CLint, microsome (µL/min/mg proteins)
B13: #1 | D13: =-SLOPE(H5:H10,D5:D10) -> 0.09108455 | E13: =0.693/D13 -> 7.6083156 | F13: =D13/0.2*1000 -> 455.42275
B14: #2 | D14: =-SLOPE(I5:I10,D5:D10) -> 0.090335778 | E14: =0.693/D14 -> 7.6713791 | F14: =D14/0.2*1000 -> 451.67889
B15: 平均值 | D15: =AVERAGE(D13:D14) -> 0.090710164 | E15: =AVERAGE(E13:E14) -> 7.6398474 | F15: =AVERAGE(F13:F14) -> 453.55082
B17: 咪达唑仑在猴肝微粒体中的代谢稳定性评估
B18: 样品 | D18: 孵育时间 (min) | E18: 峰面积比值 | F18: 平均值 | G18: 原药剩余量% | H18: Ln (原药剩余量%) | J18: 平均值
H19: #1 | I19: #2
B20: 咪达唑仑 猴肝微粒体 | C20: Midazolam_MK-LM_20min-1 | D20: 20 | E20: =VLOOKUP($C20,'Raw Data'!$A$92:$S$1716,7,0) -> 0.216 | F20: =AVERAGE(E20:E21) -> 0.216 | G20: =E20/E24*100 -> 6.6666667 | H20: =LN(G20) -> 1.89712 | I20: =LN(G21) -> 1.8909661 | J20: =AVERAGE(H20:I21) -> 1.8940431
C21: Midazolam_MK-LM_20min-2 | E21: =VLOOKUP($C21,'Raw Data'!$A$92:$S$1716,7,0) -> 0.216 | G21: =E21/E25*100 -> 6.6257669
C22: Midazolam_MK-LM_5min-1 | D22: 5 | E22: =VLOOKUP($C22,'Raw Data'!$A$92:$S$1716,7,0) -> 1.8 | F22: =AVERAGE(E22:E23) -> 1.795 | G22: =E22/E24*100 -> 55.555556 | H22: =LN(G22) -> 4.0173835 | I22: =LN(G23) -> 4.0056586 | J22: =AVERAGE(H22:I23) -> 4.0115211
C23: Midazolam_MK-LM_5min-2 | E23: =VLOOKUP($C23,'Raw Data'!$A$92:$S$1716,7,0) -> 1.79 | G23: =E23/E25*100 -> 54.907975
C24: Midazolam_MK-LM_0min-1 | D24: 0 | E24: =VLOOKUP($C24,'Raw Data'!$A$92:$S$1716,7,0) -> 3.24 | F24: =AVERAGE(E24:E25) -> 3.25 | G24: =E24/E24*100 -> 100 | H24: =LN(G24) -> 4.6051702 | I24: =LN(G25) -> 4.6051702 | J24: =AVERAGE(H24:I25) -> 4.6051702
C25: Midazolam_MK-LM_0min-2 | E25: =VLOOKUP($C25,'Raw Data'!$A$92:$S$1716,7,0) -> 3.26 | G25: =E25/E25*100 -> 100
B26: 概要 | D26: =B20 -> 咪达唑仑 猴肝微粒体
D27: k (1/min) | E27: T1/2 (min) | F27: CLint, microsome (µL/min/mg proteins)
B28: #1 | D28: =-SLOPE(H20:H25,D20:D25) -> 0.13677522 | E28: =0.693/D28 -> 5.0667074 | F28: =D28/0.2*1000 -> 683.87608
B29: #2 | D29: =-SLOPE(I20:I25,D20:D25) -> 0.13692619 | E29: =0.693/D29 -> 5.0611207 | F29: =D29/0.2*1000 -> 684.63097
B30: 平均值 | D30: =AVERAGE(D28:D29) -> 0.13685071 | E30: =AVERAGE(E28:E29) -> 5.0639141 | F30: =AVERAGE(F28:F29) -> 684.25353
B32: 咪达唑仑在犬肝微粒体中的代谢稳定性评估
B33: 样品 | D33: 孵育时间 (min) | E33: 峰面积比值 | F33: 平均值 | G33: 原药剩余量% | H33: Ln (原药剩余量%) | J33: 平均值
H34: #1 | I34: #2
B35: 咪达唑仑 犬肝微粒体 | C35: Midazolam_BD-LM_20min-1 | D35: 20 | E35: =VLOOKUP($C35,'Raw Data'!$A$92:$S$1716,7,0) -> 0.169 | F35: =AVERAGE(E35:E36) -> 0.174 | G35: =E35/E39*100 -> 5.4166667 | H35: =LN(G35) -> 1.6894806 | I35: =LN(G36) -> 1.7123186 | J35: =AVERAGE(H35:I36) -> 1.7008996
C36: Midazolam_BD-LM_20min-2 | E36: =VLOOKUP($C36,'Raw Data'!$A$92:$S$1716,7,0) -> 0.179 | G36: =E36/E40*100 -> 5.5417957
C37: Midazolam_BD-LM_5min-1 | D37: 5 | E37: =VLOOKUP($C37,'Raw Data'!$A$92:$S$1716,7,0) -> 1.8 | F37: =AVERAGE(E37:E38) -> 1.82 | G37: =E37/E39*100 -> 57.692308 | H37: =LN(G37) -> 4.0551238 | I37: =LN(G38) -> 4.0424536 | J37: =AVERAGE(H37:I38) -> 4.0487887
C38: Midazolam_BD-LM_5min-2 | E38: =VLOOKUP($C38,'Raw Data'!$A$92:$S$1716,7,0) -> 1.84 | G38: =E38/E40*100 -> 56.965944
C39: Midazolam_BD-LM_0min-1 | D39: 0 | E39: =VLOOKUP($C39,'Raw Data'!$A$92:$S$1716,7,0) -> 3.12 | F39: =AVERAGE(E39:E40) -> 3.175 | G39: =E39/E39*100 -> 100 | H39: =LN(G39) -> 4.6051702 | I39: =LN(G40) -> 4.6051702 | J39: =AVERAGE(H39:I40) -> 4.6051702
C40: Midazolam_BD-LM_0min-2 | E40: =VLOOKUP($C40,'Raw Data'!$A$92:$S$1716,7,0) -> 3.23 | G40: =E40/E40*100 -> 100
B41: 概要 | D41: =B35 -> 咪达唑仑 犬肝微粒体
D42: k (1/min) | E42: T1/2 (min) | F42: CLint, microsome (µL/min/mg proteins)
B43: #1 | D43: =-SLOPE(H35:H40,D35:D40) -> 0.14853642 | E43: =0.693/D43 -> 4.6655225 | F43: =D43/0.2*1000 -> 742.68209
...

Sheet 7-HC
B2: 7-HC在人肝微粒体中的代谢稳定性评估
B3: 样品 | D3: 孵育时间 (min) | E3: 峰面积比值 | F3: 平均值 | G3: 原药剩余量% | H3: Ln (原药剩余量%) | J3: 平均值
H4: #1 | I4: #2
B5: 7-HC 人肝微粒体 | C5: 7-HC_HM-LM_20min-1 | D5: 20 | E5: =VLOOKUP($C5,'Raw Data'!$A$92:$S$1716,7,0) -> 0.081 | F5: =AVERAGE(E5:E6) -> 0.0758 | G5: =E5/E9*100 -> 45 | H5: =LN(G5) -> 3.8066625 | I5: =LN(G6) -> 3.6257584 | J5: =AVERAGE(H5:I6) -> 3.7162104
C6: 7-HC_HM-LM_20min-2 | E6: =VLOOKUP($C6,'Raw Data'!$A$92:$S$1716,7,0) -> 0.0706 | G6: =E6/E10*100 -> 37.553191
C7: 7-HC_HM-LM_5min-1 | D7: 5 | E7: =VLOOKUP($C7,'Raw Data'!$A$92:$S$1716,7,0) -> 0.139 | F7: =AVERAGE(E7:E8) -> 0.1415 | G7: =E7/E9*100 -> 77.222222 | H7: =LN(G7) -> 4.3466873 | I7: =LN(G8) -> 4.3385415 | J7: =AVERAGE(H7:I8) -> 4.3426144
C8: 7-HC_HM-LM_5min-2 | E8: =VLOOKUP($C8,'Raw Data'!$A$92:$S$1716,7,0) -> 0.144 | G8: =E8/E10*100 -> 76.595745
C9: 7-HC_HM-LM_0min-1 | D9: 0 | E9: =VLOOKUP($C9,'Raw Data'!$A$92:$S$1716,7,0) -> 0.18 | F9: =AVERAGE(E9:E10) -> 0.184 | G9: =E9/E9*100 -> 100 | H9: =LN(G9) -> 4.6051702 | I9: =LN(G10) -> 4.6051702 | J9: =AVERAGE(H9:I10) -> 4.6051702
C10: 7-HC_HM-LM_0min-2 | E10: =VLOOKUP($C10,'Raw Data'!$A$92:$S$1716,7,0) -> 0.188 | G10: =E10/E10*100 -> 100
B11: 概要 | D11: =B5 -> 7-HC 人肝微粒体
D12: k (1/min) | E12: T1/2 (min) | F12: CLint, microsome (µL/min/mg proteins)
B13: #1 | D13: =-SLOPE(H5:H10,D5:D10) -> 0.039019908 | E13: =0.693/D13 -> 17.760165 | F13: =D13/0.2*1000 -> 195.09954
B14: #2 | D14: =-SLOPE(I5:I10,D5:D10) -> 0.04863558 | E14: =0.693/D14 -> 14.248828 | F14: =D14/0.2*1000 -> 243.1779
B15: 平均值 | D15: =AVERAGE(D13:D14) -> 0.043827744 | E15: =AVERAGE(E13:E14) -> 16.004496 | F15: =AVERAGE(F13:F14) -> 219.13872
B17: 7-HC在猴肝微粒体中的代谢稳定性评估
B18: 样品 | D18: 孵育时间 (min) | E18: 峰面积比值 | F18: 平均值 | G18: 原药剩余量% | H18: Ln (原药剩余量%) | J18: 平均值
H19: #1 | I19: #2
B20: 7-HC 猴肝微粒体 | C20: 7-HC_MK-LM_20min-1 | D20: 20 | E20: =VLOOKUP($C20,'Raw Data'!$A$92:$S$1716,7,0) -> 0.106 | F20: =AVERAGE(E20:E21) -> 0.1095 | G20: =E20/E24*100 -> 52.475248 | H20: =LN(G20) -> 3.9603416 | I20: =LN(G21) -> 4.1068113 | J20: =AVERAGE(H20:I21) -> 4.0335765
C21: 7-HC_MK-LM_20min-2 | E21: =VLOOKUP($C21,'Raw Data'!$A$92:$S$1716,7,0) -> 0.113 | G21: =E21/E25*100 -> 60.752688
C22: 7-HC_MK-LM_5min-1 | D22: 5 | E22: =VLOOKUP($C22,'Raw Data'!$A$92:$S$1716,7,0) -> 0.152 | F22: =AVERAGE(E22:E23) -> 0.158 | G22: =E22/E24*100 -> 75.247525 | H22: =LN(G22) -> 4.320783 | I22: =LN(G23) -> 4.4792899 | J22: =AVERAGE(H22:I23) -> 4.4000365
C23: 7-HC_MK-LM_5min-2 | E23: =VLOOKUP($C23,'Raw Data'!$A$92:$S$1716,7,0) -> 0.164 | G23: =E23/E25*100 -> 88.172043
C24: 7-HC_MK-LM_0min-1 | D24: 0 | E24: =VLOOKUP($C24,'Raw Data'!$A$92:$S$1716,7,0) -> 0.202 | F24: =AVERAGE(E24:E25) -> 0.194 | G24: =E24/E24*100 -> 100 | H24: =LN(G24) -> 4.6051702 | I24: =LN(G25) -> 4.6051702 | J24: =AVERAGE(H24:I25) -> 4.6051702
C25: 7-HC_MK-LM_0min-2 | E25: =VLOOKUP($C25,'Raw Data'!$A$92:$S$1716,7,0) -> 0.186 | G25: =E25/E25*100 -> 100
B26: 概要 | D26: =B20 -> 7-HC 猴肝微粒体
D27: k (1/min) | E27: T1/2 (min) | F27: CLint, microsome (µL/min/mg proteins)
B28: #1 | D28: =-SLOPE(H20:H25,D20:D25) -> 0.030346353 | E28: =0.693/D28 -> 22.836352 | F28: =D28/0.2*1000 -> 151.73176
B29: #2 | D29: =-SLOPE(I20:I25,D20:D25) -> 0.024898088 | E29: =0.693/D29 -> 27.833462 | F29: =D29/0.2*1000 -> 124.49044
B30: 平均值 | D30: =AVERAGE(D28:D29) -> 0.027622221 | E30: =AVERAGE(E28:E29) -> 25.334907 | F30: =AVERAGE(F28:F29) -> 138.1111
B32: 7-HC在犬肝微粒体中的代谢稳定性评估
B33: 样品 | D33: 孵育时间 (min) | E33: 峰面积比值 | F33: 平均值 | G33: 原药剩余量% | H33: Ln (原药剩余量%) | J33: 平均值
H34: #1 | I34: #2
B35: 7-HC 犬肝微粒体 | C35: 7-HC_BD-LM_20min-1 | D35: 20 | E35: =VLOOKUP($C35,'Raw Data'!$A$92:$S$1716,7,0) -> 0.0879 | F35: =AVERAGE(E35:E36) -> 0.08175 | G35: =E35/E39*100 -> 47.005348 | H35: =LN(G35) -> 3.8502614 | I35: =LN(G36) -> 3.7601425 | J35: =AVERAGE(H35:I36) -> 3.8052019
C36: 7-HC_BD-LM_20min-2 | E36: =VLOOKUP($C36,'Raw Data'!$A$92:$S$1716,7,0) -> 0.0756 | G36: =E36/E40*100 -> 42.954545
C37: 7-HC_BD-LM_5min-1 | D37: 5 | E37: =VLOOKUP($C37,'Raw Data'!$A$92:$S$1716,7,0) -> 0.153 | F37: =AVERAGE(E37:E38) -> 0.148 | G37: =E37/E39*100 -> 81.818182 | H37: =LN(G37) -> 4.4044995 | I37: =LN(G38) -> 4.3975308 | J37: =AVERAGE(H37:I38) -> 4.4010152
C38: 7-HC_BD-LM_5min-2 | E38: =VLOOKUP($C38,'Raw Data'!$A$92:$S$1716,7,0) -> 0.143 | G38: =E38/E40*100 -> 81.25
C39: 7-HC_BD-LM_0min-1 | D39: 0 | E39: =VLOOKUP($C39,'Raw Data'!$A$92:$S$1716,7,0) -> 0.187 | F39: =AVERAGE(E39:E40) -> 0.1815 | G39: =E39/E39*100 -> 100 | H39: =LN(G39) -> 4.6051702 | I39: =LN(G40) -> 4.6051702 | J39: =AVERAGE(H39:I40) -> 4.6051702
C40: 7-HC_BD-LM_0min-2 | E40: =VLOOKUP($C40,'Raw Data'!$A$92:$S$1716,7,0) -> 0.176 | G40: =E40/E40*100 -> 100
B41: 概要 | D41: =B35 -> 7-HC 犬肝微粒体
D42: k (1/min) | E42: T1/2 (min) | F42: CLint, microsome (µL/min/mg proteins)
B43: #1 | D43: =-SLOPE(H35:H40,D35:D40) -> 0.037561695 | E43: =0.693/D43 -> 18.449647 | F43: =D43/0.2*1000 -> 187.80847
...

Sheet Raw Data
A1: =Summary!B10 -> HW356060
A2: Peak Name: Ver
A3: Use as Internal Standard
A4: Q1/Q3 Masses: 455.20/165.10 Da
A5: Peak Name: Gli
A6: Use as Internal Standard
A7: Q1/Q3 Masses: 494.20/369.10 Da
A9: Peak Name: HW356060-Ver
A10: Internal Standard: Ver
A11: Q1/Q3 Masses: 603.10/330.00 Da
A13: Fit | B13: Linear | C13: Weighting | D13: 1 / (x * x) | E13: Iterate | F13: No
A14: Error | B14: At least 2 points are required to calculate regression.
A15: Use Area
A17: Peak Name: HW356060-Gli
A18: Internal Standard: Gli
A19: Q1/Q3 Masses: 603.10/330.00 Da
A21: Fit | B21: Linear | C21: Weighting | D21: 1 / (x * x) | E21: Iterate | F21: No
A22: Error | B22: At least 2 points are required to calculate regression.
A23: Use Area
A27: Sample Name | B27: Sample Type | C27: Analyte Concentration (nM) | D27: Dilution Factor | E27: Analyte Peak Area (counts) | F27: IS Peak Area (counts) | G27: Area Ratio | H27: Use Record | I27: Record Modified | J27: Calculated Concentration (nM) | K27: Accuracy (%) | L27: Vial Position | M27: Rack Position | N27: Acquisition Date
A28: Wash | B28: Unknown | C28: N/A | D28: 1 | E28: 0 | F28: 0 | G28: #DIV/0! | I28: 0 | J28: #DIV/0! | K28: N/A | L28: 20001 | M28: 1 | N28: 3/26/2025 12:32:05 PM
A29: Wash | B29: Unknown | C29: N/A | D29: 1 | E29: 0 | F29: 0 | G29: #DIV/0! | I29: 0 | J29: #DIV/0! | K29: N/A | L29: 20001 | M29: 1 | N29: 3/26/2025 12:35:29 PM
A30: HW356060_HM-LM_60min-1 | B30: Unknown | C30: N/A | D30: 1 | E30: 134000 | F30: 133000 | G30: 1.01 | I30: 0 | J30: 0 | K30: N/A | L30: 1 | M30: 1 | N30: 3/26/2025 12:38:56 PM
A31: HW356060_HM-LM_60min-2 | B31: Unknown | C31: N/A | D31: 1 | E31: 136000 | F31: 130000 | G31: 1.05 | I31: 0 | J31: 0 | K31: N/A | L31: 2 | M31: 1 | N31: 3/26/2025 12:42:27 PM
A32: HW356060_HM-LM_30min-1 | B32: Unknown | C32: N/A | D32: 1 | E32: 135000 | F32: 124000 | G32: 1.09 | I32: 0 | J32: 0 | K32: N/A | L32: 13 | M32: 1 | N32: 3/26/2025 12:45:56 PM
A33: HW356060_HM-LM_30min-2 | B33: Unknown | C33: N/A | D33: 1 | E33: 122000 | F33: 122000 | G33: 1 | I33: 0 | J33: 0 | K33: N/A | L33: 14 | M33: 1 | N33: 3/26/2025 12:49:24 PM
A34: HW356060_HM-LM_15min-1 | B34: Unknown | C34: N/A | D34: 1 | E34: 146000 | F34: 131000 | G34: 1.12 | I34: 0 | J34: 0 | K34: N/A | L34: 25 | M34: 1 | N34: 3/26/2025 12:52:53 PM
A35: HW356060_HM-LM_15min-2 | B35: Unknown | C35: N/A | D35: 1 | E35: 140000 | F35: 132000 | G35: 1.06 | I35: 0 | J35: 0 | K35: N/A | L35: 26 | M35: 1 | N35: 3/26/2025 12:56:21 PM
A36: HW356060_HM-LM_5min-1 | B36: Unknown | C36: N/A | D36: 1 | E36: 143000 | F36: 142000 | G36: 1.01 | I36: 0 | J36: 0 | K36: N/A | L36: 37 | M36: 1 | N36: 3/26/2025 12:59:49 PM
A37: HW356060_HM-LM_5min-2 | B37: Unknown | C37: N/A | D37: 1 | E37: 143000 | F37: 135000 | G37: 1.06 | I37: 0 | J37: 0 | K37: N/A | L37: 38 | M37: 1 | N37: 3/26/2025 1:03:18 PM
A38: HW356060_HM-LM_0min-1 | B38: Unknown | C38: N/A | D38: 1 | E38: 140000 | F38: 134000 | G38: 1.04 | I38: 0 | J38: 0 | K38: N/A | L38: 49 | M38: 1 | N38: 3/26/2025 1:06:47 PM
A39: HW356060_HM-LM_0min-2 | B39: Unknown | C39: N/A | D39: 1 | E39: 136000 | F39: 123000 | G39: 1.11 | I39: 0 | J39: 0 | K39: N/A | L39: 50 | M39: 1 | N39: 3/26/2025 1:10:14 PM
A40: Wash | B40: Unknown | C40: N/A | D40: 1 | E40: 0 | F40: 0 | G40: #DIV/0! | I40: 0 | J40: #DIV/0! | K40: N/A | L40: 20001 | M40: 1 | N40: 3/26/2025 1:13:42 PM
A41: Wash | B41: Unknown | C41: N/A | D41: 1 | E41: 0 | F41: 0 | G41: #DIV/0! | I41: 0 | J41: #DIV/0! | K41: N/A | L41: 20001 | M41: 1 | N41: 3/26/2025 1:17:07 PM
A42: HW356060_MK-LM_60min-1 | B42: Unknown | C42: N/A | D42: 1 | E42: 141000 | F42: 119000 | G42: 1.18 | I42: 0 | J42: 0 | K42: N/A | L42: 3 | M42: 1 | N42: 3/26/2025 1:20:36 PM
A43: HW356060_MK-LM_60min-2 | B43: Unknown | C43: N/A | D43: 1 | E43: 134000 | F43: 120000 | G43: 1.12 | I43: 0 | J43: 0 | K43: N/A | L43: 4 | M43: 1 | N43: 3/26/2025 1:24:04 PM
A44: HW356060_MK-LM_30min-1 | B44: Unknown | C44: N/A | D44: 1 | E44: 137000 | F44: 127000 | G44: 1.08 | I44: 0 | J44: 0 | K44: N/A | L44: 15 | M44: 1 | N44: 3/26/2025 1:27:32 PM
A45: HW356060_MK-LM_30min-2 | B45: Unknown | C45: N/A | D45: 1 | E45: 129000 | F45: 127000 | G45: 1.01 | I45: 0 | J45: 0 | K45: N/A | L45: 16 | M45: 1 | N45: 3/26/2025 1:31:01 PM
A46: HW356060_MK-LM_15min-1 | B46: Unknown | C46: N/A | D46: 1 | E46: 145000 | F46: 130000 | G46: 1.12 | I46: 0 | J46: 0 | K46: N/A | L46: 27 | M46: 1 | N46: 3/26/2025 1:34:29 PM
A47: HW356060_MK-LM_15min-2 | B47: Unknown | C47: N/A | D47: 1 | E47: 146000 | F47: 133000 | G47: 1.1 | I47: 0 | J47: 0 | K47: N/A | L47: 28 | M47: 1 | N47: 3/26/2025 1:37:57 PM
...

Sheet Analytical Method
B3: 液相分析条件
B4: Time | C4: B% | D4: Instrument | E4: LC-MS/MS (API4000: LC-MS-MS-009)
B5: 0.5 | C5: 15
B6: 1 | C6: 95 | D6: Phase A | E6: A：水（含0.1%甲酸）
B7: 1.8 | C7: =C6 -> 95 | D7: Phase B | E7: B：乙腈（含0.1%甲酸）
B8: 1.81 | C8: =C5 -> 15
B9: 3 | C9: stop | D9: Column | E9: Agilent ZORBAX XDB-C18, 5 μm, 2.1×50 mm (50-436)
B12: 质谱条件
B13: 名称 | C13: Q1 | D13: Q3 | E13: DP | F13: CE | G13: CXP
B14: =Summary!B10 -> HW356060 | C14: 603.1 | D14: 330 | E14: 60 | F14: 42 | G14: 15
B15: IS (Verapamil) | C15: 455.2 | D15: 165.1 | E15: 70 | F15: 39 | G15: 12
