Workbook
Name OLE_LINK1: CoverPage!$B$7
Name OLE_LINK10: CoverPage!$B$8
Name OLE_LINK12: CoverPage!$B$9

Sheet CoverPage
A1: 3D BioOptima Quality That Matters
A2: 实验项目 | B2: HW356009-P1在小鼠、大鼠、犬、猴和人血浆中的蛋白结合率测定
A3: 实验项目编号 | B3: 3D_PN322788
A4: 课题编号 | B4: 3D_SN322400
A5: 课题负责人 | B5: 杨德孝
A6: 化合物 | B6: =Summary!A2 -> HW356009-P1
A7: 实验开始时间 | B7: 2025 年 02 月 26 日
A8: 实验结束时间 | B8: 2025 年 03 月 04 日
A9: 实验参与人员 | B9: 韩晓逸和蔡鑫鑫
A10: 报告撰写 | B10: 钱晨艳
A11: 数据质控 | B11: 程翠
A12: 实验负责方 | B12: 苏州圣苏新药开发有限公司 苏州市吴中区吴中大道1338号
A13: 实验委托方 | B13: 湖北生物医药产业技术研究院有限公司 武汉市东湖高新区高新大道666号C7栋217室

Sheet Summary
A1: 受试化合物
A2: HW356009-P1
A7: 化合物 | B7: 人 | F7: 食蟹猴 | J7: 比格犬 | N7: 大鼠 | R7: 小鼠
B8: fu% | C8: fb% | D8: 回收率 % | E8: 稳定性 % | F8: fu% | G8: fb% | H8: 回收率 % | I8: 稳定性 % | J8: fu% | K8: fb% | L8: 回收率 % | M8: 稳定性 % | N8: fu% | O8: fb% | P8: 回收率 % | Q8: 稳定性 % | R8: fu% | S8: fb% | T8: 回收率 % | U8: 稳定性 %
A9: 华法林 | B9: =Controls!N4 -> 0.45459068 | C9: =100-B9 -> 99.545409 | D9: =Controls!P4 -> 89.043089 | E9: - | F9: =Controls!N13 -> 0.49601139 | G9: =100-F9 -> 99.503989 | H9: =Controls!P13 -> 87.624867 | I9: - | J9: =Controls!N22 -> 2.9800496 | K9: =100-J9 -> 97.01995 | L9: =Controls!P22 -> 93.705135 | M9: - | N9: =Controls!N31 -> 0.35010646 | O9: =100-N9 -> 99.649894 | P9: =Controls!P31 -> 84.955924 | Q9: - | R9: =Controls!N40 -> 5.7381689 | S9: =100-R9 -> 94.261831 | T9: =Controls!P40 -> 92.118437 | U9: -
A10: 对乙酰氨基酚 | B10: =Controls!N52 -> 80.297872 | C10: =100-B10 -> 19.702128 | D10: =Controls!P52 -> 88.051471 | E10: - | F10: =Controls!N61 -> 87.5 | G10: =100-F10 -> 12.5 | H10: =Controls!P61 -> 93.360996 | I10: - | J10: =Controls!N70 -> 82.657633 | K10: =100-J10 -> 17.342367 | L10: =Controls!P70 -> 85.093168 | M10: - | N10: =Controls!N79 -> 64.376755 | O10: =100-N10 -> 35.623245 | P10: =Controls!P79 -> 92.46988 | Q10: - | R10: =Controls!N88 -> 79.099512 | S10: =100-R10 -> 20.900488 | T10: =Controls!P88 -> 94.536082 | U10: -
A11: =A2 -> HW356009-P1 | B11: ='HW356009-P1'!$M$4 -> 2.1903007 | C11: =100-B11 -> 97.809699 | D11: ='HW356009-P1'!$O$4 -> 95.227136 | E11: ='HW356009-P1'!$J$13 -> 102.48619 | F11: ='HW356009-P1'!$M$19 -> 2.2579317 | G11: =100-F11 -> 97.742068 | H11: ='HW356009-P1'!$O$19 -> 100.85467 | I11: ='HW356009-P1'!$J$28 -> 104.71294 | J11: ='HW356009-P1'!$M$34 -> 2.2571961 | K11: =100-J11 -> 97.742804 | L11: ='HW356009-P1'!$O$34 -> 98.919158 | M11: ='HW356009-P1'!$J$43 -> 99.398625 | N11: ='HW356009-P1'!$M$49 -> 3.3287478 | O11: =100-N11 -> 96.671252 | P11: ='HW356009-P1'!$O$49 -> 97.216681 | Q11: ='HW356009-P1'!$J$58 -> 100.17376 | R11: ='HW356009-P1'!$M$64 -> 2.7190626 | S11: =100-R11 -> 97.280937 | T11: ='HW356009-P1'!$O$64 -> 95.126338 | U11: ='HW356009-P1'!$J$73 -> 97.790994
A14: CR: | B14: 接收室孔测得的峰面积比值
A15: CD: | B15: 供应室孔测得的峰面积比值
A16: CI: | B16: 孵育前供应室孔测得的峰面积比值
A17: Cs: | B17: 稳定性样品峰面积比值
A18: fu | B18: 游离蛋白百分比

Sheet HW356009-P1
A1: 人
A2: =CONCATENATE(Summary!$A$2,"-Human Plasma 100%") -> HW356009-P1-Human Plasma 100%
A3: 样品名 | B3: 孵育浓度（µM） | C3: 稀释因子 | D3: 化合物峰面积 | E3: 内标峰面积 | F3: 峰面积比 | G3: 计算峰面积比 | H3: 平均值 | I3: 总和 | J3: 平均值 | K3: Fu (%) | L3: Fb (%) | M3: 平均值Fu (%) | N3: 回收率 (%) | O3: 平均值 (%)
A4: HW356009-P1_HM-PL_1uM-B1 | B4: ='Experimental detail'!$C$6 -> 1 | C4: =VLOOKUP($A4,'Raw data'!$A$1:$T$1052,4,0) -> 1.11 | D4: =VLOOKUP($A4,'Raw data'!$A$1:$T$1052,5,0) -> 129000 | E4: =VLOOKUP($A4,'Raw data'!$A$1:$T$1052,6,0) -> 1270000 | F4: =VLOOKUP($A4,'Raw data'!$A$1:$T$1052,7,0) -> 0.102 | G4: =C4*F4 -> 0.11322 | H4: =AVERAGE(G4:G5) -> 0.1108335 | I4: =G4+G6 -> 5.18322 | J4: =AVERAGE(I4:I5) -> 5.1708335 | K4: =G4/G6*100 -> 2.2331361 | L4: =100-K4 -> 97.766864 | M4: =AVERAGE(K4:K5) -> 2.1903007 | N4: =I4/H8*100 -> 95.455249 | O4: =AVERAGE(N4:N5) -> 95.227136
A5: HW356009-P1_HM-PL_1uM-B2 | C5: =VLOOKUP($A5,'Raw data'!$A$1:$T$1052,4,0) -> 1.11 | D5: =VLOOKUP($A5,'Raw data'!$A$1:$T$1052,5,0) -> 134000 | E5: =VLOOKUP($A5,'Raw data'!$A$1:$T$1052,6,0) -> 1370000 | F5: =VLOOKUP($A5,'Raw data'!$A$1:$T$1052,7,0) -> 0.0977 | G5: =C5*F5 -> 0.108447 | I5: =G5+G7 -> 5.158447 | K5: =G5/G7*100 -> 2.1474653 | L5: =100-K5 -> 97.852535 | N5: =I5/H8*100 -> 94.999024
A6: HW356009-P1_HM-PL_1uM-A1 | B6: ='Experimental detail'!$C$6 -> 1 | C6: =VLOOKUP($A6,'Raw data'!$A$1:$T$1052,4,0) -> 10 | D6: =VLOOKUP($A6,'Raw data'!$A$1:$T$1052,5,0) -> 671000 | E6: =VLOOKUP($A6,'Raw data'!$A$1:$T$1052,6,0) -> 1320000 | F6: =VLOOKUP($A6,'Raw data'!$A$1:$T$1052,7,0) -> 0.507 | G6: =C6*F6 -> 5.07 | H6: =AVERAGE(G6:G7) -> 5.06
A7: HW356009-P1_HM-PL_1uM-A2 | C7: =VLOOKUP($A7,'Raw data'!$A$1:$T$1052,4,0) -> 10 | D7: =VLOOKUP($A7,'Raw data'!$A$1:$T$1052,5,0) -> 651000 | E7: =VLOOKUP($A7,'Raw data'!$A$1:$T$1052,6,0) -> 1290000 | F7: =VLOOKUP($A7,'Raw data'!$A$1:$T$1052,7,0) -> 0.505 | G7: =C7*F7 -> 5.05
A8: HW356009-P1_HM-PL_1uM-R1 | B8: ='Experimental detail'!$C$6 -> 1 | C8: =VLOOKUP($A8,'Raw data'!$A$1:$T$1052,4,0) -> 10 | D8: =VLOOKUP($A8,'Raw data'!$A$1:$T$1052,5,0) -> 667000 | E8: =VLOOKUP($A8,'Raw data'!$A$1:$T$1052,6,0) -> 1250000 | F8: =VLOOKUP($A8,'Raw data'!$A$1:$T$1052,7,0) -> 0.532 | G8: =C8*F8 -> 5.32 | H8: =AVERAGE(G8:G9) -> 5.43
A9: HW356009-P1_HM-PL_1uM-R2 | C9: =VLOOKUP($A9,'Raw data'!$A$1:$T$1052,4,0) -> 10 | D9: =VLOOKUP($A9,'Raw data'!$A$1:$T$1052,5,0) -> 719000 | E9: =VLOOKUP($A9,'Raw data'!$A$1:$T$1052,6,0) -> 1300000 | F9: =VLOOKUP($A9,'Raw data'!$A$1:$T$1052,7,0) -> 0.554 | G9: =C9*F9 -> 5.54
A11: =CONCATENATE("Stability of ",Summary!$A$2," in Human Plasma Incubated at 37 °C") -> Stability of HW356009-P1 in Human Plasma Incubated at 37 °C
A12: 样品名 | B12: 孵育浓度（µM） | C12: 对照样品的峰面积比平均值 | D12: 稀释因子 | E12: 化合物峰面积 | F12: 内标峰面积 | G12: 峰面积比 | H12: 计算峰面积比 | I12: 稳定性(%) | J12: 平均值(%)
A13: HW356009-P1_HM-PL_1uM-S1 | B13: ='Experimental detail'!$C$6 -> 1 | C13: =H8 -> 5.43 | D13: =VLOOKUP($A13,'Raw data'!$A$1:$T$1052,4,0) -> 10 | E13: =VLOOKUP($A13,'Raw data'!$A$1:$T$1052,5,0) -> 707000 | F13: =VLOOKUP($A13,'Raw data'!$A$1:$T$1052,6,0) -> 1330000 | G13: =VLOOKUP($A13,'Raw data'!$A$1:$T$1052,7,0) -> 0.533 | H13: =D13*G13 -> 5.33 | I13: =H13/C13*100 -> 98.158379 | J13: =AVERAGE(I13:I14) -> 102.48619
A14: HW356009-P1_HM-PL_1uM-S2 | D14: =VLOOKUP($A14,'Raw data'!$A$1:$T$1052,4,0) -> 10 | E14: =VLOOKUP($A14,'Raw data'!$A$1:$T$1052,5,0) -> 706000 | F14: =VLOOKUP($A14,'Raw data'!$A$1:$T$1052,6,0) -> 1220000 | G14: =VLOOKUP($A14,'Raw data'!$A$1:$T$1052,7,0) -> 0.58 | H14: =D14*G14 -> 5.8 | I14: =H14/C13*100 -> 106.814
A16: 食蟹猴
A17: =CONCATENATE(Summary!$A$2,"-Monkey Plasma 100%") -> HW356009-P1-Monkey Plasma 100%
A18: 样品名 | B18: 孵育浓度（µM） | C18: 稀释因子 | D18: 化合物峰面积 | E18: 内标峰面积 | F18: 峰面积比 | G18: 计算峰面积比 | H18: 平均值 | I18: 总和 | J18: 平均值 | K18: Fu (%) | L18: Fb (%) | M18: 平均值Fu (%) | N18: 回收率 (%) | O18: 平均值 (%)
A19: HW356009-P1_MK-PL_1uM-B1 | B19: ='Experimental detail'!$C$6 -> 1 | C19: =VLOOKUP($A19,'Raw data'!$A$1:$T$1052,4,0) -> 1.11 | D19: =VLOOKUP($A19,'Raw data'!$A$1:$T$1052,5,0) -> 145000 | E19: =VLOOKUP($A19,'Raw data'!$A$1:$T$1052,6,0) -> 1260000 | F19: =VLOOKUP($A19,'Raw data'!$A$1:$T$1052,7,0) -> 0.115 | G19: =C19*F19 -> 0.12765 | H19: =AVERAGE(G19:G20) -> 0.12987 | I19: =G19+G21 -> 5.68765 | J19: =AVERAGE(I19:I20) -> 5.88487 | K19: =G19/G21*100 -> 2.2958633 | L19: =100-K19 -> 97.704137 | M19: =AVERAGE(K19:K20) -> 2.2579317 | N19: =I19/H23*100 -> 97.474722 | O19: =AVERAGE(N19:N20) -> 100.85467
A20: HW356009-P1_MK-PL_1uM-B2 | C20: =VLOOKUP($A20,'Raw data'!$A$1:$T$1052,4,0) -> 1.11 | D20: =VLOOKUP($A20,'Raw data'!$A$1:$T$1052,5,0) -> 154000 | E20: =VLOOKUP($A20,'Raw data'!$A$1:$T$1052,6,0) -> 1290000 | F20: =VLOOKUP($A20,'Raw data'!$A$1:$T$1052,7,0) -> 0.119 | G20: =C20*F20 -> 0.13209 | I20: =G20+G22 -> 6.08209 | K20: =G20/G22*100 -> 2.22 | L20: =100-K20 -> 97.78 | N20: =I20/H23*100 -> 104.23462
A21: HW356009-P1_MK-PL_1uM-A1 | B21: ='Experimental detail'!$C$6 -> 1 | C21: =VLOOKUP($A21,'Raw data'!$A$1:$T$1052,4,0) -> 10 | D21: =VLOOKUP($A21,'Raw data'!$A$1:$T$1052,5,0) -> 704000 | E21: =VLOOKUP($A21,'Raw data'!$A$1:$T$1052,6,0) -> 1270000 | F21: =VLOOKUP($A21,'Raw data'!$A$1:$T$1052,7,0) -> 0.556 | G21: =C21*F21 -> 5.56 | H21: =AVERAGE(G21:G22) -> 5.755
A22: HW356009-P1_MK-PL_1uM-A2 | C22: =VLOOKUP($A22,'Raw data'!$A$1:$T$1052,4,0) -> 10 | D22: =VLOOKUP($A22,'Raw data'!$A$1:$T$1052,5,0) -> 816000 | E22: =VLOOKUP($A22,'Raw data'!$A$1:$T$1052,6,0) -> 1370000 | F22: =VLOOKUP($A22,'Raw data'!$A$1:$T$1052,7,0) -> 0.595 | G22: =C22*F22 -> 5.95
A23: HW356009-P1_MK-PL_1uM-R1 | B23: ='Experimental detail'!$C$6 -> 1 | C23: =VLOOKUP($A23,'Raw data'!$A$1:$T$1052,4,0) -> 10 | D23: =VLOOKUP($A23,'Raw data'!$A$1:$T$1052,5,0) -> 755000 | E23: =VLOOKUP($A23,'Raw data'!$A$1:$T$1052,6,0) -> 1320000 | F23: =VLOOKUP($A23,'Raw data'!$A$1:$T$1052,7,0) -> 0.571 | G23: =C23*F23 -> 5.71 | H23: =AVERAGE(G23:G24) -> 5.835
A24: HW356009-P1_MK-PL_1uM-R2 | C24: =VLOOKUP($A24,'Raw data'!$A$1:$T$1052,4,0) -> 10 | D24: =VLOOKUP($A24,'Raw data'!$A$1:$T$1052,5,0) -> 762000 | E24: =VLOOKUP($A24,'Raw data'!$A$1:$T$1052,6,0) -> 1280000 | F24: =VLOOKUP($A24,'Raw data'!$A$1:$T$1052,7,0) -> 0.596 | G24: =C24*F24 -> 5.96
A26: =CONCATENATE("Stability of ",Summary!$A$2," in Monkey Plasma Incubated at 37 °C") -> Stability of HW356009-P1 in Monkey Plasma Incubated at 37 °C
A27: 样品名 | B27: 孵育浓度（µM） | C27: 对照样品的峰面积比平均值 | D27: 稀释因子 | E27: 化合物峰面积 | F27: 内标峰面积 | G27: 峰面积比 | H27: 计算峰面积比 | I27: 稳定性(%) | J27: 平均值(%)
A28: HW356009-P1_MK-PL_1uM-S1 | B28: ='Experimental detail'!$C$6 -> 1 | C28: =H23 -> 5.835 | D28: =VLOOKUP($A28,'Raw data'!$A$1:$T$1052,4,0) -> 10 | E28: =VLOOKUP($A28,'Raw data'!$A$1:$T$1052,5,0) -> 791000 | F28: =VLOOKUP($A28,'Raw data'!$A$1:$T$1052,6,0) -> 1300000 | G28: =VLOOKUP($A28,'Raw data'!$A$1:$T$1052,7,0) -> 0.608 | H28: =D28*G28 -> 6.08 | I28: =H28/C28*100 -> 104.1988 | J28: =AVERAGE(I28:I29) -> 104.71294
A29: HW356009-P1_MK-PL_1uM-S2 | D29: =VLOOKUP($A29,'Raw data'!$A$1:$T$1052,4,0) -> 10 | E29: =VLOOKUP($A29,'Raw data'!$A$1:$T$1052,5,0) -> 770000 | F29: =VLOOKUP($A29,'Raw data'!$A$1:$T$1052,6,0) -> 1250000 | G29: =VLOOKUP($A29,'Raw data'!$A$1:$T$1052,7,0) -> 0.614 | H29: =D29*G29 -> 6.14 | I29: =H29/C28*100 -> 105.22708
A31: 比格犬
A32: =CONCATENATE(Summary!$A$2,"-Dog Plasma 100%") -> HW356009-P1-Dog Plasma 100%
A33: 样品名 | B33: 孵育浓度（µM） | C33: 稀释因子 | D33: 化合物峰面积 | E33: 内标峰面积 | F33: 峰面积比 | G33: 计算峰面积比 | H33: 平均值 | I33: 总和 | J33: 平均值 | K33: Fu (%) | L33: Fb (%) | M33: 平均值Fu (%) | N33: 回收率 (%) | O33: 平均值 (%)
A34: HW356009-P1_BD-PL_1uM-B1 | B34: ='Experimental detail'!$C$6 -> 1 | C34: =VLOOKUP($A34,'Raw data'!$A$1:$T$1052,4,0) -> 1.11 | D34: =VLOOKUP($A34,'Raw data'!$A$1:$T$1052,5,0) -> 144000 | E34: =VLOOKUP($A34,'Raw data'!$A$1:$T$1052,6,0) -> 1280000 | F34: =VLOOKUP($A34,'Raw data'!$A$1:$T$1052,7,0) -> 0.112 | G34: =C34*F34 -> 0.12432 | H34: =AVERAGE(G34:G35) -> 0.127095 | I34: =G34+G36 -> 5.68432 | J34: =AVERAGE(I34:I35) -> 5.757095 | K34: =G34/G36*100 -> 2.2359712 | L34: =100-K34 -> 97.764029 | M34: =AVERAGE(K34:K35) -> 2.2571961 | N34: =I34/H38*100 -> 97.668729 | O34: =AVERAGE(N34:N35) -> 98.919158
A35: HW356009-P1_BD-PL_1uM-B2 | C35: =VLOOKUP($A35,'Raw data'!$A$1:$T$1052,4,0) -> 1.11 | D35: =VLOOKUP($A35,'Raw data'!$A$1:$T$1052,5,0) -> 158000 | E35: =VLOOKUP($A35,'Raw data'!$A$1:$T$1052,6,0) -> 1340000 | F35: =VLOOKUP($A35,'Raw data'!$A$1:$T$1052,7,0) -> 0.117 | G35: =C35*F35 -> 0.12987 | I35: =G35+G37 -> 5.82987 | K35: =G35/G37*100 -> 2.2784211 | L35: =100-K35 -> 97.721579 | N35: =I35/H38*100 -> 100.16959
A36: HW356009-P1_BD-PL_1uM-A1 | B36: ='Experimental detail'!$C$6 -> 1 | C36: =VLOOKUP($A36,'Raw data'!$A$1:$T$1052,4,0) -> 10 | D36: =VLOOKUP($A36,'Raw data'!$A$1:$T$1052,5,0) -> 754000 | E36: =VLOOKUP($A36,'Raw data'!$A$1:$T$1052,6,0) -> 1360000 | F36: =VLOOKUP($A36,'Raw data'!$A$1:$T$1052,7,0) -> 0.556 | G36: =C36*F36 -> 5.56 | H36: =AVERAGE(G36:G37) -> 5.63
A37: HW356009-P1_BD-PL_1uM-A2 | C37: =VLOOKUP($A37,'Raw data'!$A$1:$T$1052,4,0) -> 10 | D37: =VLOOKUP($A37,'Raw data'!$A$1:$T$1052,5,0) -> 779000 | E37: =VLOOKUP($A37,'Raw data'!$A$1:$T$1052,6,0) -> 1370000 | F37: =VLOOKUP($A37,'Raw data'!$A$1:$T$1052,7,0) -> 0.57 | G37: =C37*F37 -> 5.7
A38: HW356009-P1_BD-PL_1uM-R1 | B38: ='Experimental detail'!$C$6 -> 1 | C38: =VLOOKUP($A38,'Raw data'!$A$1:$T$1052,4,0) -> 10 | D38: =VLOOKUP($A38,'Raw data'!$A$1:$T$1052,5,0) -> 777000 | E38: =VLOOKUP($A38,'Raw data'!$A$1:$T$1052,6,0) -> 1320000 | F38: =VLOOKUP($A38,'Raw data'!$A$1:$T$1052,7,0) -> 0.587 | G38: =C38*F38 -> 5.87 | H38: =AVERAGE(G38:G39) -> 5.82
A39: HW356009-P1_BD-PL_1uM-R2 | C39: =VLOOKUP($A39,'Raw data'!$A$1:$T$1052,4,0) -> 10 | D39: =VLOOKUP($A39,'Raw data'!$A$1:$T$1052,5,0) -> 765000 | E39: =VLOOKUP($A39,'Raw data'!$A$1:$T$1052,6,0) -> 1320000 | F39: =VLOOKUP($A39,'Raw data'!$A$1:$T$1052,7,0) -> 0.577 | G39: =C39*F39 -> 5.77
A41: =CONCATENATE("Stability of ",Summary!$A$2," in Dog Plasma Incubated at 37 °C") -> Stability of HW356009-P1 in Dog Plasma Incubated at 37 °C
A42: 样品名 | B42: 孵育浓度（µM） | C42: 对照样品的峰面积比平均值 | D42: 稀释因子 | E42: 化合物峰面积 | F42: 内标峰面积 | G42: 峰面积比 | H42: 计算峰面积比 | I42: 稳定性(%) | J42: 平均值(%)
A43: HW356009-P1_BD-PL_1uM-S1 | B43: ='Experimental detail'!$C$6 -> 1 | C43: =H38 -> 5.82 | D43: =VLOOKUP($A43,'Raw data'!$A$1:$T$1052,4,0) -> 10 | E43: =VLOOKUP($A43,'Raw data'!$A$1:$T$1052,5,0) -> 797000 | F43: =VLOOKUP($A43,'Raw data'!$A$1:$T$1052,6,0) -> 1370000 | G43: =VLOOKUP($A43,'Raw data'!$A$1:$T$1052,7,0) -> 0.58 | H43: =D43*G43 -> 5.8 | I43: =H43/C43*100 -> 99.656357 | J43: =AVERAGE(I43:I44) -> 99.398625
A44: HW356009-P1_BD-PL_1uM-S2 | D44: =VLOOKUP($A44,'Raw data'!$A$1:$T$1052,4,0) -> 10 | E44: =VLOOKUP($A44,'Raw data'!$A$1:$T$1052,5,0) -> 779000 | F44: =VLOOKUP($A44,'Raw data'!$A$1:$T$1052,6,0) -> 1350000 | G44: =VLOOKUP($A44,'Raw data'!$A$1:$T$1052,7,0) -> 0.577 | H44: =D44*G44 -> 5.77 | I44: =H44/C43*100 -> 99.140893
A46: 大鼠
...

Sheet Controls
B1: 华法林
B2: Warfarin-Human Plasma 100%
B3: 样品名 | C3: 孵育浓度（µM） | D3: 稀释因子 | E3: 化合物峰面积 | F3: 内标峰面积 | G3: 峰面积比 | H3: 计算峰面积比 | I3: 平均值 | J3: 总和 | K3: 平均值 | L3: Fu (%) | M3: Fb (%) | N3: 平均值Fu (%) | O3: 回收率 (%) | P3: 平均值 (%)
B4: Warfarin_HM-PL_5uM-B1 | C4: 5 | D4: =VLOOKUP($B4,'Raw data'!$A$1:$T$1052,4,0) -> 2 | E4: =VLOOKUP($B4,'Raw data'!$A$1:$R$218,5,0) -> 6230 | F4: =VLOOKUP($B4,'Raw data'!$A$1:$R$218,6,0) -> 172000 | G4: =VLOOKUP($B4,'Raw data'!$A$1:$R$218,7,0) -> 0.0362 | H4: =D4*G4 -> 0.0724 | I4: =AVERAGE(H4:H5) -> 0.072 | J4: =H4+H6 -> 15.7924 | K4: =AVERAGE(J4:J5) -> 15.912 | L4: =H4/H6*100 -> 0.4605598 | M4: =100-L4 -> 99.53944 | N4: =AVERAGE(L4:L5) -> 0.45459068 | O4: =J4/I8*100 -> 88.373811 | P4: =AVERAGE(O4:O5) -> 89.043089
B5: Warfarin_HM-PL_5uM-B2 | D5: =VLOOKUP($B5,'Raw data'!$A$1:$T$1052,4,0) -> 2 | E5: =VLOOKUP($B5,'Raw data'!$A$1:$R$218,5,0) -> 6040 | F5: =VLOOKUP($B5,'Raw data'!$A$1:$R$218,6,0) -> 169000 | G5: =VLOOKUP($B5,'Raw data'!$A$1:$R$218,7,0) -> 0.0358 | H5: =D5*G5 -> 0.0716 | J5: =H5+H7 -> 16.0316 | L5: =H5/H7*100 -> 0.44862155 | M5: =100-L5 -> 99.551378 | O5: =J5/I8*100 -> 89.712367
B6: Warfarin_HM-PL_5uM-A1 | C6: 5 | D6: =VLOOKUP($B6,'Raw data'!$A$1:$T$1052,4,0) -> 2 | E6: =VLOOKUP($B6,'Raw data'!$A$1:$R$218,5,0) -> 1390000 | F6: =VLOOKUP($B6,'Raw data'!$A$1:$R$218,6,0) -> 177000 | G6: =VLOOKUP($B6,'Raw data'!$A$1:$R$218,7,0) -> 7.86 | H6: =D6*G6 -> 15.72 | I6: =AVERAGE(H6:H7) -> 15.84
B7: Warfarin_HM-PL_5uM-A2 | D7: =VLOOKUP($B7,'Raw data'!$A$1:$T$1052,4,0) -> 2 | E7: =VLOOKUP($B7,'Raw data'!$A$1:$R$218,5,0) -> 1350000 | F7: =VLOOKUP($B7,'Raw data'!$A$1:$R$218,6,0) -> 169000 | G7: =VLOOKUP($B7,'Raw data'!$A$1:$R$218,7,0) -> 7.98 | H7: =D7*G7 -> 15.96
B8: Warfarin_HM-PL_5uM-R1 | C8: 5 | D8: =VLOOKUP($B8,'Raw data'!$A$1:$T$1052,4,0) -> 2 | E8: =VLOOKUP($B8,'Raw data'!$A$1:$R$218,5,0) -> 1450000 | F8: =VLOOKUP($B8,'Raw data'!$A$1:$R$218,6,0) -> 161000 | G8: =VLOOKUP($B8,'Raw data'!$A$1:$R$218,7,0) -> 9 | H8: =D8*G8 -> 18 | I8: =AVERAGE(H8:H9) -> 17.87
B9: Warfarin_HM-PL_5uM-R2 | D9: =VLOOKUP($B9,'Raw data'!$A$1:$T$1052,4,0) -> 2 | E9: =VLOOKUP($B9,'Raw data'!$A$1:$R$218,5,0) -> 1410000 | F9: =VLOOKUP($B9,'Raw data'!$A$1:$R$218,6,0) -> 159000 | G9: =VLOOKUP($B9,'Raw data'!$A$1:$R$218,7,0) -> 8.87 | H9: =D9*G9 -> 17.74
B11: Warfarin-Monkey Plasma 100%
B12: 样品名 | C12: 孵育浓度（µM） | D12: 稀释因子 | E12: 化合物峰面积 | F12: 内标峰面积 | G12: 峰面积比 | H12: 计算峰面积比 | I12: 平均值 | J12: 总和 | K12: 平均值 | L12: Fu (%) | M12: Fb (%) | N12: 平均值Fu (%) | O12: 回收率 (%) | P12: 平均值 (%)
B13: Warfarin_MK-PL_5uM-B1 | C13: 5 | D13: =VLOOKUP($B13,'Raw data'!$A$1:$T$1052,4,0) -> 2 | E13: =VLOOKUP($B13,'Raw data'!$A$1:$R$218,5,0) -> 6630 | F13: =VLOOKUP($B13,'Raw data'!$A$1:$R$218,6,0) -> 161000 | G13: =VLOOKUP($B13,'Raw data'!$A$1:$R$218,7,0) -> 0.0411 | H13: =D13*G13 -> 0.0822 | I13: =AVERAGE(H13:H14) -> 0.0809 | J13: =H13+H15 -> 15.8422 | K13: =AVERAGE(J13:J14) -> 16.4209 | L13: =H13/H15*100 -> 0.5215736 | M13: =100-L13 -> 99.478426 | N13: =AVERAGE(L13:L14) -> 0.49601139 | O13: =J13/I17*100 -> 84.53682 | P13: =AVERAGE(O13:O14) -> 87.624867
B14: Warfarin_MK-PL_5uM-B2 | D14: =VLOOKUP($B14,'Raw data'!$A$1:$T$1052,4,0) -> 2 | E14: =VLOOKUP($B14,'Raw data'!$A$1:$R$218,5,0) -> 6350 | F14: =VLOOKUP($B14,'Raw data'!$A$1:$R$218,6,0) -> 160000 | G14: =VLOOKUP($B14,'Raw data'!$A$1:$R$218,7,0) -> 0.0398 | H14: =D14*G14 -> 0.0796 | J14: =H14+H16 -> 16.9996 | L14: =H14/H16*100 -> 0.47044917 | M14: =100-L14 -> 99.529551 | O14: =J14/I17*100 -> 90.712914
B15: Warfarin_MK-PL_5uM-A1 | C15: 5 | D15: =VLOOKUP($B15,'Raw data'!$A$1:$T$1052,4,0) -> 2 | E15: =VLOOKUP($B15,'Raw data'!$A$1:$R$218,5,0) -> 1360000 | F15: =VLOOKUP($B15,'Raw data'!$A$1:$R$218,6,0) -> 172000 | G15: =VLOOKUP($B15,'Raw data'!$A$1:$R$218,7,0) -> 7.88 | H15: =D15*G15 -> 15.76 | I15: =AVERAGE(H15:H16) -> 16.34
B16: Warfarin_MK-PL_5uM-A2 | D16: =VLOOKUP($B16,'Raw data'!$A$1:$T$1052,4,0) -> 2 | E16: =VLOOKUP($B16,'Raw data'!$A$1:$R$218,5,0) -> 1420000 | F16: =VLOOKUP($B16,'Raw data'!$A$1:$R$218,6,0) -> 167000 | G16: =VLOOKUP($B16,'Raw data'!$A$1:$R$218,7,0) -> 8.46 | H16: =D16*G16 -> 16.92
B17: Warfarin_MK-PL_5uM-R1 | C17: 5 | D17: =VLOOKUP($B17,'Raw data'!$A$1:$T$1052,4,0) -> 2 | E17: =VLOOKUP($B17,'Raw data'!$A$1:$R$218,5,0) -> 1560000 | F17: =VLOOKUP($B17,'Raw data'!$A$1:$R$218,6,0) -> 167000 | G17: =VLOOKUP($B17,'Raw data'!$A$1:$R$218,7,0) -> 9.31 | H17: =D17*G17 -> 18.62 | I17: =AVERAGE(H17:H18) -> 18.74
B18: Warfarin_MK-PL_5uM-R2 | D18: =VLOOKUP($B18,'Raw data'!$A$1:$T$1052,4,0) -> 2 | E18: =VLOOKUP($B18,'Raw data'!$A$1:$R$218,5,0) -> 1490000 | F18: =VLOOKUP($B18,'Raw data'!$A$1:$R$218,6,0) -> 158000 | G18: =VLOOKUP($B18,'Raw data'!$A$1:$R$218,7,0) -> 9.43 | H18: =D18*G18 -> 18.86
B20: Warfarin-Dog Plasma 100%
B21: 样品名 | C21: 孵育浓度（µM） | D21: 稀释因子 | E21: 化合物峰面积 | F21: 内标峰面积 | G21: 峰面积比 | H21: 计算峰面积比 | I21: 平均值 | J21: 总和 | K21: 平均值 | L21: Fu (%) | M21: Fb (%) | N21: 平均值Fu (%) | O21: 回收率 (%) | P21: 平均值 (%)
B22: Warfarin_BD-PL_5uM-B1 | C22: 5 | D22: =VLOOKUP($B22,'Raw data'!$A$1:$T$1052,4,0) -> 2 | E22: =VLOOKUP($B22,'Raw data'!$A$1:$R$218,5,0) -> 40400 | F22: =VLOOKUP($B22,'Raw data'!$A$1:$R$218,6,0) -> 163000 | G22: =VLOOKUP($B22,'Raw data'!$A$1:$R$218,7,0) -> 0.247 | H22: =D22*G22 -> 0.494 | I22: =AVERAGE(H22:H23) -> 0.49 | J22: =H22+H24 -> 16.254 | K22: =AVERAGE(J22:J23) -> 16.97 | L22: =H22/H24*100 -> 3.1345178 | M22: =100-L22 -> 96.865482 | N22: =AVERAGE(L22:L23) -> 2.9800496 | O22: =J22/I26*100 -> 89.751518 | P22: =AVERAGE(O22:O23) -> 93.705135
B23: Warfarin_BD-PL_5uM-B2 | D23: =VLOOKUP($B23,'Raw data'!$A$1:$T$1052,4,0) -> 2 | E23: =VLOOKUP($B23,'Raw data'!$A$1:$R$218,5,0) -> 39800 | F23: =VLOOKUP($B23,'Raw data'!$A$1:$R$218,6,0) -> 164000 | G23: =VLOOKUP($B23,'Raw data'!$A$1:$R$218,7,0) -> 0.243 | H23: =D23*G23 -> 0.486 | J23: =H23+H25 -> 17.686 | L23: =H23/H25*100 -> 2.8255814 | M23: =100-L23 -> 97.174419 | O23: =J23/I26*100 -> 97.658752
B24: Warfarin_BD-PL_5uM-A1 | C24: 5 | D24: =VLOOKUP($B24,'Raw data'!$A$1:$T$1052,4,0) -> 2 | E24: =VLOOKUP($B24,'Raw data'!$A$1:$R$218,5,0) -> 1280000 | F24: =VLOOKUP($B24,'Raw data'!$A$1:$R$218,6,0) -> 163000 | G24: =VLOOKUP($B24,'Raw data'!$A$1:$R$218,7,0) -> 7.88 | H24: =D24*G24 -> 15.76 | I24: =AVERAGE(H24:H25) -> 16.48
B25: Warfarin_BD-PL_5uM-A2 | D25: =VLOOKUP($B25,'Raw data'!$A$1:$T$1052,4,0) -> 2 | E25: =VLOOKUP($B25,'Raw data'!$A$1:$R$218,5,0) -> 1370000 | F25: =VLOOKUP($B25,'Raw data'!$A$1:$R$218,6,0) -> 159000 | G25: =VLOOKUP($B25,'Raw data'!$A$1:$R$218,7,0) -> 8.6 | H25: =D25*G25 -> 17.2
B26: Warfarin_BD-PL_5uM-R1 | C26: 5 | D26: =VLOOKUP($B26,'Raw data'!$A$1:$T$1052,4,0) -> 2 | E26: =VLOOKUP($B26,'Raw data'!$A$1:$R$218,5,0) -> 1430000 | F26: =VLOOKUP($B26,'Raw data'!$A$1:$R$218,6,0) -> 155000 | G26: =VLOOKUP($B26,'Raw data'!$A$1:$R$218,7,0) -> 9.22 | H26: =D26*G26 -> 18.44 | I26: =AVERAGE(H26:H27) -> 18.11
B27: Warfarin_BD-PL_5uM-R2 | D27: =VLOOKUP($B27,'Raw data'!$A$1:$T$1052,4,0) -> 2 | E27: =VLOOKUP($B27,'Raw data'!$A$1:$R$218,5,0) -> 1410000 | F27: =VLOOKUP($B27,'Raw data'!$A$1:$R$218,6,0) -> 159000 | G27: =VLOOKUP($B27,'Raw data'!$A$1:$R$218,7,0) -> 8.89 | H27: =D27*G27 -> 17.78
B29: Warfarin-Rat Plasma 100%
B30: 样品名 | C30: 孵育浓度（µM） | D30: 稀释因子 | E30: 化合物峰面积 | F30: 内标峰面积 | G30: 峰面积比 | H30: 计算峰面积比 | I30: 平均值 | J30: 总和 | K30: 平均值 | L30: Fu (%) | M30: Fb (%) | N30: 平均值Fu (%) | O30: 回收率 (%) | P30: 平均值 (%)
B31: Warfarin_SR-PL_5uM-B1 | C31: 5 | D31: =VLOOKUP($B31,'Raw data'!$A$1:$T$1052,4,0) -> 2 | E31: =VLOOKUP($B31,'Raw data'!$A$1:$R$218,5,0) -> 4260 | F31: =VLOOKUP($B31,'Raw data'!$A$1:$R$218,6,0) -> 159000 | G31: =VLOOKUP($B31,'Raw data'!$A$1:$R$218,7,0) -> 0.0269 | H31: =D31*G31 -> 0.0538 | I31: =AVERAGE(H31:H32) -> 0.0518 | J31: =H31+H33 -> 15.1138 | K31: =AVERAGE(J31:J32) -> 14.8418 | L31: =H31/H33*100 -> 0.35723772 | M31: =100-L31 -> 99.642762 | N31: =AVERAGE(L31:L32) -> 0.35010646 | O31: =J31/I35*100 -> 86.512879 | P31: =AVERAGE(O31:O32) -> 84.955924
B32: Warfarin_SR-PL_5uM-B2 | D32: =VLOOKUP($B32,'Raw data'!$A$1:$T$1052,4,0) -> 2 | E32: =VLOOKUP($B32,'Raw data'!$A$1:$R$218,5,0) -> 4120 | F32: =VLOOKUP($B32,'Raw data'!$A$1:$R$218,6,0) -> 166000 | G32: =VLOOKUP($B32,'Raw data'!$A$1:$R$218,7,0) -> 0.0249 | H32: =D32*G32 -> 0.0498 | J32: =H32+H34 -> 14.5698 | L32: =H32/H34*100 -> 0.34297521 | M32: =100-L32 -> 99.657025 | O32: =J32/I35*100 -> 83.39897
B33: Warfarin_SR-PL_5uM-A1 | C33: 5 | D33: =VLOOKUP($B33,'Raw data'!$A$1:$T$1052,4,0) -> 2 | E33: =VLOOKUP($B33,'Raw data'!$A$1:$R$218,5,0) -> 1220000 | F33: =VLOOKUP($B33,'Raw data'!$A$1:$R$218,6,0) -> 162000 | G33: =VLOOKUP($B33,'Raw data'!$A$1:$R$218,7,0) -> 7.53 | H33: =D33*G33 -> 15.06 | I33: =AVERAGE(H33:H34) -> 14.79
B34: Warfarin_SR-PL_5uM-A2 | D34: =VLOOKUP($B34,'Raw data'!$A$1:$T$1052,4,0) -> 2 | E34: =VLOOKUP($B34,'Raw data'!$A$1:$R$218,5,0) -> 1180000 | F34: =VLOOKUP($B34,'Raw data'!$A$1:$R$218,6,0) -> 162000 | G34: =VLOOKUP($B34,'Raw data'!$A$1:$R$218,7,0) -> 7.26 | H34: =D34*G34 -> 14.52
B35: Warfarin_SR-PL_5uM-R1 | C35: 5 | D35: =VLOOKUP($B35,'Raw data'!$A$1:$T$1052,4,0) -> 2 | E35: =VLOOKUP($B35,'Raw data'!$A$1:$R$218,5,0) -> 1340000 | F35: =VLOOKUP($B35,'Raw data'!$A$1:$R$218,6,0) -> 155000 | G35: =VLOOKUP($B35,'Raw data'!$A$1:$R$218,7,0) -> 8.65 | H35: =D35*G35 -> 17.3 | I35: =AVERAGE(H35:H36) -> 17.47
B36: Warfarin_SR-PL_5uM-R2 | D36: =VLOOKUP($B36,'Raw data'!$A$1:$T$1052,4,0) -> 2 | E36: =VLOOKUP($B36,'Raw data'!$A$1:$R$218,5,0) -> 1340000 | F36: =VLOOKUP($B36,'Raw data'!$A$1:$R$218,6,0) -> 152000 | G36: =VLOOKUP($B36,'Raw data'!$A$1:$R$218,7,0) -> 8.82 | H36: =D36*G36 -> 17.64
B38: Warfarin-Mouse Plasma 100%
B39: 样品名 | C39: 孵育浓度（µM） | D39: 稀释因子 | E39: 化合物峰面积 | F39: 内标峰面积 | G39: 峰面积比 | H39: 计算峰面积比 | I39: 平均值 | J39: 总和 | K39: 平均值 | L39: Fu (%) | M39: Fb (%) | N39: 平均值Fu (%) | O39: 回收率 (%) | P39: 平均值 (%)
B40: Warfarin_MU-PL_5uM-B1 | C40: 5 | D40: =VLOOKUP($B40,'Raw data'!$A$1:$T$1052,4,0) -> 2 | E40: =VLOOKUP($B40,'Raw data'!$A$1:$R$218,5,0) -> 67500 | F40: =VLOOKUP($B40,'Raw data'!$A$1:$R$218,6,0) -> 159000 | G40: =VLOOKUP($B40,'Raw data'!$A$1:$R$218,7,0) -> 0.425 | H40: =D40*G40 -> 0.85 | I40: =AVERAGE(H40:H41) -> 0.819 | J40: =H40+H42 -> 15.57 | K40: =AVERAGE(J40:J41) -> 15.089 | L40: =H40/H42*100 -> 5.7744565 | M40: =100-L40 -> 94.225543 | N40: =AVERAGE(L40:L41) -> 5.7381689 | O40: =J40/I44*100 -> 95.054945 | P40: =AVERAGE(O40:O41) -> 92.118437
B41: Warfarin_MU-PL_5uM-B2 | D41: =VLOOKUP($B41,'Raw data'!$A$1:$T$1052,4,0) -> 2 | E41: =VLOOKUP($B41,'Raw data'!$A$1:$R$218,5,0) -> 64300 | F41: =VLOOKUP($B41,'Raw data'!$A$1:$R$218,6,0) -> 163000 | G41: =VLOOKUP($B41,'Raw data'!$A$1:$R$218,7,0) -> 0.394 | H41: =D41*G41 -> 0.788 | J41: =H41+H43 -> 14.608 | L41: =H41/H43*100 -> 5.7018813 | M41: =100-L41 -> 94.298119 | O41: =J41/I44*100 -> 89.181929
B42: Warfarin_MU-PL_5uM-A1 | C42: 5 | D42: =VLOOKUP($B42,'Raw data'!$A$1:$T$1052,4,0) -> 2 | E42: =VLOOKUP($B42,'Raw data'!$A$1:$R$218,5,0) -> 1120000 | F42: =VLOOKUP($B42,'Raw data'!$A$1:$R$218,6,0) -> 152000 | G42: =VLOOKUP($B42,'Raw data'!$A$1:$R$218,7,0) -> 7.36 | H42: =D42*G42 -> 14.72 | I42: =AVERAGE(H42:H43) -> 14.27
B43: Warfarin_MU-PL_5uM-A2 | D43: =VLOOKUP($B43,'Raw data'!$A$1:$T$1052,4,0) -> 2 | E43: =VLOOKUP($B43,'Raw data'!$A$1:$R$218,5,0) -> 1060000 | F43: =VLOOKUP($B43,'Raw data'!$A$1:$R$218,6,0) -> 153000 | G43: =VLOOKUP($B43,'Raw data'!$A$1:$R$218,7,0) -> 6.91 | H43: =D43*G43 -> 13.82
B44: Warfarin_MU-PL_5uM-R1 | C44: 5 | D44: =VLOOKUP($B44,'Raw data'!$A$1:$T$1052,4,0) -> 2 | E44: =VLOOKUP($B44,'Raw data'!$A$1:$R$218,5,0) -> 1230000 | F44: =VLOOKUP($B44,'Raw data'!$A$1:$R$218,6,0) -> 151000 | G44: =VLOOKUP($B44,'Raw data'!$A$1:$R$218,7,0) -> 8.11 | H44: =D44*G44 -> 16.22 | I44: =AVERAGE(H44:H45) -> 16.38
...

Sheet Raw data
A1: =Summary!A2 -> HW356009-P1
A2: Peak Name: Ver
A3: Use as Internal Standard
A4: Q1/Q3 Masses: 455.10/165.10 Da
A5: Peak Name: Gli
A6: Use as Internal Standard
A7: Q1/Q3 Masses: 494.20/169.10 Da
A9: Peak Name: HW356009-P1-Ver
A10: Internal Standard: Ver
A11: Q1/Q3 Masses: 604.30/411.10 Da
A13: Fit | B13: Linear | C13: Weighting | D13: 1 / (x * x) | E13: Iterate | F13: No
A14: Error | B14: At least 2 points are required to calculate regression.
A15: Use Area
A17: Peak Name: HW356009-P1-Gli
A18: Internal Standard: Gli
A19: Q1/Q3 Masses: 604.30/411.10 Da
A21: Fit | B21: Linear | C21: Weighting | D21: 1 / (x * x) | E21: Iterate | F21: No
A22: Error | B22: At least 2 points are required to calculate regression.
A23: Use Area
A27: Sample Name | B27: Sample Type | C27: Analyte Concentration (nM) | D27: Dilution Factor | E27: Analyte Peak Area (counts) | F27: IS Peak Area (counts) | G27: Area Ratio | H27: Use Record | I27: Record Modified | J27: Calculated Concentration (nM) | K27: Accuracy (%) | L27: Vial Position | M27: Plate Position | N27: Acquisition Date
A28: wash | B28: Unknown | C28: N/A | D28: 1 | E28: 0 | F28: 0 | G28: #DIV/0! | I28: 0 | J28: #DIV/0! | K28: N/A | L28: 23 | M28: 1 | N28: 2/28/2025 11:47:32 PM
A29: wash | B29: Unknown | C29: N/A | D29: 1 | E29: 0 | F29: 0 | G29: #DIV/0! | I29: 0 | J29: #DIV/0! | K29: N/A | L29: 24 | M29: 1 | N29: 2/28/2025 11:51:00 PM
A30: HW356009-P1_HM-PL_1uM-B1 | B30: Unknown | C30: N/A | D30: 1.11 | E30: 129000 | F30: 1270000 | G30: 0.102 | I30: 0 | J30: 0 | K30: N/A | L30: 1 | M30: 2 | N30: 2/28/2025 11:54:24 PM
A31: HW356009-P1_HM-PL_1uM-B2 | B31: Unknown | C31: N/A | D31: 1.11 | E31: 134000 | F31: 1370000 | G31: 0.0977 | I31: 0 | J31: 0 | K31: N/A | L31: 2 | M31: 2 | N31: 2/28/2025 11:57:48 PM
A32: HW356009-P1_HM-PL_1uM-A1 | B32: Unknown | C32: N/A | D32: 10 | E32: 671000 | F32: 1320000 | G32: 0.507 | I32: 0 | J32: 0 | K32: N/A | L32: 13 | M32: 2 | N32: 3/1/2025 12:01:12 AM
A33: HW356009-P1_HM-PL_1uM-A2 | B33: Unknown | C33: N/A | D33: 10 | E33: 651000 | F33: 1290000 | G33: 0.505 | I33: 0 | J33: 0 | K33: N/A | L33: 14 | M33: 2 | N33: 3/1/2025 12:04:37 AM
A34: HW356009-P1_HM-PL_1uM-S1 | B34: Unknown | C34: N/A | D34: 10 | E34: 707000 | F34: 1330000 | G34: 0.533 | I34: 0 | J34: 0 | K34: N/A | L34: 25 | M34: 2 | N34: 3/1/2025 12:08:00 AM
A35: HW356009-P1_HM-PL_1uM-S2 | B35: Unknown | C35: N/A | D35: 10 | E35: 706000 | F35: 1220000 | G35: 0.58 | I35: 0 | J35: 0 | K35: N/A | L35: 26 | M35: 2 | N35: 3/1/2025 12:11:24 AM
A36: HW356009-P1_HM-PL_1uM-R1 | B36: Unknown | C36: N/A | D36: 10 | E36: 667000 | F36: 1250000 | G36: 0.532 | I36: 0 | J36: 0 | K36: N/A | L36: 37 | M36: 2 | N36: 3/1/2025 12:14:47 AM
A37: HW356009-P1_HM-PL_1uM-R2 | B37: Unknown | C37: N/A | D37: 10 | E37: 719000 | F37: 1300000 | G37: 0.554 | I37: 0 | J37: 0 | K37: N/A | L37: 38 | M37: 2 | N37: 3/1/2025 12:18:11 AM
A38: wash | B38: Unknown | C38: N/A | D38: 1 | E38: 0 | F38: 0 | G38: #DIV/0! | I38: 0 | J38: #DIV/0! | K38: N/A | L38: 23 | M38: 1 | N38: 3/1/2025 12:21:36 AM
A39: wash | B39: Unknown | C39: N/A | D39: 1 | E39: 0 | F39: 0 | G39: #DIV/0! | I39: 0 | J39: #DIV/0! | K39: N/A | L39: 24 | M39: 1 | N39: 3/1/2025 12:25:00 AM
A40: HW356009-P1_MK-PL_1uM-B1 | B40: Unknown | C40: N/A | D40: 1.11 | E40: 145000 | F40: 1260000 | G40: 0.115 | I40: 0 | J40: 0 | K40: N/A | L40: 3 | M40: 2 | N40: 3/1/2025 12:28:25 AM
A41: HW356009-P1_MK-PL_1uM-B2 | B41: Unknown | C41: N/A | D41: 1.11 | E41: 154000 | F41: 1290000 | G41: 0.119 | I41: 0 | J41: 0 | K41: N/A | L41: 4 | M41: 2 | N41: 3/1/2025 12:31:47 AM
A42: HW356009-P1_MK-PL_1uM-A1 | B42: Unknown | C42: N/A | D42: 10 | E42: 704000 | F42: 1270000 | G42: 0.556 | I42: 0 | J42: 0 | K42: N/A | L42: 15 | M42: 2 | N42: 3/1/2025 12:35:14 AM
A43: HW356009-P1_MK-PL_1uM-A2 | B43: Unknown | C43: N/A | D43: 10 | E43: 816000 | F43: 1370000 | G43: 0.595 | I43: 0 | J43: 0 | K43: N/A | L43: 16 | M43: 2 | N43: 3/1/2025 12:38:39 AM
A44: HW356009-P1_MK-PL_1uM-S1 | B44: Unknown | C44: N/A | D44: 10 | E44: 791000 | F44: 1300000 | G44: 0.608 | I44: 0 | J44: 0 | K44: N/A | L44: 27 | M44: 2 | N44: 3/1/2025 12:42:03 AM
A45: HW356009-P1_MK-PL_1uM-S2 | B45: Unknown | C45: N/A | D45: 10 | E45: 770000 | F45: 1250000 | G45: 0.614 | I45: 0 | J45: 0 | K45: N/A | L45: 28 | M45: 2 | N45: 3/1/2025 12:45:27 AM
A46: HW356009-P1_MK-PL_1uM-R1 | B46: Unknown | C46: N/A | D46: 10 | E46: 755000 | F46: 1320000 | G46: 0.571 | I46: 0 | J46: 0 | K46: N/A | L46: 39 | M46: 2 | N46: 3/1/2025 12:48:51 AM
A47: HW356009-P1_MK-PL_1uM-R2 | B47: Unknown | C47: N/A | D47: 10 | E47: 762000 | F47: 1280000 | G47: 0.596 | I47: 0 | J47: 0 | K47: N/A | L47: 40 | M47: 2 | N47: 3/1/2025 12:52:15 AM
...

Sheet Experimental detail
B1: Incubation Details
B3: Test Compound | C3: =Summary!A2 -> HW356009-P1 | D3: NJTQCXA03293, NJTQCXA03295, NJTQCXA03298, NJTQCXA03300, NJTQCXA03003, NJTQCXA03244 and NJTQCXA03290 | E3: NJTQCXA03293, NJTQCXA03295, NJTQCXA03298, NJTQCXA03300, NJTQCXA03003, NJTQCXA03244 and NJTQCXA03290 | F3: NJTQCXA03293, NJTQCXA03295, NJTQCXA03298, NJTQCXA03300, NJTQCXA03003, NJTQCXA03244 and NJTQCXA03290 | G3: NJTQCXA03293, NJTQCXA03295, NJTQCXA03298, NJTQCXA03300, NJTQCXA03003, NJTQCXA03244 and NJTQCXA03290 | H3: NJTQCXA03293, NJTQCXA03295, NJTQCXA03298, NJTQCXA03300, NJTQCXA03003, NJTQCXA03244 and NJTQCXA03290 | I3: NJTQCXA03293, NJTQCXA03295, NJTQCXA03298, NJTQCXA03300, NJTQCXA03003, NJTQCXA03244 and NJTQCXA03290
B4: Positive Control Compound | C4: Warfarin and Acetaminophen
B5: Matrix | C5: Pooled human, Monkey, Dog, Rat and Mouse plasma (Anticoagulant EDTA-K2) (3D); Phosphate buffer (100 mM, pH 7.4)
B6: Target Conc. Level | C6: 1 | D6: μM
B7: Device | C7: HTD 96-well dialysis device (HTDialysis, Gales Ferry, CT, USA)
B8: Incubation Condition | C8: 6 h, 37 °C, 80 rpm
B10: Analytical Method
B11: Instrument | C11: Qtrap 5500: LC-MS/MS-011
B12: Internal standard(s) | C12: Verapamil or Glibenclamide? | D12: Glibenclamide
B13: MS conditions | C13: ESI: Negative | D13: MRM detection
C14: CAD | D14: Medium
C15: CUR | D15: 20 | E15: psi
C16: GS1 | D16: 50 | E16: psi
C17: GS2 | D17: 50 | E17: psi
C18: IS | D18: 5500 | E18: V
C19: TEM | D19: 500 | E19: °C
C20: EP | D20: 10 | E20: V
B21: Analytes | C21: Q1/Q3 | E21: DP | F21: CE | G21: CXP
B22: =Summary!A2 -> HW356009-P1 | C22: 604.3/411.1 | E22: 65 | F22: 41 | G22: 15
B23: =CONCATENATE("IS (",D12,")") -> IS (Glibenclamide) | C23: 494.2/169.1 | E23: 90 | F23: 40 | G23: 15
B25: HPLC conditions | C25: Agilent ZORBAX XDB-C18, 5 μm, 2.1×50mm（50-459）
C26: Mobile Phase A: H2O (0.1% Formic Acid)
C27: Mobile Phase B: ACN (0.1% Formic Acid)
B28: Binary Gradient | C28: Total Flow: | D28: 500 µL/min
C29: Time (min) | D29: B (%)
C30: 0.5 | D30: 10
C31: 1 | D31: 95
C32: 1.8 | D32: 95
C33: 1.81 | D33: 10
C34: 3 | D34: stop
B37: Stock Solution Preparation | C37: 10 mM in DMSO
B38: Sample Prepration Method | C38: One step protein precipitation.
B39: Precipitant | C39: ACN, with concentration of verapamil (5 ng/mL) and glibenclamide (50 ng/mL)
B40: Samples preparation | C40: At the end of incubation, 10 μL plasma sample was transferred from the donor side (in duplicate), added with 90 μL PB (0.002% Tween-80) and vortexed well. 90 μL of PB (0.002% Tween-80) sample was transferred from the receiver side (in duplicate), added with 10 μL blank plasma and vortexed well. For recovery check, 10 μL of the donor side loading sample was aliquoted into a 1.5 mL microcentrifuge tube (in duplicate), added with 90 μL PB (0.002% Tween-80) and vortexed well. For stability check, 10 μL of the donor side loading sample was aliquoted into a 1.5 mL microcentrifuge tube (in duplicate) at the end of incubation, added with 90 μL PB (0.002% Tween-80) solution and vortexed well.
C41: Aliquots of 100 μL of donor side, receiver side, stability and recovery samples were supplemented with 400 μL of precipitant. After vortexing and centrifugation, 70 uL of supernatant was removed and diluted by 70 uL of water, vortxed well and aliquot of each solution was injected for LC-MS/MS analysis.
