Workbook

Sheet Signature
A1: Study Report
A2: Report Name | B2: Inhibition of CYP2C9, CYP2D6, CYP3A4 by HW350003A in Human Liver Microsomes
A3: Study Number | B3: D-RF-2024061303
A4: Report Number | B4: ADME-人福医药-DDI-20240614
A5: Sponsor Name | B5: 人福医药
A6: Submitted by | B6: Yuguo Xu
A7: Study Start Date | B7: 45455
A8: Report Submission Date | B8: 45460
A9: Study Director | B9: Jie Shao
A10: Assay Scientist | B10: Yuguo Xu
A11: QC for Report | B11: Yu Sun
A12: Report Approval | B12: Jie Shao

Sheet Summary
A1: Data Summary
A2: Table 1. IC50 values for HW350003A and known inhibitors against CYP2C9, CYP2D6, CYP3A4.
A3: Compound | B3: IC50 (μM)
B4: CYP2C9 | C4: CYP2D6 | D4: CYP3A4 (Substrate:midazolam) | E4: CYP3A4 (Substrate:testosterone)
A5: Sulfaphenazole | B5: =Data!I8 -> 0.74708353 | C5: - | D5: - | E5: -
A6: Quinidine | B6: - | C6: =Data!I21 -> 0.27372081 | D6: - | E6: -
A7: Ketoconazole | B7: - | C7: - | D7: =Data!I34 -> 0.05311852 | E7: =Data!I47 -> 0.11039869
A8: Ketoconazole | B8: - | C8: - | D8: - | E8: -
A9: HW350003A | B9: >10 | C9: >10 | D9: >10 | E9: >10
A12: Table 2. Inhibition for HW350003A against CYP2C9, CYP2D6, CYP3A4.
A13: Compound | B13: Inhibition(% VC)
B14: CYP2C9 | C14: CYP2D6 | D14: CYP3A4 (Substrate:midazolam) | E14: CYP3A4 (Substrate:testosterone)
A15: HW350003A | B15: =Data!F6 -> 3.237858 | C15: =Data!F19 -> 0 | D15: =Data!F32 -> 0 | E15: =Data!F45 -> 2.6315789

Sheet Materials
A1: Materials
A2: 1.Test compound was provided by the sponsor. The compound information is listed in Table 3.
A3: Table 3. Compound information
A4: Molecule Name | B4: Lot No. | C4: MW (g/mol) | D4: FW (g/mol) | E4: Purity
A5: HW350003A | B5: 20240514 | C5: 437.46 | D5: 437.46 | E5: 0.9824
A6: 2.The microsomes were stored at -80°C prior to use, and the liver microsome information is listed in Table 4.
A7: Table 4. Liver microsome information
A8: Species | B8: Vendor | C8: Cat. No. | D8: Lot. No. | E8: Strain & Gender
A9: Human | B9: BiOIVT | C9: X008064 | D9: SEU | E9: 25 donor, mix

Sheet Study Design
A1: Study Design
A2: 1. Equipment, materials and reagents
A3: 1.1. Substrates
A4: Preparation details of these substrates are given in Table 5. The substrate stock solution is stored in a -20oC freezer. Prior to use, remove the substrate stock solution from the freezer and allow it to rise to room temperature. Then mix the substrate stock solution on a whirly mixer for 30 seconds.
A5: Table 5: Preparation of the substrate stock solution
A6: CYP Isoform | B6: Substrate | D6: MW(g/mol) | E6: Stock solution Conc. (mM) | G6: Final Conc. (µM)
A7: 2C9 | B7: diclofenac | D7: 318.13 | E7: 10 (in MeOH) | G7: 10
A8: 2D6 | B8: dextromethorphan | D8: 370.3 | E8: 10 (in MeOH) | G8: 10
A9: 3A4 | B9: midazolam | D9: 325.77 | E9: 2 (in DMSO) | G9: 2
B10: testosterone | D10: 412.6 | E10: 40 (in DMSO) | G10: 40
A11: 1.2. Human liver microsome(HLM)
A12: HLMs are stored in a -80oC freezer. Prior to use, remove the pooled HLM from the freezer and allow it to thaw in a 37 oC water bath and then stored on wet ice.
A13: 1.3. Inhibitors
A14: The positive control inhibitors and their concentrations used by each isozyme was prepared according to Table 6.
A15: Table 6: Preparation of the standard inhibitors solution
A16: CYP Isoform | B16: Inhibitor | D16: MW (g/moL) | E16: Stock solution Conc. (mM) | G16: Final Conc. (µM)
A17: 2C9 | B17: Sulfaphenazole | D17: 314.4 | E17: 10(in DMSO) | G17: 3
A18: 2D6 | B18: Quinidine | D18: 324.4 | E18: 10(in DMSO) | G18: 3
A19: 3A4 | B19: Ketoconazole | D19: 531.4 | E19: 10(in DMSO) | G19: 3
A20: 2. Assay procedure
A21: 2.1. Preparation of human liver microsome working solution
A22: The human liver microsome working solution was prepared according to Table 7. Obtain the substrate and HLM mixture.
A23: Table 7. Preparation of human liver microsome working solution
A24: Buffer | C24: Stock Concentration | E24: Final Concentration
A25: Microsomes | C25: 20 mg/mL | E25: 0.2 mg/mL
A26: Phosphate buffer | C26: 100 mM | E26: 100 mM
A27: Substrate | C27: - | E27: -
A28: 2.2.Compound Dilution
A29: The working solution of the test compound is configured according to the following table, and the appropriate solvent is selected according to the solubility of the compound.
A30: Table 8: Compound dilution
A31: Stock Solution/ mM | C31: Final Conc. (μM)
A33: 10 | C33: 10
A35: 2.3. Incubation
A36: All samples were incubated in a 37°C water bath, with two parallels for each concentration of the test compund and two parallels for each concentration of the positive control inhibitor. After pre-incubation, add NADPH regeneration solution to all samples to start the reaction . Then put it back in the water bath and incubate for a certain period of time.The experiments of each isozyme are summarized in the following table.
A37: Table 9. Summary table of each isozyme experiment
A38: CYP Isoform | C38: Substrate | E38: Protein Conc. | G38: Inhibitor | I38: Metabolite
A40: 2C9 | C40: diclofenac | E40: 0.100 mg/mL | G40: sulfaphenazole | I40: 4'-hydroxydiclofenac
A41: 2D6 | C41: dextromethorphan | G41: quinidine | I41: dextrorphan
A42: 3A4 | C42: midazolam | G42: ketoconazole | I42: 1-hydroxymidazolam
A43: 3A4 | C43: testosterone | G43: ketoconazole | I43: 6ß-Hydroxytesterone
...

Sheet Data
A2: Inhibition on 2C9
A4: Compounds | B4: Conc (μM) | C4: 4'-hydroxydiclofenac | D4: Mean | E4: Activity (% VC) | F4: Inhibition(% VC)
C5: Area Ratio
A6: HW350003A | B6: 10 μM | C6: 0.0374 | D6: =AVERAGE(C6:C7) -> 0.03885 | E6: =D6/D10*100 -> 96.762142 | F6: =100-E6 -> 3.237858 | H6: *IC50＞ | I6: 10 | J6: μM
C7: 0.0403
A8: Sulfaphenazole | B8: 3 μM | C8: 0.008 | D8: =AVERAGE(C8:C9) -> 0.008005 | E8: =D8/D10*100 -> 19.937733 | F8: =100-E8 -> 80.062267 | H8: *IC50= | I8: =E8/(100-E8)*3 -> 0.74708353 | J8: μM
C9: 0.00801
A10: No inhibitor | B10: 0 | C10: 0.0391 | D10: =AVERAGE(C10:C11) -> 0.04015 | E10: =D10/D10*100 -> 100 | F10: =100-E10 -> 0 | H10: *IC50 = x * (100 - %inhibition at x) / %inhibition, suppose Hill slope = 1
C11: 0.0412 | H11: x= concentration of control compound
A15: Inhibition on 2D6
A17: Compounds | B17: Conc (μM) | C17: dextrorphan | D17: Mean | E17: Activity (% VC) | F17: Inhibition(% VC)
C18: Area Ratio
A19: HW350003A | B19: 10 μM | C19: 6.54 | D19: =AVERAGE(C19:C20) -> 6.93 | E19: =D19/D23*100 -> 105.15933 | F19: 0 | H19: *IC50＞ | I19: 10 | J19: μM
C20: 7.32
A21: Quinidine | B21: 3 μM | C21: 0.567 | D21: =AVERAGE(C21:C22) -> 0.551 | E21: =D21/D23*100 -> 8.3611533 | F21: =100-E21 -> 91.638847 | H21: *IC50= | I21: =E21/(100-E21)*3 -> 0.27372081 | J21: μM
C22: 0.535
A23: No inhibitor | B23: 0 | C23: 6.66 | D23: =AVERAGE(C23:C24) -> 6.59 | E23: =D23/D23*100 -> 100 | F23: =100-E23 -> 0 | H23: *IC50 = x * (100 - %inhibition at x) / %inhibition, suppose Hill slope = 1
C24: 6.52 | H24: x= concentration of control compound
A28: Inhibition on 3A4 (midazolam)
A30: Compounds | B30: Conc (μM) | C30: 1-hydroxymidazolam | D30: Mean | E30: Activity (% VC) | F30: Inhibition(% VC)
C31: Area Ratio
A32: HW350003A | B32: 10 μM | C32: 6.44 | D32: =AVERAGE(C32:C33) -> 6.64 | E32: =D32/D36*100 -> 104.07524 | F32: 0 | H32: *IC50＞ | I32: 10 | J32: μM
C33: 6.84
A34: ketoconazole | B34: 3 μM | C34: 0.106 | D34: =AVERAGE(C34:C35) -> 0.111 | E34: =D34/D36*100 -> 1.7398119 | F34: =100-E34 -> 98.260188 | H34: *IC50= | I34: =E34/(100-E34)*3 -> 0.05311852 | J34: μM
C35: 0.116
A36: No inhibitor | B36: 0 | C36: 6.25 | D36: =AVERAGE(C36:C37) -> 6.38 | E36: =D36/D36*100 -> 100 | F36: =100-E36 -> 0 | H36: *IC50 = x * (100 - %inhibition at x) / %inhibition, suppose Hill slope = 1
C37: 6.51 | H37: x= concentration of control compound
A41: Inhibition on 3A4 (testosterone)
A43: Compounds | B43: Conc (μM) | C43: 6ß-Hydroxytesterone | D43: Mean | E43: Activity (% VC) | F43: Inhibition(% VC)
C44: Area Ratio
A45: HW350003A | B45: 10 μM | C45: 1.52 | D45: =AVERAGE(C45:C46) -> 1.48 | E45: =D45/D49*100 -> 97.368421 | F45: =100-E45 -> 2.6315789 | H45: *IC50＞ | I45: 10 | J45: μM
C46: 1.44
A47: ketoconazole | B47: 3 μM | C47: 0.0533 | D47: =AVERAGE(C47:C48) -> 0.05395 | E47: =D47/D49*100 -> 3.5493421 | F47: =100-E47 -> 96.450658 | H47: *IC50= | I47: =E47/(100-E47)*3 -> 0.11039869 | J47: μM
C48: 0.0546
A49: No inhibitor | B49: 0 | C49: 1.5 | D49: =AVERAGE(C49:C50) -> 1.52 | E49: =D49/D49*100 -> 100 | F49: =100-E49 -> 0 | H49: *IC50 = x * (100 - %inhibition at x) / %inhibition, suppose Hill slope = 1
C50: 1.54 | H50: x= concentration of control compound
A55: Peak Name: Tolbutamide
A56: Use as Internal Standard
A57: Q1/Q3 Masses: 269.20/170.00 Da
A59: Peak Name: 4-Hydroxy Diclofenac
...

Sheet Bioanalytical Method
A1: Bioanalytical Method
A2: 1. LC-MS/MS method of 4'-hydroxydiclofenac | G2: 2. LC-MS/MS method of dextrorphan
A3: Compound | B3: 4'-hydroxy diclofenac | G3: Compound | H3: dextrorphan
A4: LC Methods | G4: LC Methods
A5: Mobile phase A | B5: 0.1% Formic Acid in Water | G5: Mobile phase A | H5: 0.1% Formic Acid in Water
A6: Mobile phase B | B6: 100% Acetonitrile | G6: Mobile phase B | H6: 100% Acetonitrile
A7: Column | B7: Synergi 4 µm Fusion-RP, 2 mm *50 mm | G7: Column | H7: Synergi 4 µm Fusion-RP, 2 mm *50 mm
A8: Internal standard | B8: Tolbutamide | G8: Internal standard | H8: Tolbutamide
A9: LC system | B9: ExionLC | G9: LC system | H9: ExionLC
A10: Injection Volume | B10: 5 µL | G10: Injection Volume | H10: 2 µL
A11: Gradient conditions | B11: Time (min) | C11: Flow (mL/min) | D11: A(%) | E11: B(%) | G11: Gradient conditions | H11: Time (min) | I11: Flow (mL/min) | J11: A(%) | K11: B(%)
B12: 0 | C12: 0.8 | D12: =100-E12 -> 80 | E12: 20 | H12: 0 | I12: 0.8 | J12: =100-K12 -> 90 | K12: 10
B13: 0.9 | C13: 0.8 | D13: =100-E13 -> 5 | E13: 95 | H13: 0.1 | I13: 0.8 | J13: 90 | K13: 10
B14: 1.2 | C14: 0.8 | D14: =100-E14 -> 5 | E14: 95 | H14: 0.9 | I14: 0.8 | J14: =100-K14 -> 5 | K14: 95
B15: 1.21 | C15: 0.8 | D15: =100-E15 -> 80 | E15: 20 | H15: 1.2 | I15: 0.8 | J15: =100-K15 -> 5 | K15: 95
B16: 1.5 | C16: 0.8 | D16: =100-E16 -> 80 | E16: 20 | H16: 1.2 | I16: 0.8 | J16: =100-K16 -> 90 | K16: 10
A17: MS Methods | H17: 1.5 | I17: 0.8 | J17: =100-K17 -> 90 | K17: 10
A18: MS | B18: Triple Quad 6500+ Low Mass | G18: MS Methods
A19: Ionization model | B19: ESI | G19: MS | H19: Triple Quad 6500+ Low Mass
A20: Scan type | B20: MRM | G20: Ionization model | H20: ESI
A21: polarity | B21: Negative | G21: Scan type | H21: MRM
A22: Name | B22: Ion pair(m/z) | D22: DP(eV) | E22: CE(eV) | G22: polarity | H22: Positive
A23: 4'-hydroxy diclofenac | B23: 310.20/166.10 | D23: -93 | E23: -37 | G23: Name | H23: Ion pair(m/z) | J23: DP(eV) | K23: CE(eV)
A24: Tolbutamide | B24: 269.2/170.0 | D24: -51 | E24: -22 | G24: dextrorphan | H24: 258.40/199.20 | J24: 65 | K24: 36
G25: Tolbutamide | H25: 271.1/155.0 | J25: 52 | K25: 25
A29: 3. LC-MS/MS method of 1-hydroxymidazolam | G29: 4. LC-MS/MS method of 6ß-hydroxytesterone
A30: Compound | B30: 1-hydroxymidazolam | G30: Compound | H30: 6ß-hydroxytesterone
A31: LC Methods | G31: LC Methods
A32: Mobile phase A | B32: 0.1% Formic Acid in Water | G32: Mobile phase A | H32: 0.1% Formic Acid in Water
A33: Mobile phase B | B33: 100% Acetonitrile | G33: Mobile phase B | H33: 100% Acetonitrile
A34: Column | B34: Waters XBridge®BEH C18 2.5µm | G34: Column | H34: Waters XBridge®BEH C18 2.5µm
A35: Internal standard | B35: Tolbutamide | G35: Internal standard | H35: Tolbutamide
A36: LC system | B36: ExionLC | G36: LC system | H36: ExionLC
A37: Injection Volume | B37: 5 µL | G37: Injection Volume | H37: 1 µL
A38: Gradient conditions | B38: Time (min) | C38: Flow (mL/min) | D38: A(%) | E38: B(%) | G38: Gradient conditions | H38: Time (min) | I38: Flow (mL/min) | J38: A(%) | K38: B(%)
B39: 0 | C39: 0.8 | D39: 75 | E39: 25 | H39: 0 | I39: 0.7 | J39: =100-K39 -> 75 | K39: 25
B40: 0.8 | C40: 0.8 | D40: 65 | E40: 35 | H40: 0.2 | I40: =I39 -> 0.7 | J40: 85 | K40: 25
B41: 1.3 | C41: 0.8 | D41: 5 | E41: 95 | H41: 1.2 | I41: =I40 -> 0.7 | J41: =100-K41 -> 60 | K41: 40
B42: 1.5 | C42: 0.8 | D42: 5 | E42: 95 | H42: 1.6 | I42: =I41 -> 0.7 | J42: =100-K42 -> 5 | K42: 95
B43: 1.51 | C43: 0.8 | D43: 75 | E43: 25 | H43: 1.9 | I43: =I42 -> 0.7 | J43: 5 | K43: 95
...
