Workbook
Name OLE_LINK15: Bioanalysis!$C$15

Sheet Cover
C1: 3D BioOptima Quality That Matters
B4: 实验项目 | C4: HW356054小鼠单次给药药代动力学研究
B5: 课题编号 | C5: =Setting!B1 -> 3D_SN322418
B6: 实验方案编号 | C6: 3D_PN322819
B7: 化合物 | C7: =Setting!B2 -> HW356054
B8: 课题负责人 | C8: 杨德孝
B9: 实验参与人员 | C9: 冯本杰、胡长亮、梁永伟和郭芳
B10: 报告撰写 | C10: 钱晨艳
B11: 数据质控 | C11: 程翠
B12: 批准人 | C12: 唐开阳
B13: 生效期 | C13: 05-19-2025
B14: 实验负责方 | C14: 苏州圣苏新药开发有限公司 苏州市吴中区吴中大道1338号
B15: 实验委托方 | C15: 湖北生物医药产业技术研究院有限公司 武汉市东湖高新区高新大道666号C7栋217室
E19: Confidential

Sheet Formulation
B2: 制剂报告 Formulation Report
C4: 化合物信息 Compound Information
C5: 供试品 Compound | E5: 批号 Lot | F5: 游离/盐 Free/Salt | G5: FW | H5: MW | I5: 折算系数CF
C6: HW356054 | E6: HWH817-XQ-35-6054 | F6: NA | G6: NA | H6: 574.12 | I6: 1
C8: 溶媒信息 Reagent Information
C9: 名称 Name | F9: 生产厂商 Manufacturer | H9: 批号/编号 Lot No./ID
C10: Saline 氯化钠溶液 | F10: 安徽丰原药业股份有限公司 | H10: 1124051207
C11: DMA N-N-二甲基乙酰胺 | F11: aladdin | H11: E2226029
C12: Kolliphor® HS15(Solutol HS15) | F12: BASF | H12: 62863656P0
B15: (IG-A)给药制剂配制
C16: 化合物 Compound ID | E16: 处方 Formulation | G16: 浓度 Conc. (mg/mL) | H16: 称重 Amount (mg) | I16: 总体积 Volume (mL)
C17: HW356054 | E17: DMA:Solutol HS15:Saline = 5:10:85 (v/v/v) | G17: 1 | H17: 2.53 | I17: 2.530
C19: 配制日期 Preparation Date: | E19: 45792
C20: 配制方法 Actual Procedure:
C21: 1.加入0.127 mL DMA，涡旋，溶解。 2.加入0.253 mL 水浴融化的Kolliphor® HS15(Solutol HS15)，涡旋混匀。 3.加入2.151 mL Saline，涡旋混匀，静置5 min，析出混悬。
C22: 结论 Conclusion
C23: 滤膜/Filter | E23: 结果观察 Result | G23: 留样 Volume (mL) | H23: 注释 Comments
C24: NA | E24: 微粉色混悬液 | G24: 0.2 | H24: NA
B27: HW356054的剂量准确度
C28: 分析日期 Analyse Date: | E28: 45792
C29: 样品制备 Sample Preparation：
C30: 05-15-2025-HW356054-SS1 | D30: 1. 移取100 μL处理液 / 加入900 μL稀释液D1至100 μg/mL，涡旋，超声5 min；
C31: IG-A | D31: 1. 移取100 μL处理液 / 加入900 μL稀释液D1至100 μg/mL，涡旋，超声5 min；
D32: 所有样品处理后，离心 8000 rpm 6 min；取上清液200 μL用于HPLC分析。
D33: 稀释液D1：ACN:H2O(1:1)
C34: 液相条件 HPLC Conditions:
C35: 液相编号 LC ID | E35: EQ-HPLC-002 | F35: 检测器 Detector | G35: Agilent DAD | H35: Time（min） | I35: Ratio-B（%）
C36: 色谱柱信息 Column Info | E36: 50-321/Waters XBridge C18 3.5μm 2.1×50 mm | H36: 0.20 2.50 3.50 4.00 6.00 | I36: 5 90 90 5 stop
C37: 流动相A Mobile Phase A | E37: H2O (0.1% Formic Acid) | F37: 流速 Flow(mL/min) | G37: 0.8
C38: 流动相B Mobile Phase B | E38: ACN (0.1% Formic Acid) | F38: 进样量 Inj Volume(μL) | G38: 5
C39: 波长 Wavelength(nm) | E39: 254 | F39: 柱温 Column Temp(℃) | G39: 30
C41: 数据评估Data Evaluation
C42: 保留时间 Retention Time （min） | E42: 样品名称 ID | F42: 标示浓度 Nominal Conc.(µg/mL) | G42: 峰面积Area | H42: 分析浓度Actual Conc. (μg/mL) | I42: 相对偏差 RD(%)
C43: 3.3 | E43: 05-15-2025-HW356054-SS1 | F43: 100 | G43: 856 | H43: 100 | I43: 0
E44: IG-A | F44: 100 | G44: 883.4 | H44: 103.2 | I44: 3.2
C46: 注释 Comments
C47: NA

Sheet In-Life
B2: 实验设计
B3: 组别 | C3: 动物编号 （动物ID） | D3: 性别 | E3: 化合物 | F3: 动物只数 | G3: 给药途径 | H3: 给药剂量 (mg/kg) | I3: 制剂浓度 (mg/mL) | J3: 给药体积 (mL/kg) | K3: 采样时间点
B4: A | C4: A1 | D4: 雄 | E4: HW356054 /HWH817-XQ-35-6054 | F4: 3 | G4: 灌胃 | H4: 10 | I4: 1 | J4: 10 | K4: 给药后0.25、0.5、1、2、4、8、10、24 h。
C5: A2 | D5: 雄
C6: A3 | D6: 雄
B8: 动物信息 | C8: ICR(CD-1)，雄，n = 3，33.4-35.7 g，购买于维通利华实验动物技术有限公司。 动物质量合格证号：20250423Abzz06190000328。
B9: 动物饮食状态 | C9: 所有动物给药前禁食，禁食时间不少于12 h，于给药后4 h恢复给食，保持所有动物在实验过程中均可自由饮水。 | P9: 1
B10: 样品收集 | C10: 实验当天，分别于各设定时间点经由眼眶采血60 μL，全血样品置于含EDTA-K2的抗凝管中。
B11: 样品处理 | C11: 全血样品于1500 g，4 °C离心10 min分离血浆，收集上层血浆样品至样品管中。
B12: 溶血检查 | C12: 未发现溶血现象。
B13: 临床观察 | C13: 未发现明显临床异常。
B14: 样品储存和处理 | C14: 生物样品于-40~-20 °C条件保存待分析。 本实验获得的生物样品将在测定结束后保存在-40至-20 °C冰箱中，保存期限为两个月。
B15: 数据保存 | C15: 实验过程中所涉及的原始记录、原始图谱、实验报告册、票据、技术资料和总结均保存在苏州圣苏新药开发有限公司，保存时间为6年。

Sheet Bioanalysis
A1: Analytical Method
B3: Instrument | C3: Triple Quad 5500: LC-MS-MS-020)
B4: Matrix | C4: =CONCATENATE(Setting!B3," Plasma") -> ICR Mouse Plasma
B5: Analyte(s) | C5: =Setting!$B$2 -> HW356054
B6: Internal standard(s) | C6: Diclofenac
B7: MS conditions | C7: Positive, ESI
C8: MRM Detection
C9: Analyte: m/z 575.2/302.1
C10: IS: m/z 296.0/215.1
B11: HPLC conditions | C11: Mobile Phase
C12: Mobile Phase A: Water (0.1% Formic Acid + 5 mM NH4OAc)
C13: Mobile Phase B: ACN (0.1% Formic Acid)
C14: Time (min) | D14: Mobile phase B (%)
C15: 0.5 | D15: 45
C16: 1.1 | D16: 95
C17: 1.8 | D17: 95
C18: 1.81 | D18: 45
C19: 2.5 | D19: Stop
C20: Column: Agilent ZORBAX XDB-C18, 5.0 μm, 2.1×50 mm | F20: Column ID: 50-424
C21: Flow rate: 0.50 mL/min
B22: Injection Volume: | C22: 5 μL
B23: Retention Time: | C23: =CONCATENATE(Setting!B2,": 1.37 min") -> HW356054: 1.37 min
C24: =CONCATENATE("IS: 1.29 min") -> IS: 1.29 min
B25: Representative Chromatography
B42: Sample preparation | C42: For plasma samples: An aliquot of 10 µL of sample was added with 200 µL ACN:MeOH(1:1) which contains of Verapamil, 1 ng/mL, Glibenclamide, 10 ng/mL, Tolbutamide, 40 ng/mL and Diclofenac, 40 ng/mL, the mixture was vortexed for 10 min, then centrifuged at 3700 rpm for 10 min. Then 70 µL of supernatant was added with 70 µL water, then vortexed for 10 min.
A44: =Setting!B2 -> HW356054
B45: Calibration curve | C45: 0.5-1000 ng/mL
B47: =CONCATENATE("SD Curve and QC of ",Setting!$B$2," in ",Bioanalysis!$C$4) -> SD Curve and QC of HW356054 in ICR Mouse Plasma
B48: Sample Name | C48: Analytical. Conc. (ng/mL) | D48: Calculated Conc. (ng/mL) | E48: % RE
B49: HW356054-MC-PL-Batch1-Blank | C49: =VLOOKUP(B49,'Raw Data'!$A$16:$K$552,3,0) -> 0 | D49: =VLOOKUP($B49,'Raw Data'!$A$16:$K$552,10,0) -> N/A | E49: =VLOOKUP($B49,'Raw Data'!$A$16:$K$552,11,0) -> N/A
B50: HW356054-MC-PL-Batch1-QC0 | C50: =VLOOKUP(B50,'Raw Data'!$A$16:$K$552,3,0) -> 0 | D50: =VLOOKUP($B50,'Raw Data'!$A$16:$K$552,10,0) -> N/A | E50: =VLOOKUP($B50,'Raw Data'!$A$16:$K$552,11,0) -> N/A
B51: HW356054-MC-PL-Batch1-Cline-0.5ng | C51: =VLOOKUP(B51,'Raw Data'!$A$16:$K$552,3,0) -> 0.5 | D51: =VLOOKUP($B51,'Raw Data'!$A$16:$K$552,10,0) -> 0.5 | E51: =VLOOKUP($B51,'Raw Data'!$A$16:$K$552,11,0)-100 -> 0.1
B52: HW356054-MC-PL-Batch1-Cline-1ng | C52: =VLOOKUP(B52,'Raw Data'!$A$16:$K$552,3,0) -> 1 | D52: =VLOOKUP($B52,'Raw Data'!$A$16:$K$552,10,0) -> 0.949 | E52: =VLOOKUP($B52,'Raw Data'!$A$16:$K$552,11,0)-100 -> -5.1
B53: HW356054-MC-PL-Batch1-Cline-2ng | C53: =VLOOKUP(B53,'Raw Data'!$A$16:$K$552,3,0) -> 2 | D53: =VLOOKUP($B53,'Raw Data'!$A$16:$K$552,10,0) -> 2.19 | E53: =VLOOKUP($B53,'Raw Data'!$A$16:$K$552,11,0)-100 -> 9.6
B54: HW356054-MC-PL-Batch1-Cline-5ng | C54: =VLOOKUP(B54,'Raw Data'!$A$16:$K$552,3,0) -> 5 | D54: =VLOOKUP($B54,'Raw Data'!$A$16:$K$552,10,0) -> 5.12 | E54: =VLOOKUP($B54,'Raw Data'!$A$16:$K$552,11,0)-100 -> 2.4
B55: HW356054-MC-PL-Batch1-Cline-20ng | C55: =VLOOKUP(B55,'Raw Data'!$A$16:$K$552,3,0) -> 20 | D55: =VLOOKUP($B55,'Raw Data'!$A$16:$K$552,10,0) -> 18.5 | E55: =VLOOKUP($B55,'Raw Data'!$A$16:$K$552,11,0)-100 -> -7.5
B56: HW356054-MC-PL-Batch1-Cline-100ng | C56: =VLOOKUP(B56,'Raw Data'!$A$16:$K$552,3,0) -> 100 | D56: =VLOOKUP($B56,'Raw Data'!$A$16:$K$552,10,0) -> 100 | E56: =VLOOKUP($B56,'Raw Data'!$A$16:$K$552,11,0)-100 -> 0.2
B57: *HW356054-MC-PL-Batch1-Cline-500ng | C57: =VLOOKUP(B57,'Raw Data'!$A$16:$K$552,3,0) -> 500 | D57: =VLOOKUP($B57,'Raw Data'!$A$16:$K$552,10,0) -> 405 | E57: =VLOOKUP($B57,'Raw Data'!$A$16:$K$552,11,0)-100 -> -19
B58: HW356054-MC-PL-Batch1-Cline-1000ng | C58: =VLOOKUP(B58,'Raw Data'!$A$16:$K$552,3,0) -> 1000 | D58: =VLOOKUP($B58,'Raw Data'!$A$16:$K$552,10,0) -> 1000 | E58: =VLOOKUP($B58,'Raw Data'!$A$16:$K$552,11,0)-100 -> 0.4
B59: **HW356054-MC-PL-Batch1-LQC-1 | C59: =VLOOKUP(B59,'Raw Data'!$A$16:$K$552,3,0) -> 1.5 | D59: =VLOOKUP($B59,'Raw Data'!$A$16:$K$552,10,0) -> 2 | E59: =VLOOKUP($B59,'Raw Data'!$A$16:$K$552,11,0)-100 -> 33
...

Sheet HW356054
E1: =CONCATENATE("Individual and Mean Plasma Concentration-Time Data of ",Setting!$B$2," after an i.g. Dose of ",Setting!$B$8," ",Setting!C8," in ",Setting!$B$3) -> Individual and Mean Plasma Concentration-Time Data of HW356054 after an i.g. Dose of 10 mg/kg in ICR Mouse
E2: Dose | F2: Dose | G2: Sampling | H2: Concentration | K2: Mean | L2: SD | M2: CV (%)
E3: (mg/kg) | F3: route | G3: time | H3: (ng/mL) | K3: (ng/mL)
G4: (h) | H4: A1 | I4: A2 | J4: A3
B5: HW356054-MC-PL-Batch1-IG-A1-0.25h | C5: HW356054-MC-PL-Batch1-IG-A2-0.25h | D5: HW356054-MC-PL-Batch1-IG-A3-0.25h | E5: =Setting!B8 -> 10 | F5: =Setting!$A14 -> IG | G5: =Setting!A15 -> 0.25 | H5: =IF(OR(VLOOKUP(B5,'Raw Data'!$A$16:$K$1543,10,0)="NA",VLOOKUP(B5,'Raw Data'!$A$16:$K$1543,10,0)="No Peak",VLOOKUP(B5,'Raw Data'!$A$16:$K$1543,10,0)<Setting!$B$4),0,VLOOKUP(B5,'Raw Data'!$A$16:$K$1543,10,0)) -> 119 | I5: =IF(OR(VLOOKUP(C5,'Raw Data'!$A$16:$K$1543,10,0)="NA",VLOOKUP(C5,'Raw Data'!$A$16:$K$1543,10,0)="No Peak",VLOOKUP(C5,'Raw Data'!$A$16:$K$1543,10,0)<Setting!$B$4),0,VLOOKUP(C5,'Raw Data'!$A$16:$K$1543,10,0)) -> 190 | J5: =IF(OR(VLOOKUP(D5,'Raw Data'!$A$16:$K$1543,10,0)="NA",VLOOKUP(D5,'Raw Data'!$A$16:$K$1543,10,0)="No Peak",VLOOKUP(D5,'Raw Data'!$A$16:$K$1543,10,0)<Setting!$B$4),0,VLOOKUP(D5,'Raw Data'!$A$16:$K$1543,10,0)) -> 166 | K5: =IFERROR(ROUND(AVERAGE(H5:J5),3-(1+INT(LOG10(AVERAGE(H5:J5))))),0) -> 158 | L5: =IF(COUNT(H5:J5)>2,STDEV(H5:J5),"NA") -> 36.115555 | M5: =IFERROR(L5/K5*100,"NA") -> 22.857946
B6: HW356054-MC-PL-Batch1-IG-A1-0.5h | C6: HW356054-MC-PL-Batch1-IG-A2-0.5h | D6: HW356054-MC-PL-Batch1-IG-A3-0.5h | G6: =Setting!A16 -> 0.5 | H6: =IF(OR(VLOOKUP(B6,'Raw Data'!$A$16:$K$1543,10,0)="NA",VLOOKUP(B6,'Raw Data'!$A$16:$K$1543,10,0)="No Peak",VLOOKUP(B6,'Raw Data'!$A$16:$K$1543,10,0)<Setting!$B$4),"BLOQ",VLOOKUP(B6,'Raw Data'!$A$16:$K$1543,10,0)) -> 144 | I6: =IF(OR(VLOOKUP(C6,'Raw Data'!$A$16:$K$1543,10,0)="NA",VLOOKUP(C6,'Raw Data'!$A$16:$K$1543,10,0)="No Peak",VLOOKUP(C6,'Raw Data'!$A$16:$K$1543,10,0)<Setting!$B$4),"BLOQ",VLOOKUP(C6,'Raw Data'!$A$16:$K$1543,10,0)) -> 219 | J6: =IF(OR(VLOOKUP(D6,'Raw Data'!$A$16:$K$1543,10,0)="NA",VLOOKUP(D6,'Raw Data'!$A$16:$K$1543,10,0)="No Peak",VLOOKUP(D6,'Raw Data'!$A$16:$K$1543,10,0)<Setting!$B$4),"BLOQ",VLOOKUP(D6,'Raw Data'!$A$16:$K$1543,10,0)) -> 205 | K6: =IFERROR(ROUND(AVERAGE(H6:J6),3-(1+INT(LOG10(AVERAGE(H6:J6))))),"BLOQ") -> 189 | L6: =IF(COUNT(H6:J6)>2,ROUND(STDEV(H6:J6),3-(1+INT(LOG10(STDEV(H6:J6))))),"NA") -> 39.9 | M6: =IFERROR(L6/K6*100,"NA") -> 21.111111
B7: HW356054-MC-PL-Batch1-IG-A1-1h | C7: HW356054-MC-PL-Batch1-IG-A2-1h | D7: HW356054-MC-PL-Batch1-IG-A3-1h | G7: =Setting!A17 -> 1 | H7: =IF(OR(VLOOKUP(B7,'Raw Data'!$A$16:$K$1543,10,0)="NA",VLOOKUP(B7,'Raw Data'!$A$16:$K$1543,10,0)="No Peak",VLOOKUP(B7,'Raw Data'!$A$16:$K$1543,10,0)<Setting!$B$4),"BLOQ",VLOOKUP(B7,'Raw Data'!$A$16:$K$1543,10,0)) -> 143 | I7: =IF(OR(VLOOKUP(C7,'Raw Data'!$A$16:$K$1543,10,0)="NA",VLOOKUP(C7,'Raw Data'!$A$16:$K$1543,10,0)="No Peak",VLOOKUP(C7,'Raw Data'!$A$16:$K$1543,10,0)<Setting!$B$4),"BLOQ",VLOOKUP(C7,'Raw Data'!$A$16:$K$1543,10,0)) -> 231 | J7: =IF(OR(VLOOKUP(D7,'Raw Data'!$A$16:$K$1543,10,0)="NA",VLOOKUP(D7,'Raw Data'!$A$16:$K$1543,10,0)="No Peak",VLOOKUP(D7,'Raw Data'!$A$16:$K$1543,10,0)<Setting!$B$4),"BLOQ",VLOOKUP(D7,'Raw Data'!$A$16:$K$1543,10,0)) -> 181 | K7: =IFERROR(ROUND(AVERAGE(H7:J7),3-(1+INT(LOG10(AVERAGE(H7:J7))))),"BLOQ") -> 185 | L7: =IF(COUNT(H7:J7)>2,ROUND(STDEV(H7:J7),3-(1+INT(LOG10(STDEV(H7:J7))))),"NA") -> 44.1 | M7: =IFERROR(L7/K7*100,"NA") -> 23.837838
B8: HW356054-MC-PL-Batch1-IG-A1-2h | C8: HW356054-MC-PL-Batch1-IG-A2-2h | D8: HW356054-MC-PL-Batch1-IG-A3-2h | G8: =Setting!A18 -> 2 | H8: =IF(OR(VLOOKUP(B8,'Raw Data'!$A$16:$K$1543,10,0)="NA",VLOOKUP(B8,'Raw Data'!$A$16:$K$1543,10,0)="No Peak",VLOOKUP(B8,'Raw Data'!$A$16:$K$1543,10,0)<Setting!$B$4),"BLOQ",VLOOKUP(B8,'Raw Data'!$A$16:$K$1543,10,0)) -> 133 | I8: =IF(OR(VLOOKUP(C8,'Raw Data'!$A$16:$K$1543,10,0)="NA",VLOOKUP(C8,'Raw Data'!$A$16:$K$1543,10,0)="No Peak",VLOOKUP(C8,'Raw Data'!$A$16:$K$1543,10,0)<Setting!$B$4),"BLOQ",VLOOKUP(C8,'Raw Data'!$A$16:$K$1543,10,0)) -> 185 | J8: =IF(OR(VLOOKUP(D8,'Raw Data'!$A$16:$K$1543,10,0)="NA",VLOOKUP(D8,'Raw Data'!$A$16:$K$1543,10,0)="No Peak",VLOOKUP(D8,'Raw Data'!$A$16:$K$1543,10,0)<Setting!$B$4),"BLOQ",VLOOKUP(D8,'Raw Data'!$A$16:$K$1543,10,0)) -> 132 | K8: =IFERROR(ROUND(AVERAGE(H8:J8),3-(1+INT(LOG10(AVERAGE(H8:J8))))),"BLOQ") -> 150 | L8: =IF(COUNT(H8:J8)>2,ROUND(STDEV(H8:J8),3-(1+INT(LOG10(STDEV(H8:J8))))),"NA") -> 30.3 | M8: =IFERROR(L8/K8*100,"NA") -> 20.2
B9: HW356054-MC-PL-Batch1-IG-A1-4h | C9: HW356054-MC-PL-Batch1-IG-A2-4h | D9: HW356054-MC-PL-Batch1-IG-A3-4h | G9: =Setting!A19 -> 4 | H9: =IF(OR(VLOOKUP(B9,'Raw Data'!$A$16:$K$1543,10,0)="NA",VLOOKUP(B9,'Raw Data'!$A$16:$K$1543,10,0)="No Peak",VLOOKUP(B9,'Raw Data'!$A$16:$K$1543,10,0)<Setting!$B$4),"BLOQ",VLOOKUP(B9,'Raw Data'!$A$16:$K$1543,10,0)) -> 147 | I9: =IF(OR(VLOOKUP(C9,'Raw Data'!$A$16:$K$1543,10,0)="NA",VLOOKUP(C9,'Raw Data'!$A$16:$K$1543,10,0)="No Peak",VLOOKUP(C9,'Raw Data'!$A$16:$K$1543,10,0)<Setting!$B$4),"BLOQ",VLOOKUP(C9,'Raw Data'!$A$16:$K$1543,10,0)) -> 155 | J9: =IF(OR(VLOOKUP(D9,'Raw Data'!$A$16:$K$1543,10,0)="NA",VLOOKUP(D9,'Raw Data'!$A$16:$K$1543,10,0)="No Peak",VLOOKUP(D9,'Raw Data'!$A$16:$K$1543,10,0)<Setting!$B$4),"BLOQ",VLOOKUP(D9,'Raw Data'!$A$16:$K$1543,10,0)) -> 126 | K9: =IFERROR(ROUND(AVERAGE(H9:J9),3-(1+INT(LOG10(AVERAGE(H9:J9))))),"BLOQ") -> 143 | L9: =IF(COUNT(H9:J9)>2,ROUND(STDEV(H9:J9),3-(1+INT(LOG10(STDEV(H9:J9))))),"NA") -> 15 | M9: =IFERROR(L9/K9*100,"NA") -> 10.48951
B10: HW356054-MC-PL-Batch1-IG-A1-8h | C10: HW356054-MC-PL-Batch1-IG-A2-8h | D10: HW356054-MC-PL-Batch1-IG-A3-8h | G10: =Setting!A20 -> 8 | H10: =IF(OR(VLOOKUP(B10,'Raw Data'!$A$16:$K$1543,10,0)="NA",VLOOKUP(B10,'Raw Data'!$A$16:$K$1543,10,0)="No Peak",VLOOKUP(B10,'Raw Data'!$A$16:$K$1543,10,0)<Setting!$B$4),"BLOQ",VLOOKUP(B10,'Raw Data'!$A$16:$K$1543,10,0)) -> 144 | I10: =IF(OR(VLOOKUP(C10,'Raw Data'!$A$16:$K$1543,10,0)="NA",VLOOKUP(C10,'Raw Data'!$A$16:$K$1543,10,0)="No Peak",VLOOKUP(C10,'Raw Data'!$A$16:$K$1543,10,0)<Setting!$B$4),"BLOQ",VLOOKUP(C10,'Raw Data'!$A$16:$K$1543,10,0)) -> 116 | J10: =IF(OR(VLOOKUP(D10,'Raw Data'!$A$16:$K$1543,10,0)="NA",VLOOKUP(D10,'Raw Data'!$A$16:$K$1543,10,0)="No Peak",VLOOKUP(D10,'Raw Data'!$A$16:$K$1543,10,0)<Setting!$B$4),"BLOQ",VLOOKUP(D10,'Raw Data'!$A$16:$K$1543,10,0)) -> 113 | K10: =IFERROR(ROUND(AVERAGE(H10:J10),3-(1+INT(LOG10(AVERAGE(H10:J10))))),"BLOQ") -> 124 | L10: =IF(COUNT(H10:J10)>2,ROUND(STDEV(H10:J10),3-(1+INT(LOG10(STDEV(H10:J10))))),"NA") -> 17.1 | M10: =IFERROR(L10/K10*100,"NA") -> 13.790323
B11: HW356054-MC-PL-Batch1-IG-A1-10h | C11: HW356054-MC-PL-Batch1-IG-A2-10h | D11: HW356054-MC-PL-Batch1-IG-A3-10h | G11: =Setting!A21 -> 10 | H11: =IF(OR(VLOOKUP(B11,'Raw Data'!$A$16:$K$1543,10,0)="NA",VLOOKUP(B11,'Raw Data'!$A$16:$K$1543,10,0)="No Peak",VLOOKUP(B11,'Raw Data'!$A$16:$K$1543,10,0)<Setting!$B$4),"BLOQ",VLOOKUP(B11,'Raw Data'!$A$16:$K$1543,10,0)) -> 128 | I11: =IF(OR(VLOOKUP(C11,'Raw Data'!$A$16:$K$1543,10,0)="NA",VLOOKUP(C11,'Raw Data'!$A$16:$K$1543,10,0)="No Peak",VLOOKUP(C11,'Raw Data'!$A$16:$K$1543,10,0)<Setting!$B$4),"BLOQ",VLOOKUP(C11,'Raw Data'!$A$16:$K$1543,10,0)) -> 75.3 | J11: =IF(OR(VLOOKUP(D11,'Raw Data'!$A$16:$K$1543,10,0)="NA",VLOOKUP(D11,'Raw Data'!$A$16:$K$1543,10,0)="No Peak",VLOOKUP(D11,'Raw Data'!$A$16:$K$1543,10,0)<Setting!$B$4),"BLOQ",VLOOKUP(D11,'Raw Data'!$A$16:$K$1543,10,0)) -> 75.8 | K11: =IFERROR(ROUND(AVERAGE(H11:J11),3-(1+INT(LOG10(AVERAGE(H11:J11))))),"BLOQ") -> 93 | L11: =IF(COUNT(H11:J11)>2,ROUND(STDEV(H11:J11),3-(1+INT(LOG10(STDEV(H11:J11))))),"NA") -> 30.3 | M11: =IFERROR(L11/K11*100,"NA") -> 32.580645
B12: HW356054-MC-PL-Batch1-IG-A1-24h | C12: HW356054-MC-PL-Batch1-IG-A2-24h | D12: HW356054-MC-PL-Batch1-IG-A3-24h | G12: =Setting!A22 -> 24 | H12: =IF(OR(VLOOKUP(B12,'Raw Data'!$A$16:$K$1543,10,0)="NA",VLOOKUP(B12,'Raw Data'!$A$16:$K$1543,10,0)="No Peak",VLOOKUP(B12,'Raw Data'!$A$16:$K$1543,10,0)<Setting!$B$4),"BLOQ",VLOOKUP(B12,'Raw Data'!$A$16:$K$1543,10,0)) -> 41.6 | I12: =IF(OR(VLOOKUP(C12,'Raw Data'!$A$16:$K$1543,10,0)="NA",VLOOKUP(C12,'Raw Data'!$A$16:$K$1543,10,0)="No Peak",VLOOKUP(C12,'Raw Data'!$A$16:$K$1543,10,0)<Setting!$B$4),"BLOQ",VLOOKUP(C12,'Raw Data'!$A$16:$K$1543,10,0)) -> 2.41 | J12: =IF(OR(VLOOKUP(D12,'Raw Data'!$A$16:$K$1543,10,0)="NA",VLOOKUP(D12,'Raw Data'!$A$16:$K$1543,10,0)="No Peak",VLOOKUP(D12,'Raw Data'!$A$16:$K$1543,10,0)<Setting!$B$4),"BLOQ",VLOOKUP(D12,'Raw Data'!$A$16:$K$1543,10,0)) -> 2.01 | K12: =IFERROR(ROUND(AVERAGE(H12:J12),3-(1+INT(LOG10(AVERAGE(H12:J12))))),"BLOQ") -> 15.3 | L12: =IF(COUNT(H12:J12)>2,ROUND(STDEV(H12:J12),3-(1+INT(LOG10(STDEV(H12:J12))))),"NA") -> 22.7 | M12: =IFERROR(L12/K12*100,"NA") -> 148.36601
E14: PK Parameters | G14: Unit | H14: =H4 -> A1 | I14: =I4 -> A2 | J14: =J4 -> A3 | K14: Mean | L14: SD | M14: CV (%)
E15: Rsq_adjusted | G15: NA | H15: 0.998 | I15: 1 | J15: 0.999 | K15: NA | L15: NA | M15: NA
E16: Kel | F16: Lambda_z | G16: 1/h | H16: 0.0786 | I16: 0.243 | J16: 0.255 | K16: =IFERROR(ROUND(AVERAGE(H16:J16),3-(1+INT(LOG10(AVERAGE(H16:J16))))),"NR") -> 0.192 | L16: =IF(COUNT(H16:J16)>2,ROUND(STDEV(H16:J16),3-(1+INT(LOG10(STDEV(H16:J16))))),"NA") -> 0.0986 | M16: =IFERROR(L16/K16*100,"NA") -> 51.354167
E17: T1/2 | F17: HL_Lambda_z | G17: h | H17: 8.82 | I17: 2.85 | J17: 2.72 | K17: =IFERROR(ROUND(AVERAGE(H17:J17),3-(1+INT(LOG10(AVERAGE(H17:J17))))),"NR") -> 4.8 | L17: =IF(COUNT(H17:J17)>2,ROUND(STDEV(H17:J17),3-(1+INT(LOG10(STDEV(H17:J17))))),"NA") -> 3.48 | M17: =IFERROR(L17/K17*100,"NA") -> 72.5
E18: Tmax | G18: h | H18: 4 | I18: 1 | J18: 0.5 | K18: =IFERROR(ROUND(AVERAGE(H18:J18),3-(1+INT(LOG10(AVERAGE(H18:J18))))),"NR") -> 1.83 | L18: =IF(COUNT(H18:J18)>2,STDEV(H18:J18),"NA") -> 1.8929694 | M18: =IFERROR(L18/K18*100,"NA") -> 103.44095
E19: Cmax | G19: ng/mL | H19: 147 | I19: 231 | J19: 205 | K19: =IFERROR(ROUND(AVERAGE(H19:J19),3-(1+INT(LOG10(AVERAGE(H19:J19))))),"NR") -> 194 | L19: =IF(COUNT(H19:J19)>2,ROUND(STDEV(H19:J19),3-(1+INT(LOG10(STDEV(H19:J19))))),"NA") -> 43 | M19: =IFERROR(L19/K19*100,"NA") -> 22.164948
E20: AUC0-t | G20: ng·h/mL | H20: 2580 | I20: 2010 | J20: 1790 | K20: =IFERROR(ROUND(AVERAGE(H20:J20),3-(1+INT(LOG10(AVERAGE(H20:J20))))),"NR") -> 2130 | L20: =IF(COUNT(H20:J20)>2,ROUND(STDEV(H20:J20),3-(1+INT(LOG10(STDEV(H20:J20))))),"NA") -> 408 | M20: =IFERROR(L20/K20*100,"NA") -> 19.15493
E21: AUC0-inf | G21: ng·h/mL | H21: NR | I21: 2020 | J21: 1800 | K21: =IFERROR(ROUND(AVERAGE(H21:J21),3-(1+INT(LOG10(AVERAGE(H21:J21))))),"NR") -> 1910 | L21: =IF(COUNT(H21:J21)>2,ROUND(STDEV(H21:J21),3-(1+INT(LOG10(STDEV(H21:J21))))),"NA") -> NA | M21: =IFERROR(L21/K21*100,"NA") -> NA
E22: MRT0-t | F22: MRTlast | G22: h | H22: 8.92 | I22: 5.89 | J22: 6.26 | K22: =IFERROR(ROUND(AVERAGE(H22:J22),3-(1+INT(LOG10(AVERAGE(H22:J22))))),"NR") -> 7.02 | L22: =IF(COUNT(H22:J22)>2,ROUND(STDEV(H22:J22),3-(1+INT(LOG10(STDEV(H22:J22))))),"NA") -> 1.65 | M22: =IFERROR(L22/K22*100,"NA") -> 23.504274
E23: MRT0-inf | F23: MRTINF_obs | G23: h | H23: NR | I23: 6 | J23: 6.36 | K23: =IFERROR(ROUND(AVERAGE(H23:J23),3-(1+INT(LOG10(AVERAGE(H23:J23))))),"NR") -> 6.18 | L23: =IF(COUNT(H23:J23)>2,ROUND(STDEV(H23:J23),3-(1+INT(LOG10(STDEV(H23:J23))))),"NA") -> NA | M23: =IFERROR(L23/K23*100,"NA") -> NA
E25: =CONCATENATE("Individual Semi logarithmic-Plasma Concentration-Time Profile of ",Setting!$B$2," after an i.g. Dose of ",Setting!$B$8," ",Setting!C8," in ",Setting!$B$3) -> Individual Semi logarithmic-Plasma Concentration-Time Profile of HW356054 after an i.g. Dose of 10 mg/kg in ICR Mouse
E26: Graph
E27: =CONCATENATE("Mean Semi logarithmic-Plasma Concentration-Time Profile of ",Setting!$B$2," after an i.g. Dose of ",Setting!$B$8," ",Setting!C8," in ",Setting!$B$3,"") -> Mean Semi logarithmic-Plasma Concentration-Time Profile of HW356054 after an i.g. Dose of 10 mg/kg in ICR Mouse
E30: Note: | F30: =CONCATENATE("1) BLOQ = Below the lower limit of quantification (",Setting!$B$4," ",Setting!$B$5,") if it shows in the table above.") -> 1) BLOQ = Below the lower limit of quantification (0.5 ng/mL) if it shows in the table above.
F31: 2) PK parameters were estimated by non-compartmental model using WinNonlin 8.3.
F32: 3) NA = Not Applicable.
F33: 4) NR = Not Reportable.

Sheet Raw Data
A2: Peak Name: Dic
A3: Use as Internal Standard
A4: Q1/Q3 Masses: 296.00/215.10 Da
A6: Peak Name: HW356054
A7: Internal Standard: Dic
A8: Q1/Q3 Masses: 575.20/302.10 Da
A10: Fit | B10: Linear | C10: Weighting | D10: 1 / (x * x) | E10: Iterate | F10: No
A11: Intercept | B11: 3.82e-06
A12: Slope | B12: 0.00166
A13: Correlation coefficient | B13: 0.9979
A14: Use Area
F16: =AVERAGE(F22:F26,F30:F31,F58:F60,F62:F64) -> 741692.31 | G16: =F16*1.5 -> 1112538.5
G17: =F16*0.5 -> 370846.15
A19: Sample Name | B19: Sample Type | C19: Analyte Concentration (ng/mL) | D19: Dilution Factor | E19: Analyte Peak Area (counts) | F19: IS Peak Area (counts) | G19: Area Ratio | H19: Use Record | I19: Record Modified | J19: Calculated Concentration (ng/mL) | K19: Accuracy (%) | L19: Vial Position | M19: Plate Position | N19: Acquisition Date | O19: Analyte Retention Time (min) | P19: IS Retention Time (min) | Q19: Analyte Peak Name | R19: IS Peak Name
A20: Wash | B20: Unknown | C20: N/A | D20: 1 | E20: 0 | F20: 0 | G20: #DIV/0! | I20: 0 | J20: #DIV/0! | K20: N/A | L20: 24 | M20: 5 | N20: 5/16/2025 10:32:51 PM | O20: 0 | P20: 0 | Q20: HW356054 | R20: Dic
A21: HW356054-MC-PL-Batch1-Blank | B21: Double Blank | C21: 0 | D21: 1 | E21: 0 | F21: 0 | G21: #DIV/0! | I21: 0 | J21: N/A | K21: N/A | L21: 1 | M21: 5 | N21: 5/16/2025 10:35:54 PM | O21: 0 | P21: 0 | Q21: HW356054 | R21: Dic
A22: HW356054-MC-PL-Batch1-QC0 | B22: Blank | C22: 0 | D22: 1 | E22: 0 | F22: 708000 | G22: 0 | I22: 0 | J22: N/A | K22: N/A | L22: 2 | M22: 5 | N22: 5/16/2025 10:39:01 PM | O22: 0 | P22: 1.29 | Q22: HW356054 | R22: Dic
A23: HW356054-MC-PL-Batch1-Cline-0.5ng | B23: Standard | C23: 0.5 | D23: 1 | E23: 636 | F23: 760000 | G23: 0.000836 | H23: 1 | I23: 0 | J23: 0.5 | K23: 100.1 | L23: 3 | M23: 5 | N23: 5/16/2025 10:42:06 PM | O23: 1.37 | P23: 1.29 | Q23: HW356054 | R23: Dic
A24: HW356054-MC-PL-Batch1-Cline-2ng | B24: Standard | C24: 2 | D24: 1 | E24: 2840 | F24: 777000 | G24: 0.00365 | H24: 1 | I24: 0 | J24: 2.19 | K24: 109.6 | L24: 5 | M24: 5 | N24: 5/16/2025 10:45:09 PM | O24: 1.38 | P24: 1.3 | Q24: HW356054 | R24: Dic
A25: HW356054-MC-PL-Batch1-Cline-100ng | B25: Standard | C25: 100 | D25: 1 | E25: 125000 | F25: 752000 | G25: 0.167 | H25: 1 | I25: 0 | J25: 100 | K25: 100.2 | L25: 8 | M25: 5 | N25: 5/16/2025 10:48:12 PM | O25: 1.38 | P25: 1.3 | Q25: HW356054 | R25: Dic
A26: HW356054-MC-PL-Batch1-Cline-1000ng | B26: Standard | C26: 1000 | D26: 1 | E26: 1190000 | F26: 715000 | G26: 1.67 | H26: 1 | I26: 0 | J26: 1000 | K26: 100.4 | L26: 10 | M26: 5 | N26: 5/16/2025 10:51:19 PM | O26: 1.37 | P26: 1.29 | Q26: HW356054 | R26: Dic
A27: HW356054-MC-PL-Batch1-CO-1 | B27: Double Blank | C27: 0 | D27: 1 | E27: 0 | F27: 0 | G27: #DIV/0! | I27: 0 | J27: N/A | K27: N/A | L27: 11 | M27: 5 | N27: 5/16/2025 10:54:24 PM | O27: 0 | P27: 0 | Q27: HW356054 | R27: Dic
A28: HW356054-MC-PL-Batch1-CO-2 | B28: Double Blank | C28: 0 | D28: 1 | E28: 0 | F28: 0 | G28: #DIV/0! | I28: 0 | J28: N/A | K28: N/A | L28: 12 | M28: 5 | N28: 5/16/2025 10:57:27 PM | O28: 0 | P28: 0 | Q28: HW356054 | R28: Dic
A29: HW356054-MC-PL-Batch1-LQC-1 | B29: Quality Control | C29: 1.5 | D29: 1 | E29: 2230 | F29: 670000 | G29: 0.00332 | H29: 0 | I29: 0 | J29: 2 | K29: 133 | L29: 13 | M29: 5 | N29: 5/16/2025 11:00:30 PM | O29: 1.37 | P29: 1.29 | Q29: HW356054 | R29: Dic
A30: HW356054-MC-PL-Batch1-MQC-1 | B30: Quality Control | C30: 400 | D30: 1 | E30: 499000 | F30: 761000 | G30: 0.656 | H30: 1 | I30: 0 | J30: 394 | K30: 98.5 | L30: 14 | M30: 5 | N30: 5/16/2025 11:03:35 PM | O30: 1.38 | P30: 1.3 | Q30: HW356054 | R30: Dic
A31: HW356054-MC-PL-Batch1-HQC-1 | B31: Quality Control | C31: 800 | D31: 1 | E31: 935000 | F31: 701000 | G31: 1.33 | H31: 1 | I31: 0 | J31: 802 | K31: 100.2 | L31: 15 | M31: 5 | N31: 5/16/2025 11:06:39 PM | O31: 1.38 | P31: 1.3 | Q31: HW356054 | R31: Dic
A32: Wash | B32: Unknown | C32: N/A | D32: 1 | E32: 0 | F32: 0 | G32: #DIV/0! | I32: 0 | J32: #DIV/0! | K32: N/A | L32: 23 | M32: 5 | N32: 5/16/2025 11:09:42 PM | O32: 0 | P32: 0 | Q32: HW356054 | R32: Dic
A33: HW356054-MC-PL-Batch1-IG-A1-24h | B33: Unknown | C33: N/A | D33: 1 | E33: 49100 | F33: 710000 | G33: 0.0691 | I33: 0 | J33: 41.6 | K33: N/A | L33: 73 | M33: 5 | N33: 5/16/2025 11:12:48 PM | O33: 1.37 | P33: 1.29 | Q33: HW356054 | R33: Dic
A34: HW356054-MC-PL-Batch1-IG-A2-24h | B34: Unknown | C34: N/A | D34: 1 | E34: 2780 | F34: 691000 | G34: 0.00402 | I34: 0 | J34: 2.41 | K34: N/A | L34: 74 | M34: 5 | N34: 5/16/2025 11:15:51 PM | O34: 1.37 | P34: 1.29 | Q34: HW356054 | R34: Dic
A35: HW356054-MC-PL-Batch1-IG-A3-24h | B35: Unknown | C35: N/A | D35: 1 | E35: 2380 | F35: 709000 | G35: 0.00335 | I35: 0 | J35: 2.01 | K35: N/A | L35: 75 | M35: 5 | N35: 5/16/2025 11:18:56 PM | O35: 1.38 | P35: 1.3 | Q35: HW356054 | R35: Dic
A36: HW356054-MC-PL-Batch1-IG-A1-10h | B36: Unknown | C36: N/A | D36: 1 | E36: 159000 | F36: 749000 | G36: 0.212 | I36: 0 | J36: 128 | K36: N/A | L36: 76 | M36: 5 | N36: 5/16/2025 11:21:59 PM | O36: 1.37 | P36: 1.29 | Q36: HW356054 | R36: Dic
A37: HW356054-MC-PL-Batch1-IG-A2-10h | B37: Unknown | C37: N/A | D37: 1 | E37: 92000 | F37: 735000 | G37: 0.125 | I37: 0 | J37: 75.3 | K37: N/A | L37: 77 | M37: 5 | N37: 5/16/2025 11:25:02 PM | O37: 1.37 | P37: 1.29 | Q37: HW356054 | R37: Dic
A38: HW356054-MC-PL-Batch1-IG-A3-10h | B38: Unknown | C38: N/A | D38: 1 | E38: 93900 | F38: 745000 | G38: 0.126 | I38: 0 | J38: 75.8 | K38: N/A | L38: 78 | M38: 5 | N38: 5/16/2025 11:28:07 PM | O38: 1.37 | P38: 1.29 | Q38: HW356054 | R38: Dic
A39: HW356054-MC-PL-Batch1-IG-A1-8h | B39: Unknown | C39: N/A | D39: 1 | E39: 173000 | F39: 723000 | G39: 0.239 | I39: 0 | J39: 144 | K39: N/A | L39: 79 | M39: 5 | N39: 5/16/2025 11:31:08 PM | O39: 1.37 | P39: 1.29 | Q39: HW356054 | R39: Dic
A40: HW356054-MC-PL-Batch1-IG-A2-8h | B40: Unknown | C40: N/A | D40: 1 | E40: 140000 | F40: 723000 | G40: 0.194 | I40: 0 | J40: 116 | K40: N/A | L40: 80 | M40: 5 | N40: 5/16/2025 11:34:10 PM | O40: 1.37 | P40: 1.29 | Q40: HW356054 | R40: Dic
A41: HW356054-MC-PL-Batch1-IG-A3-8h | B41: Unknown | C41: N/A | D41: 1 | E41: 131000 | F41: 692000 | G41: 0.189 | I41: 0 | J41: 113 | K41: N/A | L41: 81 | M41: 5 | N41: 5/16/2025 11:37:17 PM | O41: 1.37 | P41: 1.29 | Q41: HW356054 | R41: Dic
A42: HW356054-MC-PL-Batch1-IG-A1-4h | B42: Unknown | C42: N/A | D42: 1 | E42: 168000 | F42: 688000 | G42: 0.245 | I42: 0 | J42: 147 | K42: N/A | L42: 82 | M42: 5 | N42: 5/16/2025 11:40:20 PM | O42: 1.37 | P42: 1.29 | Q42: HW356054 | R42: Dic
A43: HW356054-MC-PL-Batch1-IG-A2-4h | B43: Unknown | C43: N/A | D43: 1 | E43: 184000 | F43: 713000 | G43: 0.258 | I43: 0 | J43: 155 | K43: N/A | L43: 83 | M43: 5 | N43: 5/16/2025 11:43:25 PM | O43: 1.37 | P43: 1.29 | Q43: HW356054 | R43: Dic
A44: HW356054-MC-PL-Batch1-IG-A3-4h | B44: Unknown | C44: N/A | D44: 1 | E44: 144000 | F44: 687000 | G44: 0.209 | I44: 0 | J44: 126 | K44: N/A | L44: 84 | M44: 5 | N44: 5/16/2025 11:46:24 PM | O44: 1.37 | P44: 1.29 | Q44: HW356054 | R44: Dic
... A56: HW356054-MC-PL-Batch1-IG-A3-0.25h | B56: Unknown | C56: N/A | D56: 1 | E56: 198000 | F56: 716000 | G56: 0.276 | I56: 0 | J56: 166 | K56: N/A | L56: 96 | M56: 5 | N56: 5/17/2025 12:23:15 AM | O56: 1.37 | P56: 1.29 | Q56: HW356054 | R56: Dic
...

Sheet Setting
A1: Study No. | B1: 3D_SN322418
A2: Compound Name | B2: HW356054
A3: Species | B3: ICR Mouse
A4: LLOQ | B4: 0.5
B5: ng/mL
A7: Route | B7: IG
A8: Dose | B8: 10 | C8: mg/kg
A9: Sex | B9: Male
A10: =B2 -> HW356054 | B10: A1
B11: A2
B12: A3
A14: =B7 -> IG
A15: 0.25
A16: 0.5
A17: 1
A18: 2
A19: 4
A20: 8
A21: 10
A22: 24
