Workbook

Sheet 封面
B1: 合肥中科普瑞昇生物医药科技有限公司
A5: 项目编号： | B5: D-RF-2024032601
A7: 化合物名称 | B7: HW351002
A9: 项目名称： | B9: 化合物HW351002在小鼠体内药代动力学研究
A11: 关键时间结点： | B11: 动物试验给药日期： 检测开始日期： 试验结束日期： 报告日期： | IW11: 2024-03-27 2024-03-28 2024-03-29 2024-03-30
A13: 试验承担单位 | B13: 负责人：邵杰 单位名称：合肥中科普瑞昇生物医药科技有限公司 地址：合肥市高新区习友路2666号创新工程院8楼 联系方式：0551-62673491 Email：jshao@precedo.cn
A14: 委托单位 | B14: 负责人：刘勇 委托单位名称：湖北生物医药产业技术研究院有限公司 邮箱：liuyong@renfu.com 联系方式：18062052364
A15: 质控人员 | B15: 刘海宾
A16: 分析负责人 | B16: 秦琴
A17: 动物负责人 | B17: 沙梦茹

Sheet 结果汇总
B1: =封面!B7 -> HW351002 | F1: PK数据
L2: HW351002 | P2: 化合物信息和制剂配制
C3: 表1：单次灌胃给予HW351002后小鼠血浆中药物浓度 | L3: 化合物信息
M4: 化合物名称 | N4: HW351002
C5: =封面!B7 -> HW351002 | M5: 批号 | N5: HWH817-XQ-35-1002
C6: PO-10 mg/kg | M6: 分子量 | N6: 778.2
C7: Time (h) | D7: 1 | E7: 2 | F7: 3 | G7: Mean | H7: SD | M7: 纯度 | N7: 0.977
C8: 0.0833 | D8: 51.9 | E8: 70.1 | F8: 108 | G8: =AVERAGE(D8:F8) -> 76.666667 | H8: =STDEV(D8:F8) -> 28.62068 | L8: PK研究基本信息
C9: 0.25 | D9: 102 | E9: 128 | F9: 80.6 | G9: =AVERAGE(D9:F9) -> 103.53333 | H9: =STDEV(D9:F9) -> 23.737172 | L9: 给药途径: | N9: 灌胃 | P9: 推荐溶媒: | Q9: 5%DMSO+10%Solutol+85%Saline
C10: 0.5 | D10: 157 | E10: 202 | F10: 44.3 | G10: =AVERAGE(D10:F10) -> 134.43333 | H10: =STDEV(D10:F10) -> 81.23585 | L10: 剂量 (mg/kg): | N10: 10
C11: 1 | D11: 53.3 | E11: 59.9 | F11: 63.8 | G11: =AVERAGE(D11:F11) -> 59 | H11: =STDEV(D11:F11) -> 5.3075418 | L11: 浓度(mg/mL): | N11: 1
C12: 2 | D12: 17 | E12: 11.3 | F12: 42.1 | G12: =AVERAGE(D12:F12) -> 23.466667 | H12: =STDEV(D12:F12) -> 16.386682 | L12: 给药体积 (mL/kg): | N12: 10
C13: 4 | D13: 3.51 | E13: BQL | F13: 7.44 | G13: =AVERAGE(D13:F13) -> 5.475 | H13: =STDEV(D13:F13) -> 2.7789297
C14: 6 | D14: BQL | E14: BQL | F14: 1.02 | G14: =AVERAGE(D14:F14) -> 1.02 | H14: NA | L14: 制剂配制计算
C15: 8 | D15: BQL | E15: BQL | F15: BQL | G15: NA | H15: NA | L15: 给药途径 | M15: 化合物 | N15: 制剂 | O15: 浓度(mg/mL) | P15: 化合物重量(mg) | Q15: 最终总体积(mL) | R15: DMSO的体积(mL) | S15: Solutol的体积(mL) | T15: Saline 的体积(mL)
C16: 24 | D16: BQL | E16: BQL | F16: BQL | G16: NA | H16: NA
L17: 灌胃 | M17: HW351002 | N17: 5%DMSO+10%Solutol+85%Saline | O17: 1 | P17: 1.4 | Q17: 1.368 | R17: 0.068 | S17: 0.137 | T17: 1.163
L21: PO制剂配制过程（给药当天现配现用）
L22: (1) 准确称取化合物1.40 mg,放入5 mL 玻璃瓶中
L23: (2) 加入0.068 mL DMSO,涡旋超声至化合物呈黄色溶解澄清状态
L24: (3) 加入0.137 mL Solutol,涡旋超声至化合物呈淡黄色溶解澄清状态
L25: (4) 再加入1.163 mL Saline,涡旋超声至化合物呈无色溶解澄清状态，即可得到PO制剂
L28: 动物临床观察：
L30: 所有实验动物均未观察到异常现象。
C34: 表2：单次灌胃给予HW351002后小鼠血浆PK数据
L35: 动物体重：
C36: 信息/参数类型 | D36: PK参数 | G36: n | H36: 均值 | I36: 标准差 | M36: 动物编号 | N36: 1 | O36: 2 | P36: 3
C37: 分组 | D37: 1 | E37: 2 | F37: 3 | M37: 体重（g) | N37: 24.3 | O37: 25.2 | P37: 24.6
C38: 分析物 | D38: =封面!B7 -> HW351002
C39: 给药途径 | D39: PO
C40: 给药剂量 | D40: 10 | E40: mg/kg
C41: Rsq_adjusted | D41: ='PK 参数'!F3 -> 0.98081822 | E41: ='PK 参数'!F4 -> 0.98014107 | F41: ='PK 参数'!F5 -> 0.99689981 | G41: 3 | H41: =AVERAGE(D41:F41) -> 0.98595303 | I41: =STDEV(D41:F41) -> 0.0094862307
C42: No_points_lambda_z | D42: ='PK 参数'!H3 -> 3 | E42: ='PK 参数'!H4 -> 3 | F42: ='PK 参数'!H5 -> 3 | G42: 3 | H42: =AVERAGE(D42:F42) -> 3 | I42: =STDEV(D42:F42) -> 0
C43: Tlast (h) | D43: ='PK 参数'!S3 -> 4 | E43: ='PK 参数'!S4 -> 2 | F43: ='PK 参数'!S5 -> 6 | G43: 3 | H43: =AVERAGE(D43:F43) -> 4 | I43: =STDEV(D43:F43) -> 2
C44: T1/2 （h） | D44: ='PK 参数'!M3 -> 0.77888716 | E44: ='PK 参数'!M4 -> 0.36752978 | F44: ='PK 参数'!M5 -> 0.74527044 | G44: 3 | H44: =AVERAGE(D44:F44) -> 0.63056246 | I44: =STDEV(D44:F44) -> 0.22841227
C45: Tmax（h） | D45: ='PK 参数'!P3 -> 0.5 | E45: ='PK 参数'!P4 -> 0.5 | F45: ='PK 参数'!P5 -> 0.0833 | G45: 3 | H45: =AVERAGE(D45:F45) -> 0.3611 | I45: =STDEV(D45:F45) -> 0.24058186
C46: Cmax (ng/mL) | D46: ='PK 参数'!Q3 -> 157 | E46: ='PK 参数'!Q4 -> 202 | F46: ='PK 参数'!Q5 -> 108 | G46: 3 | H46: =AVERAGE(D46:F46) -> 155.66667 | I46: =STDEV(D46:F46) -> 47.014182
C47: AUC(0-t) (h*ng/mL) | D47: ='PK 参数'!V3 -> 155.5992 | E47: ='PK 参数'!V4 -> 161.7563 | F47: ='PK 参数'!V5 -> 173.80551 | G47: 3 | H47: =AVERAGE(D47:F47) -> 163.72034 | I47: =STDEV(D47:F47) -> 9.2606971
C48: AUC(0-∞）(h*ng/mL) | D48: ='PK 参数'!Y3 -> 159.54338 | E48: ='PK 参数'!Y4 -> 167.74794 | F48: ='PK 参数'!Y5 -> 174.90221 | G48: 3 | H48: =AVERAGE(D48:F48) -> 167.39784 | I48: =STDEV(D48:F48) -> 7.6853979
C49: MRT(0-t)（h） | D49: ='PK 参数'!AN3 -> 0.90171308 | E49: ='PK 参数'!AN4 -> 0.62746932 | F49: ='PK 参数'!AN5 -> 1.4580611 | G49: 3 | H49: =AVERAGE(D49:F49) -> 0.99574783 | I49: =STDEV(D49:F49) -> 0.42320512
...

Sheet PK 参数
A1: =封面!B7 -> HW351002 | B1: PK parameters
A2: PO | B2: sort | C2: N_Samples | D2: Dose(mg/kg) | E2: Rsq | F2: Rsq_adjusted | G2: Corr_XY | H2: No_points_lambda_z | I2: Lambda_z(1/h) | J2: Lambda_z_intercept | K2: Lambda_z_lower(h) | L2: Lambda_z_upper(h) | M2: HL_Lambda_z(h) | N2: Span | O2: Tlag(h) | P2: Tmax(h) | Q2: Cmax(ng/mL) | R2: Cmax_D(kg*ng/mL/mg) | S2: Tlast(h) | T2: Clast(ng/mL) | U2: Clast_pred(ng/mL) | V2: AUClast(h*ng/mL) | W2: AUClast_D(h*kg*ng/mL/mg) | X2: AUCall(h*ng/mL) | Y2: AUCINF_obs(h*ng/mL) | Z2: AUCINF_D_obs(h*kg*ng/mL/mg) | AA2: AUC_%Extrap_obs({%}) | AB2: Vz_F_obs(L/kg) | AC2: Cl_F_obs(L/h/kg) | AD2: AUCINF_pred(h*ng/mL) | AE2: AUCINF_D_pred(h*kg*ng/mL/mg) | AF2: AUC_%Extrap_pred({%}) | AG2: Vz_F_pred(L/kg) | AH2: Cl_F_pred(L/h/kg) | AI2: AUMClast(h*h*ng/mL) | AJ2: AUMCINF_obs(h*h*ng/mL) | AK2: AUMC_%Extrap_obs({%}) | AL2: AUMCINF_pred(h*h*ng/mL) | AM2: AUMC_%Extrap_pred({%}) | AN2: MRTlast(h) | AO2: MRTINF_obs(h) | AP2: MRTINF_pred(h)
B3: 1 | C3: 6 | D3: 10 | E3: 0.99040911 | F3: 0.98081822 | G3: -0.995193 | H3: 3 | I3: 0.88991989 | J3: 4.764735 | K3: 1 | L3: 4 | M3: 0.77888716 | N3: 3.851649 | O3: 0 | P3: 0.5 | Q3: 157 | R3: 15.7 | S3: 4 | T3: 3.51 | U3: 3.336944 | V3: 155.5992 | W3: 15.55992 | X3: 155.5992 | Y3: 159.54338 | Z3: 15.954338 | AA3: 2.4721648 | AB3: 70.432047 | AC3: 62.67888 | AD3: 159.34891 | AE3: 15.934891 | AF3: 2.3531461 | AG3: 70.517999 | AH3: 62.75537 | AI3: 140.30583 | AJ3: 160.51459 | AK3: 12.589982 | AL3: 159.51822 | AM3: 12.04401 | AN3: 0.90171308 | AO3: 1.0060875 | AP3: 1.0010625
B4: 2 | C4: 5 | D4: 10 | E4: 0.99007054 | F4: 0.98014107 | G4: -0.99502288 | H4: 3 | I4: 1.885962 | J4: 6.1422046 | K4: 0.5 | L4: 2 | M4: 0.36752978 | N4: 4.0813019 | O4: 0 | P4: 0.5 | Q4: 202 | R4: 20.2 | S4: 2 | T4: 11.3 | U4: 10.700395 | V4: 161.7563 | W4: 16.17563 | X4: 161.7563 | Y4: 167.74794 | Z4: 16.774794 | AA4: 3.5718098 | AB4: 31.608937 | AC4: 59.613252 | AD4: 167.43001 | AE4: 16.743001 | AF4: 3.3887037 | AG4: 31.668958 | AH4: 59.72645 | AI4: 101.49712 | AJ4: 116.65736 | AK4: 12.995529 | AL4: 115.85292 | AM4: 12.391403 | AN4: 0.62746932 | AO4: 0.69543244 | AP4: 0.69194836
B5: 3 | C5: 7 | D5: 10 | E5: 0.99844991 | F5: 0.99689981 | G5: -0.99922465 | H5: 3 | I5: 0.93006128 | J5: 5.6424855 | K5: 2 | L5: 6 | M5: 0.74527044 | N5: 5.3671792 | O5: 0 | P5: 0.0833 | Q5: 108 | R5: 10.8 | S5: 6 | T5: 1.02 | U5: 1.0640877 | V5: 173.80551 | W5: 17.380551 | X5: 173.80551 | Y5: 174.90221 | Z5: 17.490221 | AA5: 0.6270372 | AB5: 61.474235 | AC5: 57.174806 | AD5: 174.94961 | AE5: 17.494961 | AF5: 0.65396256 | AG5: 61.457579 | AH5: 57.159314 | AI5: 253.41905 | AJ5: 261.17844 | AK5: 2.9709127 | AL5: 261.51382 | AM5: 3.0953504 | AN5: 1.4580611 | AO5: 1.4932826 | AP5: 1.4947951

Sheet 原始数据
B2: Peak Name: Tolbutamide
B3: Use as Internal Standard
B4: Q1/Q3 Masses: 269.20/170.00 Da
B6: Peak Name: HW351002
B7: Internal Standard: Tolbutamide
B8: Q1/Q3 Masses: 777.20/582.00 Da
B10: Fit | C10: Linear | D10: Weighting | E10: 1 / (x * x) | F10: Iterate | G10: No
B11: Intercept | C11: 0.000142
B12: Slope | C12: 0.000241
B13: Correlation coefficient | C13: 0.9988
B14: Use Area
B18: Sample Name | C18: Sample Type | D18: File Name | E18: Analyte Peak Name | F18: Analyte Concentration (ng/mL) | G18: Calculated Concentration (ng/mL) | H18: Analyte Peak Area (counts) | I18: Analyte Retention Time (min) | J18: Area Ratio | K18: IS Peak Area (counts) | L18: IS Retention Time (min) | M18: Use Record | N18: Record Modified | O18: Accuracy (%) | P18: Dilution Factor
B19: Doubleblank | C19: Unknown | D19: HW351002-20240328-Mouse-Plasma\SA.wiff | E19: HW351002 | F19: N/A | G19: #DIV/0! | H19: 0 | I19: 0 | J19: #DIV/0! | K19: 0 | L19: 0 | N19: 0 | O19: N/A | P19: 1
B20: Doubleblank | C20: Unknown | D20: HW351002-20240328-Mouse-Plasma\SA.wiff | E20: HW351002 | F20: N/A | G20: #DIV/0! | H20: 152 | I20: 1.17 | J20: #DIV/0! | K20: 0 | L20: 0 | N20: 0 | O20: N/A | P20: 1
B21: Blank | C21: Unknown | D21: HW351002-20240328-Mouse-Plasma\SA.wiff | E21: HW351002 | F21: N/A | G21: No Peak | H21: 0 | I21: 0 | J21: 0 | K21: 1450000 | L21: 0.884 | N21: 0 | O21: N/A | P21: 1
B22: B-STD1 | C22: Standard | D22: HW351002-20240328-Mouse-Plasma\SA.wiff | E22: HW351002 | F22: 1 | G22: 0.983 | H22: 536 | I22: 1.15 | J22: 0.000379 | K22: 1420000 | L22: 0.886 | M22: 1 | N22: 0 | O22: 98.3 | P22: 1
B23: B-STD2 | C23: Standard | D23: HW351002-20240328-Mouse-Plasma\SA.wiff | E23: HW351002 | F23: 2 | G23: 1.05 | H23: 570 | I23: 1.14 | J23: 0.000394 | K23: 1440000 | L23: 0.885 | M23: 0 | N23: 0 | O23: 52.42 | P23: 1
B24: B-STD3 | C24: Standard | D24: HW351002-20240328-Mouse-Plasma\SA.wiff | E24: HW351002 | F24: 5 | G24: 5.41 | H24: 2090 | I24: 1.15 | J24: 0.00144 | K24: 1450000 | L24: 0.884 | M24: 1 | N24: 0 | O24: 108.12 | P24: 1
B25: B-STD4 | C25: Standard | D25: HW351002-20240328-Mouse-Plasma\SA.wiff | E25: HW351002 | F25: 20 | G25: 20.5 | H25: 7260 | I25: 1.15 | J25: 0.00508 | K25: 1430000 | L25: 0.884 | M25: 1 | N25: 0 | O25: 102.57 | P25: 1
B26: B-STD5 | C26: Standard | D26: HW351002-20240328-Mouse-Plasma\SA.wiff | E26: HW351002 | F26: 100 | G26: 94.8 | H26: 32800 | I26: 1.14 | J26: 0.023 | K26: 1430000 | L26: 0.88 | M26: 1 | N26: 0 | O26: 94.79 | P26: 1
B27: B-STD6 | C27: Standard | D27: HW351002-20240328-Mouse-Plasma\SA.wiff | E27: HW351002 | F27: 500 | G27: 511 | H27: 176000 | I27: 1.14 | J27: 0.123 | K27: 1430000 | L27: 0.881 | M27: 1 | N27: 0 | O27: 102.25 | P27: 1
B28: B-STD7 | C28: Standard | D28: HW351002-20240328-Mouse-Plasma\SA.wiff | E28: HW351002 | F28: 1000 | G28: 977 | H28: 337000 | I28: 1.14 | J28: 0.235 | K28: 1430000 | L28: 0.88 | M28: 1 | N28: 0 | O28: 97.68 | P28: 1
B29: B-STD8 | C29: Standard | D29: HW351002-20240328-Mouse-Plasma\SA.wiff | E29: HW351002 | F29: 2000 | G29: 1930 | H29: 674000 | I29: 1.14 | J29: 0.464 | K29: 1450000 | L29: 0.879 | M29: 1 | N29: 0 | O29: 96.29 | P29: 1
B30: Doubleblank | C30: Unknown | D30: HW351002-20240328-Mouse-Plasma\SA.wiff | E30: HW351002 | F30: N/A | G30: #DIV/0! | H30: 258 | I30: 1.13 | J30: #DIV/0! | K30: 0 | L30: 0 | N30: 0 | O30: N/A | P30: 1
B31: Doubleblank | C31: Unknown | D31: HW351002-20240328-Mouse-Plasma\SA.wiff | E31: HW351002 | F31: N/A | G31: #DIV/0! | H31: 0 | I31: 0 | J31: #DIV/0! | K31: 0 | L31: 0 | N31: 0 | O31: N/A | P31: 1
B32: Doubleblank | C32: Unknown | D32: HW351002-20240328-Mouse-Plasma\SA.wiff | E32: HW351002 | F32: N/A | G32: #DIV/0! | H32: 0 | I32: 0 | J32: #DIV/0! | K32: 0 | L32: 0 | N32: 0 | O32: N/A | P32: 1
B33: Doubleblank | C33: Unknown | D33: HW351002-20240328-Mouse-Plasma\SA.wiff | E33: HW351002 | F33: N/A | G33: #DIV/0! | H33: 0 | I33: 0 | J33: #DIV/0! | K33: 0 | L33: 0 | N33: 0 | O33: N/A | P33: 1
B34: B-LQC-1 | C34: Quality Control | D34: HW351002-20240328-Mouse-Plasma\SA.wiff | E34: HW351002 | F34: 3 | G34: 3.05 | H34: 1290 | I34: 1.14 | J34: 0.000875 | K34: 1470000 | L34: 0.882 | M34: 1 | N34: 0 | O34: 101.54 | P34: 1
B35: B-MQC-1 | C35: Quality Control | D35: HW351002-20240328-Mouse-Plasma\SA.wiff | E35: HW351002 | F35: 30 | G35: 33.1 | H35: 12000 | I35: 1.14 | J35: 0.0081 | K35: 1480000 | L35: 0.878 | M35: 1 | N35: 0 | O35: 110.28 | P35: 1
B36: B-HQC-1 | C36: Quality Control | D36: HW351002-20240328-Mouse-Plasma\SA.wiff | E36: HW351002 | F36: 1600 | G36: 1580 | H36: 556000 | I36: 1.15 | J36: 0.38 | K36: 1460000 | L36: 0.886 | M36: 1 | N36: 0 | O36: 98.63 | P36: 1
B37: PO Dose-1 | C37: Quality Control | D37: HW351002-20240328-Mouse-Plasma\SA.wiff | E37: HW351002 | F37: 50 | G37: 61.4 | H37: 22400 | I37: 1.14 | J37: 0.0149 | K37: 1500000 | L37: 0.879 | M37: 1 | N37: 0 | O37: 122.81 | P37: 1
B38: PO Dose-2 | C38: Quality Control | D38: HW351002-20240328-Mouse-Plasma\SA.wiff | E38: HW351002 | F38: 50 | G38: 55.8 | H38: 20700 | I38: 1.15 | J38: 0.0136 | K38: 1520000 | L38: 0.884 | M38: 1 | N38: 0 | O38: 111.56 | P38: 1
B39: PO Dose-3 | C39: Quality Control | D39: HW351002-20240328-Mouse-Plasma\SA.wiff | E39: HW351002 | F39: 50 | G39: 56.7 | H39: 21200 | I39: 1.14 | J39: 0.0138 | K39: 1530000 | L39: 0.878 | M39: 1 | N39: 0 | O39: 113.45 | P39: 1
B40: Doubleblank | C40: Unknown | D40: HW351002-20240328-Mouse-Plasma\SA.wiff | E40: HW351002 | F40: N/A | G40: #DIV/0! | H40: 147 | I40: 1.15 | J40: #DIV/0! | K40: 0 | L40: 0 | N40: 0 | O40: N/A | P40: 1
B41: Doubleblank | C41: Unknown | D41: HW351002-20240328-Mouse-Plasma\SA.wiff | E41: HW351002 | F41: N/A | G41: #DIV/0! | H41: 0 | I41: 0 | J41: #DIV/0! | K41: 0 | L41: 0 | N41: 0 | O41: N/A | P41: 1
B42: HW351002-Plasma-10MPK-PO-24hr-Mouse1 | C42: Unknown | D42: HW351002-20240328-Mouse-Plasma\SA.wiff | E42: HW351002 | F42: N/A | G42: No Peak | H42: 0 | I42: 0 | J42: 0 | K42: 1510000 | L42: 0.888 | N42: 0 | O42: N/A | P42: 1
B43: HW351002-Plasma-10MPK-PO-24hr-Mouse2 | C43: Unknown | D43: HW351002-20240328-Mouse-Plasma\SA.wiff | E43: HW351002 | F43: N/A | G43: No Peak | H43: 0 | I43: 0 | J43: 0 | K43: 1290000 | L43: 0.881 | N43: 0 | O43: N/A | P43: 1
B44: HW351002-Plasma-10MPK-PO-24hr-Mouse3 | C44: Unknown | D44: HW351002-20240328-Mouse-Plasma\SA.wiff | E44: HW351002 | F44: N/A | G44: No Peak | H44: 0 | I44: 0 | J44: 0 | K44: 1340000 | L44: 0.885 | N44: 0 | O44: N/A | P44: 1
B45: HW351002-Plasma-10MPK-PO-8hr-Mouse1 | C45: Unknown | D45: HW351002-20240328-Mouse-Plasma\SA.wiff | E45: HW351002 | F45: N/A | G45: No Peak | H45: 0 | I45: 0 | J45: 0 | K45: 1320000 | L45: 0.886 | N45: 0 | O45: N/A | P45: 1
B46: HW351002-Plasma-10MPK-PO-8hr-Mouse2 | C46: Unknown | D46: HW351002-20240328-Mouse-Plasma\SA.wiff | E46: HW351002 | F46: N/A | G46: No Peak | H46: 0 | I46: 0 | J46: 0 | K46: 1370000 | L46: 0.885 | N46: 0 | O46: N/A | P46: 1
...

Sheet 标曲&质控
C5: 标准曲线 | D5: 编号 | E5: 标示浓度 | F5: 实测浓度 | G5: 准确度%
D6: STD1 | E6: 1 | F6: 0.983 | G6: 98.3
D7: STD2 | E7: 2 | F7: 1.05 | G7: 52.42
D8: STD3 | E8: 5 | F8: 5.41 | G8: 108.12
D9: STD4 | E9: 20 | F9: 20.5 | G9: 102.57
D10: STD5 | E10: 100 | F10: 94.8 | G10: 94.79
D11: STD6 | E11: 500 | F11: 511 | G11: 102.25
D12: STD7 | E12: 1000 | F12: 977 | G12: 97.68
D13: STD8 | E13: 2000 | F13: 1930 | G13: 96.29
C15: 质控样本 | D15: 编号 | E15: 标示浓度 | F15: 实测浓度 | H15: 准确度%
F16: 1 | G16: 2 | H16: 1 | I16: 2
D17: LQC | E17: 3 | F17: 3.05 | G17: 2.84 | H17: 101.54 | I17: 94.66
D18: MQC | E18: 30 | F18: 33.1 | G18: 29.5 | H18: 110.28 | I18: 98.32
D19: HQC | E19: 1600 | F19: 1580 | G19: 1630 | H19: 98.63 | I19: 101.75
C21: 生物样品分析方法及所有样品的分析由合肥中科普瑞昇生物分析实验室完成，分析样品的同时进行质控样品的日内准确度评价，并要求超过66.7%的质控样品的准确度在80-120%之间。伴随样品分析的线性标准品至少6个且≥75%的校准标样满足偏差在±20%范围内。

Sheet 给药制剂浓度检测
B2: PK 给药制剂浓度测定
B3: PO | C3: 检测步骤： (将药制剂原液稀释20000倍后进行浓度检测):
C4: 1)移取口服制剂100μL，加入二甲基亚砜900 μL混合均匀（该过程稀释10倍）;
C5: 2) 将第一步中的口服制剂稀释液移取10 μL，准确加入甲醇990 μL，混合均匀（该过程稀释100倍）；
C6: 3)将步骤2的溶液移取2.5 μL 加入到47.5 μL的血浆中，按提取标准和线性一起处理（此过程稀释20倍）。
C8: 化合物 | D8: 给药方式 | E8: 设计浓度. (mg/mL) | F8: 稀释倍数 | G8: 测试浓度(ng/mL) | H8: 计算浓度 (mg/mL) | I8: 平均浓度 (mg/mL) | J8: 偏差 (%) | K8: 变异系数(%) | L8: 测试方法
C9: =封面!B7 -> HW351002 | D9: PO | E9: 1 | F9: 20000 | G9: 61.4 | H9: =G9*F9/1000000 -> 1.228 | I9: =AVERAGE(H9:H11) -> 1.1593333 | J9: =(I9-E9)/E9*100 -> 15.933333 | K9: =STDEV(H9:H11)/I9*100 -> 5.1878325 | L9: HPLC-MS/MS
F10: =F9 -> 20000 | G10: 55.8 | H10: =G10*F10/1000000 -> 1.116
F11: =F9 -> 20000 | G11: 56.7 | H11: =G11*F11/1000000 -> 1.134
C13: 结果：
C14: 与设计剂量浓度(PO:1 mg/mL)比较， 剂量浓度在(± 20%)标准范围内。

Sheet LC-MS分析方法 
B2: 分析方法
C3: 设备型号 | D3: LC-MS/MS ( API 4000)
C5: 设备编号 | D5: LC-MS/MS-001
C7: 基质类型 | D7: 小鼠血浆
C9: 分析物 | D9: HW351002
C11: 内标 | D11: Tolbutamide
C13: 质谱条件 | D13: ESI源负离子模式
D14: 多反应监测
D15: HW351002 | E15: Q1/Q3 Masses: 777.20/582.00 Da
D16: Tolbutamide | E16: Q1/Q3 Masses: 269.20/170.00 Da
C17: 液相条件
D18: 色谱柱 | E18: Synergi 4µm Fusion-RP 80A LC Column 50*2 mm
D19: 色谱型号 | E19: Shimadzu LC30AD
D20: 流动相 | E20: A: 水（含0.1%FA）
E21: B:乙腈
D22: 液相程序
E23: 时间 (min) | F23: 流速 (mL/min) | G23: A (%) | H23: B (%)
E24: 0.2 | F24: 0.8 | G24: 95 | H24: 20
E25: 1.6 | F25: =F24 -> 0.8 | G25: =100-H25 -> 5 | H25: 95
E26: 1.9 | F26: =F24 -> 0.8 | G26: =100-H26 -> 5 | H26: 95
E27: 1.91 | F27: =F24 -> 0.8 | G27: =100-H27 -> 80 | H27: 20
E28: 2.2 | F28: =F24 -> 0.8 | G28: =100-H28 -> 80 | H28: 20
D29: 柱温 (°C): | E29: 45°C
D30: 进样体积(μL): | E30: 5 μL
D31: 保留时间:
D32: HW351002 | E32: 1.15 min
D33: IS: | E33: 0.88 min
C35: 样品前处理 | D35: 1. 所有样品完全融化后，混匀10～30秒，4000rpm、4°C条件下离心0.5分钟。 2.移取20 μL血浆样品（空白样品和内标空白样品加20.0μL空白血浆）至96孔板中，加入200 μL含内标（100 ng/mL）50%甲醇乙腈溶液（Doubleblank样品加入200μL 50%甲醇乙腈溶液）。 3. 将样品涡旋5分钟后，在4000 rpm、4°C条件下离心10分钟，移取100 μL加入到100 μL的水中，混合均匀，交由LC-MS/MS分析。
C36: 线性范围 | D36: 1-2000 ng/mL

Sheet 试验设计
C3: 供试品信息
C5: 名称 | D5: 保存条件 | E5: 纯度* | F5: 盐或酯或游离形式 | G5: 分子量（盐） | H5: 分子量（游离形式）
C6: HW351002 | D6: 4℃ | E6: 0.977 | F6: 游离形式 | G6: 778.2 | H6: 778.2
C7: *:配制时需要折算纯度。
C9: 供试品配制
C11: 给药当天配制。
C12: 溶媒：5%DMSO+10%Solutol+85%Saline
C14: 实验动物
C16: 种属：ICR小鼠，SPF级；
C17: 来源：北京维通利华实验动物技术有限公司
C18: 数量：雄性4只。实验需要：雄性3只。
C19: 动物挑选：不进行随机分组
C21: 实验设计
C23: 组别 | D23: 受试物 | E23: 动物数量 | F23: 剂量 | G23: 浓度 | H23: 给药体积 | I23: 给予方式 | J23: 采集样本
E24: 雄性 | F24: (mg/kg) | G24: (mg/mL) | H24: (mL/kg)
C25: 1 | D25: HW351002 | E25: 3 | F25: 10 | G25: 1 | H25: 10 | I25: PO*，单次 | J25: 血浆
C26: 注： *, 口服给药组动物给药前禁食过夜（10-14小时），给药4小时后给食。
C28: 给药方式
C30: 给药前称重，根据体重，计算给药量。通过灌胃口服给药。
C32: 采血时间点：
C34: 给药后 0.083 h、0.25 h、0.5 h、1 h、2 h、4 h、6 h、8 h、24 h。
C35: 经脸颊采血，每个样品采集约0.05 mL，EDTA-2K抗凝，采集后放置湿冰上。
C37: 血浆样品处理
C39: 血液样本采集后置于冰上，并于1小时之内离心分离血浆(离心条件：6000 g，3分钟，2-8 ºC)。血浆样本在分析前存放时则放于-80 ºC冰箱内。
C41: 结果分析
C43: 通过不同时间点的血药浓度数据，运用Phoenix WinNonlin8.2.0计算药代动力学参数，提供AUC0-t、AUC0-∞、MRT0-∞、Cmax、Tmax、和T1/2等参数及其平均值和标准差。
C45: 剩余供试品、血浆的处置
C47: 剩余供试品和剩余血浆样品在试验结束后继续存放于-80°C冰箱暂存，保存期限为一个月。
