Workbook

Sheet 封面
B1: 合肥中科普瑞昇生物医药科技有限公司
A5: 项目编号： | B5: D-RF-2024100904
A7: 化合物名称 | B7: HW356048
A9: 项目名称： | B9: 化合物HW356048在小鼠体内药代动力学研究
A11: 关键时间结点： | B11: 动物试验给药日期： 检测开始日期： 试验结束日期： 报告日期： | IW11: 2024-10-12 2024-10-14 2024-10-17 2024-10-17
A13: 试验承担单位 | B13: 负责人：邵杰 单位名称：合肥中科普瑞昇生物医药科技有限公司 地址：安徽省合肥市高新区孔雀台路与习友路交叉路口国家健康大数据产业园A6栋 联系方式：0551-62673491 Email：jshao@precedo.cn
A14: 委托单位 | B14: 负责人：刘勇 委托单位名称：人福医药 邮箱：liuyong@renfu.com 联系方式：18062052364
A15: 质控人员 | B15: 孙玉
A16: 分析负责人 | B16: 吴素娟
A17: 动物负责人 | B17: 潘巧娟

Sheet 结果汇总
B1: =封面!B7 -> HW356048 | K1: PK数据 | V1: HW356048 | Z1: 化合物信息和制剂配制
V2: 化合物信息
C3: 表1：单次静脉注射给予HW356048后小鼠血浆中药物浓度 | L3: 表2：单次灌胃口服给予HW356048后小鼠血浆中药物浓度 | W3: 化合物名称 | X3: HW356048
W4: 批号 | X4: HWH817-XQ-35-6048-0912-P2
C5: =封面!B7 -> HW356048 | L5: =封面!B7 -> HW356048 | W5: 分子量 | X5: 508.16
C6: IV-1.0 mg/kg | L6: PO-10.0 mg/kg | W6: 纯度 | X6: 1
C7: Time (h) | D7: 1 | E7: 2 | F7: 3 | G7: Mean | H7: SD | L7: Time (h) | M7: 4 | N7: 5 | O7: 6 | P7: Mean | Q7: SD | V7: PK研究基本信息
C8: 0.0833 | D8: 126 | E8: 108 | F8: 229 | G8: =AVERAGE(D8:F8) -> 154.33333 | H8: =STDEV(D8:F8) -> 65.286548 | L8: 0.0833 | M8: 696 | N8: 571 | O8: 541 | P8: =AVERAGE(M8:O8) -> 602.66667 | Q8: =STDEV(M8:O8) -> 82.209083 | V8: 给药途径: | X8: IV | Z8: 推荐溶媒: | AA8: 5%DMSO + 10%Solutol HS 15 + 85% Saline
C9: 0.25 | D9: 29.8 | E9: 37.9 | F9: 68.8 | G9: =AVERAGE(D9:F9) -> 45.5 | H9: =STDEV(D9:F9) -> 20.580816 | L9: 0.25 | M9: 919 | N9: 185 | O9: 163 | P9: =AVERAGE(M9:O9) -> 422.33333 | Q9: =STDEV(M9:O9) -> 430.26658 | V9: 剂量 (mg/kg): | X9: 1
C10: 0.5 | D10: 17.1 | E10: 19.7 | F10: 21.1 | G10: =AVERAGE(D10:F10) -> 19.3 | H10: =STDEV(D10:F10) -> 2.0297783 | L10: 0.5 | M10: 452 | N10: 144 | O10: 78.3 | P10: =AVERAGE(M10:O10) -> 224.76667 | Q10: =STDEV(M10:O10) -> 199.51281 | V10: 浓度(mg/mL): | X10: =X9/X11 -> 0.2
C11: 1 | D11: 6.93 | E11: 15.8 | F11: 5.18 | G11: =AVERAGE(D11:F11) -> 9.3033333 | H11: =STDEV(D11:F11) -> 5.693912 | L11: 1 | M11: 53.3 | N11: 41.5 | O11: 16.3 | P11: =AVERAGE(M11:O11) -> 37.033333 | Q11: =STDEV(M11:O11) -> 18.900088 | V11: 给药体积 (mL/kg): | X11: 5
C12: 2 | D12: BQL | E12: BQL | F12: BQL | G12: NA | H12: NA | L12: 2 | M12: 8.36 | N12: BQL | O12: BQL | P12: =AVERAGE(M12:O12) -> 8.36 | Q12: NA | V12: 给药途径: | X12: PO | Z12: 推荐溶媒: | AA12: 5%DMSO + 10%Solutol HS 15 + 85% Saline
C13: 4 | D13: BQL | E13: BQL | F13: BQL | G13: NA | H13: NA | L13: 4 | M13: 4.1 | N13: 2.74 | O13: 3.1 | P13: =AVERAGE(M13:O13) -> 3.3133333 | Q13: =STDEV(M13:O13) -> 0.70465121 | V13: 剂量 (mg/kg): | X13: 10
C14: 6 | D14: BQL | E14: BQL | F14: BQL | G14: NA | H14: NA | L14: 6 | M14: 2.33 | N14: BQL | O14: BQL | P14: =AVERAGE(M14:O14) -> 2.33 | Q14: NA | V14: 浓度(mg/mL): | X14: =X13/X15 -> 1
C15: 8 | D15: BQL | E15: BQL | F15: BQL | G15: NA | H15: NA | L15: 8 | M15: BQL | N15: BQL | O15: BQL | P15: NA | Q15: NA | V15: 给药体积 (mL/kg): | X15: 10
C16: 24 | D16: BQL | E16: BQL | F16: BQL | G16: NA | H16: NA | L16: 24 | M16: BQL | N16: BQL | O16: BQL | P16: NA | Q16: NA | V16: 制剂配制计算
V17: 给药途径 | W17: 化合物 | X17: 制剂 | Y17: 浓度(mg/mL) | Z17: 化合物重量(mg) | AA17: 最终总体积(mL) | AB17: DMSO的体积(mL)
V19: 母液 | W19: HW356048 | X19: DMSO | Y19: 20 | Z19: 2.64 | AA19: 0.132 | AB19: 0.132
V21: IV配制过程（给药当天现配现用）
V22: (1)准确称取化合物2.64 mg,放入5 mL玻璃瓶中
V23: (2)加入0.132 mL DMSO,涡旋超声至化合物呈无色澄清状态，得到母液制剂
V24: (3)取0.02 mL母液放入5 mL玻璃瓶中，加入0.08 mL DMSO,涡旋超声至化合物呈无色澄清状态
V25: (4)加入0.2 mL solutol,涡旋超声至化合物呈无色澄清状态
V26: (5)加入1.7 mL Saline，涡旋超声至化合物呈无色澄清状态，即得IV制剂
V27: PO配制过程（给药当天现配现用）
V28: (1)取0.112 mL母液放入5 mL玻璃瓶中
V29: (2)加入0.224 mL solutol,涡旋超声至化合物呈无色澄清状态
V30: (3)加入1.904 mL saline,涡旋超声至化合物呈无色澄清状态，即得PO制剂
V32: 动物临床观察：
C34: 表3：单次静脉注射给予HW356048后小鼠血浆PK数据 | L34: 表4：单次灌胃给予HW356048后小鼠血浆PK数据 | V34: 所有实验动物均未观察到异常现象。
C36: 信息/参数类型 | D36: PK参数 | G36: n | H36: 均值 | I36: 标准差 | L36: 信息/参数类型 | M36: PK参数 | P36: n | Q36: 均值 | R36: 标准差
C37: 分组 | D37: 1 | E37: 2 | F37: 3 | L37: 分组 | M37: 4 | N37: 5 | O37: 6 | V37: 动物体重：
C38: 分析物 | D38: =封面!B7 -> HW356048 | L38: 分析物 | M38: =封面!B7 -> HW356048 | W38: 动物编号 | X38: 1 | Y38: 2 | Z38: 3 | AA38: 4 | AB38: 5 | AC38: 6
C39: 给药途径 | D39: IV | L39: 给药途径 | M39: PO | W39: 体重（g） | X39: 28.9 | Y39: 28.8 | Z39: 26.8 | AA39: 27.5 | AB39: 27.8 | AC39: 26.2
C40: 给药剂量 | D40: 1 | E40: mg/kg | L40: 给药剂量 | M40: 10 | N40: mg/kg
C41: Rsq_adjusted | D41: ='PK 参数'!F3 -> 0.99431795 | E41: ='PK 参数'!F4 -> 0.62061534 | F41: ='PK 参数'!F5 -> 0.96078393 | G41: 3 | H41: =AVERAGE(D41:F41) -> 0.85857241 | I41: =STDEV(D41:F41) -> 0.20675785 | L41: Rsq_adjusted | M41: ='PK 参数'!F7 -> 0.99117081 | N41: ='PK 参数'!F8 -> 0.95671412 | O41: ='PK 参数'!F9 -> 0.77614488 | P41: 3 | Q41: =AVERAGE(M41:O41) -> 0.90800994 | R41: =STDEV(M41:O41) -> 0.11549074
C42: No_points_lambda_z | D42: ='PK 参数'!H3 -> 3 | E42: ='PK 参数'!H4 -> 4 | F42: ='PK 参数'!H5 -> 3 | G42: 3 | H42: =AVERAGE(D42:F42) -> 3.3333333 | I42: =STDEV(D42:F42) -> 0.57735027 | L42: No_points_lambda_z | M42: ='PK 参数'!H7 -> 3 | N42: ='PK 参数'!H8 -> 4 | O42: ='PK 参数'!H9 -> 4 | P42: 3 | Q42: =AVERAGE(M42:O42) -> 3.6666667 | R42: =STDEV(M42:O42) -> 0.57735027
C43: Tlast (h) | D43: ='PK 参数'!S3 -> 1 | E43: ='PK 参数'!S4 -> 1 | F43: ='PK 参数'!S5 -> 1 | G43: 3 | H43: =AVERAGE(D43:F43) -> 1 | I43: =STDEV(D43:F43) -> 0 | L43: Tlast (h) | M43: ='PK 参数'!S7 -> 6 | N43: ='PK 参数'!S8 -> 4 | O43: ='PK 参数'!S9 -> 4 | P43: 3 | Q43: =AVERAGE(M43:O43) -> 4.6666667 | R43: =STDEV(M43:O43) -> 1.1547005
C44: T1/2 （h） | D44: ='PK 参数'!M3 -> 0.36005973 | E44: ='PK 参数'!M4 -> 0.37156534 | F44: ='PK 参数'!M5 -> 0.20646827 | G44: 3 | H44: =AVERAGE(D44:F44) -> 0.31269778 | I44: =STDEV(D44:F44) -> 0.092177147 | L44: T1/2 （h） | M44: ='PK 参数'!M7 -> 2.1701707 | N44: ='PK 参数'!M8 -> 0.63306588 | O44: ='PK 参数'!M9 -> 0.74133998 | P44: 3 | Q44: =AVERAGE(M44:O44) -> 1.1815255 | R44: =STDEV(M44:O44) -> 0.85790168
C45: Tmax（h） | D45: ='PK 参数'!O3 -> 0.0833 | E45: ='PK 参数'!O4 -> 0.0833 | F45: ='PK 参数'!O5 -> 0.0833 | G45: 3 | H45: =AVERAGE(D45:F45) -> 0.0833 | I45: =STDEV(D45:F45) -> 0 | L45: Tmax（h） | M45: ='PK 参数'!P7 -> 0.25 | N45: ='PK 参数'!P8 -> 0.0833 | O45: ='PK 参数'!P9 -> 0.0833 | P45: 3 | Q45: =AVERAGE(M45:O45) -> 0.13886667 | R45: =STDEV(M45:O45) -> 0.09624429
...

Sheet PK 参数
A1: =封面!B7 -> HW356048 | B1: PK parameters
A2: IV | B2: Sort | C2: N_Samples | D2: Dose(mg/kg) | E2: Rsq | F2: Rsq_adjusted | G2: Corr_XY | H2: No_points_lambda_z | I2: Lambda_z(1/h) | J2: Lambda_z_intercept | K2: Lambda_z_lower(h) | L2: Lambda_z_upper(h) | M2: HL_Lambda_z(h) | N2: Span | O2: Tmax(h) | P2: Cmax(ng/mL) | Q2: Cmax_D(kg*ng/mL/mg) | R2: C0(ng/mL) | S2: Tlast(h) | T2: Clast(ng/mL) | U2: Clast_pred(ng/mL) | V2: AUClast(h*ng/mL) | W2: AUClast_D(h*kg*ng/mL/mg) | X2: AUCall(h*ng/mL) | Y2: AUCINF_obs(h*ng/mL) | Z2: AUCINF_D_obs(h*kg*ng/mL/mg) | AA2: AUC_%Extrap_obs({%}) | AB2: AUC_%Back_Ext_obs({%}) | AC2: Vz_obs(L/kg) | AD2: Cl_obs(L/h/kg) | AE2: AUCINF_pred(h*ng/mL) | AF2: AUCINF_D_pred(h*kg*ng/mL/mg) | AG2: AUC_%Extrap_pred({%}) | AH2: AUC_%Back_Ext_pred({%}) | AI2: Vz_pred(L/kg) | AJ2: Cl_pred(L/h/kg) | AK2: AUMClast(h*h*ng/mL) | AL2: AUMCINF_obs(h*h*ng/mL) | AM2: AUMC_%Extrap_obs({%}) | AN2: AUMCINF_pred(h*h*ng/mL) | AO2: AUMC_%Extrap_pred({%}) | AP2: MRTlast(h) | AQ2: MRTINF_obs(h) | AR2: MRTINF_pred(h) | AS2: Vss_obs(L/kg) | AT2: Vss_pred(L/kg)
B3: 1 | C3: 4 | D3: 1 | E3: 0.99715898 | F3: 0.99431795 | G3: -0.99857848 | H3: 3 | I3: 1.9250894 | J3: 3.8461177 | K3: 0.25 | L3: 1 | M3: 0.36005973 | N3: 2.0829877 | O3: 0.0833 | P3: 126 | Q3: 126 | R3: 258.97621 | S3: 1 | T3: 6.93 | U3: 6.8279761 | V3: 40.890189 | W3: 40.890189 | X3: 40.890189 | Y3: 44.490022 | Z3: 44.490022 | AA3: 8.0913261 | AB3: 36.040124 | AC3: 11.675795 | AD3: 22.47695 | AE3: 44.437025 | AF3: 44.437025 | AG3: 7.981713 | AH3: 36.083107 | AI3: 11.68972 | AJ3: 22.503757 | AK3: 7.8029325 | AL3: 13.272721 | AM3: 41.210757 | AN3: 13.192195 | AO3: 40.851901 | AP3: 0.19082652 | AQ3: 0.2983303 | AR3: 0.29687394 | AS3: 6.7055551 | AT3: 6.680779
B4: 2 | C4: 4 | D4: 1 | E4: 0.74707689 | F4: 0.62061534 | G4: -0.8643361 | H4: 4 | I4: 1.8654786 | J4: 4.3694232 | K4: 0.0833 | L4: 1 | M4: 0.37156534 | N4: 2.46713 | O4: 0.0833 | P4: 108 | Q4: 108 | R4: 182.25507 | S4: 1 | T4: 15.8 | U4: 12.230644 | V4: 40.324889 | W4: 40.324889 | X4: 40.324889 | Y4: 48.794565 | Z4: 48.794565 | AA4: 17.357828 | AB4: 24.775554 | AC4: 10.985967 | AD4: 20.494086 | AE4: 46.881192 | AF4: 46.881192 | AG4: 13.984934 | AH4: 25.786724 | AI4: 11.43434 | AJ4: 21.330515 | AK4: 10.742416 | AL4: 23.752309 | AM4: 54.773171 | AN4: 20.813263 | AO4: 48.386678 | AP4: 0.26639667 | AQ4: 0.48678186 | AR4: 0.44395762 | AS4: 9.9761491 | AT4: 9.4698448
B5: 3 | C5: 4 | D5: 1 | E5: 0.98039196 | F5: 0.96078393 | G5: -0.99014745 | H5: 3 | I5: 3.3571608 | J5: 4.9334377 | K5: 0.25 | L5: 1 | M5: 0.20646827 | N5: 3.6325194 | O5: 0.0833 | P5: 229 | Q5: 229 | R5: 417.64026 | S5: 1 | T5: 5.18 | U5: 4.8369142 | V5: 69.561697 | W5: 69.561697 | X5: 69.561697 | Y5: 71.104667 | Z5: 71.104667 | AA5: 2.1699989 | AB5: 37.877355 | AC5: 4.189187 | AD5: 14.063774 | AE5: 71.002472 | AF5: 71.002472 | AG5: 2.0291903 | AH5: 37.931872 | AI5: 4.1952166 | AJ5: 14.084017 | AK5: 11.219333 | AL5: 13.221909 | AM5: 15.145894 | AN5: 13.089273 | AO5: 14.28605 | AP5: 0.16128607 | AQ5: 0.18594994 | AR5: 0.18434953 | AS5: 2.615158 | AT5: 2.5963819
A6: PO | B6: Sort | C6: N_Samples | D6: Dose(mg/kg) | E6: Rsq | F6: Rsq_adjusted | G6: Corr_XY | H6: No_points_lambda_z | I6: Lambda_z(1/h) | J6: Lambda_z_intercept | K6: Lambda_z_lower(h) | L6: Lambda_z_upper(h) | M6: HL_Lambda_z(h) | N6: Span | O6: Tlag(h) | P6: Tmax(h) | Q6: Cmax(ng/mL) | R6: Cmax_D(kg*ng/mL/mg) | S6: Tlast(h) | T6: Clast(ng/mL) | U6: Clast_pred(ng/mL) | V6: AUClast(h*ng/mL) | W6: AUClast_D(h*kg*ng/mL/mg) | X6: AUCall(h*ng/mL) | Y6: AUCINF_obs(h*ng/mL) | Z6: AUCINF_D_obs(h*kg*ng/mL/mg) | AA6: AUC_%Extrap_obs({%}) | AB6: Vz_F_obs(L/kg) | AC6: Cl_F_obs(L/h/kg) | AD6: AUCINF_pred(h*ng/mL) | AE6: AUCINF_D_pred(h*kg*ng/mL/mg) | AF6: AUC_%Extrap_pred({%}) | AG6: Vz_F_pred(L/kg) | AH6: Cl_F_pred(L/h/kg) | AI6: AUMClast(h*h*ng/mL) | AJ6: AUMCINF_obs(h*h*ng/mL) | AK6: AUMC_%Extrap_obs({%}) | AL6: AUMCINF_pred(h*h*ng/mL) | AM6: AUMC_%Extrap_pred({%}) | AN6: MRTlast(h) | AO6: MRTINF_obs(h) | AP6: MRTINF_pred(h)
B7: 4 | C7: 7 | D7: 10 | E7: 0.99558541 | F7: 0.99117081 | G7: -0.99779026 | H7: 3 | I7: 0.31939754 | J7: 2.7376947 | K7: 2 | L7: 6 | M7: 2.1701707 | N7: 1.843173 | O7: 0 | P7: 0.25 | Q7: 919 | R7: 91.9 | S7: 6 | T7: 2.33 | U7: 2.273475 | V7: 511.01865 | W7: 51.101865 | X7: 511.01865 | Y7: 518.31363 | Z7: 51.831363 | AA7: 1.4074459 | AB7: 60.405405 | AC7: 19.293338 | AD7: 518.13666 | AE7: 51.813666 | AF7: 1.3737708 | AG7: 60.426037 | AH7: 19.299928 | AI7: 251.70051 | AJ7: 318.31024 | AK7: 20.926041 | AL7: 316.69431 | AM7: 20.522566 | AN7: 0.49254663 | AO7: 0.6141267 | AP7: 0.61121773
B8: 5 | C8: 5 | D8: 10 | E8: 0.97114275 | F8: 0.95671412 | G8: -0.98546575 | H8: 4 | I8: 1.0949053 | J8: 5.3048815 | K8: 0.25 | L8: 4 | M8: 0.63306588 | N8: 5.9235541 | O8: 0 | P8: 0.0833 | Q8: 571 | R8: 57.1 | S8: 4 | T8: 2.74 | U8: 2.5225249 | V8: 240.65475 | W8: 24.065475 | X8: 240.65475 | Y8: 243.15725 | Z8: 24.315725 | AA8: 1.0291692 | AB8: 37.560921 | AC8: 41.12565 | AD8: 242.95862 | AE8: 24.295862 | AF8: 0.94825816 | AG8: 37.591627 | AH8: 41.159271 | AI8: 131.64673 | AJ8: 143.94231 | AK8: 8.542022 | AL8: 142.9664 | AM8: 7.9177185 | AN8: 0.54703564 | AO8: 0.5919721 | AP8: 0.5884393
B9: 6 | C9: 5 | D9: 10 | E9: 0.85076325 | F9: 0.77614488 | G9: -0.92236828 | H9: 4 | I9: 0.93499231 | J9: 4.6882677 | K9: 0.25 | L9: 4 | M9: 0.74133998 | N9: 5.0584079 | O9: 0 | P9: 0.0833 | Q9: 541 | R9: 54.1 | S9: 4 | T9: 3.1 | U9: 2.5813137 | V9: 164.12355 | W9: 16.412355 | X9: 164.12355 | Y9: 167.43909 | Z9: 16.743909 | AA9: 1.9801442 | AB9: 63.875618 | AC9: 59.723212 | AD9: 166.88434 | AE9: 16.688434 | AF9: 1.6543111 | AG9: 64.087951 | AH9: 59.921741 | AI9: 75.929675 | AJ9: 92.737872 | AK9: 18.124416 | AL9: 89.925556 | AM9: 15.563852 | AN9: 0.46263729 | AO9: 0.55386036 | AP9: 0.53884959

Sheet 原始数据
A2: Peak Name: Tolbutamide
A3: Use as Internal Standard
A4: Q1/Q3 Masses: 269.20/170.00 Da
A6: Peak Name: HW356048
A7: Internal Standard: Tolbutamide
A8: Q1/Q3 Masses: 507.00/427.20 Da
A10: Fit | B10: Linear | C10: Weighting | D10: 1 / (x * x) | E10: Iterate | F10: No
A11: Intercept | B11: 2.94e-05
A12: Slope | B12: 2.32e-05
A13: Correlation coefficient | B13: 0.9946
A14: Use Area
A18: Sample Name | B18: Sample Type | C18: File Name | D18: Analyte Peak Name | E18: Analyte Concentration (ng/mL) | F18: Calculated Concentration (ng/mL) | G18: Analyte Peak Area (counts) | H18: Analyte Retention Time (min) | I18: Area Ratio | J18: IS Peak Area (counts) | K18: IS Retention Time (min) | L18: Use Record | M18: Record Modified | N18: Accuracy (%) | O18: Dilution Factor
A19: Doubleblank | B19: Unknown | C19: HW356048-20241014-Mouse-Plasma\SA.wiff | D19: HW356048 | E19: N/A | F19: #DIV/0! | G19: 0 | H19: 0 | I19: #DIV/0! | J19: 0 | K19: 0 | M19: 0 | N19: N/A | O19: 1
A20: Doubleblank | B20: Unknown | C20: HW356048-20241014-Mouse-Plasma\SA.wiff | D20: HW356048 | E20: N/A | F20: #DIV/0! | G20: 0 | H20: 0 | I20: #DIV/0! | J20: 0 | K20: 0 | M20: 0 | N20: N/A | O20: 1
A21: Doubleblank | B21: Unknown | C21: HW356048-20241014-Mouse-Plasma\SA.wiff | D21: HW356048 | E21: N/A | F21: #DIV/0! | G21: 0 | H21: 0 | I21: #DIV/0! | J21: 0 | K21: 0 | M21: 0 | N21: N/A | O21: 1
A22: Blank | B22: Unknown | C22: HW356048-20241014-Mouse-Plasma\SA.wiff | D22: HW356048 | E22: N/A | F22: No Peak | G22: 0 | H22: 0 | I22: 0 | J22: 13800000 | K22: 1.16 | M22: 0 | N22: N/A | O22: 1
A23: B-STD1 | B23: Standard | C23: HW356048-20241014-Mouse-Plasma\SA.wiff | D23: HW356048 | E23: 1 | F23: < 0 | G23: 251 | H23: 1.39 | I23: 1.82e-05 | J23: 13800000 | K23: 1.17 | L23: 0 | M23: 0 | N23: N/A | O23: 1
A24: B-STD2 | B24: Standard | C24: HW356048-20241014-Mouse-Plasma\SA.wiff | D24: HW356048 | E24: 2 | F24: 1.97 | G24: 1060 | H24: 1.39 | I24: 7.51e-05 | J24: 14100000 | K24: 1.16 | L24: 1 | M24: 0 | N24: 98.41 | O24: 1
A25: B-STD3 | B25: Standard | C25: HW356048-20241014-Mouse-Plasma\SA.wiff | D25: HW356048 | E25: 10 | F25: 10.5 | G25: 3800 | H25: 1.38 | I25: 0.000273 | J25: 13900000 | K25: 1.16 | L25: 1 | M25: 0 | N25: 104.97 | O25: 1
A26: B-STD4 | B26: Standard | C26: HW356048-20241014-Mouse-Plasma\SA.wiff | D26: HW356048 | E26: 50 | F26: 58.9 | G26: 19200 | H26: 1.39 | I26: 0.0014 | J26: 13800000 | K26: 1.16 | L26: 1 | M26: 0 | N26: 117.87 | O26: 1
A27: B-STD5 | B27: Standard | C27: HW356048-20241014-Mouse-Plasma\SA.wiff | D27: HW356048 | E27: 200 | F27: 179 | G27: 57900 | H27: 1.39 | I27: 0.00419 | J27: 13800000 | K27: 1.16 | L27: 1 | M27: 0 | N27: 89.66 | O27: 1
A28: B-STD6 | B28: Standard | C28: HW356048-20241014-Mouse-Plasma\SA.wiff | D28: HW356048 | E28: 1000 | F28: 961 | G28: 308000 | H28: 1.39 | I28: 0.0223 | J28: 13800000 | K28: 1.16 | L28: 1 | M28: 0 | N28: 96.14 | O28: 1
A29: B-STD7 | B29: Standard | C29: HW356048-20241014-Mouse-Plasma\SA.wiff | D29: HW356048 | E29: 1800 | F29: 1870 | G29: 579000 | H29: 1.39 | I29: 0.0433 | J29: 13400000 | K29: 1.16 | L29: 1 | M29: 0 | N29: 103.64 | O29: 1
A30: B-STD8 | B30: Standard | C30: HW356048-20241014-Mouse-Plasma\SA.wiff | D30: HW356048 | E30: 2000 | F30: 1790 | G30: 584000 | H30: 1.38 | I30: 0.0414 | J30: 14100000 | K30: 1.16 | L30: 1 | M30: 0 | N30: 89.31 | O30: 1
A31: Doubleblank | B31: Unknown | C31: HW356048-20241014-Mouse-Plasma\SA.wiff | D31: HW356048 | E31: N/A | F31: #DIV/0! | G31: 0 | H31: 0 | I31: #DIV/0! | J31: 0 | K31: 0 | M31: 0 | N31: N/A | O31: 1
A32: Doubleblank | B32: Unknown | C32: HW356048-20241014-Mouse-Plasma\SA.wiff | D32: HW356048 | E32: N/A | F32: #DIV/0! | G32: 0 | H32: 0 | I32: #DIV/0! | J32: 0 | K32: 0 | M32: 0 | N32: N/A | O32: 1
A33: B-LQC-1 | B33: Quality Control | C33: HW356048-20241014-Mouse-Plasma\SA.wiff | D33: HW356048 | E33: 3 | F33: 3.47 | G33: 1500 | H33: 1.39 | I33: 0.00011 | J33: 13700000 | K33: 1.16 | L33: 1 | M33: 0 | N33: 115.61 | O33: 1
A34: B-MQC-1 | B34: Quality Control | C34: HW356048-20241014-Mouse-Plasma\SA.wiff | D34: HW356048 | E34: 100 | F34: 106 | G34: 35400 | H34: 1.39 | I34: 0.00249 | J34: 14200000 | K34: 1.17 | L34: 1 | M34: 0 | N34: 106.13 | O34: 1
A35: B-HQC-1 | B35: Quality Control | C35: HW356048-20241014-Mouse-Plasma\SA.wiff | D35: HW356048 | E35: 1600 | F35: 1590 | G35: 500000 | H35: 1.38 | I35: 0.0369 | J35: 13600000 | K35: 1.16 | L35: 1 | M35: 0 | N35: 99.32 | O35: 1
A36: B-DQC-2 | B36: Quality Control | C36: HW356048-20241014-Mouse-Plasma\SA.wiff | D36: HW356048 | E36: 16000 | F36: 17700 | G36: 580000 | H36: 1.38 | I36: 0.0412 | J36: 14100000 | K36: 1.16 | L36: 1 | M36: 0 | N36: 110.94 | O36: 10
A37: B-DQC-1 | B37: Quality Control | C37: HW356048-20241014-Mouse-Plasma\SA.wiff | D37: HW356048 | E37: 16000 | F37: 15700 | G37: 503000 | H37: 1.39 | I37: 0.0364 | J37: 13800000 | K37: 1.17 | L37: 1 | M37: 0 | N37: 98.01 | O37: 10
A38: B-DQC-3 | B38: Quality Control | C38: HW356048-20241014-Mouse-Plasma\SA.wiff | D38: HW356048 | E38: 16000 | F38: 19100 | G38: 600000 | H38: 1.39 | I38: 0.0444 | J38: 13500000 | K38: 1.17 | L38: 1 | M38: 0 | N38: 119.53 | O38: 10
A39: IV-dose-1 | B39: Quality Control | C39: HW356048-20241014-Mouse-Plasma\SA.wiff | D39: HW356048 | E39: 50 | F39: 59.6 | G39: 20000 | H39: 1.39 | I39: 0.00141 | J39: 14100000 | K39: 1.17 | L39: 1 | M39: 0 | N39: 119.15 | O39: 1
A40: IV-dose-2 | B40: Quality Control | C40: HW356048-20241014-Mouse-Plasma\SA.wiff | D40: HW356048 | E40: 50 | F40: 54.5 | G40: 18000 | H40: 1.39 | I40: 0.00129 | J40: 13900000 | K40: 1.16 | L40: 1 | M40: 0 | N40: 108.92 | O40: 1
A41: IV-dose-3 | B41: Quality Control | C41: HW356048-20241014-Mouse-Plasma\SA.wiff | D41: HW356048 | E41: 50 | F41: 55.3 | G41: 18500 | H41: 1.39 | I41: 0.00131 | J41: 14100000 | K41: 1.16 | L41: 1 | M41: 0 | N41: 110.61 | O41: 1
A42: PO-dose-1 | B42: Quality Control | C42: HW356048-20241014-Mouse-Plasma\SA.wiff | D42: HW356048 | E42: 50 | F42: 57.7 | G42: 19200 | H42: 1.39 | I42: 0.00137 | J42: 14100000 | K42: 1.16 | L42: 1 | M42: 0 | N42: 115.36 | O42: 1
A43: PO-dose-2 | B43: Quality Control | C43: HW356048-20241014-Mouse-Plasma\SA.wiff | D43: HW356048 | E43: 50 | F43: 45.3 | G43: 15000 | H43: 1.39 | I43: 0.00108 | J43: 13900000 | K43: 1.16 | L43: 1 | M43: 0 | N43: 90.62 | O43: 1
A44: PO-dose-3 | B44: Quality Control | C44: HW356048-20241014-Mouse-Plasma\SA.wiff | D44: HW356048 | E44: 50 | F44: 49.9 | G44: 16500 | H44: 1.39 | I44: 0.00119 | J44: 13900000 | K44: 1.16 | L44: 1 | M44: 0 | N44: 99.84 | O44: 1
A45: Doubleblank | B45: Unknown | C45: HW356048-20241014-Mouse-Plasma\SA.wiff | D45: HW356048 | E45: N/A | F45: #DIV/0! | G45: 0 | H45: 0 | I45: #DIV/0! | J45: 0 | K45: 0 | M45: 0 | N45: N/A | O45: 1
A46: Doubleblank | B46: Unknown | C46: HW356048-20241014-Mouse-Plasma\SA.wiff | D46: HW356048 | E46: N/A | F46: #DIV/0! | G46: 0 | H46: 0 | I46: #DIV/0! | J46: 0 | K46: 0 | M46: 0 | N46: N/A | O46: 1
...

Sheet 标曲&质控
C5: 标准曲线 | D5: 编号 | E5: 标示浓度 | F5: 实测浓度 | G5: 准确度%
D6: B-STD1 | E6: 1 | F6: < 0 | G6: N/A
D7: B-STD2 | E7: 2 | F7: 1.97 | G7: 98.41
D8: B-STD3 | E8: 10 | F8: 10.5 | G8: 104.97
D9: B-STD4 | E9: 50 | F9: 58.9 | G9: 117.87
D10: B-STD5 | E10: 200 | F10: 179 | G10: 89.66
D11: B-STD6 | E11: 1000 | F11: 961 | G11: 96.14
D12: B-STD7 | E12: 1800 | F12: 1870 | G12: 103.64
D13: B-STD8 | E13: 2000 | F13: 1790 | G13: 89.31
C15: 质控样本 | D15: 编号 | E15: 标示浓度 | F15: 实测浓度 | H15: 准确度%
F16: 1 | G16: 2 | H16: 1 | I16: 2
D17: B-LQC | E17: 3 | F17: 3.47 | G17: 2.64 | H17: 115.61 | I17: 88.01
D18: B-MQC | E18: 100 | F18: 106 | G18: 101 | H18: 106.13 | I18: 101.25
D19: B-HQC | E19: 1600 | F19: 1590 | G19: 1420 | H19: 99.32 | I19: 89.05
D20: B-DQC | E20: 16000 | F20: 17700 | G20: \ | H20: 110.94 | I20: \
E21: 16000 | F21: 15700 | H21: 98.01
E22: 16000 | F22: 19100 | H22: 119.53
C24: 生物样品分析方法及所有样品的分析由合肥中科普瑞昇生物分析实验室完成，分析样品的同时进行质控样品的日内准确度评价，并要求超过66.7%的质控样品的准确度在80-120%之间。伴随样品分析的线性标准品至少6个且≥75%的校准标样满足偏差在±20%范围内。

Sheet 给药制剂浓度检测
B2: PK 给药制剂浓度测定
B3: IV | C3: 检测步骤： (将药制剂原液稀释4000 倍后进行浓度检测):
C4: 1) 移取IV制剂50 μL，加入二甲基亚砜950 μL混合均匀（该过程稀释20倍)；
C5: 2) 将第一步中的制剂稀释液移取100 µL，准确加入二甲基亚砜900 µL，混合均匀（该过程稀释10倍）；
C6: 3) 将步骤2的溶液移取5.0 μL 加入到95.0 μL的血浆中，按提取标准和线性一起处理（此过程稀释20倍）。
B8: PO | C8: 检测步骤： (将药制剂原液稀释20000 倍后进行浓度检测):
C9: 1) 移取PO制剂50 μL，加入二甲基亚砜950 μL混合均匀（该过程稀释20倍)；
C10: 2) 将第一步中的制剂稀释液移取20 µL，准确加入二甲基亚砜980 µL，混合均匀（该过程稀释50倍）；
C11: 3) 将步骤2的溶液移取5.0 μL 加入到95.0 μL的血浆中，按提取标准和线性一起处理（此过程稀释20倍）。
C14: 化合物 | D14: 给药方式 | E14: 设计浓度. (mg/mL) | F14: 稀释倍数 | G14: 测试浓度(ng/mL) | H14: 计算浓度 (mg/mL) | I14: 平均浓度 (mg/mL) | J14: 偏差 (%) | K14: 变异系数(%) | L14: 测试方法
C15: HW356048 | D15: IV | E15: 0.2 | F15: =E15/0.00005 -> 4000 | G15: 59.6 | H15: =G15*F15/1000000 -> 0.2384 | I15: =AVERAGE(H15:H17) -> 0.22586667 | J15: =(I15-E15)/E15*100 -> 12.933333 | K15: =STDEV(H15:H17)/I15*100 -> 4.8575021 | L15: HPLC-MS/MS
F16: =F15 -> 4000 | G16: 54.5 | H16: =G16*F16/1000000 -> 0.218
F17: =F15 -> 4000 | G17: 55.3 | H17: =G17*F17/1000000 -> 0.2212
D18: PO | E18: 1 | F18: 20000 | G18: 57.7 | H18: =G18*F18/1000000 -> 1.154 | I18: =AVERAGE(H18:H20) -> 1.0193333 | J18: =(I18-E18)/E18*100 -> 1.9333333 | K18: =STDEV(H18:H20)/I18*100 -> 12.299096 | L18: HPLC-MS/MS
F19: =F18 -> 20000 | G19: 45.3 | H19: =G19*F19/1000000 -> 0.906
F20: =F18 -> 20000 | G20: 49.9 | H20: =G20*F20/1000000 -> 0.998
C24: 结果：
C25: 与设计剂量浓度(PO:1 mg/mL，IV:0.2 mg/mL )比较， 剂量浓度在(± 20%)标准范围内。

Sheet LC-MS分析方法 
B2: 分析方法
C3: 设备型号 | D3: LC-MS/MS ( Triple Quad 6500+)
C5: 设备编号 | D5: LC-MS/MS-003
C7: 基质类型 | D7: 小鼠血浆
C9: 分析物 | D9: HW356048
C11: 内标 | D11: Tolbutamide
C13: 质谱条件 | D13: ESI源负离子模式
D14: 多反应监测
D15: HW356048 | E15: Q1/Q3 Masses: 507.00/427.20 Da
D16: Tolbutamide | E16: Q1/Q3 Masses: 269.20/170.00 Da
C17: 液相条件
D18: 色谱柱 | E18: Synergi 4 µm Fusion-RP 80Å Luna C18 2 mm *50 mm ,4 µm
D19: 色谱型号 | E19: Shimadzu LC-30AD
D20: 流动相 | E20: A: 水（含0.1%FA）
E21: B:乙腈
D22: 液相程序
E23: 时间 (min) | F23: 流速 (mL/min) | G23: A (%) | H23: B (%)
E24: 1.6 | F24: 0.8 | G24: =100-H24 -> 5 | H24: 95
E25: 1.9 | F25: 0.8 | G25: =100-H25 -> 5 | H25: 95
E26: 1.91 | F26: =F25 -> 0.8 | G26: =100-H26 -> 80 | H26: 20
E27: 2.2 | F27: =F26 -> 0.8 | G27: =100-H27 -> 80 | H27: 20
D28: 柱温 (°C): | E28: 40
D29: 进样体积(μL): | E29: 5
D30: 保留时间:
D31: HW356048 | E31: 1.39 min
D32: IS: | E32: 1.17 min
C34: 样品前处理 | D34: 1. 所有样品完全融化后，混匀10～30秒，4000 rpm、4°C条件下离心0.5分钟。 2.移取20 μL血浆样品（空白样品和内标空白样品加20 μL空白血浆）至96孔板中，加入200 μL内标（50%甲醇乙腈溶液（浓度：100 ng/mL））溶液（Doubleblank样品加入200 μL 50%甲醇乙腈溶液）。 3. 将样品涡旋5分钟后，在4000 rpm、4°C条件下离心10分钟，移取100 μL加入到100 μL的水中，混合均匀，交由LC-MS/MS分析。
C35: 线性范围 | D35: 2-2000 ng/mL

Sheet 试验设计
C3: 供试品信息
C5: 名称 | D5: 保存条件 | E5: 纯度* | F5: 盐或酯或游离形式 | G5: 分子量（盐） | H5: 分子量（游离形式）
C6: HW356048 | D6: 常温 | E6: 1 | F6: 游离形式 | G6: NA | H6: 508.16
C7: *:配制时需要折算纯度。
C9: 供试品配制
C11: 给药当天配制。
C12: 溶媒：5%DMSO + 10%Solutol HS 15 + 85% Saline
C14: 实验动物
C16: 种属：ICR 小鼠；SPF级。
C17: 来源：北京维通利华实验动物技术有限公司
C18: 数量：雄性8只。实验需要：雄性6只。
C19: 动物挑选：不进行随机分组
C21: 实验设计
C23: 组别 | D23: 受试物 | E23: 动物数量 | F23: 剂量 | G23: 浓度 | H23: 给药体积 | I23: 给予方式 | J23: 采集样本
E24: 雄性 | F24: (mg/kg) | G24: (mg/mL) | H24: (mL/kg)
C25: 1 | D25: HW356048 | E25: 3 | F25: 1 | G25: 0.2 | H25: 5 | I25: IV，单次 | J25: 血浆
C26: 2 | D26: HW356048 | E26: 3 | F26: 10 | G26: 1 | H26: 10 | I26: PO*，单次 | J26: 血浆
C27: 注： *, 口服给药组动物给药前禁食过夜（10-14小时），给药4小时后给食。
C29: 给药方式
C31: 给药前称重，根据体重，计算给药量。通过尾静脉注射和口服给药。
C33: 采血时间点：
C35: 给药后 0.083 h、0.25 h、0.5 h、1 h、2 h、4 h、6 h、8 h、24 h
C36: 经小鼠脸颊采血，每个样品采集约0.05 mL，EDTAK2抗凝，采集后放置湿冰上。
C38: 血浆样品处理
C40: 血液样本采集后置于冰上，并于1小时之内离心分离血浆(离心条件：6000 g，3分钟，2-8 ºC)。血浆样本在分析前存放时则放于-80 ºC冰箱内。
C42: 结果分析
C44: 通过不同时间点的血药浓度数据，运用Phoenix WinNonlin8.2.0计算药代动力学参数，提供AUC0-t、AUC0-∞、MRT0-∞、Cmax、Tmax、和T1/2等参数及其平均值和标准差。
C46: 剩余供试品、血浆的处置
C48: 剩余供试品和剩余血浆样品在试验结束后继续存放于-80°C冰箱暂存，保存期限为一个月。

Sheet 血浆稳定性
B4: HW356048血浆稳定性考察
B5: 基质类型 | C5: 血浆
B6: 浓度 | C6: 100ng/mL
B7: 样本类型 | C7: 血浆新鲜配制 | D7: 血浆样品室温放置1h | E7: 血浆样品室温放置4h
B8: Peak Area | C8: 29967 | D8: 20067 | E8: 8087
B9: %Change | C9: NA | D9: =(D8-C8)/C8*100 -> -33.03634 | E9: =(E8-C8)/C8*100 -> -73.013648
B10: 结论 | C10: 室温下HW356048在小鼠血浆中不稳定
B14: Sample Name | C14: Sample Type | D14: File Name | E14: Analyte Peak Name | F14: Analyte Concentration (ng/mL) | G14: Calculated Concentration (ng/mL) | H14: Analyte Peak Area (counts) | I14: Analyte Retention Time (min) | J14: Area Ratio | K14: IS Peak Area (counts) | L14: IS Retention Time (min) | M14: Use Record | N14: Record Modified | O14: Accuracy (%) | P14: Dilution Factor
B15: T0 | C15: Unknown | D15: HW356048-20241014-Mouse-Plasma\SA.wiff | E15: HW356048 | F15: N/A | G15: 0 | H15: 27700 | I15: 1.39 | J15: 0.00214 | K15: 12900000 | L15: 1.18 | N15: 0 | O15: N/A | P15: 1
B16: T0 | C16: Unknown | D16: HW356048-20241014-Mouse-Plasma\SA.wiff | E16: HW356048 | F16: N/A | G16: 0 | H16: 31500 | I16: 1.39 | J16: 0.00239 | K16: 13200000 | L16: 1.17 | N16: 0 | O16: N/A | P16: 1
B17: T0 | C17: Unknown | D17: HW356048-20241014-Mouse-Plasma\SA.wiff | E17: HW356048 | F17: N/A | G17: 0 | H17: 30700 | I17: 1.39 | J17: 0.00235 | K17: 13100000 | L17: 1.17 | N17: 0 | O17: N/A | P17: 1
B18: T1hr | C18: Unknown | D18: HW356048-20241014-Mouse-Plasma\SA.wiff | E18: HW356048 | F18: N/A | G18: 0 | H18: 18100 | I18: 1.39 | J18: 0.00149 | K18: 12100000 | L18: 1.18 | N18: 0 | O18: N/A | P18: 1
B19: T1hr | C19: Unknown | D19: HW356048-20241014-Mouse-Plasma\SA.wiff | E19: HW356048 | F19: N/A | G19: 0 | H19: 21100 | I19: 1.39 | J19: 0.00169 | K19: 12400000 | L19: 1.17 | N19: 0 | O19: N/A | P19: 1
B20: T1hr | C20: Unknown | D20: HW356048-20241014-Mouse-Plasma\SA.wiff | E20: HW356048 | F20: N/A | G20: 0 | H20: 21000 | I20: 1.39 | J20: 0.00168 | K20: 12500000 | L20: 1.17 | N20: 0 | O20: N/A | P20: 1
B21: T4hr | C21: Unknown | D21: HW356048-20241014-Mouse-Plasma\SA.wiff | E21: HW356048 | F21: N/A | G21: 0 | H21: 6600 | I21: 1.39 | J21: 0.000647 | K21: 10200000 | L21: 1.17 | N21: 0 | O21: N/A | P21: 1
B22: T4hr | C22: Unknown | D22: HW356048-20241014-Mouse-Plasma\SA.wiff | E22: HW356048 | F22: N/A | G22: 0 | H22: 8910 | I22: 1.39 | J22: 0.000763 | K22: 11700000 | L22: 1.18 | N22: 0 | O22: N/A | P22: 1
B23: T4hr | C23: Unknown | D23: HW356048-20241014-Mouse-Plasma\SA.wiff | E23: HW356048 | F23: N/A | G23: 0 | H23: 8750 | I23: 1.39 | J23: 0.000721 | K23: 12100000 | L23: 1.17 | N23: 0 | O23: N/A | P23: 1
