Workbook

Sheet Signature
B4: Study Report
B8: Assay Name | C8: WRN(517-1238)_ATP preincubation_FI_IC50
B9: Assay Goal | C9: To assess the compounds inhibition on WRN (517-1238)_ATP preincubation
B10: Study Number | C10: RFP-2025032402
B12: Experiment Type | C12: 10 doses in duplicate, IC50
B13: Samples Receive Date | C13: 45741
B14: Experiment Date | C14: 45741
B15: Report Release Date | C15: 45741
B17: Assay Performed by | C17: Xuewei Wang
B18: Report Prepared by | C18: Xuewei Wang
B19: Report reviewer | C19: Jingxue Shi
B20: Report Approval | C20: Qiang Xia
B24: Submitted to | C24: 湖北生物医药产业技术研究院有限公司
B26: Submitted by | C26: ICE Bioscience InC.

Sheet Assay summary
A1: Assay date | B1: Assay name | C1: Compounds ID | D1: Bottom | E1: Top | F1: IC50 (nM) | G1: Hillslope | H1: Comment | I1: Compound state | J1: SOP # | K1: Scientist
A2: 2024/3/25 | B2: WRN(517-1238) FI assay_ATP preincubation | C2: ='Assay protocol'!C20 -> HW350003A | D2: =OFFSET(INDEX('Raw data analysis'!B:B,MATCH(C2,'Raw data analysis'!B:B,0)),2,5) -> -16.469494 | E2: =OFFSET(INDEX('Raw data analysis'!B:B,MATCH(C2,'Raw data analysis'!B:B,0)),2,6) -> 94.458194 | F2: =OFFSET(INDEX('Raw data analysis'!B:B,MATCH(C2,'Raw data analysis'!B:B,0)),2,7) -> 86.81258 | G2: =OFFSET(INDEX('Raw data analysis'!B:B,MATCH(C2,'Raw data analysis'!B:B,0)),2,8) -> 0.90388219 | H2: Reference | I2: clear | J2: SOP-BA-1240 | K2: Xuewei Wang
C3: ='Assay protocol'!C21 -> HW356057 | D3: =OFFSET(INDEX('Raw data analysis'!B:B,MATCH(C3,'Raw data analysis'!B:B,0)),2,5) -> -13.736449 | E3: =OFFSET(INDEX('Raw data analysis'!B:B,MATCH(C3,'Raw data analysis'!B:B,0)),2,6) -> 100 | F3: =OFFSET(INDEX('Raw data analysis'!B:B,MATCH(C3,'Raw data analysis'!B:B,0)),2,7) -> 839.72103 | G3: =OFFSET(INDEX('Raw data analysis'!B:B,MATCH(C3,'Raw data analysis'!B:B,0)),2,8) -> 0.67836634 | H3: Top fixed to 100 | I3: clear
C4: ='Assay protocol'!C22 -> HW356054 | D4: =OFFSET(INDEX('Raw data analysis'!B:B,MATCH(C4,'Raw data analysis'!B:B,0)),2,5) -> -4.4397821 | E4: =OFFSET(INDEX('Raw data analysis'!B:B,MATCH(C4,'Raw data analysis'!B:B,0)),2,6) -> 80.650389 | F4: =OFFSET(INDEX('Raw data analysis'!B:B,MATCH(C4,'Raw data analysis'!B:B,0)),2,7) -> 152.51782 | G4: =OFFSET(INDEX('Raw data analysis'!B:B,MATCH(C4,'Raw data analysis'!B:B,0)),2,8) -> 1.203836 | H4: / | I4: clear
C5: ='Assay protocol'!C23 -> HW356060 | D5: =OFFSET(INDEX('Raw data analysis'!B:B,MATCH(C5,'Raw data analysis'!B:B,0)),2,5) -> 0.61319841 | E5: =OFFSET(INDEX('Raw data analysis'!B:B,MATCH(C5,'Raw data analysis'!B:B,0)),2,6) -> 89.936753 | F5: =OFFSET(INDEX('Raw data analysis'!B:B,MATCH(C5,'Raw data analysis'!B:B,0)),2,7) -> 206.42241 | G5: =OFFSET(INDEX('Raw data analysis'!B:B,MATCH(C5,'Raw data analysis'!B:B,0)),2,8) -> 0.91668586 | H5: / | I5: clear
C6: ='Assay protocol'!C24 -> HW356064 | D6: =OFFSET(INDEX('Raw data analysis'!B:B,MATCH(C6,'Raw data analysis'!B:B,0)),2,5) -> -1.2983558 | E6: =OFFSET(INDEX('Raw data analysis'!B:B,MATCH(C6,'Raw data analysis'!B:B,0)),2,6) -> 92.678457 | F6: =OFFSET(INDEX('Raw data analysis'!B:B,MATCH(C6,'Raw data analysis'!B:B,0)),2,7) -> 173.08897 | G6: =OFFSET(INDEX('Raw data analysis'!B:B,MATCH(C6,'Raw data analysis'!B:B,0)),2,8) -> 1.2176413 | H6: / | I6: clear
C7: ='Assay protocol'!C25 -> HW356071 | D7: =OFFSET(INDEX('Raw data analysis'!B:B,MATCH(C7,'Raw data analysis'!B:B,0)),2,5) -> -10.260006 | E7: =OFFSET(INDEX('Raw data analysis'!B:B,MATCH(C7,'Raw data analysis'!B:B,0)),2,6) -> 86.62229 | F7: =OFFSET(INDEX('Raw data analysis'!B:B,MATCH(C7,'Raw data analysis'!B:B,0)),2,7) -> 226.57613 | G7: =OFFSET(INDEX('Raw data analysis'!B:B,MATCH(C7,'Raw data analysis'!B:B,0)),2,8) -> 1.0668095 | H7: / | I7: clear
C8: ='Assay protocol'!C26 -> HW356009-P1 | D8: =OFFSET(INDEX('Raw data analysis'!B:B,MATCH(C8,'Raw data analysis'!B:B,0)),2,5) -> -9.618994 | E8: =OFFSET(INDEX('Raw data analysis'!B:B,MATCH(C8,'Raw data analysis'!B:B,0)),2,6) -> 84.975464 | F8: =OFFSET(INDEX('Raw data analysis'!B:B,MATCH(C8,'Raw data analysis'!B:B,0)),2,7) -> 217.20957 | G8: =OFFSET(INDEX('Raw data analysis'!B:B,MATCH(C8,'Raw data analysis'!B:B,0)),2,8) -> 1.268738 | H8: / | I8: clear
C9: ='Assay protocol'!C27 -> HW356016 | D9: =OFFSET(INDEX('Raw data analysis'!B:B,MATCH(C9,'Raw data analysis'!B:B,0)),2,5) -> -14.107588 | E9: =OFFSET(INDEX('Raw data analysis'!B:B,MATCH(C9,'Raw data analysis'!B:B,0)),2,6) -> 84.263213 | F9: =OFFSET(INDEX('Raw data analysis'!B:B,MATCH(C9,'Raw data analysis'!B:B,0)),2,7) -> 661.06209 | G9: =OFFSET(INDEX('Raw data analysis'!B:B,MATCH(C9,'Raw data analysis'!B:B,0)),2,8) -> 0.93214332 | H9: / | I9: clear
C10: ='Assay protocol'!C28 -> HW356070 | D10: =OFFSET(INDEX('Raw data analysis'!O:O,MATCH(C10,'Raw data analysis'!O:O,0)),2,5) -> -14.841502 | E10: =OFFSET(INDEX('Raw data analysis'!O:O,MATCH(C10,'Raw data analysis'!O:O,0)),2,6) -> 86.190153 | F10: =OFFSET(INDEX('Raw data analysis'!O:O,MATCH(C10,'Raw data analysis'!O:O,0)),2,7) -> 263.92538 | G10: =OFFSET(INDEX('Raw data analysis'!O:O,MATCH(C10,'Raw data analysis'!O:O,0)),2,8) -> 0.96987181 | H10: / | I10: clear

Sheet Assay protocol
A2: Ⅰ | B2: Reagent, Consumables and Instruments
B4: Reagent | C4: Vendor | D4: Cat No.
B5: capture DNA | C5: ICE | D5: ICE-WDU-114
B6: dsDNA-secquence 2 | C6: ICE | D6: ICE-WDU-113
B7: WRN (517-1238) | C7: ICE | D7: S2212T-H56HZ
B8: ATP | C8: Ark Pharm | D8: Ak-54737
B9: Consumables | C9: Vendor | D9: Cat No.
B10: 96 Well Plates | C10: Nunc | D10: 249944
B11: 384-well plate | C11: Corning | D11: 4514
B12: Instrument | C12: Vendor | D12: Cat No.
B13: ECHO®655 SYSTEM | C13: LABCYTE | D13: 655
B14: Centrifuge | C14: Cence | D14: TDZ5-WS
B15: Microplate Reader | C15: BMG | D15: CLARIO Star Plusacu
A17: Ⅱ | B17: Compound Information and Treatment
B19: Entry | C19: Compound ID | D19: Stock Conc. (mM) | E19: Start Conc. (nM) | F19: Dilution folds
B20: R | C20: HW350003A | D20: 10 | E20: 10000 | F20: 3
B21: 1 | C21: HW356057 | D21: 20 | E21: 10000 | F21: 3
B22: 2 | C22: HW356054 | D22: 20 | E22: 10000 | F22: 3
B23: 3 | C23: HW356060 | D23: 20 | E23: 10000 | F23: 3
B24: 4 | C24: HW356064 | D24: 20 | E24: 10000 | F24: 3
B25: 5 | C25: HW356071 | D25: 20 | E25: 10000 | F25: 3
B26: 6 | C26: HW356009-P1 | D26: 20 | E26: 10000 | F26: 3
B27: 7 | C27: HW356016 | D27: 20 | E27: 10000 | F27: 3
B28: 8 | C28: HW356070 | D28: 20 | E28: 10000 | F28: 3
A30: Ⅲ | B30: Compounds Storage.
B32: All test compounds are provided by湖北生物医药产业技术研究院有限公司, and storaged in ICE.
A34: Ⅳ | B34: Reaction conditions
B36: Reaction ID | C36: WRN (517-1238) | D36: ATP | E36: dsDNA-secquence 2 | F36: capture DNA
B37: Work Conc. | C37: 5 nM | D37: 4 mM | E37: 100 nM | F37: 1 μM
A39: Ⅴ | B39: Experiment Procedure
A41: a) | B41: Add 60 μL compounds to 384-well dilution plate
A42: b) | B42: Dilute compounds 1:3 in succession in DMSO for each column for 10 pts (refer to dilution plate map)
A43: c) | B43: Transfer 0.15 μL diluted compounds solution in each row to 384 assay plate using Echo, each column containing 2 replicates (refer to assay plate map)
A44: d) | B44: Add 5 μL enzyme working solution containing 0.2 mM ATP to 384-well assay plate, and centrifuge at 1000 rpm for 1 min
A45: e) | B45: Incubate at 25℃ for 4 h
A46: f) | B46: Add 5 μL dsDNA-secquence 2 and capture DNA working solution, and centrifuge at 1000 rpm for 1 min
A47: g) | B47: Add 5 μL ATP working solution to initiate reaction , and centrifuge at 1000 rpm for 1 min
A48: h) | B48: Incubate at 25℃ for 30 min
A49: i) | B49: Reading Ex620 nm and Em685 nm fluorescence signals with BMG
A51: VI | B51: Data Analysis
...

Sheet Raw data analysis
A3: Assay platemap | B3: 1 | C3: 2 | D3: 3 | E3: 4 | F3: 5 | G3: 6 | H3: 7 | I3: 8 | J3: 9 | K3: 10 | L3: 11 | M3: 12 | N3: 13 | O3: 14 | P3: 15 | Q3: 16 | R3: 17 | S3: 18 | T3: 19 | U3: 20 | V3: 21 | W3: 22 | X3: 23 | Y3: 24
A4: A | B4: Low Control | C4: Ref | D4: 10 points | M4: High Control | N4: Low Control | O4: Cmpd-8 | P4: 10 points | Y4: High Control
A5: B | B5: Low Control | M5: High Control | N5: Low Control | Y5: High Control
A6: C | B6: Low Control | C6: Cmpd-1 | D6: 10 points | M6: High Control
A7: D | B7: Low Control | M7: High Control
A8: E | B8: Low Control | C8: Cmpd-2 | D8: 10 points | M8: High Control
A9: F | B9: Low Control | M9: High Control
A10: G | B10: Low Control | C10: Cmpd-3 | D10: 10 points | M10: High Control
A11: H | B11: Low Control | M11: High Control
A12: I | B12: Low Control | C12: Cmpd-4 | D12: 10 points | M12: High Control
A13: J | B13: Low Control | M13: High Control
A14: K | B14: Low Control | C14: Cmpd-5 | D14: 10 points | M14: High Control
A15: L | B15: Low Control | M15: High Control
A16: M | B16: Low Control | C16: Cmpd-6 | D16: 10 points | M16: High Control
A17: N | B17: Low Control | M17: High Control
A18: O | B18: Low Control | C18: Cmpd-7 | D18: 10 points | M18: High Control
A19: P | B19: Low Control | M19: High Control
A21: Raw data | B21: 1 | C21: 2 | D21: 3 | E21: 4 | F21: 5 | G21: 6 | H21: 7 | I21: 8 | J21: 9 | K21: 10 | L21: 11 | M21: 12 | N21: 13 | O21: 14 | P21: 15 | Q21: 16 | R21: 17 | S21: 18 | T21: 19 | U21: 20 | V21: 21 | W21: 22 | X21: 23 | Y21: 24
A22: A | B22: 4402 | C22: 5785 | D22: 7099 | E22: 9251 | F22: 11861 | G22: 20044 | H22: 26369 | I22: 33594 | J22: 35686 | K22: 38656 | L22: 36632 | M22: 33110 | N22: 4356 | O22: 9144 | P22: 9757 | Q22: 14102 | R22: 19846 | S22: 26321 | T22: 33253 | U22: 35471 | V22: 37695 | W22: 39810 | X22: 34674 | Y22: 35623
A23: B | B23: 4276 | C23: 5922 | D23: 7573 | E23: 9404 | F23: 12025 | G23: 19296 | H23: 26801 | I23: 32195 | J23: 35074 | K23: 35285 | L23: 37771 | M23: 32206 | N23: 4300 | O23: 9480 | P23: 10108 | Q23: 14821 | R23: 21006 | S23: 28399 | T23: 33586 | U23: 34652 | V23: 37662 | W23: 36968 | X23: 35395 | Y23: 32909
A24: C | B24: 4250 | C24: 10462 | D24: 13352 | E24: 15753 | F24: 25646 | G24: 26480 | H24: 34462 | I24: 35330 | J24: 34170 | K24: 35969 | L24: 34959 | M24: 35278
A25: D | B25: 4493 | C25: 11083 | D25: 14849 | E25: 19122 | F25: 24247 | G25: 30622 | H25: 37157 | I25: 37225 | J25: 36620 | K25: 35925 | L25: 35711 | M25: 32150
A26: E | B26: 4304 | C26: 10831 | D26: 10285 | E26: 11470 | F26: 17413 | G26: 24052 | H26: 31382 | I26: 33762 | J26: 34754 | K26: 34668 | L26: 34804 | M26: 33611
A27: F | B27: 4109 | C27: 10594 | D27: 9426 | E27: 11395 | F27: 15529 | G27: 22723 | H27: 28954 | I27: 31410 | J27: 32394 | K27: 34862 | L27: 33080 | M27: 33640
A28: G | B28: 4350 | C28: 8266 | D28: 8704 | E28: 11680 | F28: 15354 | G28: 21069 | H28: 27795 | I28: 29917 | J28: 30881 | K28: 32408 | L28: 30908 | M28: 34574
A29: H | B29: 4199 | C29: 8176 | D29: 8921 | E29: 11134 | F29: 17769 | G29: 26152 | H29: 26809 | I29: 31332 | J29: 33033 | K29: 34217 | L29: 33378 | M29: 31068
A30: I | B30: 4290 | C30: 5806 | D30: 7463 | E30: 9480 | F30: 13579 | G30: 22628 | H30: 31582 | I30: 32373 | J30: 30380 | K30: 31930 | L30: 31912 | M30: 28022
A31: J | B31: 4246 | C31: 5771 | D31: 7335 | E31: 10316 | F31: 13387 | G31: 22319 | H31: 27410 | I31: 33543 | J31: 33169 | K31: 34672 | L31: 35022 | M31: 33207
A32: K | B32: 4353 | C32: 9041 | D32: 9742 | E32: 11648 | F32: 18214 | G32: 26623 | H32: 31893 | I32: 34965 | J32: 34231 | K32: 35874 | L32: 36187 | M32: 31892
A33: L | B33: 4194 | C33: 9014 | D33: 9207 | E33: 11951 | F33: 19288 | G33: 27149 | H33: 29293 | I33: 36898 | J33: 33785 | K33: 37818 | L33: 34875 | M33: 33932
A34: M | B34: 4312 | C34: 9006 | D34: 9423 | E34: 11510 | F34: 15987 | G34: 27428 | H34: 32755 | I34: 34897 | J34: 35631 | K34: 35838 | L34: 35591 | M34: 31897
A35: N | B35: 4300 | C35: 8927 | D35: 9387 | E35: 11379 | F35: 19262 | G35: 27124 | H35: 30962 | I35: 35815 | J35: 34881 | K35: 38386 | L35: 33195 | M35: 33004
... A37: P | B37: 4361 | C37: 10779 | D37: 13169 | E37: 19616 | F37: 27403 | G37: 30263 | H37: 34098 | I37: 38201 | J37: 34840 | K37: 39320 | L37: 35135 | M37: 33704
B38: AVE | C38: SD | D38: CV | E38: Z' | F38: S/B
A39: Low Control | B39: =AVERAGE(B22:B37,N22:N23) -> 4300.2778 | C39: =STDEVP(B22:B37,N22:N23) -> 83.028647 | D39: =C39/B39 -> 0.01930774 | E39: =1-3*(C39+C40)/(B40-B39) -> 0.81808733 | F39: =B40/B39 -> 7.6531361
A40: High Control | B40: =AVERAGE(M22:M37,Y22:Y23) -> 32910.611 | C40: =STDEVP(M22:M37,Y22:Y23) -> 1651.832 | D40: =C40/B40 -> 0.050191472
A42: Inhibition | B42: 1 | C42: 2 | D42: 3 | E42: 4 | F42: 5 | G42: 6 | H42: 7 | I42: 8 | J42: 9 | K42: 10 | L42: 11 | M42: 12 | N42: 13 | O42: 14 | P42: 15 | Q42: 16 | R42: 17 | S42: 18 | T42: 19 | U42: 20 | V42: 21 | W42: 22 | X42: 23 | Y42: 24
A43: ='Assay summary'!C2 -> HW350003A | C43: =($B$40-C22)/($B$40-$B$39)*100 -> 94.810539 | D43: =($B$40-D22)/($B$40-$B$39)*100 -> 90.217792 | E43: =($B$40-E22)/($B$40-$B$39)*100 -> 82.696034 | F43: =($B$40-F22)/($B$40-$B$39)*100 -> 73.573456 | G43: =($B$40-G22)/($B$40-$B$39)*100 -> 44.971902 | H43: =($B$40-H22)/($B$40-$B$39)*100 -> 22.864505 | I43: =($B$40-I22)/($B$40-$B$39)*100 -> -2.3886086 | J43: =($B$40-J22)/($B$40-$B$39)*100 -> -9.7006521 | ... L43: =($B$40-L22)/($B$40-$B$39)*100 -> -13.00715 | N43: ='Assay summary'!C10 -> HW356070 | O43: =($B$40-O22)/($B$40-$B$39)*100 -> 83.070025 | P43: =($B$40-P22)/($B$40-$B$39)*100 -> 80.927443 | Q43: =($B$40-Q22)/($B$40-$B$39)*100 -> 65.740622 | R43: =($B$40-R22)/($B$40-$B$39)*100 -> 45.66396 | S43: =($B$40-S22)/($B$40-$B$39)*100 -> 23.032277 | T43: =($B$40-T22)/($B$40-$B$39)*100 -> -1.1967316 | U43: =($B$40-U22)/($B$40-$B$39)*100 -> -8.9491753 | V43: =($B$40-V22)/($B$40-$B$39)*100 -> -16.722591 | ... X43: =($B$40-X22)/($B$40-$B$39)*100 -> -6.1634685
C44: =($B$40-C23)/($B$40-$B$39)*100 -> 94.331691 | D44: =($B$40-D23)/($B$40-$B$39)*100 -> 88.561048 | E44: =($B$40-E23)/($B$40-$B$39)*100 -> 82.161263 | F44: =($B$40-F23)/($B$40-$B$39)*100 -> 73.000237 | G44: =($B$40-G23)/($B$40-$B$39)*100 -> 47.586342 | H44: =($B$40-H23)/($B$40-$B$39)*100 -> 21.354561 | I44: =($B$40-I23)/($B$40-$B$39)*100 -> 2.501233 | J44: =($B$40-J23)/($B$40-$B$39)*100 -> -7.5615648 | ... L44: =($B$40-L23)/($B$40-$B$39)*100 -> -16.988229 | O44: =($B$40-O23)/($B$40-$B$39)*100 -> 81.895624 | P44: =($B$40-P23)/($B$40-$B$39)*100 -> 79.700613 | Q44: =($B$40-Q23)/($B$40-$B$39)*100 -> 63.227544 | R44: =($B$40-R23)/($B$40-$B$39)*100 -> 41.609481 | S44: =($B$40-S23)/($B$40-$B$39)*100 -> 15.769167 | T44: =($B$40-T23)/($B$40-$B$39)*100 -> -2.3606467 | U44: =($B$40-U23)/($B$40-$B$39)*100 -> -6.0865732 | V44: =($B$40-V23)/($B$40-$B$39)*100 -> -16.607248 | ... X44: =($B$40-X23)/($B$40-$B$39)*100 -> -8.683537
A45: ='Assay summary'!C3 -> HW356057 | C45: =($B$40-C24)/($B$40-$B$39)*100 -> 78.463298 | D45: =($B$40-D24)/($B$40-$B$39)*100 -> 68.362053 | E45: =($B$40-E24)/($B$40-$B$39)*100 -> 59.96998 | F45: =($B$40-F24)/($B$40-$B$39)*100 -> 25.391564 | G45: =($B$40-G24)/($B$40-$B$39)*100 -> 22.476533 | H45: =($B$40-H24)/($B$40-$B$39)*100 -> -5.4224775 | I45: =($B$40-I24)/($B$40-$B$39)*100 -> -8.4563464 | J45: =($B$40-J24)/($B$40-$B$39)*100 -> -4.4018672 | ... L45: =($B$40-L24)/($B$40-$B$39)*100 -> -7.1596121
...

Sheet Raw data
A3: User: Enzyme-LT
A4: Path: C:\Program Files (x86)\BMG\CLARIOstar\Enzyme-LT\Data
A5: Test ID: 11395
A6: Test Name: wrn fi
A7: Date: 2025/3/25
A8: Time: 15:57:15
A9: Fluorescence (FI)
B13: Raw Data (620-15/685-20)
B14: 1 | C14: 2 | D14: 3 | E14: 4 | F14: 5 | G14: 6 | H14: 7 | I14: 8 | J14: 9 | K14: 10 | L14: 11 | M14: 12 | N14: 13 | O14: 14 | P14: 15 | Q14: 16 | R14: 17 | S14: 18 | T14: 19 | U14: 20 | V14: 21 | W14: 22 | X14: 23 | Y14: 24
A15: A | B15: 4402 | C15: 5785 | D15: 7099 | E15: 9251 | F15: 11861 | G15: 20044 | H15: 26369 | I15: 33594 | J15: 35686 | K15: 38656 | L15: 36632 | M15: 33110 | N15: 4356 | O15: 9144 | P15: 9757 | Q15: 14102 | R15: 19846 | S15: 26321 | T15: 33253 | U15: 35471 | V15: 37695 | W15: 39810 | X15: 34674 | Y15: 35623
A16: B | B16: 4276 | C16: 5922 | D16: 7573 | E16: 9404 | F16: 12025 | G16: 19296 | H16: 26801 | I16: 32195 | J16: 35074 | K16: 35285 | L16: 37771 | M16: 32206 | N16: 4300 | O16: 9480 | P16: 10108 | Q16: 14821 | R16: 21006 | S16: 28399 | T16: 33586 | U16: 34652 | V16: 37662 | W16: 36968 | X16: 35395 | Y16: 32909
A17: C | B17: 4250 | C17: 10462 | D17: 13352 | E17: 15753 | F17: 25646 | G17: 26480 | H17: 34462 | I17: 35330 | J17: 34170 | K17: 35969 | L17: 34959 | M17: 35278
A18: D | B18: 4493 | C18: 11083 | D18: 14849 | E18: 19122 | F18: 24247 | G18: 30622 | H18: 37157 | I18: 37225 | J18: 36620 | K18: 35925 | L18: 35711 | M18: 32150
A19: E | B19: 4304 | C19: 10831 | D19: 10285 | E19: 11470 | F19: 17413 | G19: 24052 | H19: 31382 | I19: 33762 | J19: 34754 | K19: 34668 | L19: 34804 | M19: 33611
A20: F | B20: 4109 | C20: 10594 | D20: 9426 | E20: 11395 | F20: 15529 | G20: 22723 | H20: 28954 | I20: 31410 | J20: 32394 | K20: 34862 | L20: 33080 | M20: 33640
A21: G | B21: 4350 | C21: 8266 | D21: 8704 | E21: 11680 | F21: 15354 | G21: 21069 | H21: 27795 | I21: 29917 | J21: 30881 | K21: 32408 | L21: 30908 | M21: 34574
A22: H | B22: 4199 | C22: 8176 | D22: 8921 | E22: 11134 | F22: 17769 | G22: 26152 | H22: 26809 | I22: 31332 | J22: 33033 | K22: 34217 | L22: 33378 | M22: 31068
A23: I | B23: 4290 | C23: 5806 | D23: 7463 | E23: 9480 | F23: 13579 | G23: 22628 | H23: 31582 | I23: 32373 | J23: 30380 | K23: 31930 | L23: 31912 | M23: 28022
A24: J | B24: 4246 | C24: 5771 | D24: 7335 | E24: 10316 | F24: 13387 | G24: 22319 | H24: 27410 | I24: 33543 | J24: 33169 | K24: 34672 | L24: 35022 | M24: 33207
A25: K | B25: 4353 | C25: 9041 | D25: 9742 | E25: 11648 | F25: 18214 | G25: 26623 | H25: 31893 | I25: 34965 | J25: 34231 | K25: 35874 | L25: 36187 | M25: 31892
A26: L | B26: 4194 | C26: 9014 | D26: 9207 | E26: 11951 | F26: 19288 | G26: 27149 | H26: 29293 | I26: 36898 | J26: 33785 | K26: 37818 | L26: 34875 | M26: 33932
A27: M | B27: 4312 | C27: 9006 | D27: 9423 | E27: 11510 | F27: 15987 | G27: 27428 | H27: 32755 | I27: 34897 | J27: 35631 | K27: 35838 | L27: 35591 | M27: 31897
A28: N | B28: 4300 | C28: 8927 | D28: 9387 | E28: 11379 | F28: 19262 | G28: 27124 | H28: 30962 | I28: 35815 | J28: 34881 | K28: 38386 | L28: 33195 | M28: 33004
... A30: P | B30: 4361 | C30: 10779 | D30: 13169 | E30: 19616 | F30: 27403 | G30: 30263 | H30: 34098 | I30: 38201 | J30: 34840 | K30: 39320 | L30: 35135 | M30: 33704

Sheet Compound information
B1: 北京爱思益普生物科技股份有限公司 ICE Bioscience Inc. NRF001V1.0
A2: 化合物信息单 Compound Information Sheet
A3: 专题编号 Study No.* | E3: 委托方 Sponsor* | F3: 湖北生物医药产业技术研究院有限公司 | N3: 是否申报 Application or not* | P3: 否
A4: 名称 Name* | B4: 质量(mg)/ 体积(µL)* | C4: 分子量MW* | D4: 纯度 Purity* | E4: 批号 Batch No. | F4: 溶媒 Solvent | G4: 保存条件Storage Condition* | H4: 样品性状Characters | I4: 样品性质Compound Property | J4: 有效期 Exp. Date | K4: 检测靶点 Test Targets* | L4: 重复例数Test Repetition* | M4: 检测浓度 Test Concentration* | N4: 备注 Comment | O4: 储液浓度 Storage Concentration | P4: 溶剂使用量Solvent μL
A5: HW356057 | B5: 2.36 | C5: 568.15 | D5: 1 | E5: HWH817-LHX-35-143 | O5: 20 mM | P5: =B5/C5*D5/20*1000000 -> 207.69163
A6: HW356054 | B6: 2.58 | C6: 574.12 | D6: 1 | E6: HWH817-XQ-35-6054 | O6: 20 mM | P6: =B6/C6*D6/20*1000000 -> 224.6917
A7: HW356060 | B7: 2.65 | C7: 602.64 | D7: 0.9782 | E7: HWH817-YBC-035-4-38-1 | O7: 20 mM | P7: =B7/C7*D7/20*1000000 -> 215.07285
A8: HW356064 | B8: 2.41 | C8: 570.14 | D8: 0.991 | E8: HWH817-XQ-35-6064 | O8: 20 mM | P8: =B8/C8*D8/20*1000000 -> 209.44943
A9: HW356071 | B9: 2.61 | C9: 588.13 | D9: 0.9362 | E9: HWH817-LHX-35-0311 | O9: 20 mM | P9: =B9/C9*D9/20*1000000 -> 207.73315
A10: HW356009-P1 | B10: 2.43 | C10: 603.63 | D10: 0.9748 | E10: HWH817-YBC-035-4-54-2 | O10: 20 mM | P10: =B10/C10*D10/20*1000000 -> 196.20993
A11: HW356016 | B11: 2.22 | C11: 536.15 | D11: 0.992 | E11: HWH817-XQ-35-6016 | O11: 20 mM | P11: =B11/C11*D11/20*1000000 -> 205.37536
A12: HW356070 | B12: 2.62 | C12: 576.13 | D12: 0.9713 | E12: HWH817-LHX-35-0310 | O12: 20 mM | P12: =B12/C12*D12/20*1000000 -> 220.85345
A16: 接受人/日期 Recipient/Date | H16: 检查人/日期 Checker/Date
A17: 注： 1.*号为必填内容/* is required；2.溶媒默认DMSO/The solvent defaults to DMSO；3.保存条件默认粉末类2~8℃，溶液类-25~-15℃存储/The storage condition defaults to 2~8℃ for powder and -25~-15℃ for solution； 4.样品性质请填写：小分子、肽类、蛋白类、大分子、混合物/提取物或其他类型，如不填，默认小分子Sample Property: small molecule, peptide, protein, macromolecule, mixture/extract or other type. If don't fill in, it will be small molecule by default.
