Workbook

Sheet Signature
B4: Study Report
B8: Assay Name | C8: WRN(517-1238)_ATP preincubation_FI_IC50
B9: Assay Goal | C9: To assess the compounds inhibition on WRN (517-1238)_ATP preincubation
B10: Study Number | C10: RFP-2024121601
B12: Experiment Type | C12: 10 doses in duplicate, IC50
B13: Samples Receive Date | C13: 45642
B14: Experiment Date | C14: 45642
B15: Report Release Date | C15: 45642
B17: Assay Performed by | C17: Jialong Ma
B18: Report Prepared by | C18: Jialong Ma
B19: Report reviewer | C19: Mingzhen Li
B20: Report Approval | C20: Qiang Xia
B24: Submitted to | C24: 湖北生物医药产业技术研究院有限公司
B26: Submitted by | C26: ICE Bioscience InC.

Sheet Assay summary
A1: Assay date | B1: Assay name | C1: Compounds ID | D1: Bottom | E1: Top | F1: IC50 (nM) | G1: Hillslope | H1: Comments | J1: SOP # | K1: Scientist
A2: 2024/12/16 | B2: WRN(517-1238) in FI assay_ATP preincubation | C2: ='Assay protocol'!C20 -> HW350003A | D2: =OFFSET(INDEX('Raw data analysis'!B:B,MATCH(C2,'Raw data analysis'!B:B,0)),2,5) -> -9.0437624 | E2: =OFFSET(INDEX('Raw data analysis'!B:B,MATCH(C2,'Raw data analysis'!B:B,0)),2,6) -> 97.823728 | F2: =OFFSET(INDEX('Raw data analysis'!B:B,MATCH(C2,'Raw data analysis'!B:B,0)),2,7) -> 40.062011 | G2: =OFFSET(INDEX('Raw data analysis'!B:B,MATCH(C2,'Raw data analysis'!B:B,0)),2,8) -> 0.94346586 | H2: Reference | I2: Compound state | J2: SOP-BA-1240 | K2: Jialong Ma
C3: ='Assay protocol'!C21 -> HW356058 | D3: =OFFSET(INDEX('Raw data analysis'!B:B,MATCH(C3,'Raw data analysis'!B:B,0)),2,5) -> -4.6930525 | E3: =OFFSET(INDEX('Raw data analysis'!B:B,MATCH(C3,'Raw data analysis'!B:B,0)),2,6) -> 89.328301 | F3: =OFFSET(INDEX('Raw data analysis'!B:B,MATCH(C3,'Raw data analysis'!B:B,0)),2,7) -> 262.13506 | G3: =OFFSET(INDEX('Raw data analysis'!B:B,MATCH(C3,'Raw data analysis'!B:B,0)),2,8) -> 1.1132131 | H3: / | I3: clear
C4: ='Assay protocol'!C22 -> HW356035 | D4: =OFFSET(INDEX('Raw data analysis'!B:B,MATCH(C4,'Raw data analysis'!B:B,0)),2,5) -> -7.8828639 | E4: =OFFSET(INDEX('Raw data analysis'!B:B,MATCH(C4,'Raw data analysis'!B:B,0)),2,6) -> 108.84837 | F4: =OFFSET(INDEX('Raw data analysis'!B:B,MATCH(C4,'Raw data analysis'!B:B,0)),2,7) -> 1968.8678 | G4: =OFFSET(INDEX('Raw data analysis'!B:B,MATCH(C4,'Raw data analysis'!B:B,0)),2,8) -> 0.82969978 | H4: / | I4: clear
C5: ='Assay protocol'!C23 -> HW356057 | D5: =OFFSET(INDEX('Raw data analysis'!B:B,MATCH(C5,'Raw data analysis'!B:B,0)),2,5) -> -11.797553 | E5: =OFFSET(INDEX('Raw data analysis'!B:B,MATCH(C5,'Raw data analysis'!B:B,0)),2,6) -> 96.462061 | F5: =OFFSET(INDEX('Raw data analysis'!B:B,MATCH(C5,'Raw data analysis'!B:B,0)),2,7) -> 89.279738 | G5: =OFFSET(INDEX('Raw data analysis'!B:B,MATCH(C5,'Raw data analysis'!B:B,0)),2,8) -> 1.0035513 | H5: / | I5: clear
C6: ='Assay protocol'!C24 -> HW356061 | D6: =OFFSET(INDEX('Raw data analysis'!B:B,MATCH(C6,'Raw data analysis'!B:B,0)),2,5) -> -14.607027 | E6: =OFFSET(INDEX('Raw data analysis'!B:B,MATCH(C6,'Raw data analysis'!B:B,0)),2,6) -> 82.988813 | F6: =OFFSET(INDEX('Raw data analysis'!B:B,MATCH(C6,'Raw data analysis'!B:B,0)),2,7) -> 128.54071 | G6: =OFFSET(INDEX('Raw data analysis'!B:B,MATCH(C6,'Raw data analysis'!B:B,0)),2,8) -> 0.83877709 | H6: / | I6: clear
C7: ='Assay protocol'!C25 -> HW356064 | D7: =OFFSET(INDEX('Raw data analysis'!B:B,MATCH(C7,'Raw data analysis'!B:B,0)),2,5) -> -11.942375 | E7: =OFFSET(INDEX('Raw data analysis'!B:B,MATCH(C7,'Raw data analysis'!B:B,0)),2,6) -> 97.473554 | F7: =OFFSET(INDEX('Raw data analysis'!B:B,MATCH(C7,'Raw data analysis'!B:B,0)),2,7) -> 102.90875 | G7: =OFFSET(INDEX('Raw data analysis'!B:B,MATCH(C7,'Raw data analysis'!B:B,0)),2,8) -> 0.98949404 | H7: / | I7: clear

Sheet Assay protocol
A2: Ⅰ | B2: Reagent, Consumables and Instruments
B4: Reagent | C4: Vendor | D4: Cat No.
B5: capture DNA | C5: ICE | D5: ICE-WDU-114
B6: dsDNA-secquence 2 | C6: ICE | D6: ICE-WDU-113
B7: WRN (517-1238) | C7: ICE | D7: S2212T-H56HZ
B8: ATP | C8: Ark Pharm | D8: Ak-54737
B9: Consumables | C9: Vendor | D9: Cat No.
B10: 96 Well Plates | C10: Nunc | D10: 249944
B11: 384-well plate | C11: Corning | D11: 4514
B12: Instrument | C12: Vendor | D12: Cat No.
B13: ECHO®655 SYSTEM | C13: LABCYTE | D13: 655
B14: Centrifuge | C14: Cence | D14: TDZ5-WS
B15: Microplate Reader | C15: BMG | D15: CLARIO Star Plusacu
A17: Ⅱ | B17: Compound Information and Treatment
B19: Entry | C19: Compound ID | D19: Stock Conc. (mM) | E19: Start Conc. (nM) | F19: Dilution folds
B20: R | C20: HW350003A | D20: 10 | E20: 10000 | F20: 3
B21: 1 | C21: HW356058 | D21: 10 | E21: 10000 | F21: 3
B22: 2 | C22: HW356035 | D22: 10 | E22: 10000 | F22: 3
B23: 3 | C23: HW356057 | D23: 10 | E23: 10000 | F23: 3
B24: 4 | C24: HW356061 | D24: 10 | E24: 10000 | F24: 3
B25: 5 | C25: HW356064 | D25: 10 | E25: 10000 | F25: 3
A27: Ⅲ | B27: Compounds Storage.
B29: All test compounds are provided by湖北生物医药产业技术研究院有限公司, and storaged in ICE.
A31: Ⅳ | B31: Reaction conditions
B33: Reaction ID | C33: WRN (517-1238) | D33: ATP | E33: dsDNA-secquence 2 | F33: capture DNA
B34: Work Conc. | C34: 5 nM | D34: 4 mM | E34: 100 nM | F34: 1 μM
A36: Ⅴ | B36: Experiment Procedure
A38: a) | B38: Add 60 μL compounds to 384-well dilution plate
A39: b) | B39: Dilute compounds 1:4 in succession in DMSO for each column for 10 pts (refer to dilution plate map)
A40: c) | B40: Transfer 0.15 μL diluted compounds solution in each row to 384 assay plate using Echo, each column containing 2 replicates (refer to assay plate map)
A41: d) | B41: Add 5 μL enzyme working solution containing 0.2 mM ATP to 384-well assay plate, and centrifuge at 1000 rpm for 1 min
A42: e) | B42: Incubate at 25℃ for 4 h
A43: f) | B43: Add 5 μL dsDNA-secquence 2 and capture DNA working solution, and centrifuge at 1000 rpm for 1 min
A44: g) | B44: Add 5 μL ATP working solution to initiate reaction , and centrifuge at 1000 rpm for 1 min
A45: h) | B45: Incubate at 25℃ for 30 min
A46: i) | B46: Reading Ex620 nm and Em685 nm fluorescence signals with BMG
A48: VI | B48: Data Analysis
A50: a) | B50: Percent inhibition(% inh) for compound well = 100*(ave High control - cpd well)/(ave High control - ave Low control)
A51: b) | B51: Assay robustness check with Low control and High control data:
B52: High control: DMSO and Enzyme
...

Sheet Raw data analysis
A3: Assay platemap | B3: 1 | C3: 2 | D3: 3 | E3: 4 | F3: 5 | G3: 6 | H3: 7 | I3: 8 | J3: 9 | K3: 10 | L3: 11 | M3: 12 | N3: 13 | O3: 14 | P3: 15 | Q3: 16 | R3: 17 | S3: 18 | T3: 19 | U3: 20 | V3: 21 | W3: 22 | X3: 23 | Y3: 24
A4: A | B4: Low Control | C4: Ref | D4: 10 points | M4: High Control
A5: B | B5: Low Control | M5: High Control
A6: C | B6: Low Control | C6: Cmpd-1 | D6: 10 points | M6: High Control
A7: D | B7: Low Control | M7: High Control
A8: E | B8: Low Control | C8: Cmpd-2 | D8: 10 points | M8: High Control
A9: F | B9: Low Control | M9: High Control
A10: G | B10: Low Control | C10: Cmpd-3 | D10: 10 points | M10: High Control
A11: H | B11: Low Control | M11: High Control
A12: I | B12: Low Control | C12: Cmpd-4 | D12: 10 points | M12: High Control
A13: J | B13: Low Control | M13: High Control
A14: K | B14: Low Control | C14: Cmpd-5 | D14: 10 points | M14: High Control
A15: L | B15: Low Control | M15: High Control
A16: M
A17: N
A18: O
A19: P
A21: Raw data | B21: 1 | C21: 2 | D21: 3 | E21: 4 | F21: 5 | G21: 6 | H21: 7 | I21: 8 | J21: 9 | K21: 10 | L21: 11 | M21: 12 | N21: 13 | O21: 14 | P21: 15 | Q21: 16 | R21: 17 | S21: 18 | T21: 19 | U21: 20 | V21: 21 | W21: 22 | X21: 23 | Y21: 24
A22: A | B22: 4712 | C22: 5443 | D22: 7030 | E22: 9849 | F22: 12861 | G22: 21328 | H22: 37237 | I22: 49370 | J22: 58978 | K22: 24828 | L22: 64723 | M22: 61917
A23: B | B23: 4854 | C23: 5494 | D23: 7432 | E23: 9852 | F23: 13155 | G23: 20955 | H23: 36078 | I23: 52362 | J23: 61943 | K23: 64748 | L23: 67402 | M23: 62961
A24: C | B24: 4776 | C24: 12753 | D24: 12716 | E24: 19110 | F24: 32550 | G24: 48799 | H24: 55075 | I24: 61352 | J24: 60832 | K24: 67215 | L24: 66256 | M24: 59365
A25: D | B25: 4972 | C25: 13199 | D25: 12993 | E25: 20665 | F25: 33423 | G25: 49067 | H25: 61189 | I25: 65182 | J25: 62585 | K25: 63226 | L25: 66662 | M25: 63236
A26: E | B26: 4852 | C26: 13750 | D26: 24710 | E26: 40471 | F26: 53626 | G26: 64082 | H26: 63882 | I26: 62374 | J26: 64851 | K26: 65842 | L26: 65863 | M26: 62075
A27: F | B27: 4839 | C27: 14208 | D27: 25394 | E27: 43828 | F27: 50943 | G27: 60651 | H27: 60580 | I27: 65985 | J27: 67612 | K27: 67840 | L27: 69944 | M27: 64076
A28: G | B28: 4706 | C28: 6974 | D28: 9181 | E28: 11835 | F28: 18596 | G28: 33083 | H28: 4911 | I28: 60828 | J28: 68779 | K28: 68733 | L28: 69292 | M28: 63540
A29: H | B29: 4849 | C29: 6951 | D29: 8896 | E29: 11417 | F29: 19142 | G29: 32252 | H29: 49583 | I29: 5018 | J29: 61951 | K29: 67170 | L29: 68036 | M29: 62646
A30: I | B30: 4840 | C30: 15370 | D30: 34684 | E30: 23876 | F30: 30070 | G30: 46866 | H30: 53000 | I30: 61351 | J30: 67440 | K30: 5008 | L30: 69593 | M30: 59393
A31: J | B31: 5173 | C31: 17457 | D31: 35293 | E31: 21418 | F31: 27398 | G31: 45802 | H31: 5071 | I31: 64058 | J31: 68138 | K31: 4984 | L31: 70549 | M31: 62755
A32: K | B32: 5118 | C32: 7380 | D32: 9744 | E32: 12404 | F32: 19448 | G32: 34812 | H32: 50279 | I32: 60470 | J32: 67051 | K32: 68167 | L32: 4955 | M32: 62144
A33: L | B33: 5251 | C33: 7463 | D33: 10036 | E33: 5047 | F33: 22210 | G33: 36841 | H33: 5008 | I33: 61065 | J33: 67152 | K33: 65898 | L33: 69353 | M33: 61198
A34: M
A35: N
A36: O
A37: P
C38: SD | D38: CV | E38: Z' | F38: S/B
A39: AVE(Low Control) | B39: =AVERAGE(B22:B37) -> 4911.8333 | C39: =STDEVP(B22:B37) -> 171.13729 | D39: =C39/B39 -> 0.034841836 | E39: =1-3*(C39+C40)/(B40-B39) -> 0.9162416 | F39: =B40/B39 -> 12.644736
A40: AVE(High Control) | B40: =AVERAGE(M22:M37) -> 62108.833 | C40: =STDEVP(M22:M37) -> 1425.7725 | D40: =C40/B40 -> 0.022956034
A42: Inhibition | B42: 1 | C42: 2 | D42: 3 | E42: 4 | F42: 5 | G42: 6 | H42: 7 | I42: 8 | J42: 9 | K42: 10 | L42: 11 | M42: 12 | N42: 13 | O42: 14 | P42: 15 | Q42: 16 | R42: 17 | S42: 18 | T42: 19 | U42: 20 | V42: 21 | W42: 22 | X42: 23 | Y42: 24
A43: ='Assay summary'!C2 -> HW350003A | C43: =($B$40-C22)/($B$40-$B$39)*100 -> 99.071338 | D43: =($B$40-D22)/($B$40-$B$39)*100 -> 96.296717 | E43: =($B$40-E22)/($B$40-$B$39)*100 -> 91.368137 | F43: =($B$40-F22)/($B$40-$B$39)*100 -> 86.102127 | G43: =($B$40-G22)/($B$40-$B$39)*100 -> 71.298903 | H43: =($B$40-H22)/($B$40-$B$39)*100 -> 43.484507 | I43: =($B$40-I22)/($B$40-$B$39)*100 -> 22.271856 | J43: =($B$40-J22)/($B$40-$B$39)*100 -> 5.4737719 | K43: 65.2* | L43: =($B$40-L22)/($B$40-$B$39)*100 -> -4.5704612
C44: =($B$40-C23)/($B$40-$B$39)*100 -> 98.982173 | D44: =($B$40-D23)/($B$40-$B$39)*100 -> 95.593883 | E44: =($B$40-E23)/($B$40-$B$39)*100 -> 91.362892 | F44: =($B$40-F23)/($B$40-$B$39)*100 -> 85.588114 | G44: =($B$40-G23)/($B$40-$B$39)*100 -> 71.951035 | H44: =($B$40-H23)/($B$40-$B$39)*100 -> 45.510837 | I44: =($B$40-I23)/($B$40-$B$39)*100 -> 17.040812 | J44: =($B$40-J23)/($B$40-$B$39)*100 -> 0.28993362 | ... L44: =($B$40-L23)/($B$40-$B$39)*100 -> -9.2542732
...

Sheet Raw data
A3: User: Enzyme-LT
A4: Path: C:\Program Files (x86)\BMG\CLARIOstar\Enzyme-LT\Data
A5: Test ID: 10723
A6: Test Name: wrn fi
A7: Date: 2024/12/16
A8: Time: 19:03:36
A9: Fluorescence (FI)
B13: Raw Data (620-15/685-20)
B14: 1 | C14: 2 | D14: 3 | E14: 4 | F14: 5 | G14: 6 | H14: 7 | I14: 8 | J14: 9 | K14: 10 | L14: 11 | M14: 12 | N14: 13 | O14: 14 | P14: 15 | Q14: 16 | R14: 17 | S14: 18 | T14: 19 | U14: 20 | V14: 21 | W14: 22 | X14: 23 | Y14: 24
A15: A | B15: 4712 | C15: 5443 | D15: 7030 | E15: 9849 | F15: 12861 | G15: 21328 | H15: 37237 | I15: 49370 | J15: 58978 | K15: 24828 | L15: 64723 | M15: 61917
A16: B | B16: 4854 | C16: 5494 | D16: 7432 | E16: 9852 | F16: 13155 | G16: 20955 | H16: 36078 | I16: 52362 | J16: 61943 | K16: 64748 | L16: 67402 | M16: 62961
A17: C | B17: 4776 | C17: 12753 | D17: 12716 | E17: 19110 | F17: 32550 | G17: 48799 | H17: 55075 | I17: 61352 | J17: 60832 | K17: 67215 | L17: 66256 | M17: 59365
A18: D | B18: 4972 | C18: 13199 | D18: 12993 | E18: 20665 | F18: 33423 | G18: 49067 | H18: 61189 | I18: 65182 | J18: 62585 | K18: 63226 | L18: 66662 | M18: 63236
A19: E | B19: 4852 | C19: 13750 | D19: 24710 | E19: 40471 | F19: 53626 | G19: 64082 | H19: 63882 | I19: 62374 | J19: 64851 | K19: 65842 | L19: 65863 | M19: 62075
A20: F | B20: 4839 | C20: 14208 | D20: 25394 | E20: 43828 | F20: 50943 | G20: 60651 | H20: 60580 | I20: 65985 | J20: 67612 | K20: 67840 | L20: 69944 | M20: 64076
A21: G | B21: 4706 | C21: 6974 | D21: 9181 | E21: 11835 | F21: 18596 | G21: 33083 | H21: 4911 | I21: 60828 | J21: 68779 | K21: 68733 | L21: 69292 | M21: 63540
A22: H | B22: 4849 | C22: 6951 | D22: 8896 | E22: 11417 | F22: 19142 | G22: 32252 | H22: 49583 | I22: 5018 | J22: 61951 | K22: 67170 | L22: 68036 | M22: 62646
A23: I | B23: 4840 | C23: 15370 | D23: 34684 | E23: 23876 | F23: 30070 | G23: 46866 | H23: 53000 | I23: 61351 | J23: 67440 | K23: 5008 | L23: 69593 | M23: 59393
A24: J | B24: 5173 | C24: 17457 | D24: 35293 | E24: 21418 | F24: 27398 | G24: 45802 | H24: 5071 | I24: 64058 | J24: 68138 | K24: 4984 | L24: 70549 | M24: 62755
A25: K | B25: 5118 | C25: 7380 | D25: 9744 | E25: 12404 | F25: 19448 | G25: 34812 | H25: 50279 | I25: 60470 | J25: 67051 | K25: 68167 | L25: 4955 | M25: 62144
A26: L | B26: 5251 | C26: 7463 | D26: 10036 | E26: 5047 | F26: 22210 | G26: 36841 | H26: 5008 | I26: 61065 | J26: 67152 | K26: 65898 | L26: 69353 | M26: 61198
A27: M
A28: N
A29: O
A30: P

Sheet Compound information
C3: 湖北生物医药产业技术研究院有限公司化合物样品送样单
C5: 送样人： （签名） | D5: 送样日期： （必填）
A7: 样品信息
A8: 化合物编号 （必填） | B8: 批号 | C8: 分子量（M.W) （必填） | D8: 纯度 | E8: 样品量（mg） | F8: 储液浓度(mM) | G8: 溶剂体积(μL)
A9: HW356058 | B9: HWH817-YBC-035-3-80-1 | C9: 535.58 | D9: 0.9743 | E9: 3.49 | F9: 10 | G9: 634.88312
A10: HW356035 | B10: 20241206 | C10: 471.45 | D10: 0.9487 | E10: 3.96 | F10: 10 | G10: 796.87178
A11: HW356057 | B11: HWH817-XQ-35-6057 | C11: 585.15 | D11: 0.987 | E11: 3.18 | F11: 10 | G11: 536.38554
A12: HW356061 | B12: HWH817-XQ-35-6061 | C12: 596.13 | D12: 0.94 | E12: 3.52 | F12: 10 | G12: 555.04672
A13: HW356064 | B13: HWH817-XQ-35-6064 | C13: 570.14 | D13: 0.991 | E13: 3.86 | F13: 10 | G13: 670.93345
B26: 接收单位
