Workbook

Sheet 封面
B1: 合肥中科普瑞昇生物医药科技有限公司
A5: 项目编号： | B5: D-RF-2024020702
A7: 化合物名称 | B7: HW356009
A9: 项目名称： | B9: 化合物HW356009在大鼠体内药代动力学研究
A11: 关键时间结点： | B11: 动物试验给药日期： 检测开始日期： 试验结束日期： 报告日期： | IW11: 2025-02-10 2025-02-11 2025-02-12 2025-02-12
A13: 试验承担单位 | B13: 负责人：邵杰 单位名称：合肥中科普瑞昇生物医药科技有限公司 地址：合肥市高新区孔雀台路与习友路交叉路口国家健康大数据产业园A6栋 联系方式：0551-62673491 Email：jshao@precedo.cn
A14: 委托单位 | B14: 负责人：刘勇 委托单位名称：人福医药 邮箱：liuyong@renfu.com 联系方式：18062052364
A15: 质控人员 | B15: 刘海宾
A16: 分析负责人 | B16: 奚冬冬
A17: 动物负责人 | B17: 卢秋宇

Sheet 结果汇总
B1: HW356009 PK 数据 | U1: HW356009 | Y1: 化合物信息和制剂配制
U2: 化合物信息
C3: 表1：单次静脉注射给予HW356009后大鼠血浆中药物浓度 | L3: 表2：单次灌胃口服给予HW356009后大鼠血浆中药物浓度 | V3: 化合物名称 | W3: HW356009
V4: 批号 | W4: HWH817-LHX-35-151
C5: =封面!B7 -> HW356009 | L5: =C5 -> HW356009 | V5: 分子量 | W5: 603.14
C6: IV-1 mg/kg | L6: PO-10 mg/kg | V6: 纯度 | W6: 0.971
C7: Time (h) | D7: 1 | E7: 2 | F7: 3 | G7: Mean | H7: SD | L7: Time (h) | M7: 4 | N7: 5 | O7: 6 | P7: Mean | Q7: SD | U7: PK研究基本信息
C8: 0.0833 | D8: 958 | E8: 839 | F8: 706 | G8: =AVERAGE(D8:F8) -> 834.33333 | H8: =STDEV(D8:F8) -> 126.0648 | L8: 0.0833 | M8: 8.42 | N8: 6.38 | O8: 3.36 | P8: =AVERAGE(M8:O8) -> 6.0533333 | Q8: =STDEV(M8:O8) -> 2.5457677 | U8: 给药途径: | W8: IV | Y8: 推荐溶媒: | Z8: 5%DMSO+10%Solutol+85%Saline
C9: 0.25 | D9: 536 | E9: 503 | F9: 598 | G9: =AVERAGE(D9:F9) -> 545.66667 | H9: =STDEV(D9:F9) -> 48.232078 | L9: 0.25 | M9: 66.4 | N9: 67 | O9: 60.6 | P9: =AVERAGE(M9:O9) -> 64.666667 | Q9: =STDEV(M9:O9) -> 3.534591 | U9: 剂量 (mg/kg): | W9: 1
C10: 0.5 | D10: 362 | E10: 422 | F10: 473 | G10: =AVERAGE(D10:F10) -> 419 | H10: =STDEV(D10:F10) -> 55.560778 | L10: 0.5 | M10: 227 | N10: 293 | O10: 422 | P10: =AVERAGE(M10:O10) -> 314 | Q10: =STDEV(M10:O10) -> 99.181652 | U10: 浓度(mg/mL): | W10: 0.2
C11: 1 | D11: 297 | E11: 281 | F11: 261 | G11: =AVERAGE(D11:F11) -> 279.66667 | H11: =STDEV(D11:F11) -> 18.036999 | L11: 1 | M11: 559 | N11: 399 | O11: 785 | P11: =AVERAGE(M11:O11) -> 581 | Q11: =STDEV(M11:O11) -> 193.93813 | U11: 给药体积 (mL/kg): | W11: 5
C12: 2 | D12: 151 | E12: 117 | F12: 174 | G12: =AVERAGE(D12:F12) -> 147.33333 | H12: =STDEV(D12:F12) -> 28.676355 | L12: 2 | M12: 696 | N12: 602 | O12: 813 | P12: =AVERAGE(M12:O12) -> 703.66667 | Q12: =STDEV(M12:O12) -> 105.70872
C13: 4 | D13: 86.1 | E13: 77.3 | F13: 64.6 | G13: =AVERAGE(D13:F13) -> 76 | H13: =STDEV(D13:F13) -> 10.808793 | L13: 4 | M13: 793 | N13: 740 | O13: 513 | P13: =AVERAGE(M13:O13) -> 682 | Q13: =STDEV(M13:O13) -> 148.73802 | V13: 给药途径: | W13: PO | Y13: 推荐溶媒: | Z13: 5%DMSO+10%Solutol+85%Saline
C14: 6 | D14: 50.3 | E14: 46.7 | F14: 39.6 | G14: =AVERAGE(D14:F14) -> 45.533333 | H14: =STDEV(D14:F14) -> 5.4445692 | L14: 6 | M14: 571 | N14: 456 | O14: 483 | P14: =AVERAGE(M14:O14) -> 503.33333 | Q14: =STDEV(M14:O14) -> 60.135957 | V14: 剂量 (mg/kg): | W14: 10
C15: 8 | D15: 31.7 | E15: 31.4 | F15: 35.8 | G15: =AVERAGE(D15:F15) -> 32.966667 | H15: =STDEV(D15:F15) -> 2.4583192 | L15: 8 | M15: 424 | N15: 441 | O15: 310 | P15: =AVERAGE(M15:O15) -> 391.66667 | Q15: =STDEV(M15:O15) -> 71.234355 | V15: 浓度(mg/mL): | W15: 1
C16: 24 | D16: 2.28 | E16: 2.31 | F16: 3.66 | G16: =AVERAGE(D16:F16) -> 2.75 | H16: =STDEV(D16:F16) -> 0.78822586 | L16: 24 | M16: 42.5 | N16: 20.1 | O16: 24.4 | P16: =AVERAGE(M16:O16) -> 29 | Q16: =STDEV(M16:O16) -> 11.887388 | V16: 给药体积 (mL/kg): | W16: 10
U19: 制剂配制计算
U20: 给药途径 | V20: 化合物 | W20: 制剂 | X20: 浓度(mg/mL) | Y20: 化合物重量(mg) | Z20: 最终总体积(mL) | AA20: DMSO体积(mL)
U22: 母液 | V22: HW356009 | W22: DMSO | X22: 20 | Y22: 13.2 | Z22: 0.641 | AA22: 0.641
U26: PO制剂配制过程（给药当天现配现用）
U27: (1) 准确称取化合物13.20 mg，放入5 mL 玻璃瓶中
U28: (2) 加入0.641 mL DMSO，涡旋超声至化合物呈无色澄清状态，即可得到母液
U29: (3) 取母液0.561 mL，放入15 mL 玻璃瓶中
U30: (4) 加入1.122 mL Solutol，涡旋超声至化合物呈无色澄清状态
U31: (5) 加入9.537 mL Saline，涡旋超声至化合物呈无色澄清状态，即可得到PO制剂
U33: IV制剂配制过程（给药当天现配现用）
C34: 表5：单次静脉注射给予HW356009后大鼠血浆PK数据 | L34: 表6：单次灌胃口服给予HW356009后大鼠血浆PK数据 | U34: (1) 取母液0.080 mL，放入15 mL 玻璃瓶中
U35: (2) 加入0.320 mL DMSO，涡旋超声至化合物呈无色澄清状态
C36: 信息/参数类型 | D36: PK参数 | G36: n | H36: Mean | I36: SD | L36: 信息/参数类型 | M36: PK参数 | P36: n | Q36: Mean | R36: SD | U36: (3) 加入0.800 mL Solutol，涡旋超声至化合物呈无色澄清状态
C37: 分组 | D37: 1 | E37: 2 | F37: 3 | L37: 分组 | M37: 4 | N37: 5 | O37: 6 | U37: (4) 加入6.800 mL Saline，涡旋超声至化合物呈无色澄清状态，即可得到IV制剂
C38: 分析物 | D38: =C5 -> HW356009 | L38: 分析物 | M38: =L5 -> HW356009
C39: 给药途径 | D39: IV | L39: 给药途径 | M39: PO
C40: 给药剂量 | D40: 1 | E40: mg/kg | L40: 给药剂量 | M40: 10 | N40: mg/kg | U40: 动物临床观察：
C41: Rsq_adjusted | D41: =PK参数!F3 -> 0.99723005 | E41: =PK参数!F4 -> 0.9991777 | F41: =PK参数!F5 -> 0.99218882 | G41: 3 | H41: =AVERAGE(D41:F41) -> 0.99619886 | I41: =STDEV(D41:F41) -> 0.0036067479 | L41: Rsq_adjusted | M41: =PK参数!F7 -> 0.99997776 | N41: =PK参数!F8 -> 0.98304412 | O41: =PK参数!F9 -> 0.99733131 | P41: 3 | Q41: =AVERAGE(M41:O41) -> 0.99345106 | R41: =STDEV(M41:O41) -> 0.0091092962
C42: No_points_lambda_z | D42: =PK参数!H3 -> 3 | E42: =PK参数!H4 -> 3 | F42: =PK参数!H5 -> 4 | G42: 3 | H42: =AVERAGE(D42:F42) -> 3.3333333 | I42: =STDEV(D42:F42) -> 0.57735027 | L42: No_points_lambda_z | M42: =PK参数!H7 -> 3 | N42: =PK参数!H8 -> 3 | O42: =PK参数!H9 -> 3 | P42: 3 | Q42: =AVERAGE(M42:O42) -> 3 | R42: =STDEV(M42:O42) -> 0 | U42: 所有实验动物均未观察到异常现象。
C43: Tlast (h) | D43: =PK参数!S3 -> 24 | E43: =PK参数!S4 -> 24 | F43: =PK参数!S5 -> 24 | G43: 3 | H43: =AVERAGE(D43:F43) -> 24 | I43: =STDEV(D43:F43) -> 0 | L43: Tlast (h) | M43: =PK参数!S7 -> 24 | N43: =PK参数!S8 -> 24 | O43: =PK参数!S9 -> 24 | P43: 3 | Q43: =AVERAGE(M43:O43) -> 24 | R43: =STDEV(M43:O43) -> 0
C44: T1/2 （h） | D44: =PK参数!M3 -> 4.1001926 | E44: =PK参数!M4 -> 4.1876902 | F44: =PK参数!M5 -> 4.9599094 | G44: 3 | H44: =AVERAGE(D44:F44) -> 4.4159307 | I44: =STDEV(D44:F44) -> 0.47312636 | L44: T1/2 （h） | M44: =PK参数!M7 -> 4.8098094 | N44: =PK参数!M8 -> 3.8307017 | O44: =PK参数!M9 -> 4.2477727 | P44: 3 | Q44: =AVERAGE(M44:O44) -> 4.2960946 | R44: =STDEV(M44:O44) -> 0.49133922
C45: Tmax（h） | D45: =PK参数!O3 -> 0.0833 | E45: =PK参数!O4 -> 0.0833 | F45: =PK参数!O5 -> 0.0833 | G45: 3 | H45: =AVERAGE(D45:F45) -> 0.0833 | I45: =STDEV(D45:F45) -> 0 | L45: Tmax（h） | M45: =PK参数!P7 -> 4 | N45: =PK参数!P8 -> 4 | O45: =PK参数!P9 -> 2 | P45: 3 | Q45: =AVERAGE(M45:O45) -> 3.3333333 | R45: =STDEV(M45:O45) -> 1.1547005 | U45: 动物体重：
C46: Cmax (ng/mL) | D46: =PK参数!P3 -> 958 | E46: =PK参数!P4 -> 839 | F46: =PK参数!P5 -> 706 | G46: 3 | H46: =AVERAGE(D46:F46) -> 834.33333 | I46: =STDEV(D46:F46) -> 126.0648 | L46: Cmax (ng/mL) | M46: =PK参数!Q7 -> 793 | N46: =PK参数!Q8 -> 740 | O46: =PK参数!Q9 -> 813 | P46: 3 | Q46: =AVERAGE(M46:O46) -> 782 | R46: =STDEV(M46:O46) -> 37.722672 | V46: 动物编号 | W46: 1 | X46: 2 | Y46: 3 | Z46: 4 | AA46: 5 | AB46: 6
C47: AUC(0-t) (h*ng/mL) | D47: =PK参数!V3 -> 1446.0997 | E47: =PK参数!V4 -> 1348.379 | F47: =PK参数!V5 -> 1438.7968 | G47: 3 | H47: =AVERAGE(D47:F47) -> 1411.0918 | I47: =STDEV(D47:F47) -> 54.433516 | L47: AUC(0-t) (h*ng/mL) | M47: =PK参数!V7 -> 8447.2619 | N47: =PK参数!V8 -> 7848.682 | O47: =PK参数!V9 -> 6956.746 | P47: 3 | Q47: =AVERAGE(M47:O47) -> 7750.8966 | R47: =STDEV(M47:O47) -> 750.05393 | V47: 体重(g) | W47: 342.7 | X47: 333.8 | Y47: 375.4 | Z47: 328.2 | AA47: 302.3 | AB47: 333.5
...

Sheet PK参数
A1: =结果汇总!C5 -> HW356009 | B1: PK参数
A2: IV | B2: Sort | C2: N_Samples | D2: Dose(mg/kg) | E2: Rsq | F2: Rsq_adjusted | G2: Corr_XY | H2: No_points_lambda_z | I2: Lambda_z(1/h) | J2: Lambda_z_intercept | K2: Lambda_z_lower(h) | L2: Lambda_z_upper(h) | M2: HL_Lambda_z(h) | N2: Span | O2: Tmax(h) | P2: Cmax(ng/mL) | Q2: Cmax_D(kg*ng/mL/mg) | R2: C0(ng/mL) | S2: Tlast(h) | T2: Clast(ng/mL) | U2: Clast_pred(ng/mL) | V2: AUClast(h*ng/mL) | W2: AUClast_D(h*kg*ng/mL/mg) | X2: AUCall(h*ng/mL) | Y2: AUCINF_obs(h*ng/mL) | Z2: AUCINF_D_obs(h*kg*ng/mL/mg) | AA2: AUC_%Extrap_obs({%}) | AB2: AUC_%Back_Ext_obs({%}) | AC2: Vz_obs(L/kg) | AD2: Cl_obs(L/h/kg) | AE2: AUCINF_pred(h*ng/mL) | AF2: AUCINF_D_pred(h*kg*ng/mL/mg) | AG2: AUC_%Extrap_pred({%}) | AH2: AUC_%Back_Ext_pred({%}) | AI2: Vz_pred(L/kg) | AJ2: Cl_pred(L/h/kg) | AK2: AUMClast(h*h*ng/mL) | AL2: AUMCINF_obs(h*h*ng/mL) | AM2: AUMC_%Extrap_obs({%}) | AN2: AUMCINF_pred(h*h*ng/mL) | AO2: AUMC_%Extrap_pred({%}) | AP2: MRTlast(h) | AQ2: MRTINF_obs(h) | AR2: MRTINF_pred(h) | AS2: Vss_obs(L/kg) | AT2: Vss_pred(L/kg)
B3: 1 | C3: 9 | D3: 1 | E3: 0.99861503 | F3: 0.99723005 | G3: -0.99930727 | H3: 3 | I3: 0.16905235 | J3: 4.8741621 | K3: 6 | L3: 24 | M3: 4.1001926 | N3: 4.3900377 | O3: 0.0833 | P3: 958 | Q3: 958 | R3: 1280.5314 | S3: 24 | T3: 2.28 | U3: 2.2634853 | V3: 1446.0997 | W3: 1446.0997 | X3: 1446.0997 | Y3: 1459.5867 | Z3: 1459.5867 | AA3: 0.92402507 | AB3: 6.3877557 | AC3: 4.0527415 | AD3: 0.68512546 | AE3: 1459.489 | AF3: 1459.489 | AG3: 0.91739351 | AH3: 6.3881833 | AI3: 4.0530128 | AJ3: 0.68517132 | AK3: 4794.0791 | AL3: 5197.5455 | AM3: 7.7626339 | AN3: 5194.6231 | AO3: 7.7107426 | AP3: 3.3151787 | AQ3: 3.5609708 | AR3: 3.5592068 | AS3: 2.4397118 | AT3: 2.4386664
B4: 2 | C4: 9 | D4: 1 | E4: 0.99958885 | F4: 0.9991777 | G4: -0.9997944 | H4: 3 | I4: 0.16552017 | J4: 4.8058553 | K4: 6 | L4: 24 | M4: 4.1876902 | N4: 4.2983123 | O4: 0.0833 | P4: 839 | Q4: 839 | R4: 1083.4087 | S4: 24 | T4: 2.31 | U4: 2.3010632 | V4: 1348.379 | W4: 1348.379 | X4: 1348.379 | Y4: 1362.335 | Z4: 1362.335 | AA4: 1.0244179 | AB4: 5.8772856 | AC4: 4.4347093 | AD4: 0.73403383 | AE4: 1362.281 | AF4: 1362.281 | AG4: 1.0204951 | AH4: 5.8775186 | AI4: 4.4348851 | AJ4: 0.73406293 | AK4: 4558.9311 | AL4: 4978.1912 | AM4: 8.4219366 | AN4: 4976.5692 | AO4: 8.3920887 | AP4: 3.3810457 | AQ4: 3.6541608 | AR4: 3.6531149 | AS4: 2.6822776 | AT4: 2.6816162
B5: 3 | C5: 9 | D5: 1 | E5: 0.99479255 | F5: 0.99218882 | G5: -0.99739287 | H5: 4 | I5: 0.13974997 | J5: 4.6479883 | K5: 4 | L5: 24 | M5: 4.9599094 | N5: 4.0323317 | O5: 0.0833 | P5: 706 | Q5: 706 | R5: 767.06971 | S5: 24 | T5: 3.66 | U5: 3.647307 | V5: 1438.7968 | W5: 1438.7968 | X5: 1438.7968 | Y5: 1464.9864 | Z5: 1464.9864 | AA5: 1.7877047 | AB5: 4.1879811 | AC5: 4.8844391 | AD5: 0.6826002 | AE5: 1464.8956 | AF5: 1464.8956 | AG5: 1.7816153 | AH5: 4.1882408 | AI5: 4.8847419 | AJ5: 0.68264252 | AK5: 5117.2571 | AL5: 5933.2117 | AM5: 13.752326 | AN5: 5930.3819 | AO5: 13.711172 | AP5: 3.5566226 | AQ5: 4.0500115 | AR5: 4.0483309 | AS5: 2.7645386 | AT5: 2.7635628
A6: PO | B6: Sort | C6: N_Samples | D6: Dose(mg/kg) | E6: Rsq | F6: Rsq_adjusted | G6: Corr_XY | H6: No_points_lambda_z | I6: Lambda_z(1/h) | J6: Lambda_z_intercept | K6: Lambda_z_lower(h) | L6: Lambda_z_upper(h) | M6: HL_Lambda_z(h) | N6: Span | O6: Tlag(h) | P6: Tmax(h) | Q6: Cmax(ng/mL) | R6: Cmax_D(kg*ng/mL/mg) | S6: Tlast(h) | T6: Clast(ng/mL) | U6: Clast_pred(ng/mL) | V6: AUClast(h*ng/mL) | W6: AUClast_D(h*kg*ng/mL/mg) | X6: AUCall(h*ng/mL) | Y6: AUCINF_obs(h*ng/mL) | Z6: AUCINF_D_obs(h*kg*ng/mL/mg) | AA6: AUC_%Extrap_obs({%}) | AB6: Vz_F_obs(L/kg) | AC6: Cl_F_obs(L/h/kg) | AD6: AUCINF_pred(h*ng/mL) | AE6: AUCINF_D_pred(h*kg*ng/mL/mg) | AF6: AUC_%Extrap_pred({%}) | AG6: Vz_F_pred(L/kg) | AH6: Cl_F_pred(L/h/kg) | AI6: AUMClast(h*h*ng/mL) | AJ6: AUMCINF_obs(h*h*ng/mL) | AK6: AUMC_%Extrap_obs({%}) | AL6: AUMCINF_pred(h*h*ng/mL) | AM6: AUMC_%Extrap_pred({%}) | AN6: MRTlast(h) | AO6: MRTINF_obs(h) | AP6: MRTINF_pred(h)
B7: 4 | C7: 9 | D7: 10 | E7: 0.99998888 | F7: 0.99997776 | G7: -0.99999444 | H7: 3 | I7: 0.14411115 | J7: 7.2076169 | K7: 6 | L7: 24 | M7: 4.8098094 | N7: 3.7423521 | O7: 0 | P7: 4 | Q7: 793 | R7: 79.3 | S7: 24 | T7: 42.5 | U7: 42.476423 | V7: 8447.2619 | W7: 844.72619 | X7: 8447.2619 | Y7: 8742.1732 | Z7: 874.21732 | AA7: 3.3734318 | AB7: 7.9374865 | AC7: 1.1438803 | AD7: 8742.0096 | AE7: 874.20096 | AF7: 3.3716234 | AG7: 7.937635 | AH7: 1.1439017 | AI7: 54437.359 | AJ7: 63561.644 | AK7: 14.355017 | AL7: 63556.582 | AM7: 14.348197 | AN7: 6.4443792 | AO7: 7.2706914 | AP7: 7.2702485
B8: 5 | C8: 9 | D8: 10 | E8: 0.99152206 | F8: 0.98304412 | G8: -0.99575201 | H8: 3 | I8: 0.18094522 | J8: 7.3627253 | K8: 6 | L8: 24 | M8: 3.8307017 | N8: 4.698878 | O8: 0 | P8: 4 | Q8: 740 | R8: 74 | S8: 24 | T8: 20.1 | U8: 20.492111 | V8: 7848.682 | W8: 784.8682 | X8: 7848.682 | Y8: 7959.7653 | Z8: 795.97653 | AA8: 1.3955605 | AB8: 6.9430871 | AC8: 1.2563185 | AD8: 7961.9323 | AE8: 796.19323 | AF8: 1.4223978 | AG8: 6.9411974 | AH8: 1.2559765 | AI8: 49166.944 | AJ8: 52446.85 | AK8: 6.2537714 | AL8: 52510.834 | AM8: 6.368001 | AN8: 6.2643568 | AO8: 6.5889945 | AP8: 6.5952375
B9: 6 | C9: 9 | D9: 10 | E9: 0.99866565 | F9: 0.99733131 | G9: -0.9993326 | H9: 3 | I9: 0.16317897 | J9: 7.103991 | K9: 6 | L9: 24 | M9: 4.2477727 | N9: 4.2375148 | O9: 0 | P9: 2 | Q9: 813 | R9: 81.3 | S9: 24 | T9: 24.4 | U9: 24.232524 | V9: 6956.746 | W9: 695.6746 | X9: 6956.746 | Y9: 7106.2751 | Z9: 710.62751 | AA9: 2.1041836 | AB9: 8.6237031 | AC9: 1.407207 | AD9: 7105.2487 | AE9: 710.52487 | AF9: 2.0900428 | AG9: 8.6249488 | AH9: 1.4074103 | AI9: 40014.866 | AJ9: 44519.914 | AK9: 10.119175 | AL9: 44488.993 | AM9: 10.056704 | AN9: 5.7519516 | AO9: 6.2648735 | AP9: 6.2614265

Sheet 原始数据
A2: Peak Name: Tolbutamide
A3: Use as Internal Standard
A4: Q1/Q3 Masses: 271.10/155.00 Da
A6: Peak Name: HW356009
A7: Internal Standard: Tolbutamide
A8: Q1/Q3 Masses: 604.30/411.20 Da
A10: Fit | B10: Linear | C10: Weighting | D10: 1 / (x * x) | E10: Iterate | F10: No
A11: Intercept | B11: -0.000216
A12: Slope | B12: 0.00191
A13: Correlation coefficient | B13: 0.9969
A14: Use Area
A19: Sample Name | B19: Sample Type | C19: File Name | D19: Analyte Peak Name | E19: Analyte Concentration (ng/mL) | F19: Calculated Concentration (ng/mL) | G19: Analyte Peak Area (counts) | H19: Analyte Retention Time (min) | I19: Area Ratio | J19: IS Peak Area (counts) | K19: IS Retention Time (min) | L19: Use Record | M19: Record Modified | N19: Accuracy (%) | O19: Dilution Factor
A20: Doubleblank | B20: Unknown | C20: HW356009-20250211-Rat-Plasma\SA.wiff | D20: HW356009 | E20: N/A | F20: #DIV/0! | G20: 0 | H20: 0 | I20: #DIV/0! | J20: 0 | K20: 0 | M20: 0 | N20: N/A | O20: 1
A21: Doubleblank | B21: Unknown | C21: HW356009-20250211-Rat-Plasma\SA.wiff | D21: HW356009 | E21: N/A | F21: #DIV/0! | G21: 0 | H21: 0 | I21: #DIV/0! | J21: 0 | K21: 0 | M21: 0 | N21: N/A | O21: 1
A22: Doubleblank | B22: Unknown | C22: HW356009-20250211-Rat-Plasma\SA.wiff | D22: HW356009 | E22: N/A | F22: #DIV/0! | G22: 0 | H22: 0 | I22: #DIV/0! | J22: 0 | K22: 0 | M22: 0 | N22: N/A | O22: 1
A23: Blank | B23: Unknown | C23: HW356009-20250211-Rat-Plasma\SA.wiff | D23: HW356009 | E23: N/A | F23: No Peak | G23: 0 | H23: 0 | I23: 0 | J23: 827000 | K23: 0.854 | M23: 0 | N23: N/A | O23: 1
A24: B-STD1 | B24: Standard | C24: HW356009-20250211-Rat-Plasma\SA.wiff | D24: HW356009 | E24: 1 | F24: 0.976 | G24: 1230 | H24: 1.17 | I24: 0.00165 | J24: 744000 | K24: 0.85 | L24: 1 | M24: 0 | N24: 97.59 | O24: 1
A25: B-STD2 | B25: Standard | C25: HW356009-20250211-Rat-Plasma\SA.wiff | D25: HW356009 | E25: 2 | F25: 2.01 | G25: 2740 | H25: 1.18 | I25: 0.00363 | J25: 755000 | K25: 0.854 | L25: 1 | M25: 0 | N25: 100.64 | O25: 1
A26: B-STD3 | B26: Standard | C26: HW356009-20250211-Rat-Plasma\SA.wiff | D26: HW356009 | E26: 5 | F26: 5.59 | G26: 7700 | H26: 1.18 | I26: 0.0105 | J26: 736000 | K26: 0.854 | L26: 1 | M26: 0 | N26: 111.79 | O26: 1
A27: B-STD4 | B27: Standard | C27: HW356009-20250211-Rat-Plasma\SA.wiff | D27: HW356009 | E27: 20 | F27: 18.7 | G27: 24800 | H27: 1.18 | I27: 0.0356 | J27: 696000 | K27: 0.853 | L27: 1 | M27: 0 | N27: 93.58 | O27: 1
A28: B-STD5 | B28: Standard | C28: HW356009-20250211-Rat-Plasma\SA.wiff | D28: HW356009 | E28: 100 | F28: 107 | G28: 175000 | H28: 1.18 | I28: 0.204 | J28: 855000 | K28: 0.852 | L28: 1 | M28: 0 | N28: 106.88 | O28: 1
A29: B-STD6 | B29: Standard | C29: HW356009-20250211-Rat-Plasma\SA.wiff | D29: HW356009 | E29: 500 | F29: 462 | G29: 650000 | H29: 1.18 | I29: 0.884 | J29: 735000 | K29: 0.855 | L29: 1 | M29: 0 | N29: 92.48 | O29: 1
A30: B-STD7 | B30: Standard | C30: HW356009-20250211-Rat-Plasma\SA.wiff | D30: HW356009 | E30: 1000 | F30: 1040 | G30: 1530000 | H30: 1.18 | I30: 1.98 | J30: 772000 | K30: 0.853 | L30: 1 | M30: 0 | N30: 103.76 | O30: 1
A31: B-STD8 | B31: Standard | C31: HW356009-20250211-Rat-Plasma\SA.wiff | D31: HW356009 | E31: 2000 | F31: 1870 | G31: 2900000 | H31: 1.18 | I31: 3.57 | J31: 813000 | K31: 0.854 | L31: 1 | M31: 0 | N31: 93.27 | O31: 1
A32: Doubleblank | B32: Unknown | C32: HW356009-20250211-Rat-Plasma\SA.wiff | D32: HW356009 | E32: N/A | F32: #DIV/0! | G32: 0 | H32: 0 | I32: #DIV/0! | J32: 0 | K32: 0 | M32: 0 | N32: N/A | O32: 1
A33: Doubleblank | B33: Unknown | C33: HW356009-20250211-Rat-Plasma\SA.wiff | D33: HW356009 | E33: N/A | F33: #DIV/0! | G33: 0 | H33: 0 | I33: #DIV/0! | J33: 0 | K33: 0 | M33: 0 | N33: N/A | O33: 1
A34: Doubleblank | B34: Unknown | C34: HW356009-20250211-Rat-Plasma\SA.wiff | D34: HW356009 | E34: N/A | F34: #DIV/0! | G34: 0 | H34: 0 | I34: #DIV/0! | J34: 0 | K34: 0 | M34: 0 | N34: N/A | O34: 1
A35: B-LQC-1 | B35: Quality Control | C35: HW356009-20250211-Rat-Plasma\SA.wiff | D35: HW356009 | E35: 3 | F35: 2.76 | G35: 3820 | H35: 1.18 | I35: 0.00507 | J35: 753000 | K35: 0.855 | L35: 1 | M35: 0 | N35: 92.09 | O35: 1
A36: B-MQC-1 | B36: Quality Control | C36: HW356009-20250211-Rat-Plasma\SA.wiff | D36: HW356009 | E36: 60 | F36: 52.6 | G36: 80900 | H36: 1.18 | I36: 0.1 | J36: 805000 | K36: 0.854 | L36: 1 | M36: 0 | N36: 87.73 | O36: 1
A37: B-HQC-1 | B37: Quality Control | C37: HW356009-20250211-Rat-Plasma\SA.wiff | D37: HW356009 | E37: 1600 | F37: 1690 | G37: 2620000 | H37: 1.18 | I37: 3.22 | J37: 814000 | K37: 0.852 | L37: 1 | M37: 0 | N37: 105.39 | O37: 1
A38: B-DQC-1 | B38: Quality Control | C38: HW356009-20250211-Rat-Plasma\SA.wiff | D38: HW356009 | E38: 10000 | F38: 8740 | G38: 1310000 | H38: 1.18 | I38: 1.67 | J38: 786000 | K38: 0.851 | L38: 1 | M38: 0 | N38: 87.39 | O38: 10
A39: B-DQC-2 | B39: Quality Control | C39: HW356009-20250211-Rat-Plasma\SA.wiff | D39: HW356009 | E39: 10000 | F39: 9570 | G39: 1410000 | H39: 1.18 | I39: 1.83 | J39: 769000 | K39: 0.851 | L39: 1 | M39: 0 | N39: 95.71 | O39: 10
A40: B-DQC-3 | B40: Quality Control | C40: HW356009-20250211-Rat-Plasma\SA.wiff | D40: HW356009 | E40: 10000 | F40: 10200 | G40: 1500000 | H40: 1.18 | I40: 1.95 | J40: 767000 | K40: 0.852 | L40: 1 | M40: 0 | N40: 102.17 | O40: 10
A41: Doubleblank | B41: Unknown | C41: HW356009-20250211-Rat-Plasma\SA.wiff | D41: HW356009 | E41: N/A | F41: #DIV/0! | G41: 0 | H41: 0 | I41: #DIV/0! | J41: 0 | K41: 0 | M41: 0 | N41: N/A | O41: 1
A42: IV-DOSE-1 | B42: Quality Control | C42: HW356009-20250211-Rat-Plasma\SA.wiff | D42: HW356009 | E42: 5 | F42: 5.76 | G42: 7180 | H42: 1.22 | I42: 0.0108 | J42: 664000 | K42: 0.9 | L42: 1 | M42: 0 | N42: 115.22 | O42: 1
A43: IV-DOSE-2 | B43: Quality Control | C43: HW356009-20250211-Rat-Plasma\SA.wiff | D43: HW356009 | E43: 5 | F43: 5.47 | G43: 6730 | H43: 1.2 | I43: 0.0102 | J43: 657000 | K43: 0.875 | L43: 1 | M43: 0 | N43: 109.43 | O43: 1
A44: IV-DOSE-3 | B44: Quality Control | C44: HW356009-20250211-Rat-Plasma\SA.wiff | D44: HW356009 | E44: 5 | F44: 5.05 | G44: 6260 | H44: 1.17 | I44: 0.00943 | J44: 663000 | K44: 0.849 | L44: 1 | M44: 0 | N44: 100.91 | O44: 1
A45: PO-DOSE-1 | B45: Quality Control | C45: HW356009-20250211-Rat-Plasma\SA.wiff | D45: HW356009 | E45: 25 | F45: 19.6 | G45: 34500 | H45: 1.18 | I45: 0.0373 | J45: 926000 | K45: 0.851 | L45: 1 | M45: 0 | N45: 78.44 | O45: 1
A46: PO-DOSE-2 | B46: Quality Control | C46: HW356009-20250211-Rat-Plasma\SA.wiff | D46: HW356009 | E46: 25 | F46: 21.2 | G46: 37000 | H46: 1.18 | I46: 0.0403 | J46: 918000 | K46: 0.85 | L46: 1 | M46: 0 | N46: 84.66 | O46: 1
A47: PO-DOSE-3 | B47: Quality Control | C47: HW356009-20250211-Rat-Plasma\SA.wiff | D47: HW356009 | E47: 25 | F47: 20.6 | G47: 37300 | H47: 1.18 | I47: 0.0391 | J47: 953000 | K47: 0.854 | L47: 1 | M47: 0 | N47: 82.31 | O47: 1
...

Sheet 标曲&质控
C5: 标准曲线 | D5: 编号 | E5: 标示浓度 | F5: 实测浓度 | G5: 准确度%
D6: B-STD1 | E6: 1 | F6: 0.976 | G6: 97.59
D7: B-STD2 | E7: 2 | F7: 2.01 | G7: 100.64
D8: B-STD3 | E8: 5 | F8: 5.59 | G8: 111.79
D9: B-STD4 | E9: 20 | F9: 18.7 | G9: 93.58
D10: B-STD5 | E10: 100 | F10: 107 | G10: 106.88
D11: B-STD6 | E11: 500 | F11: 462 | G11: 92.48
D12: B-STD7 | E12: 1000 | F12: 1040 | G12: 103.76
D13: B-STD8 | E13: 2000 | F13: 1870 | G13: 93.27
C15: 质控样本 | D15: 编号 | E15: 标示浓度 | F15: 实测浓度 | H15: 准确度%
F16: 1 | G16: 2 | H16: 1 | I16: 2
D17: B-LQC | E17: 3 | F17: 2.76 | G17: 3.82 | H17: 92.09 | I17: 127.49
D18: B-MQC | E18: 60 | F18: 52.6 | G18: 59.7 | H18: 87.73 | I18: 119.46
D19: B-HQC | E19: 1600 | F19: 1690 | G19: 1860 | H19: 105.39 | I19: 116.22
D20: B-DQC | E20: 10000 | F20: 8740 | G20: NA | H20: 87.39 | I20: NA
E21: 10000 | F21: 9570 | H21: 95.71
E22: 10000 | F22: 10200 | H22: 102.17
C25: 生物样品分析方法及所有样品的分析由合肥中科普瑞昇生物分析实验室完成，分析样品的同时进行质控样品的日内准确度评价，并要求超过66.7%的质控样品的准确度在80-120%之间。伴随样品分析的线性标准品至少6个且≥75%的校准标样满足偏差在±20%范围内。

Sheet 给药制剂浓度检测
B2: PK 给药制剂浓度测定
B3: IV&PO | C3: 检测步骤： (将药制剂原液稀释40000倍后进行浓度检测):
C4: 1)移取制剂50μL，加入二甲基亚砜950 μL混合均匀（该过程稀释20倍）;
C5: 2) 将第一步中的制剂稀释液移取10 μL，准确加入甲醇990 μL，混合均匀（该过程稀释100倍）；
C6: 4)将步骤三的溶液移取2.5 μL 加入到47.5 μL的血浆中，按提取标准和线性一起处理（此过程稀释20倍）。
C8: 化合物 | D8: 给药方式 | E8: 设计浓度. (mg/mL) | F8: 稀释倍数 | G8: 测试浓度(ng/mL) | H8: 计算浓度 (mg/mL) | I8: 平均浓度 (mg/mL) | J8: 偏差 (%) | K8: 变异系数(%) | L8: 测试方法
C9: HW356009 | D9: IV | E9: 0.2 | F9: 40000 | G9: 5.76 | H9: =G9*F9/1000000 -> 0.2304 | I9: =AVERAGE(H9:H11) -> 0.21706667 | J9: =(I9-E9)/E9*100 -> 8.5333333 | K9: =STDEV(H9:H11)/I9*100 -> 6.5782197 | L9: HPLC-MS/MS
F10: 40000 | G10: 5.47 | H10: =G10*F10/1000000 -> 0.2188
F11: 40000 | G11: 5.05 | H11: =G11*F11/1000000 -> 0.202
D12: PO | E12: 1 | F12: 40000 | G12: 19.6 | H12: =G12*F12/1000000 -> 0.784 | I12: =AVERAGE(H12:H14) -> 0.81866667 | J12: =(I12-E12)/E12*100 -> -18.133333 | K12: =STDEV(H12:H14)/I12*100 -> 3.9493015 | L12: HPLC-MS/MS
F13: 40000 | G13: 21.2 | H13: =G13*F13/1000000 -> 0.848
F14: 40000 | G14: 20.6 | H14: =G14*F14/1000000 -> 0.824
C16: 结果：
C17: 与设计剂量浓度(IV：0.2 mg/mL，PO:1 mg/mL)比较， 剂量浓度在(± 20%)标准范围内。

Sheet LC-MS分析方法 
B2: 分析方法
C3: 设备型号 | D3: LC-MS/MS ( Triple Quad 5500+)
C5: 设备编号 | D5: LC-MS/MS-004
C7: 基质类型 | D7: 大鼠血浆
C9: 分析物 | D9: HW356009
C11: 内标 | D11: Tolbutamide
C13: 质谱条件 | D13: ESI源正离子模式
D14: 多反应监测
D15: HW356009 | E15: Q1/Q3 Masses: 604.30/411.20 Da
D16: Tolbutamide | E16: Q1/Q3 Masses: 271.10/155.00 Da
C17: 液相条件
D18: 色谱柱 | E18: Synergi 4µm Fusion-RP 80A LC Column 50*2 mm
D19: 色谱型号 | E19: Exion LC
D20: 流动相 | E20: A: 水（含0.1%FA）
E21: B:乙腈
D22: 液相程序
E23: 时间 (min) | F23: 流速 (mL/min) | G23: A (%) | H23: B (%)
E24: 0.2 | F24: 0.9 | G24: =100-H24 -> 80 | H24: 20
E25: 1.6 | F25: 0.9 | G25: =100-H25 -> 5 | H25: 95
E26: 1.9 | F26: 0.9 | G26: =100-H26 -> 5 | H26: 95
E27: 1.91 | F27: 0.9 | G27: =100-H27 -> 80 | H27: 20
E28: 2.5 | F28: 0.9 | G28: =100-H28 -> 80 | H28: 20
D29: 柱温 (°C): | E29: 40
D30: 进样体积(μL): | E30: 10
D31: 保留时间:
D32: HW356009 | E32: 1.18 min
D33: IS: | E33: 0.85 min
C35: 样品前处理 | D35: 1. 所有样品完全融化后，混匀10～30秒，4000 rpm、4 °C条件下离心0.5 分钟。 2.移取20 μL血浆样品（空白样品加20 μL空白血浆）至96 孔板中，加入200 μL（50%甲醇乙腈溶液（浓度：100 ng/mL））溶液（Doubleblank样品加入200 μL50%甲醇乙腈溶液）。 3. 将样品涡旋5分钟后，在4000 rpm、4 °C条件下离心10 分钟，移取100 μL加入到100 μL水中，混合均匀，交由LC-MS/MS分析。
C36: 线性范围 | D36: 1-2000 ng/mL

Sheet 试验设计
C3: 供试品信息
C5: 名称 | D5: 保存条件 | E5: 纯度* | F5: 盐或酯或游离形式 | G5: 分子量（盐） | H5: 分子量（游离形式）
C6: HW356009 | D6: RT | E6: 0.971 | F6: 游离形式 | G6: - | H6: 603.14
C7: *:配制时需要折算纯度。
C9: 供试品配制
C11: 给药当天配制。
C12: 溶媒：5%DMSO+10%Solutol+85%Saline
C14: 实验动物
C16: 种属：SD大鼠，SPF级。
C17: 来源：北京维通利华实验动物技术有限公司
C18: 数量：雄性8只。实验需要：雄性6只。
C19: 动物挑选：不进行随机分组
C21: 实验设计
C23: 组别 | D23: 受试物 | E23: 动物数量 | F23: 剂量 | G23: 浓度 | H23: 给药体积 | I23: 给予方式 | J23: 采集样本
E24: 雄性 | F24: (mg/kg) | G24: (mg/mL) | H24: (mL/kg)
C25: 1 | D25: HW356009 | E25: 3 | F25: 1 | G25: 0.2 | H25: 5 | I25: IV，单次 | J25: 血浆
C26: 2 | D26: HW356009 | E26: 3 | F26: 10 | G26: 1 | H26: 10 | I26: PO*，单次 | J26: 血浆
C28: 注： *, 口服给药组动物给药前禁食过夜（10-14小时），给药4小时后给食。
C30: 给药方式
C32: 给药前称重，根据体重，计算给药量。通过静脉注射和灌胃口服给药。
C34: 采血时间点：
C36: 给药后：0.083 h，0.25 h，0.5 h，1 h，2 h，4 h，6 h，8 h，24 h
C37: 经颈静脉采血，每个样品采集约0.25 mL，EDTA-K2抗凝，采集后放置湿冰上。
C39: 血浆样品处理
C41: 血液样本采集后置于冰上，并于1小时之内离心分离血浆(离心条件：6000 g，3分钟，2-8 ºC)。血浆样本在分析前存放时则放于-80℃冰箱内。
C44: 结果分析
C46: 通过不同时间点的血药浓度数据，运用Phoenix WinNonlin8.2.0计算药代动力学参数，提供AUC0-t、AUC0-∞、MRT0-∞、Cmax、Tmax、和T1/2等参数及其平均值和标准差。
C49: 剩余供试品、血浆的处置
C51: 剩余供试品和剩余血浆样品在试验结束后继续存放于-80 °C冰箱暂存，保存期限为一个月。
