Workbook

Sheet Signature
B4: HCT116 Cell Proliferation Assay Report
B7: Assay name | C7: Cell Proliferation Assay with TEAD inhibitor
B8: Purpose | C8: To obtain IC50 of test compounds on HCT116 cell lines
B13: Assay Date | C13: 45559
B14: Report Release Date | C14: 45565
B17: Assay Performed by | C17: Xiulan Yang | D17: Signature:
B18: Study Director | C18: Xin Zhao | D18: Signature:
B19: Report Prepared by | C19: Xiulan Yang | D19: Signature:
B20: Report Approval | C20: Xin Zhao | D20: Signature:

Sheet Summary
A1: Assay Date | B1: 45565
A2: Assay name | B2: HCT116 proliferation Assay
A3: Cell line | B3: HCT116 cell lines
A4: Summary-HCT116
A5: Entry | B5: Compound ID | C5: Start Conc., nM | D5: Dilution Fold | E5: Min Inhibition% | F5: Max Inhibition% | G5: Bottom | H5: Top | I5: R_IC50, nM | J5: A_IC50, nM
A6: 1 | B6: HW350003A | C6: 10000 | D6: 3 | E6: =OFFSET(INDEX('IC50 Curve'!$A:$A,MATCH(Summary!B6,'IC50 Curve'!$A:$A,0),1),6,7) -> 0 | F6: =OFFSET(INDEX('IC50 Curve'!$A:$A,MATCH(Summary!B6,'IC50 Curve'!$A:$A,0),1),5,7) -> 0 | G6: =OFFSET(INDEX('IC50 Curve'!$A:$A,MATCH(Summary!B6,'IC50 Curve'!$A:$A,0),1),0,7) -> 1.907 | H6: =OFFSET(INDEX('IC50 Curve'!$A:$A,MATCH(Summary!B6,'IC50 Curve'!$A:$A,0),1),1,7) -> 89.87 | I6: =OFFSET(INDEX('IC50 Curve'!$A:$A,MATCH(Summary!B6,'IC50 Curve'!$A:$A,0),1),2,7) -> 34.56 | J6: =OFFSET(INDEX('IC50 Curve'!$A:$A,MATCH(Summary!B6,'IC50 Curve'!$A:$A,0),1),3,7) -> 38.459
A7: 2 | B7: HW356011 | C7: 10000 | D7: 3 | E7: =OFFSET(INDEX('IC50 Curve'!$A:$A,MATCH(Summary!B7,'IC50 Curve'!$A:$A,0),1),6,7) -> 0 | F7: =OFFSET(INDEX('IC50 Curve'!$A:$A,MATCH(Summary!B7,'IC50 Curve'!$A:$A,0),1),5,7) -> 0 | G7: =OFFSET(INDEX('IC50 Curve'!$A:$A,MATCH(Summary!B7,'IC50 Curve'!$A:$A,0),1),0,7) -> -2.544 | H7: =OFFSET(INDEX('IC50 Curve'!$A:$A,MATCH(Summary!B7,'IC50 Curve'!$A:$A,0),1),1,7) -> 98.66 | I7: =OFFSET(INDEX('IC50 Curve'!$A:$A,MATCH(Summary!B7,'IC50 Curve'!$A:$A,0),1),2,7) -> 128.8 | J7: =OFFSET(INDEX('IC50 Curve'!$A:$A,MATCH(Summary!B7,'IC50 Curve'!$A:$A,0),1),3,7) -> 136.1444
A8: 3 | B8: HW356012 | C8: 10000 | D8: 3 | E8: =OFFSET(INDEX('IC50 Curve'!$A:$A,MATCH(Summary!B8,'IC50 Curve'!$A:$A,0),1),6,7) -> 0 | F8: =OFFSET(INDEX('IC50 Curve'!$A:$A,MATCH(Summary!B8,'IC50 Curve'!$A:$A,0),1),5,7) -> 0 | G8: =OFFSET(INDEX('IC50 Curve'!$A:$A,MATCH(Summary!B8,'IC50 Curve'!$A:$A,0),1),0,7) -> -1.555 | H8: =OFFSET(INDEX('IC50 Curve'!$A:$A,MATCH(Summary!B8,'IC50 Curve'!$A:$A,0),1),1,7) -> 99.44 | I8: =OFFSET(INDEX('IC50 Curve'!$A:$A,MATCH(Summary!B8,'IC50 Curve'!$A:$A,0),1),2,7) -> 1680 | J8: =OFFSET(INDEX('IC50 Curve'!$A:$A,MATCH(Summary!B8,'IC50 Curve'!$A:$A,0),1),3,7) -> 1698.243
A9: 4 | B9: HW356020 | C9: 10000 | D9: 3 | E9: =OFFSET(INDEX('IC50 Curve'!$A:$A,MATCH(Summary!B9,'IC50 Curve'!$A:$A,0),1),6,7) -> 0 | F9: =OFFSET(INDEX('IC50 Curve'!$A:$A,MATCH(Summary!B9,'IC50 Curve'!$A:$A,0),1),5,7) -> 0 | G9: =OFFSET(INDEX('IC50 Curve'!$A:$A,MATCH(Summary!B9,'IC50 Curve'!$A:$A,0),1),0,7) -> 2.343 | H9: =OFFSET(INDEX('IC50 Curve'!$A:$A,MATCH(Summary!B9,'IC50 Curve'!$A:$A,0),1),1,7) -> 8 | I9: =OFFSET(INDEX('IC50 Curve'!$A:$A,MATCH(Summary!B9,'IC50 Curve'!$A:$A,0),1),2,7) -> ＞10000 | J9: =OFFSET(INDEX('IC50 Curve'!$A:$A,MATCH(Summary!B9,'IC50 Curve'!$A:$A,0),1),3,7) -> ＞10000
A10: 5 | B10: HW356046 | C10: 10000 | D10: 3 | E10: =OFFSET(INDEX('IC50 Curve'!$A:$A,MATCH(Summary!B10,'IC50 Curve'!$A:$A,0),1),6,7) -> 0 | F10: =OFFSET(INDEX('IC50 Curve'!$A:$A,MATCH(Summary!B10,'IC50 Curve'!$A:$A,0),1),5,7) -> 0 | G10: =OFFSET(INDEX('IC50 Curve'!$A:$A,MATCH(Summary!B10,'IC50 Curve'!$A:$A,0),1),0,7) -> -0.0603 | H10: =OFFSET(INDEX('IC50 Curve'!$A:$A,MATCH(Summary!B10,'IC50 Curve'!$A:$A,0),1),1,7) -> 92.45 | I10: =OFFSET(INDEX('IC50 Curve'!$A:$A,MATCH(Summary!B10,'IC50 Curve'!$A:$A,0),1),2,7) -> 534.2 | J10: =OFFSET(INDEX('IC50 Curve'!$A:$A,MATCH(Summary!B10,'IC50 Curve'!$A:$A,0),1),3,7) -> 562.341
A11: 6 | B11: HW356048 | C11: 10000 | D11: 3 | E11: =OFFSET(INDEX('IC50 Curve'!$A:$A,MATCH(Summary!B11,'IC50 Curve'!$A:$A,0),1),6,7) -> 0 | F11: =OFFSET(INDEX('IC50 Curve'!$A:$A,MATCH(Summary!B11,'IC50 Curve'!$A:$A,0),1),5,7) -> 0 | G11: =OFFSET(INDEX('IC50 Curve'!$A:$A,MATCH(Summary!B11,'IC50 Curve'!$A:$A,0),1),0,7) -> 0.2928 | H11: =OFFSET(INDEX('IC50 Curve'!$A:$A,MATCH(Summary!B11,'IC50 Curve'!$A:$A,0),1),1,7) -> 90.79 | I11: =OFFSET(INDEX('IC50 Curve'!$A:$A,MATCH(Summary!B11,'IC50 Curve'!$A:$A,0),1),2,7) -> 91.48 | J11: =OFFSET(INDEX('IC50 Curve'!$A:$A,MATCH(Summary!B11,'IC50 Curve'!$A:$A,0),1),3,7) -> 101.859

Sheet Protocol
A1: Objective
A2: To obtain IC50 of test compounds on HCT116 cell lines
A4: Incubation Time
A5: 120Hr
A7: Method
A8: CTG
A10: Procedure
A11: 1. When cell confluence come to 80%, collect and count cells.
A12: 2. Dilute dilute cell suspension to 500 cells/well. Seed 100uls of cell suspensions into each well of a 96-well plate.
A13: 3.Return the cell plate into a 37 ℃, 5%CO2 incubator.
A14: 4. After 24 hours incubation, add 100ul of diluted compound solution into designated wells of the plate. The compound layout is on the next slide ,the final DMSO concentration is 0.1%.
A15: 5. Return the plate into the incubator for 120Hrs.
... A17: 7. Data analysis
A18: a) | B18: Assay robustness check with DMSO and Medium control data:
B19: H=Ave (DMSO)
B20: L= Ave (Medium)
B21: SD (H) =STDEV (DMSO)
B22: SD (L) =STDEV (Medium)
B23: CV% (DMSO) =100* (SD_H/Ave_H)
B24: CV% (Medium) =100*SD_L/Ave_L
B25: Z'=1-3*(SD_H+ SD_L)/ (Ave_H - Ave_L)
B26: Inhibition%=(Ave_H-Sample)/(Ave_H-Ave_L)
A27: b) | B27: Fit the cpd IC50 from non-linear regression equation:
B28: Y=Bottom + (Top-Bottom)/(1+10^((LogIC50-X)*HillSlope))
B29: X: cpd concentration
B30: Y: inhibition%
B31: Top and Bottom: Plateaus in same units as Y
B32: logIC50: same log units as X
B33: HillSlope: Slope factor or Hill slope
A34: c) | B34: R_IC50=Relative IC50
B35: A_IC50=Absolute IC50

Sheet Compound Information
B1: Compound Information
B2: # | C2: Compound ID | D2: Solvent | E2: Storage Condition | F2: Stock (mM)
B4: 1 | C4: HW350003A | D4: DMSO | E4: -20℃ | F4: 10
B5: 2 | C5: HW356011 | D5: DMSO | E5: -20℃ | F5: 10
B6: 3 | C6: HW356012 | D6: DMSO | E6: -20℃ | F6: 10
B7: 4 | C7: HW356020 | D7: DMSO | E7: -20℃ | F7: 10
B8: 5 | C8: HW356046 | D8: DMSO | E8: -20℃ | F8: 10
B9: 6 | C9: HW356048 | D9: DMSO | E9: -20℃ | F9: 10
B11: Compound Dilution
B12: # | C12: Compound ID | D12: DMSO Stock | E12: Start Conc. | F12: Dose Dilution | G12: Add 100 μL into 100 μL medium, Final DMSO 0.1%
E13: In Source Plate | F13: 3-Fold Serial Dilution/dose 1-dose9 | G13: Final Conc. in Assay Plate, nM
B14: 1 | C14: HW350003A | D14: 10 mM | E14: 10 mM | F14: Add 5 μL 10 mM into 10 μL DMSO | G14: 10000
B15: 2 | C15: HW356011 | D15: 10 mM | E15: 10 mM | F15: Add 5 μL 10 mM into 10 μL DMSO | G15: 10000
B16: 3 | C16: HW356012 | D16: 10 mM | E16: 10 mM | F16: Add 5 μL 10 mM into 10 μL DMSO | G16: 10000
B17: 4 | C17: HW356020 | D17: 10 mM | E17: 10 mM | F17: Add 5 μL 10 mM into 10 μL DMSO | G17: 10000
B18: 5 | C18: HW356046 | D18: 10 mM | E18: 10 mM | F18: Add 5 μL 10 mM into 10 μL DMSO | G18: 10000
B19: 6 | C19: HW356048 | D19: 10 mM | E19: 10 mM | F19: Add 5 μL 10 mM into 10 μL DMSO | G19: 10000

Sheet Raw Data IC50
B2: Plate 1_Plate Map
C3: 1 | D3: 2 | E3: 3 | F3: 4 | G3: 5 | H3: 6 | I3: 7 | J3: 8 | K3: 9 | L3: 10 | M3: 11 | N3: 12
B4: A | C4: Medium | D4: Conc. nM | M4: DMSO
B5: B | D5: 10000 | E5: =D5/3 -> 3333.3333 | F5: =E5/3 -> 1111.1111 | G5: =F5/3 -> 370.37037 | H5: =G5/3 -> 123.45679 | I5: =H5/3 -> 41.152263 | J5: =I5/3 -> 13.717421 | K5: =J5/3 -> 4.5724737 | L5: =K5/3 -> 1.5241579 | M5: 0
B6: C
B7: D | D7: 10000 | E7: =D7/3 -> 3333.3333 | F7: =E7/3 -> 1111.1111 | G7: =F7/3 -> 370.37037 | H7: =G7/3 -> 123.45679 | I7: =H7/3 -> 41.152263 | J7: =I7/3 -> 13.717421 | K7: =J7/3 -> 4.5724737 | L7: =K7/3 -> 1.5241579 | M7: 0
B8: E
B9: F | D9: 10000 | E9: =D9/3 -> 3333.3333 | F9: =E9/3 -> 1111.1111 | G9: =F9/3 -> 370.37037 | H9: =G9/3 -> 123.45679 | I9: =H9/3 -> 41.152263 | J9: =I9/3 -> 13.717421 | K9: =J9/3 -> 4.5724737 | L9: =K9/3 -> 1.5241579 | M9: 0
B10: G
B11: H | C11: Low control | M11: High Control
C13: Plate 1_Raw Data
C14: 1 | D14: 2 | E14: 3 | F14: 4 | G14: 5 | H14: 6 | I14: 7 | J14: 8 | K14: 9 | L14: 10 | M14: 11 | N14: 12
B15: A
B16: B | C16: 1017 | D16: 59587 | E16: 65340 | F16: 62700 | G16: 77472 | H16: 126144 | I16: 302159 | J16: 518604 | K16: 601061 | L16: 610788 | M16: 617476
B17: C | C17: 1216 | D17: 63847 | E17: 60462 | F17: 69609 | G17: 75580 | H17: 124243 | I17: 294370 | J17: 544881 | K17: 636550 | L17: 610418 | M17: 630373
B18: D | C18: 703 | D18: 7773 | E18: 7092 | F18: 54002 | G18: 130101 | H18: 313392 | I18: 546065 | J18: 618984 | K18: 623979 | L18: 651181 | M18: 630055
B19: E | C19: 620 | D19: 8608 | E19: 8060 | F19: 59765 | G19: 134644 | H19: 352567 | I19: 548022 | J19: 634525 | K19: 633485 | L19: 666292 | M19: 654749
B20: F | C20: 794 | D20: 6091 | E20: 52718 | F20: 516195 | G20: 608195 | H20: 646625 | I20: 649108 | J20: 669413 | K20: 658310 | L20: 651488 | M20: 648798
B21: G | C21: 667 | D21: 5462 | E21: 45719 | F21: 551684 | G21: 651095 | H21: 640505 | I21: 641180 | J21: 629080 | K21: 646719 | L21: 647634 | M21: 631762
B22: H | C22: Low Control | M22: High Control
C23: 0.1%DMSO | D23: Ave | E23: SD | F23: CV | G23: Z'
C24: H | D24: =AVERAGE(M16:M21) -> 635535.5 | E24: =STDEV(M16:M21) -> 13726.796 | F24: =E24/D24 -> 0.021598787 | G24: =1-(3*(E24+E25)/(D24-D25)) -> 0.93401618
C25: L | D25: =AVERAGE(C16:C21) -> 836.16667 | E25: =STDEV(C16:C21) -> 233.16553 | F25: =E25/D25 -> 0.27885055
C27: Plate 1_Inhibition %
C28: 1 | D28: 2 | E28: 3 | F28: 4 | G28: 5 | H28: 6 | I28: 7 | J28: 8 | K28: 9 | L28: 10 | M28: 11 | N28: 12
B29: A | D29: Conc. nM
A30: =Summary!B6 -> HW350003A | B30: B | D30: =($D$24-D16)/($D$24-$D$25)*100 -> 90.743517 | E30: =($D$24-E16)/($D$24-$D$25)*100 -> 89.837104 | F30: =($D$24-F16)/($D$24-$D$25)*100 -> 90.253049 | G30: =($D$24-G16)/($D$24-$D$25)*100 -> 87.925648 | H30: =($D$24-H16)/($D$24-$D$25)*100 -> 80.257135 | I30: =($D$24-I16)/($D$24-$D$25)*100 -> 52.525106 | J30: =($D$24-J16)/($D$24-$D$25)*100 -> 18.423133 | K30: =($D$24-K16)/($D$24-$D$25)*100 -> 5.4316269 | ... M30: =($D$24-M16)/($D$24-$D$25)*100 -> 2.845363
B31: C | D31: =($D$24-D17)/($D$24-$D$25)*100 -> 90.072333 | E31: =($D$24-E17)/($D$24-$D$25)*100 -> 90.605657 | F31: =($D$24-F17)/($D$24-$D$25)*100 -> 89.164502 | G31: =($D$24-G17)/($D$24-$D$25)*100 -> 88.223742 | H31: =($D$24-H17)/($D$24-$D$25)*100 -> 80.556647 | I31: =($D$24-I17)/($D$24-$D$25)*100 -> 53.752302 | J31: =($D$24-J17)/($D$24-$D$25)*100 -> 14.283062 | K31: =($D$24-K17)/($D$24-$D$25)*100 -> -0.15983946 | ... M31: =($D$24-M17)/($D$24-$D$25)*100 -> 0.81337725
A32: =Summary!B7 -> HW356011 | B32: D | D32: =($D$24-D18)/($D$24-$D$25)*100 -> 98.907068 | E32: =($D$24-E18)/($D$24-$D$25)*100 -> 99.014363 | F32: =($D$24-F18)/($D$24-$D$25)*100 -> 91.623462 | G32: =($D$24-G18)/($D$24-$D$25)*100 -> 79.63369 | H32: =($D$24-H18)/($D$24-$D$25)*100 -> 50.755292 | I32: =($D$24-I18)/($D$24-$D$25)*100 -> 14.096517 | J32: =($D$24-J18)/($D$24-$D$25)*100 -> 2.6077702 | K32: =($D$24-K18)/($D$24-$D$25)*100 -> 1.8207834 | ... M32: =($D$24-M18)/($D$24-$D$25)*100 -> 0.86347972
B33: E | D33: =($D$24-D19)/($D$24-$D$25)*100 -> 98.775509 | E33: =($D$24-E19)/($D$24-$D$25)*100 -> 98.86185 | F33: =($D$24-F19)/($D$24-$D$25)*100 -> 90.715473 | G33: =($D$24-G19)/($D$24-$D$25)*100 -> 78.917918 | H33: =($D$24-H19)/($D$24-$D$25)*100 -> 44.583078 | I33: =($D$24-I19)/($D$24-$D$25)*100 -> 13.788182 | J33: =($D$24-J19)/($D$24-$D$25)*100 -> 0.15920924 | K33: =($D$24-K19)/($D$24-$D$25)*100 -> 0.32306635 | ... M33: =($D$24-M19)/($D$24-$D$25)*100 -> -3.0271814
A34: =Summary!B8 -> HW356012 | B34: F | D34: =($D$24-D20)/($D$24-$D$25)*100 -> 99.172075 | E34: =($D$24-E20)/($D$24-$D$25)*100 -> 91.825762 | F34: =($D$24-F20)/($D$24-$D$25)*100 -> 18.802682 | G34: =($D$24-G20)/($D$24-$D$25)*100 -> 4.3076302 | H34: =($D$24-H20)/($D$24-$D$25)*100 -> -1.7472052 | I34: =($D$24-I20)/($D$24-$D$25)*100 -> -2.1384141 | J34: =($D$24-J20)/($D$24-$D$25)*100 -> -5.3375667 | K34: =($D$24-K20)/($D$24-$D$25)*100 -> -3.5882344 | ... M34: =($D$24-M20)/($D$24-$D$25)*100 -> -2.0895721
B35: G | D35: =($D$24-D21)/($D$24-$D$25)*100 -> 99.271177 | E35: =($D$24-E21)/($D$24-$D$25)*100 -> 92.928489 | F35: =($D$24-F21)/($D$24-$D$25)*100 -> 13.211216 | G35: =($D$24-G21)/($D$24-$D$25)*100 -> -2.4514757 | H35: =($D$24-H21)/($D$24-$D$25)*100 -> -0.78296915 | I35: =($D$24-I21)/($D$24-$D$25)*100 -> -0.88931872 | J35: =($D$24-J21)/($D$24-$D$25)*100 -> 1.0170958 | K35: =($D$24-K21)/($D$24-$D$25)*100 -> -1.7620154 | ... M35: =($D$24-M21)/($D$24-$D$25)*100 -> 0.59453347
B36: H
B38: Plate 2_Plate Map
C39: 1 | D39: 2 | E39: 3 | F39: 4 | G39: 5 | H39: 6 | I39: 7 | J39: 8 | K39: 9 | L39: 10 | M39: 11 | N39: 12
B40: A | C40: Medium | D40: Conc. nM | M40: DMSO
B41: B | D41: 10000 | E41: =D41/3 -> 3333.3333 | F41: =E41/3 -> 1111.1111 | G41: =F41/3 -> 370.37037 | H41: =G41/3 -> 123.45679 | I41: =H41/3 -> 41.152263 | J41: =I41/3 -> 13.717421 | K41: =J41/3 -> 4.5724737 | L41: =K41/3 -> 1.5241579 | M41: 0
B42: C
B43: D | D43: 10000 | E43: =D43/3 -> 3333.3333 | F43: =E43/3 -> 1111.1111 | G43: =F43/3 -> 370.37037 | H43: =G43/3 -> 123.45679 | I43: =H43/3 -> 41.152263 | J43: =I43/3 -> 13.717421 | K43: =J43/3 -> 4.5724737 | L43: =K43/3 -> 1.5241579 | M43: 0
B44: E
...

Sheet IC50 Curve
A1: Title | B1: =Signature!B4 -> HCT116 Cell Proliferation Assay Report
A3: Luminescence
A4: =Summary!B6 -> HW350003A | B4: Inhibition % | G4: Bottom | H4: 1.907
A5: Cpd Conc.(nM) | B5: Data 1 | C5: Data 2 | D5: Mean | E5: SD | G5: Top | H5: 89.87
A6: =OFFSET(INDEX(Summary!B:B,MATCH(A4,Summary!B:B,0),0),0,1) -> 10000 | B6: =OFFSET(INDEX('Raw Data IC50'!$A:$A,MATCH(A4,'Raw Data IC50'!$A:$A,0),0),0,3) -> 90.743517 | C6: =OFFSET(INDEX('Raw Data IC50'!$A:$A,MATCH(A4,'Raw Data IC50'!$A:$A,0),0),1,3) -> 90.072333 | D6: =AVERAGE(B6:C6) -> 90.407925 | E6: =STDEV(B6:C6) -> 0.47459872 | G6: R_IC50 | H6: 34.56
A7: =A6/OFFSET(INDEX(Summary!B:B,MATCH(A4,Summary!B:B,0),0),0,2) -> 3333.3333 | B7: =OFFSET(INDEX('Raw Data IC50'!$A:$A,MATCH(A4,'Raw Data IC50'!$A:$A,0),0),0,4) -> 89.837104 | C7: =OFFSET(INDEX('Raw Data IC50'!$A:$A,MATCH(A4,'Raw Data IC50'!$A:$A,0),0),1,4) -> 90.605657 | D7: =AVERAGE(B7:C7) -> 90.22138 | E7: =STDEV(B7:C7) -> 0.54344895 | G7: A_IC50 | H7: 38.459
A8: =A7/OFFSET(INDEX(Summary!B:B,MATCH(A4,Summary!B:B,0),0),0,2) -> 1111.1111 | B8: =OFFSET(INDEX('Raw Data IC50'!$A:$A,MATCH(A4,'Raw Data IC50'!$A:$A,0),0),0,5) -> 90.253049 | C8: =OFFSET(INDEX('Raw Data IC50'!$A:$A,MATCH(A4,'Raw Data IC50'!$A:$A,0),0),1,5) -> 89.164502 | D8: =AVERAGE(B8:C8) -> 89.708775 | E8: =STDEV(B8:C8) -> 0.7697189
A9: =A8/OFFSET(INDEX(Summary!B:B,MATCH(A4,Summary!B:B,0),0),0,2) -> 370.37037 | B9: =OFFSET(INDEX('Raw Data IC50'!$A:$A,MATCH(A4,'Raw Data IC50'!$A:$A,0),0),0,6) -> 87.925648 | C9: =OFFSET(INDEX('Raw Data IC50'!$A:$A,MATCH(A4,'Raw Data IC50'!$A:$A,0),0),1,6) -> 88.223742 | D9: =AVERAGE(B9:C9) -> 88.074695 | E9: =STDEV(B9:C9) -> 0.21078422
A10: =A9/OFFSET(INDEX(Summary!B:B,MATCH(A4,Summary!B:B,0),0),0,2) -> 123.45679 | B10: =OFFSET(INDEX('Raw Data IC50'!$A:$A,MATCH(A4,'Raw Data IC50'!$A:$A,0),0),0,7) -> 80.257135 | C10: =OFFSET(INDEX('Raw Data IC50'!$A:$A,MATCH(A4,'Raw Data IC50'!$A:$A,0),0),1,7) -> 80.556647 | D10: =AVERAGE(B10:C10) -> 80.406891 | E10: =STDEV(B10:C10) -> 0.21178689
A11: =A10/OFFSET(INDEX(Summary!B:B,MATCH(A4,Summary!B:B,0),0),0,2) -> 41.152263 | B11: =OFFSET(INDEX('Raw Data IC50'!$A:$A,MATCH(A4,'Raw Data IC50'!$A:$A,0),0),0,8) -> 52.525106 | C11: =OFFSET(INDEX('Raw Data IC50'!$A:$A,MATCH(A4,'Raw Data IC50'!$A:$A,0),0),1,8) -> 53.752302 | D11: =AVERAGE(B11:C11) -> 53.138704 | E11: =STDEV(B11:C11) -> 0.86775808
A12: =A11/OFFSET(INDEX(Summary!B:B,MATCH(A4,Summary!B:B,0),0),0,2) -> 13.717421 | B12: =OFFSET(INDEX('Raw Data IC50'!$A:$A,MATCH(A4,'Raw Data IC50'!$A:$A,0),0),0,9) -> 18.423133 | C12: =OFFSET(INDEX('Raw Data IC50'!$A:$A,MATCH(A4,'Raw Data IC50'!$A:$A,0),0),1,9) -> 14.283062 | D12: =AVERAGE(B12:C12) -> 16.353097 | E12: =STDEV(B12:C12) -> 2.9274719
A13: =A12/OFFSET(INDEX(Summary!B:B,MATCH(A4,Summary!B:B,0),0),0,2) -> 4.5724737 | B13: =OFFSET(INDEX('Raw Data IC50'!$A:$A,MATCH(A4,'Raw Data IC50'!$A:$A,0),0),0,10) -> 5.4316269 | C13: =OFFSET(INDEX('Raw Data IC50'!$A:$A,MATCH(A4,'Raw Data IC50'!$A:$A,0),0),1,10) -> -0.15983946 | D13: =AVERAGE(B13:C13) -> 2.6358937 | E13: =STDEV(B13:C13) -> 3.9537638
A14: =A13/OFFSET(INDEX(Summary!B:B,MATCH(A4,Summary!B:B,0),0),0,2) -> 1.5241579 | B14: =OFFSET(INDEX('Raw Data IC50'!$A:$A,MATCH(A4,'Raw Data IC50'!$A:$A,0),0),0,11) -> 3.8990903 | C14: =OFFSET(INDEX('Raw Data IC50'!$A:$A,MATCH(A4,'Raw Data IC50'!$A:$A,0),0),1,11) -> 3.9573856 | D14: =AVERAGE(B14:C14) -> 3.9282379 | E14: =STDEV(B14:C14) -> 0.041221015
A15: =A14/OFFSET(INDEX(Summary!B:B,MATCH(A4,Summary!B:B,0),0),0,2)/10 -> 0.050805263 | B15: =OFFSET(INDEX('Raw Data IC50'!$A:$A,MATCH(A4,'Raw Data IC50'!$A:$A,0),0),0,12) -> 2.845363 | C15: =OFFSET(INDEX('Raw Data IC50'!$A:$A,MATCH(A4,'Raw Data IC50'!$A:$A,0),0),1,12) -> 0.81337725 | D15: =AVERAGE(B15:C15) -> 1.8293701 | E15: =STDEV(B15:C15) -> 1.4368309 | F15: DMSO
A17: Luminescence
A18: =Summary!B7 -> HW356011 | B18: Inhibition % | G18: Bottom | H18: -2.544
A19: Cpd Conc.(nM) | B19: Data 1 | C19: Data 2 | D19: Mean | E19: SD | G19: Top | H19: 98.66
A20: =OFFSET(INDEX(Summary!B:B,MATCH(A18,Summary!B:B,0),0),0,1) -> 10000 | B20: =OFFSET(INDEX('Raw Data IC50'!$A:$A,MATCH(A18,'Raw Data IC50'!$A:$A,0),0),0,3) -> 98.907068 | C20: =OFFSET(INDEX('Raw Data IC50'!$A:$A,MATCH(A18,'Raw Data IC50'!$A:$A,0),0),1,3) -> 98.775509 | D20: =AVERAGE(B20:C20) -> 98.841289 | E20: =STDEV(B20:C20) -> 0.093025805 | G20: R_IC50 | H20: 128.8
A21: =A20/OFFSET(INDEX(Summary!B:B,MATCH(A18,Summary!B:B,0),0),0,2) -> 3333.3333 | B21: =OFFSET(INDEX('Raw Data IC50'!$A:$A,MATCH(A18,'Raw Data IC50'!$A:$A,0),0),0,4) -> 99.014363 | C21: =OFFSET(INDEX('Raw Data IC50'!$A:$A,MATCH(A18,'Raw Data IC50'!$A:$A,0),0),1,4) -> 98.86185 | D21: =AVERAGE(B21:C21) -> 98.938106 | E21: =STDEV(B21:C21) -> 0.10784309 | G21: A_IC50 | H21: 136.1444
A22: =A21/OFFSET(INDEX(Summary!B:B,MATCH(A18,Summary!B:B,0),0),0,2) -> 1111.1111 | B22: =OFFSET(INDEX('Raw Data IC50'!$A:$A,MATCH(A18,'Raw Data IC50'!$A:$A,0),0),0,5) -> 91.623462 | C22: =OFFSET(INDEX('Raw Data IC50'!$A:$A,MATCH(A18,'Raw Data IC50'!$A:$A,0),0),1,5) -> 90.715473 | D22: =AVERAGE(B22:C22) -> 91.169467 | E22: =STDEV(B22:C22) -> 0.64204516
A23: =A22/OFFSET(INDEX(Summary!B:B,MATCH(A18,Summary!B:B,0),0),0,2) -> 370.37037 | B23: =OFFSET(INDEX('Raw Data IC50'!$A:$A,MATCH(A18,'Raw Data IC50'!$A:$A,0),0),0,6) -> 79.63369 | C23: =OFFSET(INDEX('Raw Data IC50'!$A:$A,MATCH(A18,'Raw Data IC50'!$A:$A,0),0),1,6) -> 78.917918 | D23: =AVERAGE(B23:C23) -> 79.275804 | E23: =STDEV(B23:C23) -> 0.50612722
A24: =A23/OFFSET(INDEX(Summary!B:B,MATCH(A18,Summary!B:B,0),0),0,2) -> 123.45679 | B24: =OFFSET(INDEX('Raw Data IC50'!$A:$A,MATCH(A18,'Raw Data IC50'!$A:$A,0),0),0,7) -> 50.755292 | C24: =OFFSET(INDEX('Raw Data IC50'!$A:$A,MATCH(A18,'Raw Data IC50'!$A:$A,0),0),1,7) -> 44.583078 | D24: =AVERAGE(B24:C24) -> 47.669185 | E24: =STDEV(B24:C24) -> 4.3644143
A25: =A24/OFFSET(INDEX(Summary!B:B,MATCH(A18,Summary!B:B,0),0),0,2) -> 41.152263 | B25: =OFFSET(INDEX('Raw Data IC50'!$A:$A,MATCH(A18,'Raw Data IC50'!$A:$A,0),0),0,8) -> 14.096517 | C25: =OFFSET(INDEX('Raw Data IC50'!$A:$A,MATCH(A18,'Raw Data IC50'!$A:$A,0),0),1,8) -> 13.788182 | D25: =AVERAGE(B25:C25) -> 13.94235 | E25: =STDEV(B25:C25) -> 0.21802575
A26: =A25/OFFSET(INDEX(Summary!B:B,MATCH(A18,Summary!B:B,0),0),0,2) -> 13.717421 | B26: =OFFSET(INDEX('Raw Data IC50'!$A:$A,MATCH(A18,'Raw Data IC50'!$A:$A,0),0),0,9) -> 2.6077702 | C26: =OFFSET(INDEX('Raw Data IC50'!$A:$A,MATCH(A18,'Raw Data IC50'!$A:$A,0),0),1,9) -> 0.15920924 | D26: =AVERAGE(B26:C26) -> 1.3834897 | E26: =STDEV(B26:C26) -> 1.731394
A27: =A26/OFFSET(INDEX(Summary!B:B,MATCH(A18,Summary!B:B,0),0),0,2) -> 4.5724737 | B27: =OFFSET(INDEX('Raw Data IC50'!$A:$A,MATCH(A18,'Raw Data IC50'!$A:$A,0),0),0,10) -> 1.8207834 | C27: =OFFSET(INDEX('Raw Data IC50'!$A:$A,MATCH(A18,'Raw Data IC50'!$A:$A,0),0),1,10) -> 0.32306635 | D27: =AVERAGE(B27:C27) -> 1.0719249 | E27: =STDEV(B27:C27) -> 1.0590459
A28: =A27/OFFSET(INDEX(Summary!B:B,MATCH(A18,Summary!B:B,0),0),0,2) -> 1.5241579 | B28: =OFFSET(INDEX('Raw Data IC50'!$A:$A,MATCH(A18,'Raw Data IC50'!$A:$A,0),0),0,11) -> -2.4650254 | C28: =OFFSET(INDEX('Raw Data IC50'!$A:$A,MATCH(A18,'Raw Data IC50'!$A:$A,0),0),1,11) -> -4.8458378 | D28: =AVERAGE(B28:C28) -> -3.6554316 | E28: =STDEV(B28:C28) -> 1.6834885
A29: =A28/OFFSET(INDEX(Summary!B:B,MATCH(A18,Summary!B:B,0),0),0,2)/10 -> 0.050805263 | B29: =OFFSET(INDEX('Raw Data IC50'!$A:$A,MATCH(A18,'Raw Data IC50'!$A:$A,0),0),0,12) -> 0.86347972 | C29: =OFFSET(INDEX('Raw Data IC50'!$A:$A,MATCH(A18,'Raw Data IC50'!$A:$A,0),0),1,12) -> -3.0271814 | D29: =AVERAGE(B29:C29) -> -1.0818508 | E29: =STDEV(B29:C29) -> 2.7511128 | F29: DMSO
A31: Luminescence
A32: =Summary!B8 -> HW356012 | B32: Inhibition % | G32: Bottom | H32: -1.555
A33: Cpd Conc.(nM) | B33: Data 1 | C33: Data 2 | D33: Mean | E33: SD | G33: Top | H33: 99.44
A34: =OFFSET(INDEX(Summary!B:B,MATCH(A32,Summary!B:B,0),0),0,1) -> 10000 | B34: =OFFSET(INDEX('Raw Data IC50'!$A:$A,MATCH(A32,'Raw Data IC50'!$A:$A,0),0),0,3) -> 99.172075 | C34: =OFFSET(INDEX('Raw Data IC50'!$A:$A,MATCH(A32,'Raw Data IC50'!$A:$A,0),0),1,3) -> 99.271177 | D34: =AVERAGE(B34:C34) -> 99.221626 | E34: =STDEV(B34:C34) -> 0.070075726 | G34: R_IC50 | H34: 1680
A35: =A34/OFFSET(INDEX(Summary!B:B,MATCH(A32,Summary!B:B,0),0),0,2) -> 3333.3333 | B35: =OFFSET(INDEX('Raw Data IC50'!$A:$A,MATCH(A32,'Raw Data IC50'!$A:$A,0),0),0,4) -> 91.825762 | C35: =OFFSET(INDEX('Raw Data IC50'!$A:$A,MATCH(A32,'Raw Data IC50'!$A:$A,0),0),1,4) -> 92.928489 | D35: =AVERAGE(B35:C35) -> 92.377126 | E35: =STDEV(B35:C35) -> 0.77974564 | G35: A_IC50 | H35: 1698.243
A36: =A35/OFFSET(INDEX(Summary!B:B,MATCH(A32,Summary!B:B,0),0),0,2) -> 1111.1111 | B36: =OFFSET(INDEX('Raw Data IC50'!$A:$A,MATCH(A32,'Raw Data IC50'!$A:$A,0),0),0,5) -> 18.802682 | C36: =OFFSET(INDEX('Raw Data IC50'!$A:$A,MATCH(A32,'Raw Data IC50'!$A:$A,0),0),1,5) -> 13.211216 | D36: =AVERAGE(B36:C36) -> 16.006949 | E36: =STDEV(B36:C36) -> 3.9537638
A37: =A36/OFFSET(INDEX(Summary!B:B,MATCH(A32,Summary!B:B,0),0),0,2) -> 370.37037 | B37: =OFFSET(INDEX('Raw Data IC50'!$A:$A,MATCH(A32,'Raw Data IC50'!$A:$A,0),0),0,6) -> 4.3076302 | C37: =OFFSET(INDEX('Raw Data IC50'!$A:$A,MATCH(A32,'Raw Data IC50'!$A:$A,0),0),1,6) -> -2.4514757 | D37: =AVERAGE(B37:C37) -> 0.92807723 | E37: =STDEV(B37:C37) -> 4.7794096
A38: =A37/OFFSET(INDEX(Summary!B:B,MATCH(A32,Summary!B:B,0),0),0,2) -> 123.45679 | B38: =OFFSET(INDEX('Raw Data IC50'!$A:$A,MATCH(A32,'Raw Data IC50'!$A:$A,0),0),0,7) -> -1.7472052 | C38: =OFFSET(INDEX('Raw Data IC50'!$A:$A,MATCH(A32,'Raw Data IC50'!$A:$A,0),0),1,7) -> -0.78296915 | D38: =AVERAGE(B38:C38) -> -1.2650872 | E38: =STDEV(B38:C38) -> 0.68181787
A39: =A38/OFFSET(INDEX(Summary!B:B,MATCH(A32,Summary!B:B,0),0),0,2) -> 41.152263 | B39: =OFFSET(INDEX('Raw Data IC50'!$A:$A,MATCH(A32,'Raw Data IC50'!$A:$A,0),0),0,8) -> -2.1384141 | C39: =OFFSET(INDEX('Raw Data IC50'!$A:$A,MATCH(A32,'Raw Data IC50'!$A:$A,0),0),1,8) -> -0.88931872 | D39: =AVERAGE(B39:C39) -> -1.5138664 | E39: =STDEV(B39:C39) -> 0.88324381
A40: =A39/OFFSET(INDEX(Summary!B:B,MATCH(A32,Summary!B:B,0),0),0,2) -> 13.717421 | B40: =OFFSET(INDEX('Raw Data IC50'!$A:$A,MATCH(A32,'Raw Data IC50'!$A:$A,0),0),0,9) -> -5.3375667 | C40: =OFFSET(INDEX('Raw Data IC50'!$A:$A,MATCH(A32,'Raw Data IC50'!$A:$A,0),0),1,9) -> 1.0170958 | D40: =AVERAGE(B40:C40) -> -2.1602355 | E40: =STDEV(B40:C40) -> 4.4934249
A41: =A40/OFFSET(INDEX(Summary!B:B,MATCH(A32,Summary!B:B,0),0),0,2) -> 4.5724737 | B41: =OFFSET(INDEX('Raw Data IC50'!$A:$A,MATCH(A32,'Raw Data IC50'!$A:$A,0),0),0,10) -> -3.5882344 | C41: =OFFSET(INDEX('Raw Data IC50'!$A:$A,MATCH(A32,'Raw Data IC50'!$A:$A,0),0),1,10) -> -1.7620154 | D41: =AVERAGE(B41:C41) -> -2.6751249 | E41: =STDEV(B41:C41) -> 1.2913319
A42: =A41/OFFSET(INDEX(Summary!B:B,MATCH(A32,Summary!B:B,0),0),0,2) -> 1.5241579 | B42: =OFFSET(INDEX('Raw Data IC50'!$A:$A,MATCH(A32,'Raw Data IC50'!$A:$A,0),0),0,11) -> -2.5133948 | C42: =OFFSET(INDEX('Raw Data IC50'!$A:$A,MATCH(A32,'Raw Data IC50'!$A:$A,0),0),1,11) -> -1.9061781 | D42: =AVERAGE(B42:C42) -> -2.2097865 | E42: =STDEV(B42:C42) -> 0.42936701
A43: =A42/OFFSET(INDEX(Summary!B:B,MATCH(A32,Summary!B:B,0),0),0,2)/10 -> 0.050805263 | B43: =OFFSET(INDEX('Raw Data IC50'!$A:$A,MATCH(A32,'Raw Data IC50'!$A:$A,0),0),0,12) -> -2.0895721 | C43: =OFFSET(INDEX('Raw Data IC50'!$A:$A,MATCH(A32,'Raw Data IC50'!$A:$A,0),0),1,12) -> 0.59453347 | D43: =AVERAGE(B43:C43) -> -0.7475193 | E43: =STDEV(B43:C43) -> 1.8979492 | F43: DMSO
...
